Workbook

Sheet Neighbors-by-O-OOS
B1: FULLNAME | C1: Alabama | D1: Alaska | E1: Arizona | F1: Arkansas | G1: California | H1: Colorado | I1: Connecticut | J1: Delaware | K1: Distict-of-Columbia | L1: Florida | M1: Georgia | N1: Hawaii | O1: Idaho | P1: Illinois | Q1: Indiana | R1: Iowa | S1: Kansas | T1: Kentucky | U1: Louisiana | V1: Maine | W1: Maryland | X1: Massachusetts | Y1: Michigan | Z1: Minnesota | AA1: Mississippi | AB1: Missouri | AC1: Montana | AD1: Nebraska | AE1: Nevada | AF1: New-Hampshire | AG1: New-Jersey | AH1: New-Mexico | AI1: New-York | AJ1: North-Carolina | AK1: North-Dakota | AL1: Ohio | AM1: Oklahoma | AN1: Oregon | AO1: Pennsylvania | AP1: Rhode-Island | AQ1: South-Carolina | AR1: South-Dakota | AS1: Tennessee | AT1: Texas | AU1: Utah | AV1: Vermont | AW1: Virginia | AX1: Washington | AY1: West-Virginia | AZ1: Wisconsin | BA1: Wyoming
B2: TollShare | C2: 0 | D2: 0.062887408 | E2: 0 | F2: 0 | G2: 0.021141521 | H2: 0.0029577777 | I2: 0.00025988579 | J2: 0.25259005 | K2: 0 | L2: 0.077833555 | M2: 0.0041858291 | N2: 0 | O2: 0.001073349 | P2: 0 | Q2: 0.092502027 | R2: 0.042572953 | S2: 0.064564023 | T2: 0.008453283 | U2: 0.029383964 | V2: 0.10508832 | W2: 0.070257916 | X2: 0.10394482 | Y2: 0.0073878771 | Z2: 0 | AA2: 0 | AB2: 0.0007596858 | AC2: 0 | AD2: 0.0019950831 | AE2: 0 | AF2: 0.11777737 | AG2: 0.27330336 | AH2: 0 | AI2: 0.33182204 | AJ2: 0.00073844304 | AK2: 0 | AL2: 0.032875764 | AM2: 0.075978257 | AN2: 0.0052990403 | AO2: 0.11697723 | AP2: 0.037366118 | AQ2: 0 | AR2: 0 | AS2: 5.8005165e-05 | AT2: 0.024747469 | AU2: 0.0006229862 | AV2: 0 | AW2: 0.046528368 | AX2: 0.04142763 | AY2: 0.065724566 | AZ2: 1.1333251e-05 | BA2: 0 | BF2: Vistors to State by Origin | BH2: Destinations by Residents of | BK2: Visitors | BL2: Residents
A3: FULLNAME | B3: TollShare | C3: Alabama | D3: Alaska | E3: Arizona | F3: Arkansas | G3: California | H3: Colorado | I3: Connecticut | J3: Delaware | K3: Distict-of-Columbia | L3: Florida | M3: Georgia | N3: Hawaii | O3: Idaho | P3: Illinois | Q3: Indiana | R3: Iowa | S3: Kansas | T3: Kentucky | U3: Louisiana | V3: Maine | W3: Maryland | X3: Massachusetts | Y3: Michigan | Z3: Minnesota | AA3: Mississippi | AB3: Missouri | AC3: Montana | AD3: Nebraska | AE3: Nevada | AF3: New-Hampshire | AG3: New-Jersey | AH3: New-Mexico | AI3: New-York | AJ3: North-Carolina | AK3: North-Dakota | AL3: Ohio | AM3: Oklahoma | AN3: Oregon | AO3: Pennsylvania | AP3: Rhode-Island | AQ3: South-Carolina | AR3: South-Dakota | AS3: Tennessee | AT3: Texas | AU3: Utah | AV3: Vermont | AW3: Virginia | AX3: Washington | AY3: West-Virginia | AZ3: Wisconsin | BA3: Wyoming | BB3: TOTAL | BC3: TOTAL/TOTALTRIPS | BD3: TOTAL/TOTAL-OOS | BE3: STATE | BF3: In-State | BG3: Out-of-State | BH3: In-State | BI3: Out-Of-Staet | BK3: Visitors In-State Ratio | BL3: Residents In-State Ratio | BM3: STATE
A4: Alabama | B4: 0 | D4: =D$2*TripTable!C2 -> 0.56598667 | E4: =E$2*TripTable!D2 -> 0 | F4: =F$2*TripTable!E2 -> 0 | G4: =G$2*TripTable!F2 -> 3.2135112 | H4: =H$2*TripTable!G2 -> 0.14788888 | I4: =I$2*TripTable!H2 -> 0.0025988579 | J4: =J$2*TripTable!I2 -> 1.2629502 | K4: =K$2*TripTable!J2 -> 0 | ... BA4: =BA$2*TripTable!AZ2 -> 0 | BB4: =SUM(C4:BA4) -> 252.87588 | BC4: =BB4/TripTable!BA2 -> 0.014599381 | BD4: =BB4/BG4 -> 0.026365956 | BE4: AL | BF4: 7205 | BG4: 9591 | BH4: 7205 | BI4: 9734 | BK4: 0.42897118 | BL4: 0.42534978 | BM4: AL
A5: Alaska | B5: 0.062887408 | C5: =C$2*TripTable!B3 -> 0 | E5: =E$2*TripTable!D3 -> 0 | F5: =F$2*TripTable!E3 -> 0 | G5: =G$2*TripTable!F3 -> 2.0718691 | H5: =H$2*TripTable!G3 -> 0.065071109 | I5: =I$2*TripTable!H3 -> 0.0015593147 | J5: =J$2*TripTable!I3 -> 0 | K5: =K$2*TripTable!J3 -> 0 | L5: =L$2*TripTable!K3 -> 1.2453369 | ... BA5: =BA$2*TripTable!AZ3 -> 0 | BB5: =SUM(C5:BA5) -> 16.927928 | BC5: =BB5/TripTable!BA3 -> 0.0069805889 | BD5: =BB5/BG5 -> 0.0028808591 | BE5: AK | BF5: 4485 | BG5: 5876 | BH5: 1798 | BI5: 636 | BK5: 0.59144737 | BL5: 0.73870173 | BM5: AK
A6: Arizona | B6: 0 | C6: =C$2*TripTable!B4 -> 0 | D6: =D$2*TripTable!C4 -> 2.4526089 | F6: =F$2*TripTable!E4 -> 0 | G6: =G$2*TripTable!F4 -> 86.172841 | H6: =H$2*TripTable!G4 -> 1.0233911 | I6: =I$2*TripTable!H4 -> 0.0070169162 | J6: =J$2*TripTable!I4 -> 1.2629502 | K6: =K$2*TripTable!J4 -> 0 | L6: =L$2*TripTable!K4 -> 7.3163541 | M6: =M$2*TripTable!L4 -> 0.21347728 | ... BA6: =BA$2*TripTable!AZ4 -> 0 | BB6: =SUM(C6:BA6) -> 197.02356 | BC6: =BB6/TripTable!BA4 -> 0.010104291 | BD6: =BB6/BG6 -> 0.018853929 | BE6: AR | BF6: 10895 | BG6: 10450 | BH6: 4485 | BI6: 5856 | BK6: 0.43287327 | BL6: 0.43371047 | BM6: AR
A7: Arkansas | B7: 0 | C7: =C$2*TripTable!B5 -> 0 | D7: =D$2*TripTable!C5 -> 1.5092978 | E7: =E$2*TripTable!D5 -> 0 | G7: =G$2*TripTable!F5 -> 2.0507276 | H7: =H$2*TripTable!G5 -> 0.31352444 | I7: =I$2*TripTable!H5 -> 0.0015593147 | J7: =J$2*TripTable!I5 -> 0 | K7: =K$2*TripTable!J5 -> 0 | L7: =L$2*TripTable!K5 -> 12.375535 | M7: =M$2*TripTable!L5 -> 0.30556552 | N7: =N$2*TripTable!M5 -> 0 | ... BA7: =BA$2*TripTable!AZ5 -> 0 | BB7: =SUM(C7:BA7) -> 155.15035 | BC7: =BB7/TripTable!BA5 -> 0.015083643 | BD7: =BB7/BG7 -> 0.0063479542 | BE7: AZ | BF7: 64843 | BG7: 24441 | BH7: 10895 | BI7: 8689 | BK7: 0.51042399 | BL7: 0.55632149 | BM7: AZ
A8: California | B8: 0.021141521 | C8: =C$2*TripTable!B6 -> 0 | D8: =D$2*TripTable!C6 -> 6.3516282 | E8: =E$2*TripTable!D6 -> 0 | F8: =F$2*TripTable!E6 -> 0 | H8: =H$2*TripTable!G6 -> 4.164551 | I8: =I$2*TripTable!H6 -> 0.049378299 | J8: =J$2*TripTable!I6 -> 3.2836706 | K8: =K$2*TripTable!J6 -> 0 | L8: =L$2*TripTable!K6 -> 73.864043 | M8: =M$2*TripTable!L6 -> 1.3185362 | N8: =N$2*TripTable!M6 -> 0 | O8: =O$2*TripTable!N6 -> 0.35313182 | ... BA8: =BA$2*TripTable!AZ6 -> 0 | BB8: =SUM(C8:BA8) -> 982.09448 | BC8: =BB8/TripTable!BA6 -> 0.0096336663 | BD8: =BB8/BG8 -> 0.088973952 | BE8: CA | BF8: 6982 | BG8: 11038 | BH8: 64843 | BI8: 37526 | BK8: 0.72625554 | BL8: 0.63342418 | BM8: CA
A9: Colorado | B9: 0.0029577777 | C9: =C$2*TripTable!B7 -> 0 | D9: =D$2*TripTable!C7 -> 2.7041585 | E9: =E$2*TripTable!D7 -> 0 | F9: =F$2*TripTable!E7 -> 0 | G9: =G$2*TripTable!F7 -> 22.156314 | I9: =I$2*TripTable!H7 -> 0.0033785152 | J9: =J$2*TripTable!I7 -> 0.25259005 | K9: =K$2*TripTable!J7 -> 0 | L9: =L$2*TripTable!K7 -> 24.51757 | M9: =M$2*TripTable!L7 -> 0.5902019 | N9: =N$2*TripTable!M7 -> 0 | O9: =O$2*TripTable!N7 -> 0.084794572 | P9: =P$2*TripTable!O7 -> 0 | ... BA9: =BA$2*TripTable!AZ7 -> 0 | BB9: =SUM(C9:BA9) -> 235.29698 | BC9: =BB9/TripTable!BA7 -> 0.014779033 | BD9: =BB9/BG9 -> 0.032917876 | BE9: CO | BF9: 177 | BG9: 7148 | BH9: 6982 | BI9: 9048 | BK9: 0.38745838 | BL9: 0.43555833 | BM9: CO
A10: Connecticut | B10: 0.00025988579 | C10: =C$2*TripTable!B8 -> 0 | D10: =D$2*TripTable!C8 -> 0.8175363 | E10: =E$2*TripTable!D8 -> 0 | F10: =F$2*TripTable!E8 -> 0 | G10: =G$2*TripTable!F8 -> 4.1437382 | H10: =H$2*TripTable!G8 -> 0.19521333 | J10: =J$2*TripTable!I8 -> 12.882092 | K10: =K$2*TripTable!J8 -> 0 | L10: =L$2*TripTable!K8 -> 54.483488 | M10: =M$2*TripTable!L8 -> 0.43951205 | N10: =N$2*TripTable!M8 -> 0 | O10: =O$2*TripTable!N8 -> 0.0053667451 | P10: =P$2*TripTable!O8 -> 0 | Q10: =Q$2*TripTable!P8 -> 2.7750608 | ... BA10: =BA$2*TripTable!AZ8 -> 0 | BB10: =SUM(C10:BA10) -> 1494.7062 | BC10: =BB10/TripTable!BA8 -> 0.12651991 | BD10: =BB10/BG10 -> 0.29125218 | BE10: CT | BF10: 82 | BG10: 5132 | BH10: 177 | BI10: 11859 | BK10: 0.024163823 | BL10: 0.014705882 | BM10: CT
A11: Delaware | B11: 0.25259005 | C11: =C$2*TripTable!B9 -> 0 | D11: =D$2*TripTable!C9 -> 0.12577482 | E11: =E$2*TripTable!D9 -> 0 | F11: =F$2*TripTable!E9 -> 0 | G11: =G$2*TripTable!F9 -> 0.5919626 | H11: =H$2*TripTable!G9 -> 0.029577777 | I11: =I$2*TripTable!H9 -> 0.0083163451 | K11: =K$2*TripTable!J9 -> 0 | L11: =L$2*TripTable!K9 -> 7.861189 | M11: =M$2*TripTable!L9 -> 0.12138904 | N11: =N$2*TripTable!M9 -> 0 | O11: =O$2*TripTable!N9 -> 0.001073349 | P11: =P$2*TripTable!O9 -> 0 | Q11: =Q$2*TripTable!P9 -> 1.1100243 | R11: =R$2*TripTable!Q9 -> 0.12771886 | ... BA11: =BA$2*TripTable!AZ9 -> 0 | BB11: =SUM(C11:BA11) -> 246.92029 | BC11: =BB11/TripTable!BA9 -> 0.11213456 | BD11: =BB11/BG11 -> 0.0070425912 | BE11: DE | BF11: 24083 | BG11: 35061 | BH11: 82 | BI11: 2198 | BK11: 0.015726889 | BL11: 0.035964912 | BM11: DE
A12: Distict-of-Columbia | B12: 0 | C12: =C$2*TripTable!B10 -> 0 | D12: =D$2*TripTable!C10 -> 0.062887408 | E12: =E$2*TripTable!D10 -> 0 | F12: =F$2*TripTable!E10 -> 0 | G12: =G$2*TripTable!F10 -> 1.9661615 | H12: =H$2*TripTable!G10 -> 0.070986665 | I12: =I$2*TripTable!H10 -> 0.011434975 | J12: =J$2*TripTable!I10 -> 26.016775 | L12: =L$2*TripTable!K10 -> 8.0946897 | M12: =M$2*TripTable!L10 -> 0.2009198 | N12: =N$2*TripTable!M10 -> 0 | O12: =O$2*TripTable!N10 -> 0.001073349 | P12: =P$2*TripTable!O10 -> 0 | Q12: =Q$2*TripTable!P10 -> 1.1100243 | R12: =R$2*TripTable!Q10 -> 0.085145906 | S12: =S$2*TripTable!R10 -> 0.25825609 | ... BA12: =BA$2*TripTable!AZ10 -> 0 | BB12: =SUM(C12:BA12) -> 258.77922 | BC12: =BB12/TripTable!BA10 -> 0.11897895 | BD12: =BB12/BG12 -> 0.013488622 | BE12: DC | BF12: 9448 | BG12: 19185 | BM12: DC
A13: Florida | B13: 0.077833555 | C13: =C$2*TripTable!B11 -> 0 | D13: =D$2*TripTable!C11 -> 5.2196549 | E13: =E$2*TripTable!D11 -> 0 | F13: =F$2*TripTable!E11 -> 0 | G13: =G$2*TripTable!F11 -> 14.143678 | H13: =H$2*TripTable!G11 -> 0.64775331 | I13: =I$2*TripTable!H11 -> 0.063931903 | J13: =J$2*TripTable!I11 -> 13.387273 | K13: =K$2*TripTable!J11 -> 0 | M13: =M$2*TripTable!L11 -> 13.821608 | N13: =N$2*TripTable!M11 -> 0 | O13: =O$2*TripTable!N11 -> 0.016100235 | P13: =P$2*TripTable!O11 -> 0 | Q13: =Q$2*TripTable!P11 -> 23.310511 | R13: =R$2*TripTable!Q11 -> 3.1078256 | S13: =S$2*TripTable!R11 -> 3.3573292 | T13: =T$2*TripTable!S11 -> 2.7135038 | ... BA13: =BA$2*TripTable!AZ11 -> 0 | BB13: =SUM(C13:BA13) -> 949.90584 | BC13: =BB13/TripTable!BA11 -> 0.022298259 | BD13: =BB13/BG13 -> 0.28741478 | BE13: FL | BF13: 1322 | BG13: 3305 | BH13: 24083 | BI13: 18841 | BK13: 0.40719261 | BL13: 0.56106141 | BM13: FL
A14: Georgia | B14: 0.0041858291 | C14: =C$2*TripTable!B12 -> 0 | D14: =D$2*TripTable!C12 -> 1.2577482 | E14: =E$2*TripTable!D12 -> 0 | F14: =F$2*TripTable!E12 -> 0 | G14: =G$2*TripTable!F12 -> 6.4693055 | H14: =H$2*TripTable!G12 -> 0.2514111 | I14: =I$2*TripTable!H12 -> 0.020011205 | J14: =J$2*TripTable!I12 -> 1.2629502 | ... L14: =L$2*TripTable!K12 -> 355.54368 | N14: =N$2*TripTable!M12 -> 0 | O14: =O$2*TripTable!N12 -> 0.0085867921 | P14: =P$2*TripTable!O12 -> 0 | Q14: =Q$2*TripTable!P12 -> 17.297879 | R14: =R$2*TripTable!Q12 -> 0.7237402 | S14: =S$2*TripTable!R12 -> 0.5810762 | T14: =T$2*TripTable!S12 -> 2.299293 | U14: =U$2*TripTable!T12 -> 8.3156619 | ... BA14: =BA$2*TripTable!AZ12 -> 0 | BB14: =SUM(C14:BA14) -> 629.94876 | BC14: =BB14/TripTable!BA12 -> 0.022869804 | BD14: =BB14/BG14 -> 0.17099586 | BE14: GA | BF14: 3077 | BG14: 3684 | BH14: 9448 | BI14: 18337 | BK14: 0.32996892 | BL14: 0.34003959 | BM14: GA
A15: Hawaii | B15: 0 | C15: =C$2*TripTable!B13 -> 0 | D15: =D$2*TripTable!C13 -> 0.62887408 | E15: =E$2*TripTable!D13 -> 0 | F15: =F$2*TripTable!E13 -> 0 | G15: =G$2*TripTable!F13 -> 4.4397195 | H15: =H$2*TripTable!G13 -> 0.047324443 | I15: =I$2*TripTable!H13 -> 0 | J15: =J$2*TripTable!I13 -> 0.25259005 | ... M15: =M$2*TripTable!L13 -> 0.016743316 | O15: =O$2*TripTable!N13 -> 0.004293396 | P15: =P$2*TripTable!O13 -> 0 | Q15: =Q$2*TripTable!P13 -> 0.83251825 | R15: =R$2*TripTable!Q13 -> 0.042572953 | S15: =S$2*TripTable!R13 -> 0.064564023 | T15: =T$2*TripTable!S13 -> 0.016906566 | U15: =U$2*TripTable!T13 -> 0.11753586 | V15: =V$2*TripTable!U13 -> 0.31526496 | ... BA15: =BA$2*TripTable!AZ13 -> 0 | BB15: =SUM(C15:BA15) -> 22.646331 | BC15: =BB15/TripTable!BA13 -> 0.010913895 | BD15: =BB15/BG15 -> 0.0010718635 | BE15: HI | BF15: 11964 | BG15: 21128 | BH15: 1322 | BI15: 765 | BK15: 0.28571429 | BL15: 0.63344514 | BM15: HI
A16: Idaho | B16: 0.001073349 | C16: =C$2*TripTable!B14 -> 0 | D16: =D$2*TripTable!C14 -> 0.94331112 | E16: =E$2*TripTable!D14 -> 0 | F16: =F$2*TripTable!E14 -> 0 | G16: =G$2*TripTable!F14 -> 6.976702 | H16: =H$2*TripTable!G14 -> 0.24253777 | I16: =I$2*TripTable!H14 -> 0.00077965736 | J16: =J$2*TripTable!I14 -> 0.25259005 | ... N16: =N$2*TripTable!M14 -> 0 | P16: =P$2*TripTable!O14 -> 0 | Q16: =Q$2*TripTable!P14 -> 0.55501216 | R16: =R$2*TripTable!Q14 -> 0.68116725 | S16: =S$2*TripTable!R14 -> 0.32282011 | T16: =T$2*TripTable!S14 -> 0.016906566 | U16: =U$2*TripTable!T14 -> 0.23507171 | V16: =V$2*TripTable!U14 -> 0 | W16: =W$2*TripTable!V14 -> 0.21077375 | ... BA16: =BA$2*TripTable!AZ14 -> 0 | BB16: =SUM(C16:BA16) -> 54.423988 | BC16: =BB16/TripTable!BA14 -> 0.0079742106 | BD16: =BB16/BG16 -> 0.0046318287 | BE16: ID | BF16: 8278 | BG16: 11750 | BH16: 3077 | BI16: 3761 | BK16: 0.45511019 | BL16: 0.44998538 | BM16: ID
A17: Illinois | B17: 0 | C17: =C$2*TripTable!B15 -> 0 | D17: =D$2*TripTable!C15 -> 3.1443704 | E17: =E$2*TripTable!D15 -> 0 | F17: =F$2*TripTable!E15 -> 0 | G17: =G$2*TripTable!F15 -> 20.401568 | H17: =H$2*TripTable!G15 -> 1.0884622 | I17: =I$2*TripTable!H15 -> 0.0054576015 | J17: =J$2*TripTable!I15 -> 0 | ... O17: =O$2*TripTable!N15 -> 0.018246933 | Q17: =Q$2*TripTable!P15 -> 279.07862 | R17: =R$2*TripTable!Q15 -> 45.382768 | S17: =S$2*TripTable!R15 -> 19.433771 | T17: =T$2*TripTable!S15 -> 5.5960733 | U17: =U$2*TripTable!T15 -> 3.4379238 | V17: =V$2*TripTable!U15 -> 11.980068 | W17: =W$2*TripTable!V15 -> 4.8477962 | X17: =X$2*TripTable!W15 -> 10.602371 | ... BA17: =BA$2*TripTable!AZ15 -> 0 | BB17: =SUM(C17:BA17) -> 996.54119 | BC17: =BB17/TripTable!BA15 -> 0.025267912 | BD17: =BB17/BG17 -> 0.15619768 | BE17: IL | BF17: 5811 | BG17: 6380 | BH17: 11964 | BI17: 27788 | BK17: 0.36153753 | BL17: 0.30096599 | BM17: IL
A18: Indiana | B18: 0.092502027 | C18: =C$2*TripTable!B16 -> 0 | D18: =D$2*TripTable!C16 -> 1.1319733 | E18: =E$2*TripTable!D16 -> 0 | F18: =F$2*TripTable!E16 -> 0 | G18: =G$2*TripTable!F16 -> 3.6152001 | H18: =H$2*TripTable!G16 -> 0.44662443 | I18: =I$2*TripTable!H16 -> 0.0088361167 | J18: =J$2*TripTable!I16 -> 1.7681303 | ... P18: =P$2*TripTable!O16 -> 0 | R18: =R$2*TripTable!Q16 -> 5.3216191 | S18: =S$2*TripTable!R16 -> 2.7116889 | T18: =T$2*TripTable!S16 -> 14.446661 | U18: =U$2*TripTable!T16 -> 1.4398143 | V18: =V$2*TripTable!U16 -> 1.3661481 | W18: =W$2*TripTable!V16 -> 2.8805746 | X18: =X$2*TripTable!W16 -> 7.2761371 | Y18: =Y$2*TripTable!X16 -> 15.13776 | ... BA18: =BA$2*TripTable!AZ16 -> 0 | BB18: =SUM(C18:BA18) -> 300.08679 | BC18: =BB18/TripTable!BA16 -> 0.013673249 | BD18: =BB18/BG18 -> 0.050957173 | BE18: IN | BF18: 4560 | BG18: 5889 | BH18: 8278 | BI18: 13821 | BK18: 0.41332135 | BL18: 0.37458709 | BM18: IN
A19: Iowa | B19: 0.042572953 | C19: =C$2*TripTable!B17 -> 0 | D19: =D$2*TripTable!C17 -> 0.69176149 | E19: =E$2*TripTable!D17 -> 0 | F19: =F$2*TripTable!E17 -> 0 | G19: =G$2*TripTable!F17 -> 4.947116 | H19: =H$2*TripTable!G17 -> 0.79859998 | I19: =I$2*TripTable!H17 -> 0.0012994289 | J19: =J$2*TripTable!I17 -> 2.7784905 | ... Q19: =Q$2*TripTable!P17 -> 17.390381 | S19: =S$2*TripTable!R17 -> 12.52542 | T19: =T$2*TripTable!S17 -> 0.21978536 | U19: =U$2*TripTable!T17 -> 0.73459911 | V19: =V$2*TripTable!U17 -> 0.10508832 | W19: =W$2*TripTable!V17 -> 0.70257916 | X19: =X$2*TripTable!W17 -> 1.143393 | Y19: =Y$2*TripTable!X17 -> 0.64274531 | Z19: =Z$2*TripTable!Y17 -> 0 | ... BA19: =BA$2*TripTable!AZ17 -> 0 | BB19: =SUM(C19:BA19) -> 100.96204 | BC19: =BB19/TripTable!BA17 -> 0.0079372675 | BD19: =BB19/BG19 -> 0.011856963 | BE19: IO | BF19: 5574 | BG19: 8515 | BH19: 5811 | BI19: 6939 | BK19: 0.47666311 | BL19: 0.45576471 | BM19: IO
A20: Kansas | B20: 0.064564023 | C20: =C$2*TripTable!B18 -> 0 | D20: =D$2*TripTable!C18 -> 0.62887408 | E20: =E$2*TripTable!D18 -> 0 | F20: =F$2*TripTable!E18 -> 0 | G20: =G$2*TripTable!F18 -> 3.9111814 | H20: =H$2*TripTable!G18 -> 2.487491 | I20: =I$2*TripTable!H18 -> 0.0012994289 | J20: =J$2*TripTable!I18 -> 0 | ... R20: =R$2*TripTable!Q18 -> 10.770957 | T20: =T$2*TripTable!S18 -> 0.32122475 | U20: =U$2*TripTable!T18 -> 1.1459746 | V20: =V$2*TripTable!U18 -> 0.52544159 | W20: =W$2*TripTable!V18 -> 1.1241267 | X20: =X$2*TripTable!W18 -> 2.286786 | Y20: =Y$2*TripTable!X18 -> 0.49498777 | Z20: =Z$2*TripTable!Y18 -> 0 | AA20: =AA$2*TripTable!Z18 -> 0 | ... BA20: =BA$2*TripTable!AZ18 -> 0 | BB20: =SUM(C20:BA20) -> 166.68283 | BC20: =BB20/TripTable!BA18 -> 0.013774302 | BD20: =BB20/BG20 -> 0.016156134 | BE20: KS | BF20: 6052 | BG20: 10317 | BH20: 4560 | BI20: 7596 | BK20: 0.4364054 | BL20: 0.3751234 | BM20: KS
A21: Kentucky | B21: 0.008453283 | C21: =C$2*TripTable!B19 -> 0 | D21: =D$2*TripTable!C19 -> 0.12577482 | E21: =E$2*TripTable!D19 -> 0 | F21: =F$2*TripTable!E19 -> 0 | G21: =G$2*TripTable!F19 -> 2.4946995 | H21: =H$2*TripTable!G19 -> 0.13901555 | I21: =I$2*TripTable!H19 -> 0.00051977157 | J21: =J$2*TripTable!I19 -> 0.5051801 | ... S21: =S$2*TripTable!R19 -> 2.1306127 | U21: =U$2*TripTable!T19 -> 1.616118 | V21: =V$2*TripTable!U19 -> 1.4712365 | W21: =W$2*TripTable!V19 -> 4.2857329 | X21: =X$2*TripTable!W19 -> 2.5986204 | Y21: =Y$2*TripTable!X19 -> 2.5488176 | Z21: =Z$2*TripTable!Y19 -> 0 | AA21: =AA$2*TripTable!Z19 -> 0 | AB21: =AB$2*TripTable!AA19 -> 0.30843243 | ... BA21: =BA$2*TripTable!AZ19 -> 0 | BB21: =SUM(C21:BA21) -> 383.23369 | BC21: =BB21/TripTable!BA19 -> 0.024605695 | BD21: =BB21/BG21 -> 0.027568786 | BE21: KY | BF21: 2722 | BG21: 13901 | BH21: 5574 | BI21: 10081 | BK21: 0.39562779 | BL21: 0.35605238 | BM21: KY
A22: Louisiana | B22: 0.029383964 | C22: =C$2*TripTable!B20 -> 0 | D22: =D$2*TripTable!C20 -> 0.62887408 | E22: =E$2*TripTable!D20 -> 0 | F22: =F$2*TripTable!E20 -> 0 | G22: =G$2*TripTable!F20 -> 3.446068 | H22: =H$2*TripTable!G20 -> 0.28098888 | I22: =I$2*TripTable!H20 -> 0.0057174873 | J22: =J$2*TripTable!I20 -> 0 | ... T22: =T$2*TripTable!S20 -> 0.28741162 | V22: =V$2*TripTable!U20 -> 0.94579487 | W22: =W$2*TripTable!V20 -> 2.3887691 | X22: =X$2*TripTable!W20 -> 2.0788963 | Y22: =Y$2*TripTable!X20 -> 0.31767872 | Z22: =Z$2*TripTable!Y20 -> 0 | AA22: =AA$2*TripTable!Z20 -> 0 | AB22: =AB$2*TripTable!AA20 -> 0.15041779 | AC22: =AC$2*TripTable!AB20 -> 0 | ... BA22: =BA$2*TripTable!AZ20 -> 0 | BB22: =SUM(C22:BA22) -> 221.59007 | BC22: =BB22/TripTable!BA20 -> 0.01534451 | BD22: =BB22/BG22 -> 0.02355587 | BE22: LA | BF22: 3462 | BG22: 9407 | BH22: 6052 | BI22: 8474 | BK22: 0.36972326 | BL22: 0.41663225 | BM22: LA
A23: Maine | B23: 0.10508832 | C23: =C$2*TripTable!B21 -> 0 | D23: =D$2*TripTable!C21 -> 0.50309926 | E23: =E$2*TripTable!D21 -> 0 | F23: =F$2*TripTable!E21 -> 0 | G23: =G$2*TripTable!F21 -> 0.5919626 | H23: =H$2*TripTable!G21 -> 0.020704444 | I23: =I$2*TripTable!H21 -> 0.051717271 | J23: =J$2*TripTable!I21 -> 1.5155403 | ... U23: =U$2*TripTable!T21 -> 0.20568775 | W23: =W$2*TripTable!V21 -> 2.1077375 | X23: =X$2*TripTable!W21 -> 102.80142 | Y23: =Y$2*TripTable!X21 -> 0.14036967 | Z23: =Z$2*TripTable!Y21 -> 0 | AA23: =AA$2*TripTable!Z21 -> 0 | AB23: =AB$2*TripTable!AA21 -> 0.0091162296 | AC23: =AC$2*TripTable!AB21 -> 0 | AD23: =AD$2*TripTable!AC21 -> 0 | ... BA23: =BA$2*TripTable!AZ21 -> 0 | BB23: =SUM(C23:BA23) -> 282.68286 | BC23: =BB23/TripTable!BA21 -> 0.056099 | BD23: =BB23/BG23 -> 0.030008796 | BE23: ME | BF23: 15379 | BG23: 9420 | BH23: 2144 | BI23: 2927 | BK23: 0.23416339 | BL23: 0.42279629 | BM23: ME
A24: Maryland | B24: 0.070257916 | C24: =C$2*TripTable!B22 -> 0 | D24: =D$2*TripTable!C22 -> 1.1319733 | E24: =E$2*TripTable!D22 -> 0 | F24: =F$2*TripTable!E22 -> 0 | G24: =G$2*TripTable!F22 -> 5.961909 | H24: =H$2*TripTable!G22 -> 0.17155111 | I24: =I$2*TripTable!H22 -> 0.083423337 | J24: =J$2*TripTable!I22 -> 216.21708 | ... V24: =V$2*TripTable!U22 -> 7.9867122 | X24: =X$2*TripTable!W22 -> 42.409485 | Y24: =Y$2*TripTable!X22 -> 0.95303615 | Z24: =Z$2*TripTable!Y22 -> 0 | AA24: =AA$2*TripTable!Z22 -> 0 | AB24: =AB$2*TripTable!AA22 -> 0.04330209 | AC24: =AC$2*TripTable!AB22 -> 0 | AD24: =AD$2*TripTable!AC22 -> 0.013965582 | AE24: =AE$2*TripTable!AD22 -> 0 | ... BA24: =BA$2*TripTable!AZ22 -> 0 | BB24: =SUM(C24:BA24) -> 2310.6077 | BC24: =BB24/TripTable!BA22 -> 0.11204033 | BD24: =BB24/BG24 -> 0.18447966 | BE24: MD | BF24: 22000 | BG24: 12525 | BH24: 3462 | BI24: 17188 | BK24: 0.26901857 | BL24: 0.16765133 | BM24: MD
A25: Massachusetts | B25: 0.10394482 | C25: =C$2*TripTable!B23 -> 0 | D25: =D$2*TripTable!C23 -> 1.3206356 | E25: =E$2*TripTable!D23 -> 0 | F25: =F$2*TripTable!E23 -> 0 | G25: =G$2*TripTable!F23 -> 9.2388448 | H25: =H$2*TripTable!G23 -> 0.19817111 | I25: =I$2*TripTable!H23 -> 0.39866479 | J25: =J$2*TripTable!I23 -> 12.882092 | ... W25: =W$2*TripTable!V23 -> 7.8688866 | Y25: =Y$2*TripTable!X23 -> 0.39894536 | Z25: =Z$2*TripTable!Y23 -> 0 | AA25: =AA$2*TripTable!Z23 -> 0 | AB25: =AB$2*TripTable!AA23 -> 0.025069631 | AC25: =AC$2*TripTable!AB23 -> 0 | AD25: =AD$2*TripTable!AC23 -> 0.017955748 | AE25: =AE$2*TripTable!AD23 -> 0 | AF25: =AF$2*TripTable!AE23 -> 348.50323 | ... BA25: =BA$2*TripTable!AZ23 -> 0 | BB25: =SUM(C25:BA25) -> 1911.2867 | BC25: =BB25/TripTable!BA23 -> 0.10156154 | BD25: =BB25/BG25 -> 0.27257368 | BE25: MA | BF25: 2144 | BG25: 7012 | BH25: 2722 | BI25: 16479 | BK25: 0.16374902 | BL25: 0.14176345 | BM25: MA
A26: Michigan | B26: 0.0073878771 | C26: =C$2*TripTable!B24 -> 0 | D26: =D$2*TripTable!C24 -> 5.3454297 | E26: =E$2*TripTable!D24 -> 0 | F26: =F$2*TripTable!E24 -> 0 | G26: =G$2*TripTable!F24 -> 10.951308 | H26: =H$2*TripTable!G24 -> 0.34605999 | I26: =I$2*TripTable!H24 -> 0.0067570304 | J26: =J$2*TripTable!I24 -> 4.5466209 | ... X26: =X$2*TripTable!W24 -> 29.000604 | Z26: =Z$2*TripTable!Y24 -> 0 | AA26: =AA$2*TripTable!Z24 -> 0 | AB26: =AB$2*TripTable!AA24 -> 0.27500626 | AC26: =AC$2*TripTable!AB24 -> 0 | AD26: =AD$2*TripTable!AC24 -> 0.055862326 | AE26: =AE$2*TripTable!AD24 -> 0 | AF26: =AF$2*TripTable!AE24 -> 4.8288721 | AG26: =AG$2*TripTable!AF24 -> 36.349346 | ... BA26: =BA$2*TripTable!AZ24 -> 0 | BB26: =SUM(C26:BA26) -> 716.09252 | BC26: =BB26/TripTable!BA24 -> 0.018021253 | BD26: =BB26/BG26 -> 0.045330919 | BE26: MI | BF26: 12275 | BG26: 15797 | BH26: 22000 | BI26: 17916 | BK26: 0.63721941 | BL26: 0.55115743 | BM26: MI
A27: Minnesota | B27: 0 | C27: =C$2*TripTable!B25 -> 0 | D27: =D$2*TripTable!C25 -> 1.383523 | E27: =E$2*TripTable!D25 -> 0 | F27: =F$2*TripTable!E25 -> 0 | G27: =G$2*TripTable!F25 -> 9.2811279 | H27: =H$2*TripTable!G25 -> 0.64183776 | I27: =I$2*TripTable!H25 -> 0.0057174873 | J27: =J$2*TripTable!I25 -> 0 | ... Y27: =Y$2*TripTable!X25 -> 2.4453873 | AA27: =AA$2*TripTable!Z25 -> 0 | AB27: =AB$2*TripTable!AA25 -> 0.21119265 | AC27: =AC$2*TripTable!AB25 -> 0 | AD27: =AD$2*TripTable!AC25 -> 0.33716904 | AE27: =AE$2*TripTable!AD25 -> 0 | AF27: =AF$2*TripTable!AE25 -> 0.82444158 | AG27: =AG$2*TripTable!AF25 -> 5.1927638 | AH27: =AH$2*TripTable!AG25 -> 0 | ... BA27: =BA$2*TripTable!AZ25 -> 0 | BB27: =SUM(C27:BA27) -> 209.34827 | BC27: =BB27/TripTable!BA25 -> 0.00813888 | BD27: =BB27/BG27 -> 0.029435921 | BE27: MN | BF27: 4613 | BG27: 7112 | BH27: 15379 | BI27: 10468 | BK27: 0.62014597 | BL27: 0.59500135 | BM27: MN
A28: Mississippi | B28: 0 | C28: =C$2*TripTable!B26 -> 0 | D28: =D$2*TripTable!C26 -> 1.6350726 | E28: =E$2*TripTable!D26 -> 0 | F28: =F$2*TripTable!E26 -> 0 | G28: =G$2*TripTable!F26 -> 1.5221895 | H28: =H$2*TripTable!G26 -> 0.091691109 | I28: =I$2*TripTable!H26 -> 0.00077965736 | J28: =J$2*TripTable!I26 -> 0.25259005 | ... Z28: =Z$2*TripTable!Y26 -> 0 | AB28: =AB$2*TripTable!AA26 -> 0.11623193 | AC28: =AC$2*TripTable!AB26 -> 0 | AD28: =AD$2*TripTable!AC26 -> 0.0019950831 | AE28: =AE$2*TripTable!AD26 -> 0 | AF28: =AF$2*TripTable!AE26 -> 1.4133284 | AG28: =AG$2*TripTable!AF26 -> 3.2796403 | AH28: =AH$2*TripTable!AG26 -> 0 | AI28: =AI$2*TripTable!AH26 -> 12.277415 | ... BA28: =BA$2*TripTable!AZ26 -> 0 | BB28: =SUM(C28:BA28) -> 143.61357 | BC28: =BB28/TripTable!BA26 -> 0.013260718 | BD28: =BB28/BG28 -> 0.0082683846 | BE28: MS | BF28: 12665 | BG28: 17369 | BH28: 4613 | BI28: 6289 | BK28: 0.39343284 | BL28: 0.42313337 | BM28: MS
A29: Missouri | B29: 0.0007596858 | C29: =C$2*TripTable!B27 -> 0 | D29: =D$2*TripTable!C27 -> 0.94331112 | E29: =E$2*TripTable!D27 -> 0 | F29: =F$2*TripTable!E27 -> 0 | G29: =G$2*TripTable!F27 -> 5.6236447 | H29: =H$2*TripTable!G27 -> 1.4079022 | I29: =I$2*TripTable!H27 -> 0.0023389721 | J29: =J$2*TripTable!I27 -> 0.5051801 | ... AA29: =AA$2*TripTable!Z27 -> 0 | AC29: =AC$2*TripTable!AB27 -> 0 | AD29: =AD$2*TripTable!AC27 -> 0.66835283 | AE29: =AE$2*TripTable!AD27 -> 0 | AF29: =AF$2*TripTable!AE27 -> 0 | AG29: =AG$2*TripTable!AF27 -> 12.845258 | AH29: =AH$2*TripTable!AG27 -> 0 | AI29: =AI$2*TripTable!AH27 -> 32.186738 | AJ29: =AJ$2*TripTable!AI27 -> 0.083444064 | ... BA29: =BA$2*TripTable!AZ27 -> 0 | BB29: =SUM(C29:BA29) -> 409.75907 | BC29: =BB29/TripTable!BA27 -> 0.016312065 | BD29: =BB29/BG29 -> 0.13087163 | BE29: MO | BF29: 4117 | BG29: 3131 | BH29: 12275 | BI29: 13002 | BK29: 0.43726845 | BL29: 0.48561934 | BM29: MO
A30: Montana | B30: 0 | C30: =C$2*TripTable!B28 -> 0 | D30: =D$2*TripTable!C28 -> 0.56598667 | E30: =E$2*TripTable!D28 -> 0 | F30: =F$2*TripTable!E28 -> 0 | G30: =G$2*TripTable!F28 -> 1.8815954 | H30: =H$2*TripTable!G28 -> 0.25732666 | I30: =I$2*TripTable!H28 -> 0.00051977157 | J30: =J$2*TripTable!I28 -> 0 | ... AB30: =AB$2*TripTable!AA28 -> 0.018992145 | AD30: =AD$2*TripTable!AC28 -> 0.023940997 | AE30: =AE$2*TripTable!AD28 -> 0 | AF30: =AF$2*TripTable!AE28 -> 0.11777737 | AG30: =AG$2*TripTable!AF28 -> 0.81991007 | AH30: =AH$2*TripTable!AG28 -> 0 | AI30: =AI$2*TripTable!AH28 -> 4.3136865 | AJ30: =AJ$2*TripTable!AI28 -> 0.0029537722 | AK30: =AK$2*TripTable!AJ28 -> 0 | ... BA30: =BA$2*TripTable!AZ28 -> 0 | BB30: =SUM(C30:BA30) -> 31.258391 | BC30: =BB30/TripTable!BA28 -> 0.0052446965 | BD30: =BB30/BG30 -> 0.014118514 | BE30: MT | BF30: 2389 | BG30: 2214 | BH30: 4117 | BI30: 1848 | BK30: 0.56801876 | BL30: 0.69019279 | BM30: MT
A31: Nebraska | B31: 0.0019950831 | C31: =C$2*TripTable!B29 -> 0 | D31: =D$2*TripTable!C29 -> 0.44021186 | E31: =E$2*TripTable!D29 -> 0 | F31: =F$2*TripTable!E29 -> 0 | G31: =G$2*TripTable!F29 -> 2.7483978 | H31: =H$2*TripTable!G29 -> 1.7628355 | I31: =I$2*TripTable!H29 -> 0.0018192005 | J31: =J$2*TripTable!I29 -> 0.5051801 | ... AC31: =AC$2*TripTable!AB29 -> 0 | AE31: =AE$2*TripTable!AD29 -> 0 | AF31: =AF$2*TripTable!AE29 -> 0.23555474 | AG31: =AG$2*TripTable!AF29 -> 3.2796403 | AH31: =AH$2*TripTable!AG29 -> 0 | AI31: =AI$2*TripTable!AH29 -> 7.9637289 | AJ31: =AJ$2*TripTable!AI29 -> 0.0081228735 | AK31: =AK$2*TripTable!AJ29 -> 0 | AL31: =AL$2*TripTable!AK29 -> 0.78901834 | ... BA31: =BA$2*TripTable!AZ29 -> 0 | BB31: =SUM(C31:BA31) -> 113.52237 | BC31: =BB31/TripTable!BA29 -> 0.013203346 | BD31: =BB31/BG31 -> 0.0066746455 | BE31: NE | BF31: 3431 | BG31: 17008 | BH31: 3653 | BI31: 4966 | BK31: 0.49238442 | BL31: 0.42383107 | BM31: NE
A32: Nevada | B32: 0 | C32: =C$2*TripTable!B30 -> 0 | D32: =D$2*TripTable!C30 -> 1.0061985 | E32: =E$2*TripTable!D30 -> 0 | F32: =F$2*TripTable!E30 -> 0 | G32: =G$2*TripTable!F30 -> 61.775525 | H32: =H$2*TripTable!G30 -> 0.31056666 | I32: =I$2*TripTable!H30 -> 0.0010395431 | J32: =J$2*TripTable!I30 -> 0 | ... AD32: =AD$2*TripTable!AC30 -> 0.021945914 | AF32: =AF$2*TripTable!AE30 -> 0.23555474 | AG32: =AG$2*TripTable!AF30 -> 2.7330336 | AH32: =AH$2*TripTable!AG30 -> 0 | AI32: =AI$2*TripTable!AH30 -> 5.3091526 | AJ32: =AJ$2*TripTable!AI30 -> 0.0044306583 | AK32: =AK$2*TripTable!AJ30 -> 0 | AL32: =AL$2*TripTable!AK30 -> 1.3150306 | AM32: =AM$2*TripTable!AL30 -> 1.1396738 | ... BA32: =BA$2*TripTable!AZ30 -> 0 | BB32: =SUM(C32:BA32) -> 90.196127 | BC32: =BB32/TripTable!BA30 -> 0.013536864 | BD32: =BB32/BG32 -> 0.0048999883 | BE32: NV | BF32: 15997 | BG32: 18407.417 | BH32: 1173 | BI32: 5504 | BK32: 0.04453303 | BL32: 0.1756777 | BM32: NV
A33: New-Hampshire | B33: 0.11777737 | C33: =C$2*TripTable!B31 -> 0 | D33: =D$2*TripTable!C31 -> 0.12577482 | E33: =E$2*TripTable!D31 -> 0 | F33: =F$2*TripTable!E31 -> 0 | G33: =G$2*TripTable!F31 -> 1.2262082 | H33: =H$2*TripTable!G31 -> 0.068028887 | I33: =I$2*TripTable!H31 -> 0.16424782 | J33: =J$2*TripTable!I31 -> 2.5259005 | ... AE33: =AE$2*TripTable!AD31 -> 0 | AG33: =AG$2*TripTable!AF31 -> 39.355683 | AH33: =AH$2*TripTable!AG31 -> 0 | AI33: =AI$2*TripTable!AH31 -> 152.63814 | AJ33: =AJ$2*TripTable!AI31 -> 0.020676405 | AK33: =AK$2*TripTable!AJ31 -> 0 | AL33: =AL$2*TripTable!AK31 -> 1.0520245 | AM33: =AM$2*TripTable!AL31 -> 0.37989128 | AN33: =AN$2*TripTable!AM31 -> 0.042392322 | ... BA33: =BA$2*TripTable!AZ31 -> 0 | BB33: =SUM(C33:BA33) -> 388.81828 | BC33: =BB33/TripTable!BA31 -> 0.081650206 | BD33: =BB33/BG33 -> 0.080484015 | BE33: NH | BF33: 5437 | BG33: 4831 | BH33: 814 | BI33: 4000 | BK33: 0.11740949 | BL33: 0.16909015 | BM33: NH
A34: New-Jersey | B34: 0.27330336 | C34: =C$2*TripTable!B32 -> 0 | D34: =D$2*TripTable!C32 -> 1.5092978 | E34: =E$2*TripTable!D32 -> 0 | F34: =F$2*TripTable!E32 -> 0 | G34: =G$2*TripTable!F32 -> 11.39528 | H34: =H$2*TripTable!G32 -> 0.37267999 | I34: =I$2*TripTable!H32 -> 0.19127594 | J34: =J$2*TripTable!I32 -> 42.940308 | ... AF34: =AF$2*TripTable!AE32 -> 21.199926 | AH34: =AH$2*TripTable!AG32 -> 0 | AI34: =AI$2*TripTable!AH32 -> 1114.2584 | AJ34: =AJ$2*TripTable!AI32 -> 0.52429456 | AK34: =AK$2*TripTable!AJ32 -> 0 | AL34: =AL$2*TripTable!AK32 -> 19.166571 | AM34: =AM$2*TripTable!AL32 -> 1.7474999 | AN34: =AN$2*TripTable!AM32 -> 0.11127985 | AO34: =AO$2*TripTable!AN32 -> 468.61079 | ... BA34: =BA$2*TripTable!AZ32 -> 0 | BB34: =SUM(C34:BA34) -> 2136.8882 | BC34: =BB34/TripTable!BA32 -> 0.093686186 | BD34: =BB34/BG34 -> 0.084908341 | BE34: NJ | BF34: 1173 | BG34: 25167 | BH34: 3431 | BI34: 19801.458 | BK34: 0.16786536 | BL34: 0.14768132 | BM34: NJ
A35: New-Mexico | B35: 0 | C35: =C$2*TripTable!B33 -> 0 | D35: =D$2*TripTable!C33 -> 0.37732445 | E35: =E$2*TripTable!D33 -> 0 | F35: =F$2*TripTable!E33 -> 0 | G35: =G$2*TripTable!F33 -> 6.7864283 | H35: =H$2*TripTable!G33 -> 2.2094599 | I35: =I$2*TripTable!H33 -> 0.00025988579 | J35: =J$2*TripTable!I33 -> 0.25259005 | ... AG35: =AG$2*TripTable!AF33 -> 1.9131235 | AI35: =AI$2*TripTable!AH33 -> 13.604704 | AJ35: =AJ$2*TripTable!AI33 -> 0.0073844304 | AK35: =AK$2*TripTable!AJ33 -> 0 | AL35: =AL$2*TripTable!AK33 -> 0.88764564 | AM35: =AM$2*TripTable!AL33 -> 6.9140213 | AN35: =AN$2*TripTable!AM33 -> 0.17486833 | AO35: =AO$2*TripTable!AN33 -> 1.8716357 | AP35: =AP$2*TripTable!AO33 -> 0 | ... BA35: =BA$2*TripTable!AZ33 -> 0 | BB35: =SUM(C35:BA35) -> 88.520821 | BC35: =BB35/TripTable!BA33 -> 0.0088071655 | BD35: =BB35/BG35 -> 0.0035662244 | BE35: NM | BF35: 15983 | BG35: 24822 | BH35: 5437 | BI35: 4668 | BK35: 0.52950915 | BL35: 0.53805047 | BM35: NM
A36: New-York | B36: 0.33182204 | C36: =C$2*TripTable!B34 -> 0 | D36: =D$2*TripTable!C34 -> 2.5783837 | E36: =E$2*TripTable!D34 -> 0 | F36: =F$2*TripTable!E34 -> 0 | G36: =G$2*TripTable!F34 -> 17.843444 | H36: =H$2*TripTable!G34 -> 0.36084888 | I36: =I$2*TripTable!H34 -> 0.3602017 | J36: =J$2*TripTable!I34 -> 125.53725 | ... AH36: =AH$2*TripTable!AG34 -> 0 | AJ36: =AJ$2*TripTable!AI34 -> 0.62029216 | AK36: =AK$2*TripTable!AJ34 -> 0 | AL36: =AL$2*TripTable!AK34 -> 32.316876 | AM36: =AM$2*TripTable!AL34 -> 5.0145649 | AN36: =AN$2*TripTable!AM34 -> 0.16427025 | AO36: =AO$2*TripTable!AN34 -> 561.72466 | AP36: =AP$2*TripTable!AO34 -> 15.469573 | AQ36: =AQ$2*TripTable!AP34 -> 0 | ... BA36: =BA$2*TripTable!AZ34 -> 0 | BB36: =SUM(C36:BA36) -> 2482.7934 | BC36: =BB36/TripTable!BA34 -> 0.055330571 | BD36: =BB36/BG36 -> 0.3469042 | BE36: NY | BF36: 7378 | BG36: 7157 | BH36: 15983 | BI36: 29959 | BK36: 0.39169219 | BL36: 0.34789517 | BM36: NY
A37: North-Carolina | B37: 0.00073844304 | C37: =C$2*TripTable!B35 -> 0 | D37: =D$2*TripTable!C35 -> 0.69176149 | E37: =E$2*TripTable!D35 -> 0 | F37: =F$2*TripTable!E35 -> 0 | G37: =G$2*TripTable!F35 -> 3.7631908 | H37: =H$2*TripTable!G35 -> 0.20112888 | I37: =I$2*TripTable!H35 -> 0.02157052 | J37: =J$2*TripTable!I35 -> 11.366552 | ... AI37: =AI$2*TripTable!AH35 -> 172.21564 | AK37: =AK$2*TripTable!AJ35 -> 0 | AL37: =AL$2*TripTable!AK35 -> 6.7724074 | AM37: =AM$2*TripTable!AL35 -> 1.9754347 | AN37: =AN$2*TripTable!AM35 -> 0.042392322 | AO37: =AO$2*TripTable!AN35 -> 58.371638 | AP37: =AP$2*TripTable!AO35 -> 0.44839341 | AQ37: =AQ$2*TripTable!AP35 -> 0 | AR37: =AR$2*TripTable!AQ35 -> 0 | ... BA37: =BA$2*TripTable!AZ35 -> 0 | BB37: =SUM(C37:BA37) -> 667.03344 | BC37: =BB37/TripTable!BA35 -> 0.022994017 | BD37: =BB37/BG37 -> 0.17711987 | BE37: NC | BF37: 3653 | BG37: 3766 | BH37: 12665 | BI37: 16703 | BK37: 0.42168875 | BL37: 0.4312517 | BM37: NC
A38: North-Dakota | B38: 0 | C38: =C$2*TripTable!B36 -> 0 | D38: =D$2*TripTable!C36 -> 0.062887408 | E38: =E$2*TripTable!D36 -> 0 | F38: =F$2*TripTable!E36 -> 0 | G38: =G$2*TripTable!F36 -> 0.65538716 | H38: =H$2*TripTable!G36 -> 0.14197333 | I38: =I$2*TripTable!H36 -> 0.00051977157 | J38: =J$2*TripTable!I36 -> 0 | ... AJ38: =AJ$2*TripTable!AI36 -> 0.0022153291 | AL38: =AL$2*TripTable!AK36 -> 0.16437882 | AM38: =AM$2*TripTable!AL36 -> 0.30391303 | AN38: =AN$2*TripTable!AM36 -> 0.026495201 | AO38: =AO$2*TripTable!AN36 -> 0.58488615 | AP38: =AP$2*TripTable!AO36 -> 0 | AQ38: =AQ$2*TripTable!AP36 -> 0 | AR38: =AR$2*TripTable!AQ36 -> 0 | AS38: =AS$2*TripTable!AR36 -> 0.00023202066 | ... BA38: =BA$2*TripTable!AZ36 -> 0 | BB38: =SUM(C38:BA38) -> 11.475368 | BC38: =BB38/TripTable!BA36 -> 0.0028063995 | BD38: =BB38/BG38 -> 0.0018753665 | BE38: ND | BF38: 814 | BG38: 6119 | BH38: 2389 | BI38: 1706 | BK38: 0.51900934 | BL38: 0.58339438 | BM38: ND
A39: Ohio | B39: 0.032875764 | C39: =C$2*TripTable!B37 -> 0 | D39: =D$2*TripTable!C37 -> 2.0752845 | E39: =E$2*TripTable!D37 -> 0 | F39: =F$2*TripTable!E37 -> 0 | G39: =G$2*TripTable!F37 -> 11.374138 | H39: =H$2*TripTable!G37 -> 0.6891622 | I39: =I$2*TripTable!H37 -> 0.063412132 | J39: =J$2*TripTable!I37 -> 15.407993 | ... AK39: =AK$2*TripTable!AJ37 -> 0 | AM39: =AM$2*TripTable!AL37 -> 4.8626084 | AN39: =AN$2*TripTable!AM37 -> 0.14307409 | AO39: =AO$2*TripTable!AN37 -> 234.30539 | AP39: =AP$2*TripTable!AO37 -> 1.9430381 | AQ39: =AQ$2*TripTable!AP37 -> 0 | AR39: =AR$2*TripTable!AQ37 -> 0 | AS39: =AS$2*TripTable!AR37 -> 0.059455294 | AT39: =AT$2*TripTable!AS37 -> 7.5232304 | ... BA39: =BA$2*TripTable!AZ37 -> 0 | BB39: =SUM(C39:BA39) -> 1269.2221 | BC39: =BB39/TripTable!BA37 -> 0.033390916 | BD39: =BB39/BG39 -> 0.18545034 | BE39: OH | BF39: 7420 | BG39: 6844 | BH39: 15997 | BI39: 22303 | BK39: 0.46496937 | BL39: 0.41767624 | BM39: OH
A40: Oklahoma | B40: 0.075978257 | C40: =C$2*TripTable!B38 -> 0 | D40: =D$2*TripTable!C38 -> 0.62887408 | E40: =E$2*TripTable!D38 -> 0 | F40: =F$2*TripTable!E38 -> 0 | G40: =G$2*TripTable!F38 -> 3.5729171 | H40: =H$2*TripTable!G38 -> 0.96423553 | I40: =I$2*TripTable!H38 -> 0.0010395431 | J40: =J$2*TripTable!I38 -> 0 | ... AL40: =AL$2*TripTable!AK38 -> 3.0903218 | AN40: =AN$2*TripTable!AM38 -> 0.15367217 | AO40: =AO$2*TripTable!AN38 -> 8.8902695 | AP40: =AP$2*TripTable!AO38 -> 0.11209835 | AQ40: =AQ$2*TripTable!AP38 -> 0 | AR40: =AR$2*TripTable!AQ38 -> 0 | AS40: =AS$2*TripTable!AR38 -> 0.0070186249 | AT40: =AT$2*TripTable!AS38 -> 70.258063 | AU40: =AU$2*TripTable!AT38 -> 0.0087218068 | ... BA40: =BA$2*TripTable!AZ38 -> 0 | BB40: =SUM(C40:BA40) -> 213.51097 | BC40: =BB40/TripTable!BA38 -> 0.013350276 | BD40: =BB40/BG40 -> 0.0091557019 | BE40: OK | BF40: 12548 | BG40: 23320 | BH40: 7378 | BI40: 8679 | BK40: 0.50760234 | BL40: 0.45948807 | BM40: OK
...

Sheet Destinations (2)
A1: TRIPS-WITHIN-ALABAMA | B1: 7205 | C1: 9734
A2: TRIPS-WITHIN-ALASKA | B2: 1798 | C2: 636
A3: TRIPS-WITHIN-ARIZONA | B3: 10895 | C3: 8689
A4: TRIPS-WITHIN-ARKANSAS | B4: 4485 | C4: 5856
A5: TRIPS-WITHIN-CALIFORNIA | B5: 64843 | C5: 37526
A6: TRIPS-WITHIN-COLORADO | B6: 6982 | C6: 9048
A7: TRIPS-WITHIN-CONNECTICUT | B7: 177 | C7: 11859
A8: TRIPS-WITHIN-DELAWARE | B8: 82 | C8: 2198
A9: TRIPS-WITHIN-FLORIDA | B9: 24083 | C9: 18841
A10: TRIPS-WITHIN-GEORGIA | B10: 9448 | C10: 18337
A11: TRIPS-WITHIN-HAWAII | B11: 1322 | C11: 765
A12: TRIPS-WITHIN-IDAHO | B12: 3077 | C12: 3761
... A38: TRIPS-WITHIN-PENNSYLVANIA | B38: 7205 | C38: 9734
A39: TRIPS-WITHIN-RHODE-ISLAND | B39: - | C39: 2258
A40: TRIPS-WITHIN-SOUTH-CAROLINA | B40: 6033 | C40: 9024
A41: TRIPS-WITHIN-SOUTH-DAKOTA | B41: 2733 | C41: 2142
A42: TRIPS-WITHIN-TENNESSEE | B42: 5864 | C42: 13941
A43: TRIPS-WITHIN-TEXAS | B43: 56808 | C43: 23496
A44: TRIPS-WITHIN-UTAH | B44: 4495 | C44: 6206
A45: TRIPS-WITHIN-VERMONT | B45: 317 | C45: 2547
A46: TRIPS-WITHIN-VIRGINIA | B46: 9012 | C46: 18941
A47: TRIPS-WITHIN-WASHINGTON | B47: 13744 | C47: 10556
A48: TRIPS-WITHIN-WEST-VIRGINIA | B48: 1854 | C48: 4176
A49: TRIPS-WITHIN-WISCONSIN | B49: 14023 | C49: 11784
A50: TRIPS-WITHIN-WYOMING | B50: 1723 | C50: 2368

Sheet Summary
B1: Vistors to State by Origin | D1: Destinations by Residents of | G1: Visitors | H1: Residents
A2: FULLNAME | B2: In-State | C2: Out-of-State | D2: In-State | E2: Out-Of-Staet | G2: Ratio | H2: Ratio | I2: STATE
A3: ALABAMA | B3: 7205 | C3: 9591 | D3: 7205 | E3: 9734 | G3: =B3/(B3+C3) -> 0.42897118 | H3: =D3/(D3+E3) -> 0.42534978 | I3: AL
A4: ARKANSAS | B4: 4485 | C4: 5876 | D4: 4485 | E4: 5856 | G4: =B4/(B4+C4) -> 0.43287327 | H4: =D4/(D4+E4) -> 0.43371047 | I4: AR
A5: ARIZONA | B5: 10895 | C5: 10450 | D5: 10895 | E5: 8689 | G5: =B5/(B5+C5) -> 0.51042399 | H5: =D5/(D5+E5) -> 0.55632149 | I5: AZ
A6: CALIFORNIA | B6: 64843 | C6: 24441 | D6: 64843 | E6: 37526 | G6: =B6/(B6+C6) -> 0.72625554 | H6: =D6/(D6+E6) -> 0.63342418 | I6: CA | J6: =B6+C6 -> 89284 | K6: =D6+E6 -> 102369
A7: COLORADO | B7: 6982 | C7: 11038 | D7: 6982 | E7: 9048 | G7: =B7/(B7+C7) -> 0.38745838 | H7: =D7/(D7+E7) -> 0.43555833 | I7: CO
A8: CONNECTICUT | B8: 177 | C8: 7148 | D8: 177 | E8: 11859 | G8: =B8/(B8+C8) -> 0.024163823 | H8: =D8/(D8+E8) -> 0.014705882 | I8: CT
A9: DELAWARE | B9: 82 | C9: 5132 | D9: 82 | E9: 2198 | G9: =B9/(B9+C9) -> 0.015726889 | H9: =D9/(D9+E9) -> 0.035964912 | I9: DE
A10: FLORIDA | B10: 24083 | C10: 35061 | D10: 24083 | E10: 18841 | G10: =B10/(B10+C10) -> 0.40719261 | H10: =D10/(D10+E10) -> 0.56106141 | I10: FL
A11: GEORGIA | B11: 9448 | C11: 19185 | D11: 9448 | E11: 18337 | G11: =B11/(B11+C11) -> 0.32996892 | H11: =D11/(D11+E11) -> 0.34003959 | I11: GA
A12: HAWAII | B12: 1322 | C12: 3305 | D12: 1322 | E12: 765 | G12: =B12/(B12+C12) -> 0.28571429 | H12: =D12/(D12+E12) -> 0.63344514 | I12: HI
A13: IDAHO | B13: 3077 | C13: 3684 | D13: 3077 | E13: 3761 | G13: =B13/(B13+C13) -> 0.45511019 | H13: =D13/(D13+E13) -> 0.44998538 | I13: ID
A14: ILLINOIS | B14: 11964 | C14: 21128 | D14: 11964 | E14: 27788 | G14: =B14/(B14+C14) -> 0.36153753 | H14: =D14/(D14+E14) -> 0.30096599 | I14: IL
A15: INDIANA | B15: 8278 | C15: 11750 | D15: 8278 | E15: 13821 | G15: =B15/(B15+C15) -> 0.41332135 | H15: =D15/(D15+E15) -> 0.37458709 | I15: IN
A16: IOWA | B16: 5811 | C16: 6380 | D16: 5811 | E16: 6939 | G16: =B16/(B16+C16) -> 0.47666311 | H16: =D16/(D16+E16) -> 0.45576471 | I16: IO
A17: KANSAS | B17: 4560 | C17: 5889 | D17: 4560 | E17: 7596 | G17: =B17/(B17+C17) -> 0.4364054 | H17: =D17/(D17+E17) -> 0.3751234 | I17: KS
B18: 5574 | C18: 8515 | D18: 5574 | E18: 10081 | G18: =B18/(B18+C18) -> 0.39562779 | H18: =D18/(D18+E18) -> 0.35605238 | I18: KY
A19: LOUISIANA | B19: 6052 | C19: 10317 | D19: 6052 | E19: 33.101562 | G19: =B19/(B19+C19) -> 0.36972326 | H19: =D19/(D19+E19) -> 0.99456023 | I19: LA
A20: MASSACHUSETTS | B20: 2722 | C20: 13901 | D20: 2722 | E20: 16479 | G20: =B20/(B20+C20) -> 0.16374902 | H20: =D20/(D20+E20) -> 0.14176345 | I20: MA
A21: MARYLAND | B21: 3462 | C21: 9407 | D21: 3462 | E21: 17188 | G21: =B21/(B21+C21) -> 0.26901857 | H21: =D21/(D21+E21) -> 0.16765133 | I21: MD
A22: MAINE | B22: 2144 | C22: 7012 | D22: 2144 | E22: 2927 | G22: =B22/(B22+C22) -> 0.23416339 | H22: =D22/(D22+E22) -> 0.42279629 | I22: ME
A23: MICHIGAN | B23: 22000 | C23: 12525 | D23: 22000 | E23: 17916 | G23: =B23/(B23+C23) -> 0.63721941 | H23: =D23/(D23+E23) -> 0.55115743 | I23: MI
A24: MINNESOTA | B24: 15379 | C24: 9420 | D24: 15379 | E24: 10468 | G24: =B24/(B24+C24) -> 0.62014597 | H24: =D24/(D24+E24) -> 0.59500135 | I24: MN
A25: MISSOURI | B25: 12275 | C25: 15797 | D25: 12275 | E25: 13002 | G25: =B25/(B25+C25) -> 0.43726845 | H25: =D25/(D25+E25) -> 0.48561934 | I25: MO
A26: MISSISSIPPI | B26: 4613 | C26: 7112 | D26: 4613 | E26: 6289 | G26: =B26/(B26+C26) -> 0.39343284 | H26: =D26/(D26+E26) -> 0.42313337 | I26: MS
A27: MONTANA | B27: 4117 | C27: 3131 | D27: 4117 | E27: 1848 | G27: =B27/(B27+C27) -> 0.56801876 | H27: =D27/(D27+E27) -> 0.69019279 | I27: MT
A28: NORTH-CAROLINA | B28: 12665 | C28: 17369 | D28: 12665 | E28: 16703 | G28: =B28/(B28+C28) -> 0.42168875 | H28: =D28/(D28+E28) -> 0.4312517 | I28: NC
A29: NORTH-DAKOTA | B29: 2389 | C29: 2214 | D29: 2389 | E29: 1706 | G29: =B29/(B29+C29) -> 0.51900934 | H29: =D29/(D29+E29) -> 0.58339438 | I29: ND
A30: NEBRASKA | B30: 3653 | C30: 3766 | D30: 3653 | E30: 4966 | G30: =B30/(B30+C30) -> 0.49238442 | H30: =D30/(D30+E30) -> 0.42383107 | I30: NE
... A39: PENNSYLVANIA | B39: 12548 | C39: 23320 | D39: 7205 | E39: 9734 | G39: =B39/(B39+C39) -> 0.3498383 | H39: =D39/(D39+E39) -> 0.42534978 | I39: PA
A40: RHODE-ISLAND | B40: - | C40: 2049 | D40: - | E40: 2258 | G40: =B40/(B40+C40) -> #VALUE! | H40: =D40/(D40+E40) -> #VALUE! | I40: RI
A41: SOUTH-CAROLINA | B41: 6033 | C41: 13294 | D41: 6033 | E41: 9024 | G41: =B41/(B41+C41) -> 0.31215398 | H41: =D41/(D41+E41) -> 0.40067743 | I41: SC
A42: SOUTH-DAKOTA | B42: 7205 | C42: 2885 | D42: 2733 | E42: 2142 | G42: =B42/(B42+C42) -> 0.71407334 | H42: =D42/(D42+E42) -> 0.56061538 | I42: SD
A43: TENNESSEE | B43: 5864 | C43: 16875 | D43: 5864 | E43: 13941 | G43: =B43/(B43+C43) -> 0.25788293 | H43: =D43/(D43+E43) -> 0.29608685 | I43: TN
A44: TEXAS | B44: 56808 | C44: 19166 | D44: 56808 | E44: 23496 | G44: =B44/(B44+C44) -> 0.74772949 | H44: =D44/(D44+E44) -> 0.70741184 | I44: TX
A45: UTAH | B45: 4495 | C45: 5172 | D45: 4495 | E45: 6206 | G45: =B45/(B45+C45) -> 0.46498397 | H45: =D45/(D45+E45) -> 0.4200542 | I45: UT
A46: VIRGINIA | B46: 9012 | C46: 14238 | D46: 9012 | E46: 18941 | G46: =B46/(B46+C46) -> 0.3876129 | H46: =D46/(D46+E46) -> 0.32239831 | I46: VA
A47: VERMONT | B47: 317 | C47: 4784 | D47: 317 | E47: 2547 | G47: =B47/(B47+C47) -> 0.062144678 | H47: =D47/(D47+E47) -> 0.11068436 | I47: VT
A48: WASHINGTON | B48: 13744 | C48: 7823 | D48: 13744 | E48: 10556 | G48: =B48/(B48+C48) -> 0.6372699 | H48: =D48/(D48+E48) -> 0.56559671 | I48: WA
...

Sheet Origins
A1: TRIPS-WITHIN-ALABAMA | B1: 7205 | C1: 9591 | D1: =SUM(B2:B52) -> 9591
A2: Alaska | B2: 6 | C2: 9585
A3: Arizona | B3: 29 | C3: 9556
A4: Arkansas | B4: 122 | C4: 11232
A5: California | B5: 97 | C5: 11144
A6: Colorado | B6: 43 | C6: 11140
A7: Connecticut | B7: 7 | C7: 11157
A8: Delaware | B8: 11 | C8: 11247
A9: Distict-of-Columbia | B9: 12 | C9: 11278
A10: Florida | B10: 1514 | C10: 9777
A11: Georgia | B11: 2477 | C11: 7302
A12: Hawaii | B12: 9 | C12: 7294
A13: Idaho | B13: 2 | C13: 7375
... A51: Wyoming | B51: 2 | C51: 3012
C52: 3014
C53: 3035
A54: TRIPS-WITHIN-ALASKA | B54: 1798 | C54: 1242 | D54: =SUM(B55:B105) -> 1242
A55: Alabama | B55: 9 | C55: 1233
A56: Arizona | B56: 39 | C56: 1194
A57: Arkansas | B57: 24 | C57: 12065
A58: California | B58: 101 | C58: 11991
A59: Colorado | B59: 43 | C59: 11985
A60: Connecticut | B60: 13 | C60: 12009
A61: Delaware | B61: 2 | C61: 15839
A62: Distict-of-Columbia | B62: 1 | C62: 16370
A63: Florida | B63: 83 | C63: 16332
A64: Georgia | B64: 20 | C64: 16314
A65: Hawaii | B65: 10 | C65: 16315
A66: Idaho | B66: 15 | C66: 16418
... A93: Rhode-Island | B93: 1 | C93: 19600
A94: South-Carolina | B94: - | C94: 19891
A95: South-Dakota | B95: 2 | C95: 20069
A96: Tennessee | B96: 27 | C96: 20055
A97: Texas | B97: 146 | C97: 19922
A98: Utah | B98: 20 | C98: 19938
A99: Vermont | B99: 3 | C99: 19993
A100: Virginia | B100: 4 | C100: 20540
A101: Washington | B101: 114 | C101: 20873
A102: West-Virginia | B102: 2 | C102: 20878
A103: Wisconsin | B103: 21 | C103: 20978
...

Sheet Neighbors-by-O
B1: FULLNAME | C1: Alabama | D1: Alaska | E1: Arizona | F1: Arkansas | G1: California | H1: Colorado | I1: Connecticut | J1: Delaware | K1: Distict-of-Columbia | L1: Florida | M1: Georgia | N1: Hawaii | O1: Idaho | P1: Illinois | Q1: Indiana | R1: Iowa | S1: Kansas | T1: Kentucky | U1: Louisiana | V1: Maine | W1: Maryland | X1: Massachusetts | Y1: Michigan | Z1: Minnesota | AA1: Mississippi | AB1: Missouri | AC1: Montana | AD1: Nebraska | AE1: Nevada | AF1: New-Hampshire | AG1: New-Jersey | AH1: New-Mexico | AI1: New-York | AJ1: North-Carolina | AK1: North-Dakota | AL1: Ohio | AM1: Oklahoma | AN1: Oregon | AO1: Pennsylvania | AP1: Rhode-Island | AQ1: South-Carolina | AR1: South-Dakota | AS1: Tennessee | AT1: Texas | AU1: Utah | AV1: Vermont | AW1: Virginia | AX1: Washington | AY1: West-Virginia | AZ1: Wisconsin | BA1: Wyoming
B2: TollShare | C2: 0 | D2: 0.062887408 | E2: 0 | F2: 0 | G2: 0.021141521 | H2: 0.0029577777 | I2: 0.00025988579 | J2: 0.25259005 | K2: 0 | L2: 0.077833555 | M2: 0.0041858291 | N2: 0 | O2: 0.001073349 | P2: 0 | Q2: 0.092502027 | R2: 0.042572953 | S2: 0.064564023 | T2: 0.008453283 | U2: 0.029383964 | V2: 0.10508832 | W2: 0.070257916 | X2: 0.10394482 | Y2: 0.0073878771 | Z2: 0 | AA2: 0 | AB2: 0.0007596858 | AC2: 0 | AD2: 0.0019950831 | AE2: 0 | AF2: 0.11777737 | AG2: 0.27330336 | AH2: 0 | AI2: 0.33182204 | AJ2: 0.00073844304 | AK2: 0 | AL2: 0.032875764 | AM2: 0.075978257 | AN2: 0.0052990403 | AO2: 0.11697723 | AP2: 0.037366118 | AQ2: 0 | AR2: 0 | AS2: 5.8005165e-05 | AT2: 0.024747469 | AU2: 0.0006229862 | AV2: 0 | AW2: 0.046528368 | AX2: 0.04142763 | AY2: 0.065724566 | AZ2: 1.1333251e-05 | BA2: 0
A3: FULLNAME | B3: TollShare | C3: Alabama | D3: Alaska | E3: Arizona | F3: Arkansas | G3: California | H3: Colorado | I3: Connecticut | J3: Delaware | K3: Distict-of-Columbia | L3: Florida | M3: Georgia | N3: Hawaii | O3: Idaho | P3: Illinois | Q3: Indiana | R3: Iowa | S3: Kansas | T3: Kentucky | U3: Louisiana | V3: Maine | W3: Maryland | X3: Massachusetts | Y3: Michigan | Z3: Minnesota | AA3: Mississippi | AB3: Missouri | AC3: Montana | AD3: Nebraska | AE3: Nevada | AF3: New-Hampshire | AG3: New-Jersey | AH3: New-Mexico | AI3: New-York | AJ3: North-Carolina | AK3: North-Dakota | AL3: Ohio | AM3: Oklahoma | AN3: Oregon | AO3: Pennsylvania | AP3: Rhode-Island | AQ3: South-Carolina | AR3: South-Dakota | AS3: Tennessee | AT3: Texas | AU3: Utah | AV3: Vermont | AW3: Virginia | AX3: Washington | AY3: West-Virginia | AZ3: Wisconsin | BA3: Wyoming | BB3: TOTAL | BC3: TOTAL/TOTALTRIPS
A4: Alabama | B4: 0 | C4: =C$2*TripTable!B2 -> 0 | D4: =D$2*TripTable!C2 -> 0.56598667 | E4: =E$2*TripTable!D2 -> 0 | F4: =F$2*TripTable!E2 -> 0 | G4: =G$2*TripTable!F2 -> 3.2135112 | H4: =H$2*TripTable!G2 -> 0.14788888 | I4: =I$2*TripTable!H2 -> 0.0025988579 | J4: =J$2*TripTable!I2 -> 1.2629502 | ... BA4: =BA$2*TripTable!AZ2 -> 0 | BB4: =SUM(C4:BA4) -> 252.87588 | BC4: =BB4/TripTable!BA2 -> 0.014599381
A5: Alaska | B5: 0.062887408 | C5: =C$2*TripTable!B3 -> 0 | D5: =D$2*TripTable!C3 -> 113.07156 | E5: =E$2*TripTable!D3 -> 0 | F5: =F$2*TripTable!E3 -> 0 | G5: =G$2*TripTable!F3 -> 2.0718691 | H5: =H$2*TripTable!G3 -> 0.065071109 | I5: =I$2*TripTable!H3 -> 0.0015593147 | J5: =J$2*TripTable!I3 -> 0 | ... BA5: =BA$2*TripTable!AZ3 -> 0 | BB5: =SUM(C5:BA5) -> 129.99949 | BC5: =BB5/TripTable!BA3 -> 0.053608036
A6: Arizona | B6: 0 | C6: =C$2*TripTable!B4 -> 0 | D6: =D$2*TripTable!C4 -> 2.4526089 | E6: =E$2*TripTable!D4 -> 0 | F6: =F$2*TripTable!E4 -> 0 | G6: =G$2*TripTable!F4 -> 86.172841 | H6: =H$2*TripTable!G4 -> 1.0233911 | I6: =I$2*TripTable!H4 -> 0.0070169162 | J6: =J$2*TripTable!I4 -> 1.2629502 | ... BA6: =BA$2*TripTable!AZ4 -> 0 | BB6: =SUM(C6:BA6) -> 197.02356 | BC6: =BB6/TripTable!BA4 -> 0.010104291
A7: Arkansas | B7: 0 | C7: =C$2*TripTable!B5 -> 0 | D7: =D$2*TripTable!C5 -> 1.5092978 | E7: =E$2*TripTable!D5 -> 0 | F7: =F$2*TripTable!E5 -> 0 | G7: =G$2*TripTable!F5 -> 2.0507276 | H7: =H$2*TripTable!G5 -> 0.31352444 | I7: =I$2*TripTable!H5 -> 0.0015593147 | J7: =J$2*TripTable!I5 -> 0 | ... BA7: =BA$2*TripTable!AZ5 -> 0 | BB7: =SUM(C7:BA7) -> 155.15035 | BC7: =BB7/TripTable!BA5 -> 0.015083643
A8: California | B8: 0.021141521 | C8: =C$2*TripTable!B6 -> 0 | D8: =D$2*TripTable!C6 -> 6.3516282 | E8: =E$2*TripTable!D6 -> 0 | F8: =F$2*TripTable!E6 -> 0 | G8: =G$2*TripTable!F6 -> 1370.8797 | H8: =H$2*TripTable!G6 -> 4.164551 | I8: =I$2*TripTable!H6 -> 0.049378299 | J8: =J$2*TripTable!I6 -> 3.2836706 | ... BA8: =BA$2*TripTable!AZ6 -> 0 | BB8: =SUM(C8:BA8) -> 2352.9741 | BC8: =BB8/TripTable!BA6 -> 0.023081046
A9: Colorado | B9: 0.0029577777 | C9: =C$2*TripTable!B7 -> 0 | D9: =D$2*TripTable!C7 -> 2.7041585 | E9: =E$2*TripTable!D7 -> 0 | F9: =F$2*TripTable!E7 -> 0 | G9: =G$2*TripTable!F7 -> 22.156314 | H9: =H$2*TripTable!G7 -> 20.651204 | I9: =I$2*TripTable!H7 -> 0.0033785152 | J9: =J$2*TripTable!I7 -> 0.25259005 | ... BA9: =BA$2*TripTable!AZ7 -> 0 | BB9: =SUM(C9:BA9) -> 255.94818 | BC9: =BB9/TripTable!BA7 -> 0.016076137
A10: Connecticut | B10: 0.00025988579 | C10: =C$2*TripTable!B8 -> 0 | D10: =D$2*TripTable!C8 -> 0.8175363 | E10: =E$2*TripTable!D8 -> 0 | F10: =F$2*TripTable!E8 -> 0 | G10: =G$2*TripTable!F8 -> 4.1437382 | H10: =H$2*TripTable!G8 -> 0.19521333 | I10: =I$2*TripTable!H8 -> 0.045999784 | J10: =J$2*TripTable!I8 -> 12.882092 | ... BA10: =BA$2*TripTable!AZ8 -> 0 | BB10: =SUM(C10:BA10) -> 1494.7522 | BC10: =BB10/TripTable!BA8 -> 0.1265238
A11: Delaware | B11: 0.25259005 | C11: =C$2*TripTable!B9 -> 0 | D11: =D$2*TripTable!C9 -> 0.12577482 | E11: =E$2*TripTable!D9 -> 0 | F11: =F$2*TripTable!E9 -> 0 | G11: =G$2*TripTable!F9 -> 0.5919626 | H11: =H$2*TripTable!G9 -> 0.029577777 | I11: =I$2*TripTable!H9 -> 0.0083163451 | J11: =J$2*TripTable!I9 -> 20.712384 | ... BA11: =BA$2*TripTable!AZ9 -> 0 | BB11: =SUM(C11:BA11) -> 267.63268 | BC11: =BB11/TripTable!BA9 -> 0.12154072
A12: Distict-of-Columbia | B12: 0 | C12: =C$2*TripTable!B10 -> 0 | D12: =D$2*TripTable!C10 -> 0.062887408 | E12: =E$2*TripTable!D10 -> 0 | F12: =F$2*TripTable!E10 -> 0 | G12: =G$2*TripTable!F10 -> 1.9661615 | H12: =H$2*TripTable!G10 -> 0.070986665 | I12: =I$2*TripTable!H10 -> 0.011434975 | J12: =J$2*TripTable!I10 -> 26.016775 | ... BA12: =BA$2*TripTable!AZ10 -> 0 | BB12: =SUM(C12:BA12) -> 258.77922 | BC12: =BB12/TripTable!BA10 -> 0.11897895
A13: Florida | B13: 0.077833555 | C13: =C$2*TripTable!B11 -> 0 | D13: =D$2*TripTable!C11 -> 5.2196549 | E13: =E$2*TripTable!D11 -> 0 | F13: =F$2*TripTable!E11 -> 0 | G13: =G$2*TripTable!F11 -> 14.143678 | H13: =H$2*TripTable!G11 -> 0.64775331 | I13: =I$2*TripTable!H11 -> 0.063931903 | J13: =J$2*TripTable!I11 -> 13.387273 | ... BA13: =BA$2*TripTable!AZ11 -> 0 | BB13: =SUM(C13:BA13) -> 2824.3713 | BC13: =BB13/TripTable!BA11 -> 0.066299797
A14: Georgia | B14: 0.0041858291 | C14: =C$2*TripTable!B12 -> 0 | D14: =D$2*TripTable!C12 -> 1.2577482 | E14: =E$2*TripTable!D12 -> 0 | F14: =F$2*TripTable!E12 -> 0 | G14: =G$2*TripTable!F12 -> 6.4693055 | H14: =H$2*TripTable!G12 -> 0.2514111 | I14: =I$2*TripTable!H12 -> 0.020011205 | J14: =J$2*TripTable!I12 -> 1.2629502 | ... BA14: =BA$2*TripTable!AZ12 -> 0 | BB14: =SUM(C14:BA14) -> 669.49647 | BC14: =BB14/TripTable!BA12 -> 0.024305554
A15: Hawaii | B15: 0 | C15: =C$2*TripTable!B13 -> 0 | D15: =D$2*TripTable!C13 -> 0.62887408 | E15: =E$2*TripTable!D13 -> 0 | F15: =F$2*TripTable!E13 -> 0 | G15: =G$2*TripTable!F13 -> 4.4397195 | H15: =H$2*TripTable!G13 -> 0.047324443 | I15: =I$2*TripTable!H13 -> 0 | J15: =J$2*TripTable!I13 -> 0.25259005 | ... BA15: =BA$2*TripTable!AZ13 -> 0 | BB15: =SUM(C15:BA15) -> 22.646331 | BC15: =BB15/TripTable!BA13 -> 0.010913895
... A54: Wyoming | B54: 0 | C54: =C$2*TripTable!B52 -> 0 | D54: =D$2*TripTable!C52 -> 0.31443704 | E54: =E$2*TripTable!D52 -> 0 | F54: =F$2*TripTable!E52 -> 0 | G54: =G$2*TripTable!F52 -> 0.86680237 | H54: =H$2*TripTable!G52 -> 2.0467822 | I54: =I$2*TripTable!H52 -> 0.00025988579 | J54: =J$2*TripTable!I52 -> 0 | ... BA54: =BA$2*TripTable!AZ52 -> 0 | BB54: =SUM(C54:BA54) -> 16.656595 | BC54: =BB54/TripTable!BA52 -> 0.0040755064

Sheet TripTable
A1: O \ D | B1: Alabama | C1: Alaska | D1: Arizona | E1: Arkansas | F1: California | G1: Colorado | H1: Connecticut | I1: Delaware | J1: Distict0of0Columbia | K1: Florida | L1: Georgia | M1: Hawaii | N1: Idaho | O1: Illinois | P1: Indiana | Q1: Iowa | R1: Kansas | S1: Kentucky | T1: Louisiana | U1: Maine | V1: Maryland | W1: Massachusetts | X1: Michigan | Y1: Minnesota | Z1: Mississippi | AA1: Missouri | AB1: Montana | AC1: Nebraska | AD1: Nevada | AE1: New0Hampshire | AF1: New0Jersey | AG1: New0Mexico | AH1: New0York | AI1: North0Carolina | AJ1: North0Dakota | AK1: Ohio | AL1: Oklahoma | AM1: Oregon | AN1: Pennsylvania | AO1: Rhode0Island | AP1: South0Carolina | AQ1: South0Dakota | AR1: Tennessee | AS1: Texas | AT1: Utah | AU1: Vermont | AV1: Virginia | AW1: Washington | AX1: West0Virginia | AY1: Wisconsin | AZ1: Wyoming | BA1: TOTAL
A2: Alabama | B2: 7205 | C2: 9 | D2: 27 | E2: 55 | F2: 152 | G2: 50 | H2: 10 | I2: 5 | J2: 0 | K2: 1934 | L2: 2539 | M2: 3 | N2: 2 | O2: 128 | P2: 76 | Q2: 35 | R2: 17 | S2: 107 | T2: 510 | U2: 3 | V2: 32 | W2: 69 | X2: 56 | Y2: 18 | Z2: 985 | AA2: 197 | AB2: 10 | AC2: 3 | AD2: 25 | AE2: 2 | AF2: 40 | AG2: 10 | AH2: 37 | AI2: 284 | AJ2: 2 | AK2: 96 | AL2: 20 | AM2: 1 | AN2: 50 | AO2: 2 | AP2: 203 | AQ2: 4 | AR2: 1831 | AS2: 231 | AT2: 26 | AU2: 0 | AV2: 166 | AW2: 11 | AX2: 37 | AY2: 4 | AZ2: 2 | BA2: =SUM(B2:AZ2) -> 17321
A3: Alaska | B3: 6 | C3: 1798 | D3: 37 | E3: 10 | F3: 98 | G3: 22 | H3: 6 | I3: 0 | J3: 0 | K3: 16 | L3: 4 | M3: 23 | N3: 7 | O3: 19 | P3: 2 | Q3: 1 | R3: 3 | S3: 1 | T3: 6 | U3: 1 | V3: 3 | W3: 7 | X3: 8 | Y3: 11 | Z3: 1 | AA3: 10 | AB3: 10 | AC3: 3 | AD3: 36 | AE3: 0 | AF3: 2 | AG3: 5 | AH3: 12 | AI3: 3 | AJ3: 1 | AK3: 8 | AL3: 5 | AM3: 60 | AN3: 6 | AO3: 0 | AP3: 1 | AQ3: 2 | AR3: 3 | AS3: 25 | AT3: 9 | AU3: 1 | AV3: 5 | AW3: 113 | AX3: 1 | AY3: 9 | AZ3: 5 | BA3: =SUM(B3:AZ3) -> 2425
A4: Arizona | B4: 29 | C4: 39 | D4: 10895 | E4: 15 | F4: 4076 | G4: 346 | H4: 27 | I4: 5 | J4: 0 | K4: 94 | L4: 51 | M4: 89 | N4: 33 | O4: 215 | P4: 45 | Q4: 58 | R4: 74 | S4: 12 | T4: 29 | U4: 0 | V4: 36 | W4: 41 | X4: 68 | Y4: 111 | Z4: 1 | AA4: 64 | AB4: 36 | AC4: 61 | AD4: 1046 | AE4: 40 | AF4: 23 | AG4: 339 | AH4: 96 | AI4: 51 | AJ4: 9 | AK4: 64 | AL4: 65 | AM4: 114 | AN4: 82 | AO4: 1 | AP4: 17 | AQ4: 21 | AR4: 12 | AS4: 362 | AT4: 273 | AU4: 8 | AV4: 35 | AW4: 188 | AX4: 0 | AY4: 47 | AZ4: 56 | BA4: =SUM(B4:AZ4) -> 19499
A5: Arkansas | B5: 122 | C5: 24 | D5: 37 | E5: 4485 | F5: 97 | G5: 106 | H5: 6 | I5: 0 | J5: 0 | K5: 159 | L5: 73 | M5: 4 | N5: 13 | O5: 146 | P5: 40 | Q5: 32 | R5: 131 | S5: 65 | T5: 519 | U5: 3 | V5: 11 | W5: 11 | X5: 48 | Y5: 16 | Z5: 475 | AA5: 923 | AB5: 5 | AC5: 31 | AD5: 56 | AE5: 0 | AF5: 10 | AG5: 28 | AH5: 38 | AI5: 36 | AJ5: 5 | AK5: 57 | AL5: 784 | AM5: 9 | AN5: 14 | AO5: 4 | AP5: 19 | AQ5: 9 | AR5: 505 | AS5: 997 | AT5: 5 | AU5: 2 | AV5: 30 | AW5: 17 | AX5: 7 | AY5: 53 | AZ5: 19 | BA5: =SUM(B5:AZ5) -> 10286
A6: California | B6: 97 | C6: 101 | D6: 3832 | E6: 226 | F6: 64843 | G6: 1408 | H6: 190 | I6: 13 | J6: 0 | K6: 949 | L6: 315 | M6: 1530 | N6: 329 | O6: 594 | P6: 247 | Q6: 69 | R6: 141 | S6: 45 | T6: 139 | U6: 284 | V6: 133 | W6: 377 | X6: 452 | Y6: 493 | Z6: 106 | AA6: 477 | AB6: 533 | AC6: 17 | AD6: 15175 | AE6: 39 | AF6: 314 | AG6: 526 | AH6: 1441 | AI6: 286 | AJ6: 22 | AK6: 651 | AL6: 114 | AM6: 1172 | AN6: 686 | AO6: 24 | AP6: 71 | AQ6: 122 | AR6: 183 | AS6: 911 | AT6: 615 | AU6: 126 | AV6: 187 | AW6: 1102 | AX6: 118 | AY6: 59 | AZ6: 60 | BA6: =SUM(B6:AZ6) -> 101944
A7: Colorado | B7: 43 | C7: 43 | D7: 532 | E7: 21 | F7: 1048 | G7: 6982 | H7: 13 | I7: 1 | J7: 0 | K7: 315 | L7: 141 | M7: 38 | N7: 79 | O7: 215 | P7: 40 | Q7: 107 | R7: 333 | S7: 7 | T7: 33 | U7: 12 | V7: 43 | W7: 77 | X7: 106 | Y7: 226 | Z7: 14 | AA7: 205 | AB7: 105 | AC7: 439 | AD7: 463 | AE7: 5 | AF7: 78 | AG7: 969 | AH7: 216 | AI7: 114 | AJ7: 55 | AK7: 119 | AL7: 168 | AM7: 103 | AN7: 66 | AO7: 25 | AP7: 20 | AQ7: 135 | AR7: 72 | AS7: 504 | AT7: 655 | AU7: 2 | AV7: 36 | AW7: 129 | AX7: 10 | AY7: 56 | AZ7: 703 | BA7: =SUM(B7:AZ7) -> 15921
A8: Connecticut | B8: 7 | C8: 13 | D8: 45 | E8: 12 | F8: 196 | G8: 66 | H8: 177 | I8: 51 | J8: 0 | K8: 700 | L8: 105 | M8: 27 | N8: 5 | O8: 122 | P8: 30 | Q8: 24 | R8: 3 | S8: 11 | T8: 51 | U8: 832 | V8: 166 | W8: 2613 | X8: 88 | Y8: 42 | Z8: 18 | AA8: 44 | AB8: 11 | AC8: 6 | AD8: 60 | AE8: 576 | AF8: 677 | AG8: 4 | AH8: 1981 | AI8: 160 | AJ8: 10 | AK8: 123 | AL8: 7 | AM8: 7 | AN8: 841 | AO8: 473 | AP8: 117 | AQ8: 4 | AR8: 73 | AS8: 99 | AT8: 27 | AU8: 833 | AV8: 181 | AW8: 25 | AX8: 28 | AY8: 39 | AZ8: 4 | BA8: =SUM(B8:AZ8) -> 11814
A9: Delaware | B9: 11 | C9: 2 | D9: 2 | E9: 2 | F9: 28 | G9: 10 | H9: 32 | I9: 82 | J9: 0 | K9: 101 | L9: 29 | M9: 3 | N9: 1 | O9: 24 | P9: 12 | Q9: 3 | R9: 1 | S9: 5 | T9: 8 | U9: 16 | V9: 225 | W9: 74 | X9: 17 | Y9: 10 | Z9: 1 | AA9: 7 | AB9: 0 | AC9: 0 | AD9: 10 | AE9: 7 | AF9: 257 | AG9: 3 | AH9: 237 | AI9: 88 | AJ9: 0 | AK9: 35 | AL9: 1 | AM9: 1 | AN9: 347 | AO9: 8 | AP9: 31 | AQ9: 1 | AR9: 26 | AS9: 27 | AT9: 2 | AU9: 19 | AV9: 365 | AW9: 4 | AX9: 24 | AY9: 3 | AZ9: 0 | BA9: =SUM(B9:AZ9) -> 2202
A10: Distict0of0Columbia | B10: 12 | C10: 1 | D10: 11 | E10: 7 | F10: 93 | G10: 24 | H10: 44 | I10: 103 | J10: 0 | K10: 104 | L10: 48 | M10: 4 | N10: 1 | O10: 45 | P10: 12 | Q10: 2 | R10: 4 | S10: 9 | T10: 17 | U10: 17 | V10: 45 | W10: 92 | X10: 15 | Y10: 12 | Z10: 6 | AA10: 11 | AB10: 4 | AC10: 2 | AD10: 12 | AE10: 9 | AF10: 131 | AG10: 4 | AH10: 368 | AI10: 150 | AJ10: 1 | AK10: 39 | AL10: 1 | AM10: 5 | AN10: 231 | AO10: 4 | AP10: 57 | AQ10: 1 | AR10: 16 | AS10: 45 | AT10: 2 | AU10: 10 | AV10: 262 | AW10: 13 | AX10: 64 | AY10: 4 | AZ10: 1 | BA10: =SUM(B10:AZ10) -> 2175
A11: Florida | B11: 1514 | C11: 83 | D11: 118 | E11: 231 | F11: 669 | G11: 219 | H11: 246 | I11: 53 | J11: 0 | K11: 24083 | L11: 3302 | M11: 24 | N11: 15 | O11: 512 | P11: 252 | Q11: 73 | R11: 52 | S11: 321 | T11: 710 | U11: 68 | V11: 190 | W11: 336 | X11: 556 | Y11: 42 | Z11: 1162 | AA11: 216 | AB11: 38 | AC11: 34 | AD11: 274 | AE11: 64 | AF11: 659 | AG11: 86 | AH11: 1484 | AI11: 1227 | AJ11: 10 | AK11: 653 | AL11: 21 | AM11: 55 | AN11: 411 | AO11: 23 | AP11: 467 | AQ11: 0 | AR11: 609 | AS11: 471 | AT11: 190 | AU11: 85 | AV11: 265 | AW11: 95 | AX11: 124 | AY11: 194 | AZ11: 14 | BA11: =SUM(B11:AZ11) -> 42600
A12: Georgia | B12: 2477 | C12: 20 | D12: 33 | E12: 37 | F12: 306 | G12: 85 | H12: 77 | I12: 5 | J12: 0 | K12: 4568 | L12: 9448 | M12: 26 | N12: 8 | O12: 307 | P12: 187 | Q12: 17 | R12: 9 | S12: 272 | T12: 283 | U12: 42 | V12: 111 | W12: 93 | X12: 259 | Y12: 28 | Z12: 514 | AA12: 223 | AB12: 15 | AC12: 51 | AD12: 57 | AE12: 1 | AF12: 176 | AG12: 6 | AH12: 272 | AI12: 1550 | AJ12: 10 | AK12: 366 | AL12: 16 | AM12: 18 | AN12: 164 | AO12: 4 | AP12: 1900 | AQ12: 6 | AR12: 2454 | AS12: 373 | AT12: 36 | AU12: 3 | AV12: 435 | AW12: 38 | AX12: 127 | AY12: 23 | AZ12: 9 | BA12: =SUM(B12:AZ12) -> 27545
A13: Hawaii | B13: 9 | C13: 10 | D13: 10 | E13: 2 | F13: 210 | G13: 16 | H13: 0 | I13: 1 | J13: 0 | K13: 28 | L13: 4 | M13: 1322 | N13: 4 | O13: 13 | P13: 9 | Q13: 1 | R13: 1 | S13: 2 | T13: 4 | U13: 3 | V13: 7 | W13: 6 | X13: 3 | Y13: 13 | Z13: 0 | AA13: 2 | AB13: 2 | AC13: 1 | AD13: 218 | AE13: 0 | AF13: 6 | AG13: 3 | AH13: 16 | AI13: 5 | AJ13: 0 | AK13: 9 | AL13: 0 | AM13: 8 | AN13: 15 | AO13: 0 | AP13: 4 | AQ13: 0 | AR13: 1 | AS13: 26 | AT13: 11 | AU13: 0 | AV13: 10 | AW13: 56 | AX13: 1 | AY13: 3 | AZ13: 0 | BA13: =SUM(B13:AZ13) -> 2075
... A52: Wyoming | B52: 2 | C52: 5 | D52: 28 | E52: 3 | F52: 41 | G52: 692 | H52: 1 | I52: 0 | J52: 0 | K52: 13 | L52: 4 | M52: 5 | N52: 31 | O52: 10 | P52: 7 | Q52: 17 | R52: 28 | S52: 1 | T52: 7 | U52: 1 | V52: 1 | W52: 2 | X52: 5 | Y52: 25 | Z52: 1 | AA52: 36 | AB52: 657 | AC52: 91 | AD52: 46 | AE52: 0 | AF52: 5 | AG52: 21 | AH52: 9 | AI52: 2 | AJ52: 21 | AK52: 7 | AL52: 7 | AM52: 12 | AN52: 7 | AO52: 0 | AP52: 1 | AQ52: 223 | AR52: 5 | AS52: 37 | AT52: 205 | AU52: 2 | AV52: 2 | AW52: 26 | AX52: 2 | AY52: 10 | AZ52: 1723 | BA52: =SUM(B52:AZ52) -> 4087
