Workbook

Sheet OD-MSA(Val)
A1: Sum of TRIPS | B1: D-MSA | AP1: NoNeighbor
A2: O-MSA | B2: 0 | C2: 360 | D2: 680 | E2: 1620 | F2: 2840 | G2: 4480 | H2: 4940 | I2: 5170 | J2: 5775 | K2: 6000 | L2: 6690 | M2: 6780 | N2: 6920 | O2: 7120 | P2: 7320 | Q2: 7360 | R2: 7400 | S2: 7480 | T2: 7485 | U2: 7500 | V2: 8120 | W2: 8720 | X2: 8780 | Y2: 9340 | Z2: 9999 | AA2: Grand Total | AC2: O-MSA | AD2: NAME | AE2: Residents who Work of DMLPUMA | AF2: Residents Who Work In DML PUMA | AG2: Total Workers | AH2: Total Population | AI2: ExportedLabor | AK2: ResidentWorkers | AL2: Non-ResidentWorkers | AM2: Total Workers | AN2: ImportedLabor | AO2: =AC2 -> O-MSA | AP2: TollShare | AR2: TotalPop*TollShare
A3: 360 | B3: 1138865 | C3: 1047085 | D3: 221 | E3: 78 | F3: 208 | G3: 198133 | H3: 0 | I3: 0 | J3: 806 | K3: 468 | L3: 364 | M3: 18707 | N3: 1144 | O3: 0 | P3: 7098 | Q3: 624 | R3: 416 | S3: 611 | T3: 0 | U3: 78 | V3: 78 | W3: 286 | X3: 0 | Y3: 0 | Z3: 1404 | AA3: 2417701 | AC3: =A3 -> 360 | AD3: Anaheim | AE3: =SUM(C3:Z3)-MAX(C3:Z3) -> 230724 | AF3: =MAX(C3:Z3) -> 1047085 | AG3: =SUM(C3:Z3) -> 1277809 | AH3: =SUM(B3:Z3) -> 2416674 | AI3: =AE3/AG3 -> 0.1805622 | AK3: 1047085 | AL3: 230425 | AM3: 1277510 | AN3: 0.18037041 | AO3: =AC3 -> 360 | AP3: =-0.0364+0.00000000386*$AH3+0.844*$AN3 -> 0.12516099 | AR3: =AH3*AP3 -> 302473.3
A4: 680 | B4: 320827 | C4: 169 | D4: 207935 | E4: 0 | F4: 156 | G4: 7618 | H4: 0 | I4: 0 | J4: 104 | K4: 208 | L4: 0 | M4: 1755 | N4: 0 | O4: 208 | P4: 0 | Q4: 169 | R4: 0 | S4: 351 | T4: 0 | U4: 0 | V4: 91 | W4: 0 | X4: 1469 | Y4: 0 | Z4: 1222 | AA4: 542386 | AC4: =A4 -> 680 | AD4: Bakersfield | AE4: =SUM(C4:Z4)-MAX(C4:Z4) -> 13520 | AF4: =MAX(C4:Z4) -> 207935 | AG4: =SUM(C4:Z4) -> 221455 | AH4: =SUM(B4:Z4) -> 542282 | AI4: =AE4/AG4 -> 0.061050778 | AK4: 207935 | AL4: 16198 | AM4: 224133 | AN4: 0.07226959 | AO4: =AC4 -> 680 | AP4: =-0.0364+0.00000000386*$AH4+0.844*$AN4 -> 0.026688742 | AR4: =AH4*AP4 -> 14472.825
A5: 1620 | B5: 111722 | C5: 0 | D5: 0 | E5: 62647 | F5: 78 | G5: 0 | H5: 0 | I5: 0 | J5: 0 | K5: 0 | L5: 65 | M5: 0 | N5: 247 | O5: 117 | P5: 117 | Q5: 0 | R5: 156 | S5: 0 | T5: 0 | U5: 0 | V5: 0 | W5: 234 | X5: 0 | Y5: 1651 | Z5: 1911 | AA5: 179322 | AC5: =A5 -> 1620 | AD5: Chico | AE5: =SUM(C5:Z5)-MAX(C5:Z5) -> 4576 | AF5: =MAX(C5:Z5) -> 62647 | AG5: =SUM(C5:Z5) -> 67223 | AH5: =SUM(B5:Z5) -> 178945 | AI5: =AE5/AG5 -> 0.06807194 | AK5: 62647 | AL5: 3887 | AM5: 66534 | AN5: 0.058421258 | AO5: =AC5 -> 1620 | AP5: =-0.0364+0.00000000386*$AH5+0.844*$AN5 -> 0.01359827 | AR5: =AH5*AP5 -> 2433.3424
A6: 2840 | B6: 405808 | C6: 117 | D6: 104 | E6: 182 | F6: 250822 | G6: 741 | H6: 1313 | I6: 195 | J6: 377 | K6: 377 | L6: 0 | M6: 130 | N6: 338 | O6: 520 | P6: 104 | Q6: 741 | R6: 91 | S6: 91 | T6: 78 | U6: 0 | V6: 143 | W6: 0 | X6: 3107 | Y6: 91 | Z6: 8398 | AA6: 673868 | AC6: =A6 -> 2840 | AD6: Fresno | AE6: =SUM(C6:Z6)-MAX(C6:Z6) -> 17238 | AF6: =MAX(C6:Z6) -> 250822 | AG6: =SUM(C6:Z6) -> 268060 | AH6: =SUM(B6:Z6) -> 673868 | AI6: =AE6/AG6 -> 0.064306499 | AK6: 250822 | AL6: 18941 | AM6: 269763 | AN6: 0.070213484 | AO6: =AC6 -> 2840 | AP6: =-0.0364+0.00000000386*$AH6+0.844*$AN6 -> 0.025461311 | AR6: =AH6*AP6 -> 17157.563
A7: 4480 | B7: 4714869 | C7: 136591 | D7: 9503 | E7: 273 | F7: 650 | G7: 3859648 | H7: 0 | I7: 156 | J7: 2743 | K7: 21801 | L7: 1079 | M7: 38948 | N7: 1235 | O7: 793 | P7: 3419 | Q7: 4173 | R7: 520 | S7: 1131 | T7: 0 | U7: 0 | V7: 156 | W7: 611 | X7: 0 | Y7: 364 | Z7: 6201 | AA7: 8808738 | AC7: =A7 -> 4480 | AD7: Los Angeles (LA) | AE7: =SUM(C7:Z7)-MAX(C7:Z7) -> 230347 | AF7: =MAX(C7:Z7) -> 3859648 | AG7: =SUM(C7:Z7) -> 4089995 | AH7: =SUM(B7:Z7) -> 8804864 | AI7: =AE7/AG7 -> 0.056319629 | AK7: 3859648 | AL7: 458328 | AM7: 4317976 | AN7: 0.10614417 | AO7: =AC7 -> 4480 | AP7: =-0.0364+0.00000000386*$AH7+0.844*$AN7 -> 0.087172459 | AR7: =AH7*AP7 -> 767541.64
A8: 4940 | B8: 108225 | C8: 0 | D8: 0 | E8: 0 | F8: 572 | G8: 0 | H8: 59956 | I8: 5148 | J8: 52 | K8: 0 | L8: 0 | M8: 0 | N8: 0 | O8: 0 | P8: 0 | Q8: 182 | R8: 949 | S8: 0 | T8: 0 | U8: 0 | V8: 117 | W8: 0 | X8: 0 | Y8: 0 | Z8: 1456 | AA8: 176657 | AC8: =A8 -> 4940 | AD8: Merced | AE8: =SUM(C8:Z8)-MAX(C8:Z8) -> 8476 | AF8: =MAX(C8:Z8) -> 59956 | AG8: =SUM(C8:Z8) -> 68432 | AH8: =SUM(B8:Z8) -> 176657 | AI8: =AE8/AG8 -> 0.12386018 | AK8: 59956 | AL8: 6682 | AM8: 66638 | AN8: 0.10027312 | AO8: =AC8 -> 4940 | AP8: =-0.0364+0.00000000386*$AH8+0.844*$AN8 -> 0.048912407 | AR8: =AH8*AP8 -> 8640.7191
A9: 5170 | B9: 219609 | C9: 0 | D9: 0 | E9: 0 | F9: 182 | G9: 78 | H9: 3653 | I9: 119210 | J9: 6175 | K9: 0 | L9: 0 | M9: 169 | N9: 390 | O9: 0 | P9: 0 | Q9: 377 | R9: 3458 | S9: 0 | T9: 234 | U9: 0 | V9: 8528 | W9: 208 | X9: 0 | Y9: 0 | Z9: 611 | AA9: 363090 | AC9: =A9 -> 5170 | AD9: Modesto | AE9: =SUM(C9:Z9)-MAX(C9:Z9) -> 24063 | AF9: =MAX(C9:Z9) -> 119210 | AG9: =SUM(C9:Z9) -> 143273 | AH9: =SUM(B9:Z9) -> 362882 | AI9: =AE9/AG9 -> 0.16795209 | AK9: 119210 | AL9: 14547 | AM9: 133757 | AN9: 0.10875692 | AO9: =AC9 -> 5170 | AP9: =-0.0364+0.00000000386*$AH9+0.844*$AN9 -> 0.056791569 | AR9: =AH9*AP9 -> 20608.638
A10: 5775 | B10: 1036776 | C10: 468 | D10: 0 | E10: 286 | F10: 169 | G10: 2574 | H10: 0 | I10: 299 | J10: 811031 | K10: 0 | L10: 130 | M10: 169 | N10: 2340 | O10: 0 | P10: 494 | Q10: 144573 | R10: 57941 | S10: 104 | T10: 494 | U10: 1469 | V10: 1417 | W10: 8164 | X10: 117 | Y10: 0 | Z10: 676 | AA10: 2070887 | AC10: =A10 -> 5775 | AD10: Oakland (SF) | AE10: =SUM(C10:Z10)-MAX(C10:Z10) -> 221884 | AF10: =MAX(C10:Z10) -> 811031 | AG10: =SUM(C10:Z10) -> 1032915 | AH10: =SUM(B10:Z10) -> 2069691 | AI10: =AE10/AG10 -> 0.21481342 | AK10: 811031 | AL10: 161356 | AM10: 972387 | AN10: 0.16593805 | AO10: =AC10 -> 5775 | AP10: =-0.0364+0.00000000386*$AH10+0.844*$AN10 -> 0.11164072 | AR10: =AH10*AP10 -> 231061.79
A11: 6000 | B11: 331552 | C11: 299 | D11: 481 | E11: 104 | F11: 0 | G11: 76375 | H11: 0 | I11: 0 | J11: 338 | K11: 249158 | L11: 52 | M11: 676 | N11: 104 | O11: 169 | P11: 533 | Q11: 2002 | R11: 65 | S11: 4381 | T11: 0 | U11: 0 | V11: 91 | W11: 0 | X11: 0 | Y11: 0 | Z11: 663 | AA11: 667108 | AC11: =A11 -> 6000 | AD11: Oxnard-Ventura (LA) | AE11: =SUM(C11:Z11)-MAX(C11:Z11) -> 86333 | AF11: =MAX(C11:Z11) -> 249158 | AG11: =SUM(C11:Z11) -> 335491 | AH11: =SUM(B11:Z11) -> 667043 | AI11: =AE11/AG11 -> 0.25733328 | AK11: 249158 | AL11: 26650 | AM11: 275808 | AN11: 0.096625189 | AO11: =AC11 -> 6000 | AP11: =-0.0364+0.00000000386*$AH11+0.844*$AN11 -> 0.047726445 | AR11: =AH11*AP11 -> 31835.591
A12: 6690 | B12: 93327 | C12: 0 | D12: 117 | E12: 91 | F12: 0 | G12: 0 | H12: 0 | I12: 0 | J12: 520 | K12: 0 | L12: 55562 | M12: 78 | N12: 260 | O12: 0 | P12: 52 | Q12: 91 | R12: 286 | S12: 0 | T12: 0 | U12: 52 | V12: 0 | W12: 0 | X12: 0 | Y12: 0 | Z12: 1404 | AA12: 152490 | AC12: =A12 -> 6690 | AD12: Redding | AE12: =SUM(C12:Z12)-MAX(C12:Z12) -> 2951 | AF12: =MAX(C12:Z12) -> 55562 | AG12: =SUM(C12:Z12) -> 58513 | AH12: =SUM(B12:Z12) -> 151840 | AI12: =AE12/AG12 -> 0.050433237 | AK12: 55562 | AL12: 8437 | AM12: 63999 | AN12: 0.13183018 | AO12: =AC12 -> 6690 | AP12: =-0.0364+0.00000000386*$AH12+0.844*$AN12 -> 0.075450778 | AR12: =AH12*AP12 -> 11456.446
A13: 6780 | B13: 1509872 | C13: 78507 | D13: 1638 | E13: 117 | F13: 91 | G13: 157287 | H13: 117 | I13: 65 | J13: 377 | K13: 442 | L13: 806 | M13: 837356 | N13: 767 | O13: 533 | P13: 7917 | Q13: 663 | R13: 221 | S13: 325 | T13: 104 | U13: 117 | V13: 130 | W13: 104 | X13: 0 | Y13: 0 | Z13: 2145 | AA13: 2600689 | AC13: =A13 -> 6780 | AD13: Riverside (LA) | AE13: =SUM(C13:Z13)-MAX(C13:Z13) -> 252473 | AF13: =MAX(C13:Z13) -> 837356 | AG13: =SUM(C13:Z13) -> 1089829 | AH13: =SUM(B13:Z13) -> 2599701 | AI13: =AE13/AG13 -> 0.23166295 | AK13: 837356 | AL13: 70083 | AM13: 907439 | AN13: 0.077231638 | AO13: =AC13 -> 6780 | AP13: =-0.0364+0.00000000386*$AH13+0.844*$AN13 -> 0.038818348 | AR13: =AH13*AP13 -> 100916.1
A14: 6920 | B14: 792038 | C14: 520 | D14: 0 | E14: 533 | F14: 234 | G14: 728 | H14: 0 | I14: 494 | J14: 4628 | K14: 234 | L14: 1066 | M14: 299 | N14: 644345 | O14: 221 | P14: 949 | Q14: 2808 | R14: 1820 | S14: 0 | T14: 0 | U14: 117 | V14: 7085 | W14: 5408 | X14: 0 | Y14: 1183 | Z14: 12818 | AA14: 1478230 | AC14: =A14 -> 6920 | AD14: Sacramento | AE14: =SUM(C14:Z14)-MAX(C14:Z14) -> 41145 | AF14: =MAX(C14:Z14) -> 644345 | AG14: =SUM(C14:Z14) -> 685490 | AH14: =SUM(B14:Z14) -> 1477528 | AI14: =AE14/AG14 -> 0.060022757 | AK14: 644345 | AL14: 32994 | AM14: 677339 | AN14: 0.048711207 | AO14: =AC14 -> 6920 | AP14: =-0.0364+0.00000000386*$AH14+0.844*$AN14 -> 0.010415516 | AR14: =AH14*AP14 -> 15389.217
... A26: 9999 | B26: 776880 | C26: 0 | D26: 650 | E26: 1430 | F26: 10257 | G26: 1690 | H26: 1235 | I26: 2262 | J26: 1924 | K26: 312 | L26: 3705 | M26: 806 | N26: 7267 | O26: 1482 | P26: 637 | Q26: 1898 | R26: 5499 | S26: 6175 | T26: 351 | U26: 1989 | V26: 3224 | W26: 1001 | X26: 1599 | Y26: 767 | Z26: 394589 | AA26: 1261052 | AC26: =A26 -> 9999 | AD26: Non-Metro | AE26: =SUM(C26:Z26)-MAX(C26:Z26) -> 56160 | AF26: =MAX(C26:Z26) -> 394589 | AG26: =SUM(C26:Z26) -> 450749 | AH26: =SUM(B26:Z26) -> 1227629 | AI26: =AE26/AG26 -> 0.12459262 | AK26: 394589 | AL26: 53326 | AM26: 447915 | AN26: 0.11905384 | AO26: =AC26 -> 9999 | AP26: =-0.0364+0.00000000386*$AH26+0.844*$AN26 -> 0.068820087 | AR26: =AH26*AP26 -> 84485.535
A27: Grand Total | B27: 15631931 | C27: 1277510 | D27: 224133 | E27: 66534 | F27: 269763 | G27: 4317976 | H27: 66638 | I27: 133757 | J27: 972387 | K27: 275808 | L27: 63999 | M27: 907439 | N27: 677339 | O27: 162877 | P27: 1206452 | Q27: 988949 | R27: 863954 | S27: 183118 | T27: 102440 | U27: 157183 | V27: 108069 | W27: 170261 | X27: 112515 | Y27: 43238 | Z27: 447915 | AA27: 29483067 | AC27: =A27 -> Grand Total | AE27: =SUM(C27:Z27)-MAX(C27:Z27) -> 9482278 | AF27: =MAX(C27:Z27) -> 4317976 | AG27: =SUM(C27:Z27) -> 13800254 | AH27: =SUM(B27:Z27) -> 29432185 | AK27: =SUM(I27:AF27)-MAX(I27:AF27) -> 21377954 | AL27: =SUM(J27:AG27)-MAX(J27:AG27) -> 35044451 | AM27: =SUM(K27:AH27)-MAX(K27:AH27) -> 63504249
B28: ResidentWorkers | C28: =MAX(C3:C26) -> 1047085 | D28: =MAX(D3:D26) -> 207935 | E28: =MAX(E3:E26) -> 62647 | F28: =MAX(F3:F26) -> 250822 | G28: =MAX(G3:G26) -> 3859648 | H28: =MAX(H3:H26) -> 59956 | I28: =MAX(I3:I26) -> 119210 | J28: =MAX(J3:J26) -> 811031 | ... AA28: =MAX(AA3:AA26) -> 8808738 | AQ28: TOTAL | AR28: =SUM(AR3:AR26) -> 2170431.3
B29: Non-ResidentWorkers | C29: =SUM(C3:C26)-MAX(C3:C26) -> 230425 | D29: =SUM(D3:D26)-MAX(D3:D26) -> 16198 | E29: =SUM(E3:E26)-MAX(E3:E26) -> 3887 | F29: =SUM(F3:F26)-MAX(F3:F26) -> 18941 | G29: =SUM(G3:G26)-MAX(G3:G26) -> 458328 | H29: =SUM(H3:H26)-MAX(H3:H26) -> 6682 | I29: =SUM(I3:I26)-MAX(I3:I26) -> 14547 | J29: =SUM(J3:J26)-MAX(J3:J26) -> 161356 | ... AA29: =SUM(AA3:AA26)-MAX(AA3:AA26) -> 20674329 | AQ29: AVERAGE | AR29: =AR28/AH27 -> 0.073743464
B30: Total Workers | C30: =SUM(C3:C26) -> 1277510 | D30: =SUM(D3:D26) -> 224133 | E30: =SUM(E3:E26) -> 66534 | F30: =SUM(F3:F26) -> 269763 | G30: =SUM(G3:G26) -> 4317976 | H30: =SUM(H3:H26) -> 66638 | I30: =SUM(I3:I26) -> 133757 | J30: =SUM(J3:J26) -> 972387 | ... AA30: =SUM(AA3:AA26) -> 29483067
B31: ImportedLabor | C31: =C29/C30 -> 0.18037041 | D31: =D29/D30 -> 0.07226959 | E31: =E29/E30 -> 0.058421258 | F31: =F29/F30 -> 0.070213484 | G31: =G29/G30 -> 0.10614417 | H31: =H29/H30 -> 0.10027312 | I31: =I29/I30 -> 0.10875692 | J31: =J29/J30 -> 0.16593805 | ... AA31: =AA29/AA30 -> 0.70122722
B33: TollShare | C33: 0.062706778 | D33: 0.077656553 | E33: 0.076591292 | F33: 0.058851179 | G33: 0.11684038 | H33: 0.27678777 | I33: 0.27416958 | J33: 0.075779832 | K33: 0.2249761 | L33: 0.34812564 | M33: 0.26730986 | N33: 0.036930033 | O33: 0.13615079 | P33: 0.051055621 | Q33: 0.1291345 | R33: 0.029600677 | S33: 0.014345952 | T33: 0.078507458 | U33: 0.0010100298 | V33: 0.044373321 | W33: 0.21514133 | X33: 0.21096532 | Y33: 0.027533096 | Z33: 0.028768739 | AA33: 0.089082701

Sheet OD-MSA
A1: Sum of TRIPS | B1: D-MSA
A2: O-MSA | B2: 0 | C2: 1 | D2: 360 | E2: 680 | F2: 858 | G2: 983 | H2: 999 | I2: 1620 | J2: 2840 | K2: 4480 | L2: 4940 | M2: 5170 | N2: 5775 | O2: 6000 | P2: 6690 | Q2: 6780 | R2: 6920 | S2: 7120 | T2: 7320 | U2: 7360 | V2: 7400 | W2: 7480 | X2: 7485 | Y2: 7500 | Z2: 8120 | AA2: 8720 | AB2: 8780 | AC2: 9340 | AD2: 9999 | AE2: Grand Total
A3: 360 | B3: 1138865 | C3: 390 | D3: 1047085 | E3: 221 | F3: 0 | G3: 0 | H3: 637 | I3: 78 | J3: 208 | K3: 198133 | L3: 0 | M3: 0 | N3: 806 | O3: 468 | P3: 364 | Q3: 18707 | R3: 1144 | S3: 0 | T3: 7098 | U3: 624 | V3: 416 | W3: 611 | X3: 0 | Y3: 78 | Z3: 78 | AA3: 286 | AB3: 0 | AC3: 0 | AD3: 1404 | AE3: 2417701
A4: 680 | B4: 320827 | C4: 104 | D4: 169 | E4: 207935 | F4: 0 | G4: 0 | H4: 0 | I4: 0 | J4: 156 | K4: 7618 | L4: 0 | M4: 0 | N4: 104 | O4: 208 | P4: 0 | Q4: 1755 | R4: 0 | S4: 208 | T4: 0 | U4: 169 | V4: 0 | W4: 351 | X4: 0 | Y4: 0 | Z4: 91 | AA4: 0 | AB4: 1469 | AC4: 0 | AD4: 1222 | AE4: 542386
A5: 1620 | B5: 111722 | C5: 299 | E5: 0 | H5: 78 | I5: 62647 | J5: 78 | K5: 0 | N5: 0 | P5: 65 | Q5: 0 | R5: 247 | S5: 117 | T5: 117 | U5: 0 | V5: 156 | Y5: 0 | AA5: 234 | AB5: 0 | AC5: 1651 | AD5: 1911 | AE5: 179322
A6: 2840 | B6: 405808 | C6: 0 | D6: 117 | E6: 104 | F6: 0 | G6: 0 | H6: 0 | I6: 182 | J6: 250822 | K6: 741 | L6: 1313 | M6: 195 | N6: 377 | O6: 377 | P6: 0 | Q6: 130 | R6: 338 | S6: 520 | T6: 104 | U6: 741 | V6: 91 | W6: 91 | X6: 78 | Y6: 0 | Z6: 143 | AA6: 0 | AB6: 3107 | AC6: 91 | AD6: 8398 | AE6: 673868
A7: 4480 | B7: 4714869 | C7: 1573 | D7: 136591 | E7: 9503 | F7: 0 | G7: 0 | H7: 2301 | I7: 273 | J7: 650 | K7: 3859648 | L7: 0 | M7: 156 | N7: 2743 | O7: 21801 | P7: 1079 | Q7: 38948 | R7: 1235 | S7: 793 | T7: 3419 | U7: 4173 | V7: 520 | W7: 1131 | X7: 0 | Y7: 0 | Z7: 156 | AA7: 611 | AB7: 0 | AC7: 364 | AD7: 6201 | AE7: 8808738
A8: 4940 | B8: 108225 | C8: 0 | D8: 0 | E8: 0 | F8: 0 | H8: 0 | I8: 0 | J8: 572 | K8: 0 | L8: 59956 | M8: 5148 | N8: 52 | O8: 0 | P8: 0 | Q8: 0 | R8: 0 | S8: 0 | T8: 0 | U8: 182 | V8: 949 | W8: 0 | X8: 0 | Y8: 0 | Z8: 117 | AA8: 0 | AB8: 0 | AC8: 0 | AD8: 1456 | AE8: 176657
A9: 5170 | B9: 219609 | C9: 208 | D9: 0 | E9: 0 | F9: 0 | H9: 0 | I9: 0 | J9: 182 | K9: 78 | L9: 3653 | M9: 119210 | N9: 6175 | O9: 0 | P9: 0 | Q9: 169 | R9: 390 | S9: 0 | T9: 0 | U9: 377 | V9: 3458 | W9: 0 | X9: 234 | Y9: 0 | Z9: 8528 | AA9: 208 | AB9: 0 | AC9: 0 | AD9: 611 | AE9: 363090
A10: 5775 | B10: 1036776 | C10: 364 | D10: 468 | E10: 0 | F10: 78 | G10: 0 | H10: 754 | I10: 286 | J10: 169 | K10: 2574 | L10: 0 | M10: 299 | N10: 811031 | O10: 0 | P10: 130 | Q10: 169 | R10: 2340 | S10: 0 | T10: 494 | U10: 144573 | V10: 57941 | W10: 104 | X10: 494 | Y10: 1469 | Z10: 1417 | AA10: 8164 | AB10: 117 | AC10: 0 | AD10: 676 | AE10: 2070887
A11: 6000 | B11: 331552 | C11: 65 | D11: 299 | E11: 481 | F11: 0 | G11: 0 | H11: 0 | I11: 104 | J11: 0 | K11: 76375 | L11: 0 | M11: 0 | N11: 338 | O11: 249158 | P11: 52 | Q11: 676 | R11: 104 | S11: 169 | T11: 533 | U11: 2002 | V11: 65 | W11: 4381 | X11: 0 | Y11: 0 | Z11: 91 | AA11: 0 | AB11: 0 | AC11: 0 | AD11: 663 | AE11: 667108
A12: 6690 | B12: 93327 | C12: 650 | E12: 117 | I12: 91 | J12: 0 | K12: 0 | N12: 520 | P12: 55562 | Q12: 78 | R12: 260 | T12: 52 | U12: 91 | V12: 286 | Y12: 52 | AA12: 0 | AB12: 0 | AD12: 1404 | AE12: 152490
A13: 6780 | B13: 1509872 | C13: 754 | D13: 78507 | E13: 1638 | F13: 0 | G13: 0 | H13: 234 | I13: 117 | J13: 91 | K13: 157287 | L13: 117 | M13: 65 | N13: 377 | O13: 442 | P13: 806 | Q13: 837356 | R13: 767 | S13: 533 | T13: 7917 | U13: 663 | V13: 221 | W13: 325 | X13: 104 | Y13: 117 | Z13: 130 | AA13: 104 | AB13: 0 | AC13: 0 | AD13: 2145 | AE13: 2600689
A14: 6920 | B14: 792038 | C14: 455 | D14: 520 | E14: 0 | F14: 0 | H14: 247 | I14: 533 | J14: 234 | K14: 728 | L14: 0 | M14: 494 | N14: 4628 | O14: 234 | P14: 1066 | Q14: 299 | R14: 644345 | S14: 221 | T14: 949 | U14: 2808 | V14: 1820 | W14: 0 | X14: 0 | Y14: 117 | Z14: 7085 | AA14: 5408 | AB14: 0 | AC14: 1183 | AD14: 12818 | AE14: 1478230
A15: 7120 | B15: 195273 | C15: 91 | D15: 0 | E15: 0 | F15: 0 | G15: 0 | H15: 195 | I15: 0 | J15: 91 | K15: 260 | L15: 0 | M15: 0 | N15: 338 | O15: 143 | P15: 130 | Q15: 143 | R15: 0 | S15: 152750 | T15: 0 | U15: 247 | V15: 2275 | W15: 65 | X15: 6643 | Y15: 0 | Z15: 0 | AA15: 0 | AB15: 0 | AC15: 130 | AD15: 1053 | AE15: 359827
A16: 7320 | B16: 1264757 | C16: 572 | D16: 13065 | E16: 390 | F16: 0 | G16: 117 | H16: 4251 | I16: 130 | J16: 143 | K16: 7631 | L16: 208 | M16: 234 | N16: 1469 | O16: 429 | P16: 130 | Q16: 7046 | R16: 650 | S16: 351 | T16: 1184040 | U16: 2301 | V16: 403 | W16: 91 | X16: 169 | Y16: 91 | Z16: 169 | AA16: 143 | AB16: 39 | AC16: 260 | AD16: 1378 | AE16: 2490657
A17: 7360 | B17: 764140 | C17: 312 | D17: 0 | E17: 0 | F17: 0 | H17: 1118 | I17: 0 | J17: 195 | K17: 1495 | L17: 0 | M17: 338 | N17: 52572 | O17: 0 | P17: 481 | Q17: 260 | R17: 767 | S17: 247 | T17: 351 | U17: 742391 | V17: 54431 | W17: 104 | X17: 624 | Y17: 3978 | Z17: 117 | AA17: 1768 | AB17: 0 | AC17: 195 | AD17: 650 | AE17: 1626534
A18: 7400 | B18: 686517 | C18: 91 | D18: 156 | E18: 195 | F18: 0 | G18: 0 | H18: 182 | I18: 0 | J18: 0 | K18: 975 | L18: 0 | M18: 156 | N18: 36153 | O18: 130 | P18: 234 | Q18: 0 | R18: 1287 | S18: 715 | T18: 221 | U18: 40768 | V18: 714948 | W18: 65 | X18: 4875 | Y18: 273 | Z18: 780 | AA18: 403 | AB18: 0 | AC18: 0 | AD18: 1638 | AE18: 1490762
A19: 7480 | B19: 187317 | C19: 0 | D19: 91 | E19: 0 | F19: 0 | H19: 0 | I19: 0 | J19: 143 | K19: 1599 | L19: 13 | M19: 0 | N19: 156 | O19: 2015 | P19: 65 | Q19: 637 | R19: 0 | S19: 208 | T19: 65 | U19: 377 | V19: 104 | W19: 169559 | X19: 0 | Y19: 0 | Z19: 0 | AA19: 0 | AB19: 0 | AC19: 0 | AD19: 5109 | AE19: 367458
A20: 7485 | B20: 116324 | C20: 0 | D20: 0 | E20: 273 | F20: 0 | G20: 0 | H20: 208 | I20: 0 | J20: 52 | K20: 247 | L20: 0 | M20: 104 | N20: 1053 | O20: 91 | P20: 0 | Q20: 0 | R20: 0 | S20: 4420 | T20: 91 | U20: 2106 | V20: 15444 | W20: 0 | X20: 88868 | Y20: 0 | Z20: 0 | AA20: 0 | AB20: 0 | AC20: 0 | AD20: 247 | AE20: 229528
A21: 7500 | B21: 195936 | C21: 156 | D21: 0 | E21: 0 | H21: 0 | I21: 0 | J21: 0 | K21: 156 | M21: 0 | N21: 3536 | O21: 0 | P21: 130 | Q21: 130 | R21: 325 | S21: 0 | T21: 273 | U21: 27222 | V21: 351 | Y21: 146120 | Z21: 130 | AA21: 3393 | AB21: 0 | AC21: 0 | AD21: 780 | AE21: 378638
A22: 8120 | B22: 154115 | C22: 0 | D22: 0 | E22: 0 | F22: 0 | H22: 117 | I22: 0 | J22: 91 | K22: 65 | L22: 91 | M22: 4927 | N22: 11791 | O22: 0 | P22: 0 | Q22: 0 | R22: 2301 | S22: 0 | T22: 0 | U22: 1313 | V22: 3159 | W22: 65 | X22: 0 | Y22: 0 | Z22: 85462 | AA22: 234 | AB22: 0 | AC22: 0 | AD22: 91 | AE22: 263822
A23: 8720 | B23: 240682 | C23: 273 | D23: 169 | E23: 0 | F23: 0 | G23: 0 | H23: 494 | I23: 0 | J23: 0 | K23: 182 | L23: 52 | M23: 91 | N23: 36062 | O23: 0 | P23: 0 | Q23: 0 | R23: 7215 | S23: 78 | T23: 91 | U23: 13832 | V23: 1326 | W23: 0 | X23: 0 | Y23: 2899 | Z23: 156 | AA23: 147940 | AB23: 0 | AC23: 104 | AD23: 377 | AE23: 452023
A24: 8780 | B24: 192426 | C24: 0 | D24: 273 | E24: 2626 | F24: 0 | G24: 0 | H24: 91 | I24: 0 | J24: 5629 | K24: 494 | L24: 0 | M24: 0 | N24: 91 | O24: 0 | P24: 0 | Q24: 130 | R24: 0 | S24: 65 | T24: 0 | U24: 91 | V24: 91 | W24: 0 | X24: 0 | Y24: 0 | Z24: 117 | AA24: 0 | AB24: 106184 | AC24: 0 | AD24: 2379 | AE24: 310687
A25: 9340 | B25: 74074 | C25: 0 | E25: 0 | H25: 0 | I25: 663 | J25: 0 | K25: 0 | M25: 78 | N25: 91 | P25: 0 | Q25: 0 | R25: 6357 | S25: 0 | T25: 0 | U25: 0 | V25: 0 | Y25: 0 | Z25: 78 | AA25: 364 | AB25: 0 | AC25: 38493 | AD25: 715 | AE25: 120913
A26: 9999 | B26: 776880 | C26: 33280 | D26: 0 | E26: 650 | F26: 0 | G26: 0 | H26: 143 | I26: 1430 | J26: 10257 | K26: 1690 | L26: 1235 | M26: 2262 | N26: 1924 | O26: 312 | P26: 3705 | Q26: 806 | R26: 7267 | S26: 1482 | T26: 637 | U26: 1898 | V26: 5499 | W26: 6175 | X26: 351 | Y26: 1989 | Z26: 3224 | AA26: 1001 | AB26: 1599 | AC26: 767 | AD26: 394589 | AE26: 1261052
A27: Grand Total | B27: 15631931 | C27: 39637 | D27: 1277510 | E27: 224133 | F27: 78 | G27: 117 | H27: 11050 | I27: 66534 | J27: 269763 | K27: 4317976 | L27: 66638 | M27: 133757 | N27: 972387 | O27: 275808 | P27: 63999 | Q27: 907439 | R27: 677339 | S27: 162877 | T27: 1206452 | U27: 988949 | V27: 863954 | W27: 183118 | X27: 102440 | Y27: 157183 | Z27: 108069 | AA27: 170261 | AB27: 112515 | AC27: 43238 | AD27: 447915 | AE27: 29483067

Sheet OD-CMSA(Val)
A1: Sum of TRIPS | B1: D-CMSA | U1: DMLPUMA
A2: O-CMSA | B2: 0 | C2: 680 | D2: 1620 | E2: 2840 | F2: 4472 | G2: 4940 | H2: 5170 | I2: 6690 | J2: 6920 | K2: 7120 | L2: 7320 | M2: 7362 | N2: 7480 | O2: 8120 | P2: 8780 | Q2: 9340 | R2: 9999 | S2: Grand Total | U2: =A2 -> O-CMSA | V2: NAME | W2: Residents who Work of DMLPUMA | X2: Residents Who Work In DML PUMA | Y2: Total Workers | Z2: Total Population | AA2: ExportedLabor | AC2: Resident Workers | AD2: InMetroWorkers | AE2: Non-MetroWorkers | AF2: ImportedWorkers | AG2: =U2 -> O-CMSA | AH2: PredictedTollShare | AJ2: TotalPop*TollShare
A3: 680 | B3: 320827 | C3: 207935 | D3: 0 | E3: 156 | F3: 9750 | G3: 0 | H3: 0 | I3: 0 | J3: 0 | K3: 208 | L3: 0 | M3: 273 | N3: 351 | O3: 91 | P3: 1469 | Q3: 0 | R3: 1222 | S3: 542386 | U3: =A3 -> 680 | V3: Bakersfield | W3: =SUM(C3:R3)-MAX(C3:R3) -> 13520 | X3: =MAX(C3:R3) -> 207935 | Y3: =SUM(C3:R3) -> 221455 | Z3: =S3 -> 542386 | AA3: =W3/Y3 -> 0.061050778 | AC3: 224133 | AD3: 207935 | AE3: 16198 | AF3: 0.07226959 | AG3: =U3 -> 680 | AH3: =-0.0364+0.00000000386*Z3+0.844*AF3 -> 0.026689144 | AJ3: =Z3*AH3 -> 14475.818
A4: 1620 | B4: 111722 | C4: 0 | D4: 62647 | E4: 78 | F4: 0 | G4: 0 | H4: 0 | I4: 65 | J4: 247 | K4: 117 | L4: 117 | M4: 390 | P4: 0 | Q4: 1651 | R4: 1911 | S4: 179322 | U4: =A4 -> 1620 | V4: Chico | W4: =SUM(C4:R4)-MAX(C4:R4) -> 4576 | X4: =MAX(C4:R4) -> 62647 | Y4: =SUM(C4:R4) -> 67223 | Z4: =S4 -> 179322 | AA4: =W4/Y4 -> 0.06807194 | AC4: 66534 | AD4: 62647 | AE4: 3887 | AF4: 0.058421258 | AG4: =U4 -> 1620 | AH4: =-0.0364+0.00000000386*Z4+0.844*AF4 -> 0.013599725 | AJ4: =Z4*AH4 -> 2438.7299
A5: 2840 | B5: 405808 | C5: 104 | D5: 182 | E5: 250822 | F5: 1365 | G5: 1313 | H5: 195 | I5: 0 | J5: 338 | K5: 520 | L5: 104 | M5: 1287 | N5: 91 | O5: 143 | P5: 3107 | Q5: 91 | R5: 8398 | S5: 673868 | U5: =A5 -> 2840 | V5: Fresno | W5: =SUM(C5:R5)-MAX(C5:R5) -> 17238 | X5: =MAX(C5:R5) -> 250822 | Y5: =SUM(C5:R5) -> 268060 | Z5: =S5 -> 673868 | AA5: =W5/Y5 -> 0.064306499 | AC5: 269763 | AD5: 250822 | AE5: 18941 | AF5: 0.070213484 | AG5: =U5 -> 2840 | AH5: =-0.0364+0.00000000386*Z5+0.844*AF5 -> 0.025461311 | AJ5: =Z5*AH5 -> 17157.563
A6: 4472 | B6: 7695158 | C6: 11843 | D6: 572 | E6: 949 | F6: 6721481 | G6: 117 | H6: 221 | I6: 2301 | J6: 3250 | K6: 1495 | L6: 18967 | M6: 14248 | N6: 6448 | O6: 455 | P6: 0 | Q6: 364 | R6: 10413 | S6: 14494236 | U6: =A6 -> 4472 | V6: Los Angeles | W6: =SUM(C6:R6)-MAX(C6:R6) -> 71643 | X6: =MAX(C6:R6) -> 6721481 | Y6: =SUM(C6:R6) -> 6793124 | Z6: =S6 -> 14494236 | AA6: =W6/Y6 -> 0.0105464 | AC6: 6778733 | AD6: 6721481 | AE6: 57252 | AF6: 0.0084458261 | AG6: =U6 -> 4472 | AH6: =-0.0364+0.00000000386*Z6+0.844*AF6 -> 0.026676028 | AJ6: =Z6*AH6 -> 386648.65
A7: 4940 | B7: 108225 | C7: 0 | D7: 0 | E7: 572 | F7: 0 | G7: 59956 | H7: 5148 | I7: 0 | J7: 0 | K7: 0 | L7: 0 | M7: 1183 | N7: 0 | O7: 117 | P7: 0 | Q7: 0 | R7: 1456 | S7: 176657 | U7: =A7 -> 4940 | V7: Merced | W7: =SUM(C7:R7)-MAX(C7:R7) -> 8476 | X7: =MAX(C7:R7) -> 59956 | Y7: =SUM(C7:R7) -> 68432 | Z7: =S7 -> 176657 | AA7: =W7/Y7 -> 0.12386018 | AC7: 66638 | AD7: 59956 | AE7: 6682 | AF7: 0.10027312 | AG7: =U7 -> 4940 | AH7: =-0.0364+0.00000000386*Z7+0.844*AF7 -> 0.048912407 | AJ7: =Z7*AH7 -> 8640.7191
A8: 5170 | B8: 219609 | C8: 0 | D8: 0 | E8: 182 | F8: 247 | G8: 3653 | H8: 119210 | I8: 0 | J8: 390 | K8: 0 | L8: 0 | M8: 10452 | N8: 0 | O8: 8528 | P8: 0 | Q8: 0 | R8: 611 | S8: 363090 | U8: =A8 -> 5170 | V8: Modesto | W8: =SUM(C8:R8)-MAX(C8:R8) -> 24063 | X8: =MAX(C8:R8) -> 119210 | Y8: =SUM(C8:R8) -> 143273 | Z8: =S8 -> 363090 | AA8: =W8/Y8 -> 0.16795209 | AC8: 133757 | AD8: 119210 | AE8: 14547 | AF8: 0.10875692 | AG8: =U8 -> 5170 | AH8: =-0.0364+0.00000000386*Z8+0.844*AF8 -> 0.056792372 | AJ8: =Z8*AH8 -> 20620.742
A9: 6690 | B9: 93327 | C9: 117 | D9: 91 | E9: 0 | F9: 78 | G9: 0 | H9: 0 | I9: 55562 | J9: 260 | K9: 0 | L9: 52 | M9: 949 | N9: 0 | O9: 0 | P9: 0 | Q9: 0 | R9: 1404 | S9: 152490 | U9: =A9 -> 6690 | V9: Redding | W9: =SUM(C9:R9)-MAX(C9:R9) -> 2951 | X9: =MAX(C9:R9) -> 55562 | Y9: =SUM(C9:R9) -> 58513 | Z9: =S9 -> 152490 | AA9: =W9/Y9 -> 0.050433237 | AC9: 63999 | AD9: 55562 | AE9: 8437 | AF9: 0.13183018 | AG9: =U9 -> 6690 | AH9: =-0.0364+0.00000000386*Z9+0.844*AF9 -> 0.075453287 | AJ9: =Z9*AH9 -> 11505.872
A10: 6920 | B10: 792038 | C10: 0 | D10: 533 | E10: 234 | F10: 1781 | G10: 0 | H10: 494 | I10: 1066 | J10: 644345 | K10: 221 | L10: 949 | M10: 14781 | N10: 0 | O10: 7085 | P10: 0 | Q10: 1183 | R10: 12818 | S10: 1478230 | U10: =A10 -> 6920 | V10: Sacramento | W10: =SUM(C10:R10)-MAX(C10:R10) -> 41145 | X10: =MAX(C10:R10) -> 644345 | Y10: =SUM(C10:R10) -> 685490 | Z10: =S10 -> 1478230 | AA10: =W10/Y10 -> 0.060022757 | AC10: 677339 | AD10: 644345 | AE10: 32994 | AF10: 0.048711207 | AG10: =U10 -> 6920 | AH10: =-0.0364+0.00000000386*Z10+0.844*AF10 -> 0.010418226 | AJ10: =Z10*AH10 -> 15400.535
A11: 7120 | B11: 195273 | C11: 0 | D11: 0 | E11: 91 | F11: 546 | G11: 0 | H11: 0 | I11: 130 | J11: 0 | K11: 152750 | L11: 0 | M11: 9503 | N11: 65 | O11: 0 | P11: 0 | Q11: 130 | R11: 1053 | S11: 359827 | U11: =A11 -> 7120 | V11: Salinas | W11: =SUM(C11:R11)-MAX(C11:R11) -> 11518 | X11: =MAX(C11:R11) -> 152750 | Y11: =SUM(C11:R11) -> 164268 | Z11: =S11 -> 359827 | AA11: =W11/Y11 -> 0.070117126 | AC11: 162877 | AD11: 152750 | AE11: 10127 | AF11: 0.062175752 | AG11: =U11 -> 7120 | AH11: =-0.0364+0.00000000386*Z11+0.844*AF11 -> 0.017465267 | AJ11: =Z11*AH11 -> 6284.4747
A12: 7320 | B12: 1264757 | C12: 390 | D12: 130 | E12: 143 | F12: 28171 | G12: 208 | H12: 234 | I12: 130 | J12: 650 | K12: 351 | L12: 1184040 | M12: 4576 | N12: 91 | O12: 169 | P12: 39 | Q12: 260 | R12: 1378 | S12: 2490657 | U12: =A12 -> 7320 | V12: San Diego | W12: =SUM(C12:R12)-MAX(C12:R12) -> 36920 | X12: =MAX(C12:R12) -> 1184040 | Y12: =SUM(C12:R12) -> 1220960 | Z12: =S12 -> 2490657 | AA12: =W12/Y12 -> 0.030238501 | AC12: 1206452 | AD12: 1184040 | AE12: 22412 | AF12: 0.018576785 | AG12: =U12 -> 7320 | AH12: =-0.0364+0.00000000386*Z12+0.844*AF12 -> -0.011107257 | AJ12: =Z12*AH12 -> -27664.367
A13: 7362 | B13: 3040375 | C13: 468 | D13: 286 | E13: 416 | F13: 7202 | G13: 52 | H13: 988 | I13: 975 | J13: 11934 | K13: 5460 | L13: 1521 | M13: 3167008 | N13: 273 | O13: 2600 | P13: 117 | Q13: 299 | R13: 4368 | S13: 6248372 | U13: =A13 -> 7362 | V13: San Francisco | W13: =SUM(C13:R13)-MAX(C13:R13) -> 36959 | X13: =MAX(C13:R13) -> 3167008 | Y13: =SUM(C13:R13) -> 3203967 | Z13: =S13 -> 6248372 | AA13: =W13/Y13 -> 0.011535387 | AC13: 3255174 | AD13: 3167008 | AE13: 88166 | AF13: 0.027084881 | AG13: =U13 -> 7362 | AH13: =-0.0364+0.00000000386*Z13+0.844*AF13 -> 0.010578355 | AJ13: =Z13*AH13 -> 66097.5
A14: 7480 | B14: 187317 | C14: 0 | D14: 0 | E14: 143 | F14: 4342 | G14: 13 | H14: 0 | I14: 65 | J14: 0 | K14: 208 | L14: 65 | M14: 637 | N14: 169559 | O14: 0 | P14: 0 | Q14: 0 | R14: 5109 | S14: 367458 | U14: =A14 -> 7480 | V14: Santa Barbara | W14: =SUM(C14:R14)-MAX(C14:R14) -> 10582 | X14: =MAX(C14:R14) -> 169559 | Y14: =SUM(C14:R14) -> 180141 | Z14: =S14 -> 367458 | AA14: =W14/Y14 -> 0.058742874 | AC14: 183118 | AD14: 169559 | AE14: 13559 | AF14: 0.074045151 | AG14: =U14 -> 7480 | AH14: =-0.0364+0.00000000386*Z14+0.844*AF14 -> 0.027512496 | AJ14: =Z14*AH14 -> 10109.687
A15: 8120 | B15: 154115 | C15: 0 | D15: 0 | E15: 91 | F15: 65 | G15: 91 | H15: 4927 | I15: 0 | J15: 2301 | K15: 0 | L15: 0 | M15: 16497 | N15: 65 | O15: 85462 | P15: 0 | Q15: 0 | R15: 91 | S15: 263822 | U15: =A15 -> 8120 | V15: Stockton | W15: =SUM(C15:R15)-MAX(C15:R15) -> 24128 | X15: =MAX(C15:R15) -> 85462 | Y15: =SUM(C15:R15) -> 109590 | Z15: =S15 -> 263822 | AA15: =W15/Y15 -> 0.22016607 | AC15: 108069 | AD15: 85462 | AE15: 22607 | AF15: 0.20919042 | AG15: =U15 -> 8120 | AH15: =-0.0364+0.00000000386*Z15+0.844*AF15 -> 0.14117507 | AJ15: =Z15*AH15 -> 37245.09
A16: 8780 | B16: 192426 | C16: 2626 | D16: 0 | E16: 5629 | F16: 897 | G16: 0 | H16: 0 | I16: 0 | J16: 0 | K16: 65 | L16: 0 | M16: 273 | N16: 0 | O16: 117 | P16: 106184 | Q16: 0 | R16: 2379 | S16: 310687 | U16: =A16 -> 8780 | V16: Visalia | W16: =SUM(C16:R16)-MAX(C16:R16) -> 11986 | X16: =MAX(C16:R16) -> 106184 | Y16: =SUM(C16:R16) -> 118170 | Z16: =S16 -> 310687 | AA16: =W16/Y16 -> 0.10143014 | AC16: 112515 | AD16: 106184 | AE16: 6331 | AF16: 0.056268053 | AG16: =U16 -> 8780 | AH16: =-0.0364+0.00000000386*Z16+0.844*AF16 -> 0.012289489 | AJ16: =Z16*AH16 -> 3818.1844
A17: 9340 | B17: 74074 | C17: 0 | D17: 663 | E17: 0 | F17: 0 | H17: 78 | I17: 0 | J17: 6357 | K17: 0 | L17: 0 | M17: 455 | O17: 78 | P17: 0 | Q17: 38493 | R17: 715 | S17: 120913 | U17: =A17 -> 9340 | V17: Yuba | W17: =SUM(C17:R17)-MAX(C17:R17) -> 8346 | X17: =MAX(C17:R17) -> 38493 | Y17: =SUM(C17:R17) -> 46839 | Z17: =S17 -> 120913 | AA17: =W17/Y17 -> 0.17818485 | AC17: 43238 | AD17: 38493 | AE17: 4745 | AF17: 0.10974143 | AG17: =U17 -> 9340 | AH17: =-0.0364+0.00000000386*Z17+0.844*AF17 -> 0.056688492 | AJ17: =Z17*AH17 -> 6854.3756
A18: 9999 | B18: 776880 | C18: 650 | D18: 1430 | E18: 10257 | F18: 2808 | G18: 1235 | H18: 2262 | I18: 3705 | J18: 7267 | K18: 1482 | L18: 637 | M18: 12662 | N18: 6175 | O18: 3224 | P18: 1599 | Q18: 767 | R18: 394589 | S18: 1261052 | U18: =A18 -> 9999 | V18: NonMetro | W18: =SUM(C18:R18)-MAX(C18:R18) -> 56160 | X18: =MAX(C18:R18) -> 394589 | Y18: =SUM(C18:R18) -> 450749 | Z18: =S18 -> 1261052 | AA18: =W18/Y18 -> 0.12459262 | AC18: 447915 | AD18: 394589 | AE18: 53326 | AF18: 0.11905384 | AG18: =U18 -> 9999 | AH18: =-0.0364+0.00000000386*Z18+0.844*AF18 -> 0.0689491 | AJ18: =Z18*AH18 -> 86948.401
A19: Grand Total | B19: 15631931 | C19: 224133 | D19: 66534 | E19: 269763 | F19: 6778733 | G19: 66638 | H19: 133757 | I19: 63999 | J19: 677339 | K19: 162877 | L19: 1206452 | M19: 3255174 | N19: 183118 | O19: 108069 | P19: 112515 | Q19: 43238 | R19: 447915 | S19: 29483067
V20: TOTAL | W20: =SUM(W3:W18) -> 380211 | X20: =SUM(X3:X18) -> 13420043 | Y20: =SUM(Y3:Y18) -> 13800254 | Z20: =SUM(Z3:Z18) -> 29483067 | AC20: =SUM(AC3:AC18) -> 13800254 | AD20: =SUM(AD3:AD18) -> 13420043 | AE20: =SUM(AE3:AE18) -> 380211 | AI20: TOTAL | AJ20: =SUM(AJ3:AJ18) -> 666581.97
B21: Resident Workers | C21: =SUM(C3:C18) -> 224133 | D21: =SUM(D3:D18) -> 66534 | E21: =SUM(E3:E18) -> 269763 | F21: =SUM(F3:F18) -> 6778733 | G21: =SUM(G3:G18) -> 66638 | H21: =SUM(H3:H18) -> 133757 | I21: =SUM(I3:I18) -> 63999 | J21: =SUM(J3:J18) -> 677339 | ... R21: =SUM(R3:R18) -> 447915 | AI21: AVERAGE | AJ21: =AJ20/Z20 -> 0.022608977
B22: InMetroWorkers | C22: =MAX(C3:C18) -> 207935 | D22: =MAX(D3:D18) -> 62647 | E22: =MAX(E3:E18) -> 250822 | F22: =MAX(F3:F18) -> 6721481 | G22: =MAX(G3:G18) -> 59956 | H22: =MAX(H3:H18) -> 119210 | I22: =MAX(I3:I18) -> 55562 | J22: =MAX(J3:J18) -> 644345 | ... R22: =MAX(R3:R18) -> 394589
B23: Non-MetroWorkers | C23: =C21-C22 -> 16198 | D23: =D21-D22 -> 3887 | E23: =E21-E22 -> 18941 | F23: =F21-F22 -> 57252 | G23: =G21-G22 -> 6682 | H23: =H21-H22 -> 14547 | I23: =I21-I22 -> 8437 | J23: =J21-J22 -> 32994 | ... R23: =R21-R22 -> 53326
B24: ImportedWorkers | C24: =C23/C21 -> 0.07226959 | D24: =D23/D21 -> 0.058421258 | E24: =E23/E21 -> 0.070213484 | F24: =F23/F21 -> 0.0084458261 | G24: =G23/G21 -> 0.10027312 | H24: =H23/H21 -> 0.10875692 | I24: =I23/I21 -> 0.13183018 | J24: =J23/J21 -> 0.048711207 | ... R24: =R23/R21 -> 0.11905384

Sheet OD-CMSA
A1: Sum of TRIPS | B1: D-CMSA
A2: O-CMSA | B2: 0 | C2: 1 | D2: 680 | E2: 858 | F2: 983 | G2: 999 | H2: 1620 | I2: 2840 | J2: 4472 | K2: 4940 | L2: 5170 | M2: 6690 | N2: 6920 | O2: 7120 | P2: 7320 | Q2: 7362 | R2: 7480 | S2: 8120 | T2: 8780 | U2: 9340 | V2: 9999 | W2: Grand Total
A3: 680 | B3: 320827 | C3: 104 | D3: 207935 | E3: 0 | F3: 0 | G3: 0 | H3: 0 | I3: 156 | J3: 9750 | K3: 0 | L3: 0 | M3: 0 | N3: 0 | O3: 208 | P3: 0 | Q3: 273 | R3: 351 | S3: 91 | T3: 1469 | U3: 0 | V3: 1222 | W3: 542386
A4: 1620 | B4: 111722 | C4: 299 | D4: 0 | G4: 78 | H4: 62647 | I4: 78 | J4: 0 | M4: 65 | N4: 247 | O4: 117 | P4: 117 | Q4: 390 | T4: 0 | U4: 1651 | V4: 1911 | W4: 179322
A5: 2840 | B5: 405808 | C5: 0 | D5: 104 | E5: 0 | F5: 0 | G5: 0 | H5: 182 | I5: 250822 | J5: 1365 | K5: 1313 | L5: 195 | M5: 0 | N5: 338 | O5: 520 | P5: 104 | Q5: 1287 | R5: 91 | S5: 143 | T5: 3107 | U5: 91 | V5: 8398 | W5: 673868
A6: 4472 | B6: 7695158 | C6: 2782 | D6: 11843 | E6: 0 | F6: 0 | G6: 3172 | H6: 572 | I6: 949 | J6: 6721481 | K6: 117 | L6: 221 | M6: 2301 | N6: 3250 | O6: 1495 | P6: 18967 | Q6: 14248 | R6: 6448 | S6: 455 | T6: 0 | U6: 364 | V6: 10413 | W6: 14494236
A7: 4940 | B7: 108225 | C7: 0 | D7: 0 | E7: 0 | G7: 0 | H7: 0 | I7: 572 | J7: 0 | K7: 59956 | L7: 5148 | M7: 0 | N7: 0 | O7: 0 | P7: 0 | Q7: 1183 | R7: 0 | S7: 117 | T7: 0 | U7: 0 | V7: 1456 | W7: 176657
A8: 5170 | B8: 219609 | C8: 208 | D8: 0 | E8: 0 | G8: 0 | H8: 0 | I8: 182 | J8: 247 | K8: 3653 | L8: 119210 | M8: 0 | N8: 390 | O8: 0 | P8: 0 | Q8: 10452 | R8: 0 | S8: 8528 | T8: 0 | U8: 0 | V8: 611 | W8: 363090
A9: 6690 | B9: 93327 | C9: 650 | D9: 117 | H9: 91 | I9: 0 | J9: 78 | M9: 55562 | N9: 260 | P9: 52 | Q9: 949 | T9: 0 | V9: 1404 | W9: 152490
A10: 6920 | B10: 792038 | C10: 455 | D10: 0 | E10: 0 | G10: 247 | H10: 533 | I10: 234 | J10: 1781 | K10: 0 | L10: 494 | M10: 1066 | N10: 644345 | O10: 221 | P10: 949 | Q10: 14781 | R10: 0 | S10: 7085 | T10: 0 | U10: 1183 | V10: 12818 | W10: 1478230
A11: 7120 | B11: 195273 | C11: 91 | D11: 0 | E11: 0 | F11: 0 | G11: 195 | H11: 0 | I11: 91 | J11: 546 | K11: 0 | L11: 0 | M11: 130 | N11: 0 | O11: 152750 | P11: 0 | Q11: 9503 | R11: 65 | S11: 0 | T11: 0 | U11: 130 | V11: 1053 | W11: 359827
A12: 7320 | B12: 1264757 | C12: 572 | D12: 390 | E12: 0 | F12: 117 | G12: 4251 | H12: 130 | I12: 143 | J12: 28171 | K12: 208 | L12: 234 | M12: 130 | N12: 650 | O12: 351 | P12: 1184040 | Q12: 4576 | R12: 91 | S12: 169 | T12: 39 | U12: 260 | V12: 1378 | W12: 2490657
A13: 7362 | B13: 3040375 | C13: 1196 | D13: 468 | E13: 78 | F13: 0 | G13: 2756 | H13: 286 | I13: 416 | J13: 7202 | K13: 52 | L13: 988 | M13: 975 | N13: 11934 | O13: 5460 | P13: 1521 | Q13: 3167008 | R13: 273 | S13: 2600 | T13: 117 | U13: 299 | V13: 4368 | W13: 6248372
A14: 7480 | B14: 187317 | C14: 0 | D14: 0 | E14: 0 | G14: 0 | H14: 0 | I14: 143 | J14: 4342 | K14: 13 | L14: 0 | M14: 65 | N14: 0 | O14: 208 | P14: 65 | Q14: 637 | R14: 169559 | S14: 0 | T14: 0 | U14: 0 | V14: 5109 | W14: 367458
A15: 8120 | B15: 154115 | C15: 0 | D15: 0 | E15: 0 | G15: 117 | H15: 0 | I15: 91 | J15: 65 | K15: 91 | L15: 4927 | M15: 0 | N15: 2301 | O15: 0 | P15: 0 | Q15: 16497 | R15: 65 | S15: 85462 | T15: 0 | U15: 0 | V15: 91 | W15: 263822
A16: 8780 | B16: 192426 | C16: 0 | D16: 2626 | E16: 0 | F16: 0 | G16: 91 | H16: 0 | I16: 5629 | J16: 897 | K16: 0 | L16: 0 | M16: 0 | N16: 0 | O16: 65 | P16: 0 | Q16: 273 | R16: 0 | S16: 117 | T16: 106184 | U16: 0 | V16: 2379 | W16: 310687
A17: 9340 | B17: 74074 | C17: 0 | D17: 0 | G17: 0 | H17: 663 | I17: 0 | J17: 0 | L17: 78 | M17: 0 | N17: 6357 | O17: 0 | P17: 0 | Q17: 455 | S17: 78 | T17: 0 | U17: 38493 | V17: 715 | W17: 120913
A18: 9999 | B18: 776880 | C18: 33280 | D18: 650 | E18: 0 | F18: 0 | G18: 143 | H18: 1430 | I18: 10257 | J18: 2808 | K18: 1235 | L18: 2262 | M18: 3705 | N18: 7267 | O18: 1482 | P18: 637 | Q18: 12662 | R18: 6175 | S18: 3224 | T18: 1599 | U18: 767 | V18: 394589 | W18: 1261052
A19: Grand Total | B19: 15631931 | C19: 39637 | D19: 224133 | E19: 78 | F19: 117 | G19: 11050 | H19: 66534 | I19: 269763 | J19: 6778733 | K19: 66638 | L19: 133757 | M19: 63999 | N19: 677339 | O19: 162877 | P19: 1206452 | Q19: 3255174 | R19: 183118 | S19: 108069 | T19: 112515 | U19: 43238 | V19: 447915 | W19: 29483067

Sheet MASTER6
B1: O-INTPUMA | C1: D-INTPUMA | D1: TRIPS | E1: O-MSA | F1: D-MSA | G1: O-CMSA | H1: D-CMSA
A2: =B2*1000+C2 -> 1000 | B2: 1 | C2: 0 | D2: 70434 | E2: =VLOOKUP(B2,'MSA-Lookup'!$H$2:$I$86,2) -> 9999 | F2: =IF(C2>1,IF(C2<99,VLOOKUP(C2,'MSA-Lookup'!$H$1:$I$86,2),C2),C2) -> 0 | G2: =VLOOKUP(E2,'MSA-Lookup'!$AA$1:$AB$25,2) -> 9999 | H2: =IF(C2>1,IF(C2<99,VLOOKUP(F2,'MSA-Lookup'!$AA$1:$AB$25,2),C2),C2) -> 0
A3: =B3*1000+C3 -> 1001 | B3: 1 | C3: 1 | D3: 32903 | E3: =VLOOKUP(B3,'MSA-Lookup'!$H$2:$I$86,2) -> 9999 | F3: =IF(C3>1,IF(C3<99,VLOOKUP(C3,'MSA-Lookup'!$H$1:$I$86,2),C3),C3) -> 1 | G3: =VLOOKUP(E3,'MSA-Lookup'!$AA$1:$AB$25,2) -> 9999 | H3: =IF(C3>1,IF(C3<99,VLOOKUP(F3,'MSA-Lookup'!$AA$1:$AB$25,2),C3),C3) -> 1
A4: =B4*1000+C4 -> 1002 | B4: 1 | C4: 2 | D4: 221 | E4: =VLOOKUP(B4,'MSA-Lookup'!$H$2:$I$86,2) -> 9999 | F4: =IF(C4>1,IF(C4<99,VLOOKUP(C4,'MSA-Lookup'!$H$1:$I$86,2),C4),C4) -> 9999 | G4: =VLOOKUP(E4,'MSA-Lookup'!$AA$1:$AB$25,2) -> 9999 | H4: =IF(C4>1,IF(C4<99,VLOOKUP(F4,'MSA-Lookup'!$AA$1:$AB$25,2),C4),C4) -> 9999
A5: =B5*1000+C5 -> 1003 | B5: 1 | C5: 3 | D5: 780 | E5: =VLOOKUP(B5,'MSA-Lookup'!$H$2:$I$86,2) -> 9999 | F5: =IF(C5>1,IF(C5<99,VLOOKUP(C5,'MSA-Lookup'!$H$1:$I$86,2),C5),C5) -> 6690 | G5: =VLOOKUP(E5,'MSA-Lookup'!$AA$1:$AB$25,2) -> 9999 | H5: =IF(C5>1,IF(C5<99,VLOOKUP(F5,'MSA-Lookup'!$AA$1:$AB$25,2),C5),C5) -> 6690
A6: =B6*1000+C6 -> 1004 | B6: 1 | C6: 4 | D6: 104 | E6: =VLOOKUP(B6,'MSA-Lookup'!$H$2:$I$86,2) -> 9999 | F6: =IF(C6>1,IF(C6<99,VLOOKUP(C6,'MSA-Lookup'!$H$1:$I$86,2),C6),C6) -> 9999 | G6: =VLOOKUP(E6,'MSA-Lookup'!$AA$1:$AB$25,2) -> 9999 | H6: =IF(C6>1,IF(C6<99,VLOOKUP(F6,'MSA-Lookup'!$AA$1:$AB$25,2),C6),C6) -> 9999
A7: =B7*1000+C7 -> 1005 | B7: 1 | C7: 5 | D7: 65 | E7: =VLOOKUP(B7,'MSA-Lookup'!$H$2:$I$86,2) -> 9999 | F7: =IF(C7>1,IF(C7<99,VLOOKUP(C7,'MSA-Lookup'!$H$1:$I$86,2),C7),C7) -> 9999 | G7: =VLOOKUP(E7,'MSA-Lookup'!$AA$1:$AB$25,2) -> 9999 | H7: =IF(C7>1,IF(C7<99,VLOOKUP(F7,'MSA-Lookup'!$AA$1:$AB$25,2),C7),C7) -> 9999
A8: =B8*1000+C8 -> 1006 | B8: 1 | C8: 6 | D8: 117 | E8: =VLOOKUP(B8,'MSA-Lookup'!$H$2:$I$86,2) -> 9999 | F8: =IF(C8>1,IF(C8<99,VLOOKUP(C8,'MSA-Lookup'!$H$1:$I$86,2),C8),C8) -> 1620 | G8: =VLOOKUP(E8,'MSA-Lookup'!$AA$1:$AB$25,2) -> 9999 | H8: =IF(C8>1,IF(C8<99,VLOOKUP(F8,'MSA-Lookup'!$AA$1:$AB$25,2),C8),C8) -> 1620
A9: =B9*1000+C9 -> 1007 | B9: 1 | C9: 7 | D9: 403 | E9: =VLOOKUP(B9,'MSA-Lookup'!$H$2:$I$86,2) -> 9999 | F9: =IF(C9>1,IF(C9<99,VLOOKUP(C9,'MSA-Lookup'!$H$1:$I$86,2),C9),C9) -> 9999 | G9: =VLOOKUP(E9,'MSA-Lookup'!$AA$1:$AB$25,2) -> 9999 | H9: =IF(C9>1,IF(C9<99,VLOOKUP(F9,'MSA-Lookup'!$AA$1:$AB$25,2),C9),C9) -> 9999
A10: =B10*1000+C10 -> 1014 | B10: 1 | C10: 14 | D10: 65 | E10: =VLOOKUP(B10,'MSA-Lookup'!$H$2:$I$86,2) -> 9999 | F10: =IF(C10>1,IF(C10<99,VLOOKUP(C10,'MSA-Lookup'!$H$1:$I$86,2),C10),C10) -> 7500 | G10: =VLOOKUP(E10,'MSA-Lookup'!$AA$1:$AB$25,2) -> 9999 | H10: =IF(C10>1,IF(C10<99,VLOOKUP(F10,'MSA-Lookup'!$AA$1:$AB$25,2),C10),C10) -> 7362
A11: =B11*1000+C11 -> 1016 | B11: 1 | C11: 16 | D11: 273 | E11: =VLOOKUP(B11,'MSA-Lookup'!$H$2:$I$86,2) -> 9999 | F11: =IF(C11>1,IF(C11<99,VLOOKUP(C11,'MSA-Lookup'!$H$1:$I$86,2),C11),C11) -> 8720 | G11: =VLOOKUP(E11,'MSA-Lookup'!$AA$1:$AB$25,2) -> 9999 | H11: =IF(C11>1,IF(C11<99,VLOOKUP(F11,'MSA-Lookup'!$AA$1:$AB$25,2),C11),C11) -> 7362
A12: =B12*1000+C12 -> 1019 | B12: 1 | C12: 19 | D12: 26 | E12: =VLOOKUP(B12,'MSA-Lookup'!$H$2:$I$86,2) -> 9999 | F12: =IF(C12>1,IF(C12<99,VLOOKUP(C12,'MSA-Lookup'!$H$1:$I$86,2),C12),C12) -> 7360 | G12: =VLOOKUP(E12,'MSA-Lookup'!$AA$1:$AB$25,2) -> 9999 | H12: =IF(C12>1,IF(C12<99,VLOOKUP(F12,'MSA-Lookup'!$AA$1:$AB$25,2),C12),C12) -> 7362
A13: =B13*1000+C13 -> 1026 | B13: 1 | C13: 26 | D13: 104 | E13: =VLOOKUP(B13,'MSA-Lookup'!$H$2:$I$86,2) -> 9999 | F13: =IF(C13>1,IF(C13<99,VLOOKUP(C13,'MSA-Lookup'!$H$1:$I$86,2),C13),C13) -> 9999 | G13: =VLOOKUP(E13,'MSA-Lookup'!$AA$1:$AB$25,2) -> 9999 | H13: =IF(C13>1,IF(C13<99,VLOOKUP(F13,'MSA-Lookup'!$AA$1:$AB$25,2),C13),C13) -> 9999
... A6334: =B6334*1000+C6334 -> 84999 | B6334: 84 | C6334: 999 | D6334: 143 | E6334: =VLOOKUP(B6334,'MSA-Lookup'!$H$2:$I$86,2) -> 360 | F6334: =IF(C6334>1,IF(C6334<99,VLOOKUP(C6334,'MSA-Lookup'!$H$1:$I$86,2),C6334),C6334) -> 999 | G6334: =VLOOKUP(E6334,'MSA-Lookup'!$AA$1:$AB$25,2) -> 4472 | H6334: =IF(C6334>1,IF(C6334<99,VLOOKUP(F6334,'MSA-Lookup'!$AA$1:$AB$25,2),C6334),C6334) -> 999
D6336: =SUM(D2:D6335) -> 29483067

Sheet MSA-Lookup
A1: INTPUMA | B1: COU | C1: NAME | E1: COU | F1: NAME | H1: INTPUMA | I1: MSA/PMSA | J1: Representative County | M1: MSA/PMSA | N1: Representative County | Q1: MSA/PMSA | R1: CMSA | S1: Representative County | V1: CMSA | X1: MSA/PMSA | Y1: CMSA | AA1: MSA/PMSA | AB1: CMSA | AD1: O-MSA | AE1: NAME | AG1: O-CMSA | AH1: NAME
A2: 1 | B2: 15 | C2: =VLOOKUP(B2,$E$1:$F$59,2) -> Del Norte County | E2: 1 | F2: Alameda County (part) | H2: 1 | I2: 9999 | J2: =VLOOKUP(H2,$A$1:$C$103,3) -> Siskiyou County | M2: 360 | N2: Orange County (part) | Q2: 360 | R2: 4472 | S2: Orange County (part) | V2: 4472 | X2: 360 | Y2: 4472 | AA2: 360 | AB2: 4472 | AD2: 360 | AE2: Anaheim | AG2: 680 | AH2: Bakersfield
A3: 1 | B3: 35 | C3: =VLOOKUP(B3,$E$1:$F$59,2) -> Lassen County | E3: 3 | F3: Alpine County | H3: 2 | I3: 9999 | J3: =VLOOKUP(H3,$A$1:$C$103,3) -> Humboldt County | M3: 360 | N3: Orange County (part) | Q3: 680 | R3: 680 | S3: Kern County (part) | V3: 680 | X3: 680 | Y3: 680 | AA3: 680 | AB3: 680 | AD3: 680 | AE3: Bakersfield | AG3: 1620 | AH3: Chico
A4: 1 | B4: 49 | C4: =VLOOKUP(B4,$E$1:$F$59,2) -> Modoc County | E4: 5 | F4: Amador County | H4: 3 | I4: 6690 | J4: =VLOOKUP(H4,$A$1:$C$103,3) -> Shasta County | M4: 360 | N4: Orange County (part) | Q4: 1620 | R4: 1620 | S4: Butte County | V4: 1620 | X4: 1620 | Y4: 1620 | AA4: 1620 | AB4: 1620 | AD4: 1620 | AE4: Chico | AG4: 2840 | AH4: Fresno
A5: 1 | B5: 93 | C5: =VLOOKUP(B5,$E$1:$F$59,2) -> Siskiyou County | E5: 7 | F5: Butte County | H5: 4 | I5: 9999 | J5: =VLOOKUP(H5,$A$1:$C$103,3) -> Mendocino County | M5: 360 | N5: Orange County (part) | Q5: 2840 | R5: 2840 | S5: Fresno County (part) | V5: 2840 | X5: 2840 | Y5: 2840 | AA5: 2840 | AB5: 2840 | AD5: 2840 | AE5: Fresno | AG5: 4472 | AH5: Los Angeles
A6: 2 | B6: 23 | C6: =VLOOKUP(B6,$E$1:$F$59,2) -> Humboldt County | E6: 9 | F6: Calaveras County | H6: 5 | I6: 9999 | J6: =VLOOKUP(H6,$A$1:$C$103,3) -> Trinity County | M6: 360 | N6: Orange County (part) | Q6: 4480 | R6: 4472 | S6: Los Angeles County (part) | V6: 4472 | X6: 4480 | Y6: 4472 | AA6: 4480 | AB6: 4472 | AD6: 4480 | AE6: Los Angeles (LA) | AG6: 4940 | AH6: Merced
A7: 3 | B7: 89 | C7: =VLOOKUP(B7,$E$1:$F$59,2) -> Shasta County | E7: 11 | F7: Colusa County | H7: 6 | I7: 1620 | J7: =VLOOKUP(H7,$A$1:$C$103,3) -> Butte County | M7: 360 | N7: Orange County (part) | Q7: 4940 | R7: 4940 | S7: Merced County | V7: 4940 | X7: 4940 | Y7: 4940 | AA7: 4940 | AB7: 4940 | AD7: 4940 | AE7: Merced | AG7: 5170 | AH7: Modesto
A8: 4 | B8: 33 | C8: =VLOOKUP(B8,$E$1:$F$59,2) -> Lake County | E8: 13 | F8: Contra Costa County (part) | H8: 7 | I8: 9999 | J8: =VLOOKUP(H8,$A$1:$C$103,3) -> Sierra County | M8: 360 | N8: Orange County (part) | Q8: 5170 | R8: 5170 | S8: Stanislaus County (part) | V8: 5170 | X8: 5170 | Y8: 5170 | AA8: 5170 | AB8: 5170 | AD8: 5170 | AE8: Modesto | AG8: 6690 | AH8: Redding
A9: 4 | B9: 45 | C9: =VLOOKUP(B9,$E$1:$F$59,2) -> Mendocino County | E9: 15 | F9: Del Norte County | H9: 8 | I9: 9340 | J9: =VLOOKUP(H9,$A$1:$C$103,3) -> Yuba County | M9: 360 | N9: Orange County (part) | Q9: 5775 | R9: 7362 | S9: Contra Costa County (part) | V9: 7362 | X9: 5775 | Y9: 7362 | AA9: 5775 | AB9: 7362 | AD9: 5775 | AE9: Oakland (SF) | AG9: 6920 | AH9: Sacramento
A10: 5 | B10: 11 | C10: =VLOOKUP(B10,$E$1:$F$59,2) -> Colusa County | E10: 17 | F10: El Dorado County | H10: 9 | I10: 8720 | J10: =VLOOKUP(H10,$A$1:$C$103,3) -> Napa County | M10: 680 | N10: Kern County (part) | Q10: 5775 | R10: 7362 | S10: Alameda County (part) | V10: 7362 | X10: 5775 | Y10: 7362 | AA10: 6000 | AB10: 4472 | AD10: 6000 | AE10: Oxnard-Ventura (LA) | AG10: 7120 | AH10: Salinas
A11: 5 | B11: 21 | C11: =VLOOKUP(B11,$E$1:$F$59,2) -> Glenn County | E11: 19 | F11: Fresno County (part) | H11: 10 | I11: 6920 | J11: =VLOOKUP(H11,$A$1:$C$103,3) -> Yolo County | M11: 680 | N11: Kern County (part) | Q11: 6000 | R11: 4472 | S11: Ventura County (part) | V11: 4472 | X11: 6000 | Y11: 4472 | AA11: 6690 | AB11: 6690 | AD11: 6690 | AE11: Redding | AG11: 7320 | AH11: San Diego
A12: 5 | B12: 103 | C12: =VLOOKUP(B12,$E$1:$F$59,2) -> Tehama County | E12: 21 | F12: Glenn County | H12: 11 | I12: 6920 | J12: =VLOOKUP(H12,$A$1:$C$103,3) -> Placer County | M12: 1620 | N12: Butte County | Q12: 6690 | R12: 6690 | S12: Shasta County | V12: 6690 | X12: 6690 | Y12: 6690 | AA12: 6780 | AB12: 4472 | AD12: 6780 | AE12: Riverside (LA) | AG12: 7362 | AH12: San Francisco
A13: 5 | B13: 105 | C13: =VLOOKUP(B13,$E$1:$F$59,2) -> Trinity County | E13: 23 | F13: Humboldt County | H13: 12 | I13: 6920 | J13: =VLOOKUP(H13,$A$1:$C$103,3) -> El Dorado County | M13: 2840 | N13: Fresno County (part) | Q13: 6780 | R13: 4472 | S13: Riverside County (part) | V13: 4472 | X13: 6780 | Y13: 4472 | AA13: 6920 | AB13: 6920 | AD13: 6920 | AE13: Sacramento | AG13: 7480 | AH13: Santa Barbara
... A17: 7 | B17: 91 | C17: =VLOOKUP(B17,$E$1:$F$59,2) -> Sierra County | E17: 31 | F17: Kings County | H17: 16 | I17: 8720 | J17: =VLOOKUP(H17,$A$1:$C$103,3) -> Solano County | M17: 4480 | N17: Los Angeles County (part) | Q17: 6920 | R17: 6920 | S17: El Dorado County | V17: 6920 | X17: 6920 | Y17: 6920 | AA17: 7400 | AB17: 7362 | AD17: 7400 | AE17: San Jose (SF) | AG17: 9999 | AH17: NonMetro
A18: 8 | B18: 101 | C18: =VLOOKUP(B18,$E$1:$F$59,2) -> Sutter County | E18: 33 | F18: Lake County | H18: 17 | I18: 5775 | J18: =VLOOKUP(H18,$A$1:$C$103,3) -> Contra Costa County (part) | M18: 4480 | N18: Los Angeles County (part) | Q18: 6920 | R18: 6920 | S18: Sacramento County (part) | V18: 6920 | X18: 6920 | Y18: 6920 | AA18: 7480 | AB18: 7480 | AD18: 7480 | AE18: Santa Barbara
A19: 8 | B19: 115 | C19: =VLOOKUP(B19,$E$1:$F$59,2) -> Yuba County | E19: 35 | F19: Lassen County | H19: 18 | I19: 5775 | J19: =VLOOKUP(H19,$A$1:$C$103,3) -> Contra Costa County (part) | M19: 4480 | N19: Los Angeles County (part) | Q19: 7120 | R19: 7120 | S19: Monterey County (part) | V19: 7120 | X19: 7120 | Y19: 7120 | AA19: 7485 | AB19: 7362 | AD19: 7485 | AE19: Santa Cruz (SF)
A20: 9 | B20: 55 | C20: =VLOOKUP(B20,$E$1:$F$59,2) -> Napa County | E20: 37 | F20: Los Angeles County (part) | H20: 19 | I20: 7360 | J20: =VLOOKUP(H20,$A$1:$C$103,3) -> San Francisco city (part) | M20: 4480 | N20: Los Angeles County (part) | Q20: 7320 | R20: 7320 | S20: San Diego County (part) | V20: 7320 | X20: 7320 | Y20: 7320 | AA20: 7500 | AB20: 7362 | AD20: 7500 | AE20: Santa Rosa (SF)
A21: 10 | B21: 113 | C21: =VLOOKUP(B21,$E$1:$F$59,2) -> Yolo County | E21: 39 | F21: Madera County | H21: 20 | I21: 5775 | J21: =VLOOKUP(H21,$A$1:$C$103,3) -> Alameda County (part) | M21: 4480 | N21: Los Angeles County (part) | Q21: 7360 | R21: 7362 | S21: Marin County (part) | V21: 7362 | X21: 7360 | Y21: 7362 | AA21: 8120 | AB21: 8120 | AD21: 8120 | AE21: Stockton
A22: 11 | B22: 61 | C22: =VLOOKUP(B22,$E$1:$F$59,2) -> Placer County | E22: 41 | F22: Marin County (part) | H22: 21 | I22: 5775 | J22: =VLOOKUP(H22,$A$1:$C$103,3) -> Alameda County (part) | M22: 4480 | N22: Los Angeles County (part) | Q22: 7360 | R22: 7362 | S22: San Francisco city (part) | V22: 7362 | X22: 7360 | Y22: 7362 | AA22: 8720 | AB22: 7362 | AD22: 8720 | AE22: Vallejo (SF)
A23: 12 | B23: 17 | C23: =VLOOKUP(B23,$E$1:$F$59,2) -> El Dorado County | E23: 43 | F23: Mariposa County | H23: 22 | I23: 7360 | J23: =VLOOKUP(H23,$A$1:$C$103,3) -> San Mateo County (part) | M23: 4480 | N23: Los Angeles County (part) | Q23: 7360 | R23: 7362 | S23: San Mateo County (part) | V23: 7362 | X23: 7360 | Y23: 7362 | AA23: 8780 | AB23: 8780 | AD23: 8780 | AE23: Visalia
A24: 13 | B24: 97 | C24: =VLOOKUP(B24,$E$1:$F$59,2) -> Sonoma County (part) | E24: 45 | F24: Mendocino County | H24: 23 | I24: 8120 | J24: =VLOOKUP(H24,$A$1:$C$103,3) -> San Joaquin County (part) | M24: 4480 | N24: Los Angeles County (part) | Q24: 7400 | R24: 7362 | S24: Santa Clara County (part) | V24: 7362 | X24: 7400 | Y24: 7362 | AA24: 9340 | AB24: 9340 | AD24: 9340 | AE24: Yuba
A25: 14 | B25: 97 | C25: =VLOOKUP(B25,$E$1:$F$59,2) -> Sonoma County (part) | E25: 47 | F25: Merced County | H25: 24 | I25: 5170 | J25: =VLOOKUP(H25,$A$1:$C$103,3) -> Stanislaus County (part) | M25: 4480 | N25: Los Angeles County (part) | Q25: 7480 | R25: 7480 | S25: Santa Barbara County (part) | V25: 7480 | X25: 7480 | Y25: 7480 | AA25: 9999 | AB25: 9999 | AD25: 9999 | AE25: Non-Metro
A26: 15 | B26: 41 | C26: =VLOOKUP(B26,$E$1:$F$59,2) -> Marin County (part) | E26: 49 | F26: Modoc County | H26: 25 | I26: 5170 | J26: =VLOOKUP(H26,$A$1:$C$103,3) -> Stanislaus County (part) | M26: 4480 | N26: Los Angeles County (part) | Q26: 7485 | R26: 7362 | S26: Santa Cruz County | V26: 7362 | X26: 7485 | Y26: 7362
A27: 16 | B27: 95 | C27: =VLOOKUP(B27,$E$1:$F$59,2) -> Solano County | E27: 51 | F27: Mono County | H27: 26 | I27: 9999 | J27: =VLOOKUP(H27,$A$1:$C$103,3) -> Tuolumne County | M27: 4480 | N27: Los Angeles County (part) | Q27: 7500 | R27: 7362 | S27: Sonoma County (part) | V27: 7362 | X27: 7500 | Y27: 7362
A28: 17 | B28: 13 | C28: =VLOOKUP(B28,$E$1:$F$59,2) -> Contra Costa County (part) | E28: 53 | F28: Monterey County (part) | H28: 27 | I28: 9999 | J28: =VLOOKUP(H28,$A$1:$C$103,3) -> San Benito County | M28: 4480 | N28: Los Angeles County (part) | Q28: 8120 | R28: 8120 | S28: San Joaquin County (part) | V28: 8120 | X28: 8120 | Y28: 8120
A29: 18 | B29: 13 | C29: =VLOOKUP(B29,$E$1:$F$59,2) -> Contra Costa County (part) | E29: 55 | F29: Napa County | H29: 28 | I29: 6920 | J29: =VLOOKUP(H29,$A$1:$C$103,3) -> Sacramento County (part) | M29: 4480 | N29: Los Angeles County (part) | Q29: 8720 | R29: 7362 | S29: Napa County | V29: 7362 | X29: 8720 | Y29: 7362
A30: 19 | B30: 75 | C30: =VLOOKUP(B30,$E$1:$F$59,2) -> San Francisco city (part) | E30: 57 | F30: Nevada County | H30: 29 | I30: 6920 | J30: =VLOOKUP(H30,$A$1:$C$103,3) -> Sacramento County (part) | M30: 4940 | N30: Merced County | Q30: 8720 | R30: 7362 | S30: Solano County | V30: 7362 | X30: 8720 | Y30: 7362
A31: 20 | B31: 1 | C31: =VLOOKUP(B31,$E$1:$F$59,2) -> Alameda County (part) | E31: 59 | F31: Orange County (part) | H31: 30 | I31: 4940 | J31: =VLOOKUP(H31,$A$1:$C$103,3) -> Merced County | M31: 5170 | N31: Stanislaus County (part) | Q31: 8780 | R31: 8780 | S31: Tulare County | V31: 8780 | X31: 8780 | Y31: 8780
A32: 21 | B32: 1 | C32: =VLOOKUP(B32,$E$1:$F$59,2) -> Alameda County (part) | E32: 61 | F32: Placer County | H32: 31 | I32: 9999 | J32: =VLOOKUP(H32,$A$1:$C$103,3) -> Kings County | M32: 5170 | N32: Stanislaus County (part) | Q32: 9340 | R32: 9340 | S32: Yuba County | V32: 9340 | X32: 9340 | Y32: 9340
A33: 22 | B33: 81 | C33: =VLOOKUP(B33,$E$1:$F$59,2) -> San Mateo County (part) | E33: 63 | F33: Plumas County | H33: 32 | I33: 7480 | J33: =VLOOKUP(H33,$A$1:$C$103,3) -> Santa Barbara County (part) | M33: 5775 | N33: Contra Costa County (part) | Q33: 9999 | R33: 9999 | S33: Siskiyou County | V33: 9999 | X33: 9999 | Y33: 9999
A34: 23 | B34: 77 | C34: =VLOOKUP(B34,$E$1:$F$59,2) -> San Joaquin County (part) | E34: 65 | F34: Riverside County (part) | H34: 33 | I34: 7320 | J34: =VLOOKUP(H34,$A$1:$C$103,3) -> San Diego County (part) | M34: 5775 | N34: Contra Costa County (part) | Q34: 9999 | R34: 9999 | S34: Humboldt County | V34: 9999 | X34: 9999 | Y34: 9999
A35: 24 | B35: 99 | C35: =VLOOKUP(B35,$E$1:$F$59,2) -> Stanislaus County (part) | E35: 67 | F35: Sacramento County (part) | H35: 34 | I35: 7320 | J35: =VLOOKUP(H35,$A$1:$C$103,3) -> San Diego County (part) | M35: 5775 | N35: Alameda County (part) | Q35: 9999 | R35: 9999 | S35: Mendocino County | V35: 9999 | X35: 9999 | Y35: 9999
A36: 25 | B36: 99 | C36: =VLOOKUP(B36,$E$1:$F$59,2) -> Stanislaus County (part) | E36: 69 | F36: San Benito County | H36: 35 | I36: 7320 | J36: =VLOOKUP(H36,$A$1:$C$103,3) -> San Diego County (part) | M36: 5775 | N36: Alameda County (part) | Q36: 9999 | R36: 9999 | S36: Trinity County | V36: 9999 | X36: 9999 | Y36: 9999
A37: 26 | B37: 3 | C37: =VLOOKUP(B37,$E$1:$F$59,2) -> Alpine County | E37: 71 | F37: San Bernardino County (part) | H37: 36 | I37: 7320 | J37: =VLOOKUP(H37,$A$1:$C$103,3) -> San Diego County (part) | M37: 5775 | N37: Alameda County (part) | Q37: 9999 | R37: 9999 | S37: Sierra County | V37: 9999 | X37: 9999 | Y37: 9999
... A42: 26 | B42: 51 | C42: =VLOOKUP(B42,$E$1:$F$59,2) -> Mono County | E42: 81 | F42: San Mateo County (part) | H42: 41 | I42: 2840 | J42: =VLOOKUP(H42,$A$1:$C$103,3) -> Fresno County (part) | M42: 6780 | N42: Riverside County (part) | Q42: 9999 | R42: 9999 | S42: San Luis Obispo County (part) | V42: 9999 | X42: 9999 | Y42: 9999
A43: 26 | B43: 109 | C43: =VLOOKUP(B43,$E$1:$F$59,2) -> Tuolumne County | E43: 83 | F43: Santa Barbara County (part) | H43: 42 | I43: 360 | J43: =VLOOKUP(H43,$A$1:$C$103,3) -> Orange County (part) | M43: 6780 | N43: San Bernardino County (part)
A44: 27 | B44: 39 | C44: =VLOOKUP(B44,$E$1:$F$59,2) -> Madera County | E44: 85 | F44: Santa Clara County (part) | H44: 43 | I44: 360 | J44: =VLOOKUP(H44,$A$1:$C$103,3) -> Orange County (part) | M44: 6780 | N44: San Bernardino County (part)
A45: 27 | B45: 69 | C45: =VLOOKUP(B45,$E$1:$F$59,2) -> San Benito County | E45: 87 | F45: Santa Cruz County | H45: 44 | I45: 360 | J45: =VLOOKUP(H45,$A$1:$C$103,3) -> Orange County (part) | M45: 6780 | N45: San Bernardino County (part)
A46: 28 | B46: 67 | C46: =VLOOKUP(B46,$E$1:$F$59,2) -> Sacramento County (part) | E46: 89 | F46: Shasta County | H46: 45 | I46: 360 | J46: =VLOOKUP(H46,$A$1:$C$103,3) -> Orange County (part) | M46: 6780 | N46: Riverside County (part)
A47: 29 | B47: 67 | C47: =VLOOKUP(B47,$E$1:$F$59,2) -> Sacramento County (part) | E47: 91 | F47: Sierra County | H47: 46 | I47: 360 | J47: =VLOOKUP(H47,$A$1:$C$103,3) -> Orange County (part) | M47: 6780 | N47: San Bernardino County (part)
...
