Workbook

Sheet NeighborEffect-i-UB
A1: Sum of TRIPS | B1: D-APUMA
A2: O-APUMA | B2: 0 | C2: 1 | D2: 2 | E2: 3 | F2: 4 | G2: 5 | H2: 6 | I2: 7 | J2: 8 | K2: 9 | L2: 10 | M2: 11 | N2: 12 | O2: 15 | P2: 19 | Q2: 22 | R2: 26 | S2: 27 | T2: 30 | U2: 31 | V2: 32 | W2: 75 | X2: 76 | Y2: 77 | Z2: 80 | AA2: 86 | AB2: 87 | AC2: 88 | AD2: 89 | AE2: 90 | AF2: 91 | AG2: 92 | AH2: 93 | AI2: 94 | AJ2: 95 | AK2: 96 | AL2: 97 | AM2: 98 | AN2: 99 | AO2: 100 | AP2: 101 | AQ2: 103 | AR2: Work | AS2: Locals | AT2: OutOfStateSum | AU2: N1^4
A3: 1 | B3: 70434 | C3: 0 | D3: ='OD-APUMA(Val)'!D3*D$49 -> 221 | E3: ='OD-APUMA(Val)'!E3*E$49 -> 780 | F3: ='OD-APUMA(Val)'!F3*F$49 -> 104 | G3: ='OD-APUMA(Val)'!G3*G$49 -> 65 | H3: ='OD-APUMA(Val)'!H3*H$49 -> 117 | I3: ='OD-APUMA(Val)'!I3*I$49 -> 403 | J3: ='OD-APUMA(Val)'!J3*J$49 -> 0 | K3: ='OD-APUMA(Val)'!K3*K$49 -> 0 | ... AQ3: ='OD-APUMA(Val)'!AQ3*AQ$49 -> 0 | AR3: =SUM('OD-APUMA(Val)'!C3:AQ3) -> 35412 | AS3: =MAX('OD-APUMA(Val)'!C3:AQ3) -> 32903 | AT3: =SUM(C3:AQ3)/AR3 -> 0.070851689 | AU3: =AT3^4 -> 2.5200016e-05
A4: 2 | B4: 70551 | C4: ='OD-APUMA(Val)'!C4*C$49 -> 273 | D4: 0 | E4: ='OD-APUMA(Val)'!E4*E$49 -> 0 | F4: ='OD-APUMA(Val)'!F4*F$49 -> 273 | G4: ='OD-APUMA(Val)'!G4*G$49 -> 0 | H4: ='OD-APUMA(Val)'!H4*H$49 -> 0 | I4: ='OD-APUMA(Val)'!I4*I$49 -> 0 | J4: ='OD-APUMA(Val)'!J4*J$49 -> 0 | K4: ='OD-APUMA(Val)'!K4*K$49 -> 0 | L4: ='OD-APUMA(Val)'!L4*L$49 -> 0 | ... AQ4: ='OD-APUMA(Val)'!AQ4*AQ$49 -> 0 | AR4: =SUM('OD-APUMA(Val)'!C4:AQ4) -> 50492 | AS4: =MAX('OD-APUMA(Val)'!C4:AQ4) -> 49764 | AT4: =SUM(C4:AQ4)/AR4 -> 0.014418126 | AU4: =AT4^4 -> 4.321507e-08
A5: 3 | B5: 93327 | C5: ='OD-APUMA(Val)'!C5*C$49 -> 650 | D5: ='OD-APUMA(Val)'!D5*D$49 -> 117 | E5: 0 | F5: ='OD-APUMA(Val)'!F5*F$49 -> 52 | G5: ='OD-APUMA(Val)'!G5*G$49 -> 1235 | H5: ='OD-APUMA(Val)'!H5*H$49 -> 91 | I5: ='OD-APUMA(Val)'!I5*I$49 -> 0 | J5: ='OD-APUMA(Val)'!J5*J$49 -> 0 | K5: ='OD-APUMA(Val)'!K5*K$49 -> 0 | L5: ='OD-APUMA(Val)'!L5*L$49 -> 91 | M5: ='OD-APUMA(Val)'!M5*M$49 -> 0 | ... AQ5: ='OD-APUMA(Val)'!AQ5*AQ$49 -> 0 | AR5: =SUM('OD-APUMA(Val)'!C5:AQ5) -> 59163 | AS5: =MAX('OD-APUMA(Val)'!C5:AQ5) -> 55562 | AT5: =SUM(C5:AQ5)/AR5 -> 0.060865744 | AU5: =AT5^4 -> 1.3724348e-05
A6: 4 | B6: 79183 | C6: ='OD-APUMA(Val)'!C6*C$49 -> 0 | D6: ='OD-APUMA(Val)'!D6*D$49 -> 0 | E6: ='OD-APUMA(Val)'!E6*E$49 -> 0 | F6: 0 | G6: ='OD-APUMA(Val)'!G6*G$49 -> 39 | H6: ='OD-APUMA(Val)'!H6*H$49 -> 0 | I6: ='OD-APUMA(Val)'!I6*I$49 -> 182 | J6: ='OD-APUMA(Val)'!J6*J$49 -> 117 | K6: ='OD-APUMA(Val)'!K6*K$49 -> 65 | L6: ='OD-APUMA(Val)'!L6*L$49 -> 0 | M6: ='OD-APUMA(Val)'!M6*M$49 -> 0 | N6: ='OD-APUMA(Val)'!N6*N$49 -> 0 | ... AQ6: ='OD-APUMA(Val)'!AQ6*AQ$49 -> 0 | AR6: =SUM('OD-APUMA(Val)'!C6:AQ6) -> 51012 | AS6: =MAX('OD-APUMA(Val)'!C6:AQ6) -> 47697 | AT6: =SUM(C6:AQ6)/AR6 -> 0.064984709 | AU6: =AT6^4 -> 1.7833834e-05
A7: 5 | B7: 66183 | C7: ='OD-APUMA(Val)'!C7*C$49 -> 0 | D7: ='OD-APUMA(Val)'!D7*D$49 -> 533 | E7: ='OD-APUMA(Val)'!E7*E$49 -> 2275 | F7: ='OD-APUMA(Val)'!F7*F$49 -> 65 | G7: 0 | H7: ='OD-APUMA(Val)'!H7*H$49 -> 1105 | I7: ='OD-APUMA(Val)'!I7*I$49 -> 572 | J7: ='OD-APUMA(Val)'!J7*J$49 -> 0 | K7: ='OD-APUMA(Val)'!K7*K$49 -> 0 | L7: ='OD-APUMA(Val)'!L7*L$49 -> 0 | M7: ='OD-APUMA(Val)'!M7*M$49 -> 143 | N7: ='OD-APUMA(Val)'!N7*N$49 -> 0 | O7: ='OD-APUMA(Val)'!O7*O$49 -> 0 | ... AQ7: ='OD-APUMA(Val)'!AQ7*AQ$49 -> 0 | AR7: =SUM('OD-APUMA(Val)'!C7:AQ7) -> 34164 | AS7: =MAX('OD-APUMA(Val)'!C7:AQ7) -> 28613 | AT7: =SUM(C7:AQ7)/AR7 -> 0.16248097 | AU7: =AT7^4 -> 0.00069696354
A8: 6 | B8: 111722 | C8: ='OD-APUMA(Val)'!C8*C$49 -> 299 | D8: ='OD-APUMA(Val)'!D8*D$49 -> 0 | E8: ='OD-APUMA(Val)'!E8*E$49 -> 65 | F8: ='OD-APUMA(Val)'!F8*F$49 -> 0 | G8: ='OD-APUMA(Val)'!G8*G$49 -> 1391 | H8: 0 | I8: ='OD-APUMA(Val)'!I8*I$49 -> 260 | J8: ='OD-APUMA(Val)'!J8*J$49 -> 1651 | K8: ='OD-APUMA(Val)'!K8*K$49 -> 117 | L8: ='OD-APUMA(Val)'!L8*L$49 -> 0 | M8: ='OD-APUMA(Val)'!M8*M$49 -> 117 | N8: ='OD-APUMA(Val)'!N8*N$49 -> 0 | O8: ='OD-APUMA(Val)'!O8*O$49 -> 0 | P8: ='OD-APUMA(Val)'!P8*P$49 -> 0 | ... AQ8: ='OD-APUMA(Val)'!AQ8*AQ$49 -> 0 | AR8: =SUM('OD-APUMA(Val)'!C8:AQ8) -> 67522 | AS8: =MAX('OD-APUMA(Val)'!C8:AQ8) -> 62647 | AT8: =SUM(C8:AQ8)/AR8 -> 0.072198691 | AU8: =AT8^4 -> 2.717173e-05
A9: 7 | B9: 61087 | C9: ='OD-APUMA(Val)'!C9*C$49 -> 104 | D9: ='OD-APUMA(Val)'!D9*D$49 -> 0 | E9: ='OD-APUMA(Val)'!E9*E$49 -> 624 | F9: ='OD-APUMA(Val)'!F9*F$49 -> 377 | G9: ='OD-APUMA(Val)'!G9*G$49 -> 78 | H9: ='OD-APUMA(Val)'!H9*H$49 -> 208 | I9: 0 | J9: ='OD-APUMA(Val)'!J9*J$49 -> 650 | K9: ='OD-APUMA(Val)'!K9*K$49 -> 78 | L9: ='OD-APUMA(Val)'!L9*L$49 -> 0 | M9: ='OD-APUMA(Val)'!M9*M$49 -> 3822 | N9: ='OD-APUMA(Val)'!N9*N$49 -> 0 | O9: ='OD-APUMA(Val)'!O9*O$49 -> 0 | P9: ='OD-APUMA(Val)'!P9*P$49 -> 117 | Q9: ='OD-APUMA(Val)'!Q9*Q$49 -> 117 | ... AQ9: ='OD-APUMA(Val)'!AQ9*AQ$49 -> 0 | AR9: =SUM('OD-APUMA(Val)'!C9:AQ9) -> 41067 | AS9: =MAX('OD-APUMA(Val)'!C9:AQ9) -> 32396 | AT9: =SUM(C9:AQ9)/AR9 -> 0.21114277 | AU9: =AT9^4 -> 0.0019874895
A10: 8 | B10: 74074 | C10: ='OD-APUMA(Val)'!C10*C$49 -> 0 | D10: ='OD-APUMA(Val)'!D10*D$49 -> 0 | E10: ='OD-APUMA(Val)'!E10*E$49 -> 0 | F10: ='OD-APUMA(Val)'!F10*F$49 -> 0 | G10: ='OD-APUMA(Val)'!G10*G$49 -> 403 | H10: ='OD-APUMA(Val)'!H10*H$49 -> 663 | I10: ='OD-APUMA(Val)'!I10*I$49 -> 312 | J10: 0 | K10: ='OD-APUMA(Val)'!K10*K$49 -> 0 | L10: ='OD-APUMA(Val)'!L10*L$49 -> 1521 | M10: ='OD-APUMA(Val)'!M10*M$49 -> 1196 | N10: ='OD-APUMA(Val)'!N10*N$49 -> 0 | O10: ='OD-APUMA(Val)'!O10*O$49 -> 0 | P10: ='OD-APUMA(Val)'!P10*P$49 -> 0 | Q10: ='OD-APUMA(Val)'!Q10*Q$49 -> 0 | R10: ='OD-APUMA(Val)'!R10*R$49 -> 0 | ... AQ10: ='OD-APUMA(Val)'!AQ10*AQ$49 -> 0 | AR10: =SUM('OD-APUMA(Val)'!C10:AQ10) -> 46839 | AS10: =MAX('OD-APUMA(Val)'!C10:AQ10) -> 38493 | AT10: =SUM(C10:AQ10)/AR10 -> 0.17818485 | AU10: =AT10^4 -> 0.0010080523
A11: 9 | B11: 57291 | C11: ='OD-APUMA(Val)'!C11*C$49 -> 143 | D11: ='OD-APUMA(Val)'!D11*D$49 -> 0 | E11: ='OD-APUMA(Val)'!E11*E$49 -> 0 | F11: ='OD-APUMA(Val)'!F11*F$49 -> 208 | G11: ='OD-APUMA(Val)'!G11*G$49 -> 0 | H11: ='OD-APUMA(Val)'!H11*H$49 -> 0 | I11: ='OD-APUMA(Val)'!I11*I$49 -> 0 | J11: ='OD-APUMA(Val)'!J11*J$49 -> 0 | K11: 0 | L11: ='OD-APUMA(Val)'!L11*L$49 -> 104 | M11: ='OD-APUMA(Val)'!M11*M$49 -> 0 | N11: ='OD-APUMA(Val)'!N11*N$49 -> 0 | O11: ='OD-APUMA(Val)'!O11*O$49 -> 429 | P11: ='OD-APUMA(Val)'!P11*P$49 -> 897 | Q11: ='OD-APUMA(Val)'!Q11*Q$49 -> 195 | R11: ='OD-APUMA(Val)'!R11*R$49 -> 0 | S11: ='OD-APUMA(Val)'!S11*S$49 -> 0 | ... AQ11: ='OD-APUMA(Val)'!AQ11*AQ$49 -> 0 | AR11: =SUM('OD-APUMA(Val)'!C11:AQ11) -> 51909 | AS11: =MAX('OD-APUMA(Val)'!C11:AQ11) -> 37791 | AT11: =SUM(C11:AQ11)/AR11 -> 0.27197596 | AU11: =AT11^4 -> 0.0054716973
A12: 10 | B12: 75231 | C12: ='OD-APUMA(Val)'!C12*C$49 -> 65 | D12: ='OD-APUMA(Val)'!D12*D$49 -> 0 | E12: ='OD-APUMA(Val)'!E12*E$49 -> 221 | F12: ='OD-APUMA(Val)'!F12*F$49 -> 0 | G12: ='OD-APUMA(Val)'!G12*G$49 -> 182 | H12: ='OD-APUMA(Val)'!H12*H$49 -> 221 | I12: ='OD-APUMA(Val)'!I12*I$49 -> 0 | J12: ='OD-APUMA(Val)'!J12*J$49 -> 507 | K12: ='OD-APUMA(Val)'!K12*K$49 -> 169 | L12: 0 | M12: ='OD-APUMA(Val)'!M12*M$49 -> 208 | N12: ='OD-APUMA(Val)'!N12*N$49 -> 195 | O12: ='OD-APUMA(Val)'!O12*O$49 -> 0 | P12: ='OD-APUMA(Val)'!P12*P$49 -> 0 | Q12: ='OD-APUMA(Val)'!Q12*Q$49 -> 78 | R12: ='OD-APUMA(Val)'!R12*R$49 -> 117 | S12: ='OD-APUMA(Val)'!S12*S$49 -> 0 | T12: ='OD-APUMA(Val)'!T12*T$49 -> 0 | ... AQ12: ='OD-APUMA(Val)'!AQ12*AQ$49 -> 0 | AR12: =SUM('OD-APUMA(Val)'!C12:AQ12) -> 66885 | AS12: =MAX('OD-APUMA(Val)'!C12:AQ12) -> 44408 | AT12: =SUM(C12:AQ12)/AR12 -> 0.33605442 | AU12: =AT12^4 -> 0.012753766
A13: 11 | B13: 90948 | C13: ='OD-APUMA(Val)'!C13*C$49 -> 0 | D13: ='OD-APUMA(Val)'!D13*D$49 -> 0 | E13: ='OD-APUMA(Val)'!E13*E$49 -> 429 | F13: ='OD-APUMA(Val)'!F13*F$49 -> 1456 | G13: ='OD-APUMA(Val)'!G13*G$49 -> 416 | H13: ='OD-APUMA(Val)'!H13*H$49 -> 0 | I13: ='OD-APUMA(Val)'!I13*I$49 -> 1872 | J13: ='OD-APUMA(Val)'!J13*J$49 -> 247 | ... L13: ='OD-APUMA(Val)'!L13*L$49 -> 1131 | M13: 0 | N13: ='OD-APUMA(Val)'!N13*N$49 -> 104 | O13: ='OD-APUMA(Val)'!O13*O$49 -> 0 | P13: ='OD-APUMA(Val)'!P13*P$49 -> 91 | Q13: ='OD-APUMA(Val)'!Q13*Q$49 -> 26 | R13: ='OD-APUMA(Val)'!R13*R$49 -> 312 | S13: ='OD-APUMA(Val)'!S13*S$49 -> 0 | T13: ='OD-APUMA(Val)'!T13*T$49 -> 0 | U13: ='OD-APUMA(Val)'!U13*U$49 -> 0 | ... AQ13: ='OD-APUMA(Val)'!AQ13*AQ$49 -> 156 | AR13: =SUM('OD-APUMA(Val)'!C13:AQ13) -> 80626 | AS13: =MAX('OD-APUMA(Val)'!C13:AQ13) -> 46007 | AT13: =SUM(C13:AQ13)/AR13 -> 0.42937762 | AU13: =AT13^4 -> 0.033990505
A14: 12 | B14: 66781 | C14: ='OD-APUMA(Val)'!C14*C$49 -> 0 | D14: ='OD-APUMA(Val)'!D14*D$49 -> 143 | E14: ='OD-APUMA(Val)'!E14*E$49 -> 299 | F14: ='OD-APUMA(Val)'!F14*F$49 -> 0 | G14: ='OD-APUMA(Val)'!G14*G$49 -> 5811 | H14: ='OD-APUMA(Val)'!H14*H$49 -> 143 | I14: ='OD-APUMA(Val)'!I14*I$49 -> 130 | J14: ='OD-APUMA(Val)'!J14*J$49 -> 0 | ... M14: ='OD-APUMA(Val)'!M14*M$49 -> 1651 | N14: 0 | O14: ='OD-APUMA(Val)'!O14*O$49 -> 0 | P14: ='OD-APUMA(Val)'!P14*P$49 -> 156 | Q14: ='OD-APUMA(Val)'!Q14*Q$49 -> 182 | R14: ='OD-APUMA(Val)'!R14*R$49 -> 312 | S14: ='OD-APUMA(Val)'!S14*S$49 -> 0 | T14: ='OD-APUMA(Val)'!T14*T$49 -> 0 | U14: ='OD-APUMA(Val)'!U14*U$49 -> 0 | V14: ='OD-APUMA(Val)'!V14*V$49 -> 0 | ... AQ14: ='OD-APUMA(Val)'!AQ14*AQ$49 -> 78 | AR14: =SUM('OD-APUMA(Val)'!C14:AQ14) -> 56082 | AS14: =MAX('OD-APUMA(Val)'!C14:AQ14) -> 30693 | AT14: =SUM(C14:AQ14)/AR14 -> 0.4527121 | AU14: =AT14^4 -> 0.042003783
A15: 15 | B15: 103519 | C15: ='OD-APUMA(Val)'!C15*C$49 -> 0 | D15: ='OD-APUMA(Val)'!D15*D$49 -> 0 | E15: ='OD-APUMA(Val)'!E15*E$49 -> 104 | F15: ='OD-APUMA(Val)'!F15*F$49 -> 130 | G15: ='OD-APUMA(Val)'!G15*G$49 -> 0 | H15: ='OD-APUMA(Val)'!H15*H$49 -> 0 | I15: ='OD-APUMA(Val)'!I15*I$49 -> 0 | J15: ='OD-APUMA(Val)'!J15*J$49 -> 195 | ... N15: ='OD-APUMA(Val)'!N15*N$49 -> 0 | O15: 0 | P15: ='OD-APUMA(Val)'!P15*P$49 -> 33098 | Q15: ='OD-APUMA(Val)'!Q15*Q$49 -> 3744 | R15: ='OD-APUMA(Val)'!R15*R$49 -> 0 | S15: ='OD-APUMA(Val)'!S15*S$49 -> 0 | T15: ='OD-APUMA(Val)'!T15*T$49 -> 0 | U15: ='OD-APUMA(Val)'!U15*U$49 -> 0 | V15: ='OD-APUMA(Val)'!V15*V$49 -> 0 | W15: ='OD-APUMA(Val)'!W15*W$49 -> 0 | ... AQ15: ='OD-APUMA(Val)'!AQ15*AQ$49 -> 0 | AR15: =SUM('OD-APUMA(Val)'!C15:AQ15) -> 124878 | AS15: =MAX('OD-APUMA(Val)'!C15:AQ15) -> 72592 | AT15: =SUM(C15:AQ15)/AR15 -> 0.41869665 | AU15: =AT15^4 -> 0.030732503
A16: 19 | B16: 347230 | C16: ='OD-APUMA(Val)'!C16*C$49 -> 143 | D16: ='OD-APUMA(Val)'!D16*D$49 -> 78 | E16: ='OD-APUMA(Val)'!E16*E$49 -> 156 | F16: ='OD-APUMA(Val)'!F16*F$49 -> 182 | G16: ='OD-APUMA(Val)'!G16*G$49 -> 0 | H16: ='OD-APUMA(Val)'!H16*H$49 -> 0 | I16: ='OD-APUMA(Val)'!I16*I$49 -> 78 | J16: ='OD-APUMA(Val)'!J16*J$49 -> 0 | ... O16: ='OD-APUMA(Val)'!O16*O$49 -> 4095 | P16: 0 | Q16: ='OD-APUMA(Val)'!Q16*Q$49 -> 29393 | R16: ='OD-APUMA(Val)'!R16*R$49 -> 0 | S16: ='OD-APUMA(Val)'!S16*S$49 -> 0 | T16: ='OD-APUMA(Val)'!T16*T$49 -> 0 | U16: ='OD-APUMA(Val)'!U16*U$49 -> 0 | V16: ='OD-APUMA(Val)'!V16*V$49 -> 104 | W16: ='OD-APUMA(Val)'!W16*W$49 -> 0 | X16: ='OD-APUMA(Val)'!X16*X$49 -> 299 | ... AQ16: ='OD-APUMA(Val)'!AQ16*AQ$49 -> 0 | AR16: =SUM('OD-APUMA(Val)'!C16:AQ16) -> 385580 | AS16: =MAX('OD-APUMA(Val)'!C16:AQ16) -> 313768 | AT16: =SUM(C16:AQ16)/AR16 -> 0.1862441 | AU16: =AT16^4 -> 0.0012031786
A17: 22 | B17: 313391 | C17: ='OD-APUMA(Val)'!C17*C$49 -> 169 | D17: ='OD-APUMA(Val)'!D17*D$49 -> 0 | E17: ='OD-APUMA(Val)'!E17*E$49 -> 221 | F17: ='OD-APUMA(Val)'!F17*F$49 -> 0 | G17: ='OD-APUMA(Val)'!G17*G$49 -> 182 | H17: ='OD-APUMA(Val)'!H17*H$49 -> 0 | I17: ='OD-APUMA(Val)'!I17*I$49 -> 0 | J17: ='OD-APUMA(Val)'!J17*J$49 -> 0 | ... P17: ='OD-APUMA(Val)'!P17*P$49 -> 80925 | Q17: 0 | R17: ='OD-APUMA(Val)'!R17*R$49 -> 0 | S17: ='OD-APUMA(Val)'!S17*S$49 -> 0 | T17: ='OD-APUMA(Val)'!T17*T$49 -> 0 | U17: ='OD-APUMA(Val)'!U17*U$49 -> 0 | V17: ='OD-APUMA(Val)'!V17*V$49 -> 0 | W17: ='OD-APUMA(Val)'!W17*W$49 -> 0 | X17: ='OD-APUMA(Val)'!X17*X$49 -> 325 | Y17: ='OD-APUMA(Val)'!Y17*Y$49 -> 0 | ... AQ17: ='OD-APUMA(Val)'!AQ17*AQ$49 -> 0 | AR17: =SUM('OD-APUMA(Val)'!C17:AQ17) -> 350818 | AS17: =MAX('OD-APUMA(Val)'!C17:AQ17) -> 203580 | AT17: =SUM(C17:AQ17)/AR17 -> 0.4196991 | AU17: =AT17^4 -> 0.031027884
A18: 26 | B18: 95186 | C18: ='OD-APUMA(Val)'!C18*C$49 -> 0 | D18: ='OD-APUMA(Val)'!D18*D$49 -> 0 | E18: ='OD-APUMA(Val)'!E18*E$49 -> 26 | F18: ='OD-APUMA(Val)'!F18*F$49 -> 0 | G18: ='OD-APUMA(Val)'!G18*G$49 -> 208 | H18: ='OD-APUMA(Val)'!H18*H$49 -> 0 | I18: ='OD-APUMA(Val)'!I18*I$49 -> 0 | J18: ='OD-APUMA(Val)'!J18*J$49 -> 0 | ... Q18: ='OD-APUMA(Val)'!Q18*Q$49 -> 299 | R18: 0 | S18: ='OD-APUMA(Val)'!S18*S$49 -> 520 | T18: ='OD-APUMA(Val)'!T18*T$49 -> 130 | U18: ='OD-APUMA(Val)'!U18*U$49 -> 0 | V18: ='OD-APUMA(Val)'!V18*V$49 -> 0 | W18: ='OD-APUMA(Val)'!W18*W$49 -> 0 | X18: ='OD-APUMA(Val)'!X18*X$49 -> 0 | Y18: ='OD-APUMA(Val)'!Y18*Y$49 -> 0 | Z18: ='OD-APUMA(Val)'!Z18*Z$49 -> 0 | ... AQ18: ='OD-APUMA(Val)'!AQ18*AQ$49 -> 0 | AR18: =SUM('OD-APUMA(Val)'!C18:AQ18) -> 59358 | AS18: =MAX('OD-APUMA(Val)'!C18:AQ18) -> 49543 | AT18: =SUM(C18:AQ18)/AR18 -> 0.16535261 | AU18: =AT18^4 -> 0.00074755677
A19: 27 | B19: 78299 | C19: ='OD-APUMA(Val)'!C19*C$49 -> 0 | D19: ='OD-APUMA(Val)'!D19*D$49 -> 0 | E19: ='OD-APUMA(Val)'!E19*E$49 -> 0 | F19: ='OD-APUMA(Val)'!F19*F$49 -> 0 | G19: ='OD-APUMA(Val)'!G19*G$49 -> 0 | H19: ='OD-APUMA(Val)'!H19*H$49 -> 0 | I19: ='OD-APUMA(Val)'!I19*I$49 -> 0 | J19: ='OD-APUMA(Val)'!J19*J$49 -> 0 | ... R19: ='OD-APUMA(Val)'!R19*R$49 -> 429 | S19: 0 | T19: ='OD-APUMA(Val)'!T19*T$49 -> 1105 | U19: ='OD-APUMA(Val)'!U19*U$49 -> 156 | V19: ='OD-APUMA(Val)'!V19*V$49 -> 78 | W19: ='OD-APUMA(Val)'!W19*W$49 -> 130 | X19: ='OD-APUMA(Val)'!X19*X$49 -> 351 | Y19: ='OD-APUMA(Val)'!Y19*Y$49 -> 13 | Z19: ='OD-APUMA(Val)'!Z19*Z$49 -> 0 | AA19: ='OD-APUMA(Val)'!AA19*AA$49 -> 91 | ... AQ19: ='OD-APUMA(Val)'!AQ19*AQ$49 -> 0 | AR19: =SUM('OD-APUMA(Val)'!C19:AQ19) -> 50674 | AS19: =MAX('OD-APUMA(Val)'!C19:AQ19) -> 34346 | AT19: =SUM(C19:AQ19)/AR19 -> 0.32221652 | AU19: =AT19^4 -> 0.010779316
A20: 30 | B20: 108225 | C20: ='OD-APUMA(Val)'!C20*C$49 -> 0 | D20: ='OD-APUMA(Val)'!D20*D$49 -> 0 | E20: ='OD-APUMA(Val)'!E20*E$49 -> 0 | F20: ='OD-APUMA(Val)'!F20*F$49 -> 0 | G20: ='OD-APUMA(Val)'!G20*G$49 -> 0 | H20: ='OD-APUMA(Val)'!H20*H$49 -> 0 | I20: ='OD-APUMA(Val)'!I20*I$49 -> 0 | J20: ='OD-APUMA(Val)'!J20*J$49 -> 0 | ... S20: ='OD-APUMA(Val)'!S20*S$49 -> 1261 | T20: 0 | U20: ='OD-APUMA(Val)'!U20*U$49 -> 195 | V20: ='OD-APUMA(Val)'!V20*V$49 -> 0 | W20: ='OD-APUMA(Val)'!W20*W$49 -> 0 | X20: ='OD-APUMA(Val)'!X20*X$49 -> 0 | Y20: ='OD-APUMA(Val)'!Y20*Y$49 -> 0 | Z20: ='OD-APUMA(Val)'!Z20*Z$49 -> 0 | AA20: ='OD-APUMA(Val)'!AA20*AA$49 -> 52 | AB20: ='OD-APUMA(Val)'!AB20*AB$49 -> 0 | ... AQ20: ='OD-APUMA(Val)'!AQ20*AQ$49 -> 0 | AR20: =SUM('OD-APUMA(Val)'!C20:AQ20) -> 68432 | AS20: =MAX('OD-APUMA(Val)'!C20:AQ20) -> 59956 | AT20: =SUM(C20:AQ20)/AR20 -> 0.12386018 | AU20: =AT20^4 -> 0.00023535686
A21: 31 | B21: 63609 | C21: ='OD-APUMA(Val)'!C21*C$49 -> 0 | D21: ='OD-APUMA(Val)'!D21*D$49 -> 0 | E21: ='OD-APUMA(Val)'!E21*E$49 -> 0 | F21: ='OD-APUMA(Val)'!F21*F$49 -> 0 | G21: ='OD-APUMA(Val)'!G21*G$49 -> 0 | H21: ='OD-APUMA(Val)'!H21*H$49 -> 0 | I21: ='OD-APUMA(Val)'!I21*I$49 -> 0 | J21: ='OD-APUMA(Val)'!J21*J$49 -> 0 | ... T21: ='OD-APUMA(Val)'!T21*T$49 -> 0 | U21: 0 | V21: ='OD-APUMA(Val)'!V21*V$49 -> 117 | W21: ='OD-APUMA(Val)'!W21*W$49 -> 1417 | X21: ='OD-APUMA(Val)'!X21*X$49 -> 0 | Y21: ='OD-APUMA(Val)'!Y21*Y$49 -> 0 | Z21: ='OD-APUMA(Val)'!Z21*Z$49 -> 507 | AA21: ='OD-APUMA(Val)'!AA21*AA$49 -> 169 | AB21: ='OD-APUMA(Val)'!AB21*AB$49 -> 0 | AC21: ='OD-APUMA(Val)'!AC21*AC$49 -> 2483 | ... AQ21: ='OD-APUMA(Val)'!AQ21*AQ$49 -> 0 | AR21: =SUM('OD-APUMA(Val)'!C21:AQ21) -> 35698 | AS21: =MAX('OD-APUMA(Val)'!C21:AQ21) -> 30563 | AT21: =SUM(C21:AQ21)/AR21 -> 0.14384559 | AU21: =AT21^4 -> 0.00042814044
A22: 32 | B22: 187317 | C22: ='OD-APUMA(Val)'!C22*C$49 -> 0 | D22: ='OD-APUMA(Val)'!D22*D$49 -> 0 | E22: ='OD-APUMA(Val)'!E22*E$49 -> 65 | F22: ='OD-APUMA(Val)'!F22*F$49 -> 0 | G22: ='OD-APUMA(Val)'!G22*G$49 -> 0 | H22: ='OD-APUMA(Val)'!H22*H$49 -> 0 | I22: ='OD-APUMA(Val)'!I22*I$49 -> 0 | J22: ='OD-APUMA(Val)'!J22*J$49 -> 0 | ... U22: ='OD-APUMA(Val)'!U22*U$49 -> 0 | V22: 0 | W22: ='OD-APUMA(Val)'!W22*W$49 -> 0 | X22: ='OD-APUMA(Val)'!X22*X$49 -> 0 | Y22: ='OD-APUMA(Val)'!Y22*Y$49 -> 0 | Z22: ='OD-APUMA(Val)'!Z22*Z$49 -> 5109 | AA22: ='OD-APUMA(Val)'!AA22*AA$17 -> 2135484 | AB22: ='OD-APUMA(Val)'!AB22*AB$49 -> 0 | AC22: ='OD-APUMA(Val)'!AC22*AC$49 -> 143 | AD22: ='OD-APUMA(Val)'!AD22*AD$49 -> 0 | AE22: ='OD-APUMA(Val)'!AE22*AE$49 -> 1599 | AF22: ='OD-APUMA(Val)'!AF22*AF$49 -> 208 | AG22: ='OD-APUMA(Val)'!AG22*AG$49 -> 91 | AH22: ='OD-APUMA(Val)'!AH22*AH$49 -> 156 | AI22: ='OD-APUMA(Val)'!AI22*AI$49 -> 0 | ... AQ22: ='OD-APUMA(Val)'!AQ22*AQ$49 -> 2015 | AR22: =SUM('OD-APUMA(Val)'!C22:AQ22) -> 180141 | AS22: =MAX('OD-APUMA(Val)'!C22:AQ22) -> 169559 | AT22: =SUM(C22:AQ22)/AR22 -> 11.912391 | AU22: =AT22^4 -> 20137.045
A23: 75 | B23: 192426 | C23: ='OD-APUMA(Val)'!C23*C$49 -> 0 | D23: ='OD-APUMA(Val)'!D23*D$49 -> 104 | E23: ='OD-APUMA(Val)'!E23*E$49 -> 0 | F23: ='OD-APUMA(Val)'!F23*F$49 -> 0 | G23: ='OD-APUMA(Val)'!G23*G$49 -> 0 | H23: ='OD-APUMA(Val)'!H23*H$49 -> 0 | I23: ='OD-APUMA(Val)'!I23*I$49 -> 0 | J23: ='OD-APUMA(Val)'!J23*J$49 -> 0 | ... V23: ='OD-APUMA(Val)'!V23*V$49 -> 0 | W23: 0 | X23: ='OD-APUMA(Val)'!X23*X$49 -> 0 | Y23: ='OD-APUMA(Val)'!Y23*Y$49 -> 0 | Z23: ='OD-APUMA(Val)'!Z23*Z$49 -> 65 | AA23: ='OD-APUMA(Val)'!AA23*AA$49 -> 0 | AB23: ='OD-APUMA(Val)'!AB23*AB$49 -> 91 | AC23: ='OD-APUMA(Val)'!AC23*AC$49 -> 5629 | AD23: ='OD-APUMA(Val)'!AD23*AD$49 -> 2626 | AE23: ='OD-APUMA(Val)'!AE23*AE$49 -> 494 | ... AQ23: ='OD-APUMA(Val)'!AQ23*AQ$49 -> 0 | AR23: =SUM('OD-APUMA(Val)'!C23:AQ23) -> 118170 | AS23: =MAX('OD-APUMA(Val)'!C23:AQ23) -> 106184 | AT23: =SUM(C23:AQ23)/AR23 -> 0.10143014 | AU23: =AT23^4 -> 0.00010584446
A24: 76 | B24: 116324 | C24: ='OD-APUMA(Val)'!C24*C$49 -> 0 | D24: ='OD-APUMA(Val)'!D24*D$49 -> 0 | E24: ='OD-APUMA(Val)'!E24*E$49 -> 0 | F24: ='OD-APUMA(Val)'!F24*F$49 -> 143 | G24: ='OD-APUMA(Val)'!G24*G$49 -> 0 | H24: ='OD-APUMA(Val)'!H24*H$49 -> 0 | I24: ='OD-APUMA(Val)'!I24*I$49 -> 0 | J24: ='OD-APUMA(Val)'!J24*J$49 -> 0 | ... W24: ='OD-APUMA(Val)'!W24*W$49 -> 0 | X24: 0 | Y24: ='OD-APUMA(Val)'!Y24*Y$49 -> 0 | Z24: ='OD-APUMA(Val)'!Z24*Z$49 -> 0 | AA24: ='OD-APUMA(Val)'!AA24*AA$49 -> 871 | AB24: ='OD-APUMA(Val)'!AB24*AB$49 -> 182 | AC24: ='OD-APUMA(Val)'!AC24*AC$49 -> 52 | AD24: ='OD-APUMA(Val)'!AD24*AD$49 -> 273 | AE24: ='OD-APUMA(Val)'!AE24*AE$49 -> 247 | AF24: ='OD-APUMA(Val)'!AF24*AF$49 -> 4420 | ... AQ24: ='OD-APUMA(Val)'!AQ24*AQ$49 -> 91 | AR24: =SUM('OD-APUMA(Val)'!C24:AQ24) -> 112996 | AS24: =MAX('OD-APUMA(Val)'!C24:AQ24) -> 88868 | AT24: =SUM(C24:AQ24)/AR24 -> 0.21352968 | AU24: =AT24^4 -> 0.0020788972
A25: 77 | B25: 73463 | C25: ='OD-APUMA(Val)'!C25*C$49 -> 0 | D25: ='OD-APUMA(Val)'!D25*D$49 -> 0 | E25: ='OD-APUMA(Val)'!E25*E$49 -> 0 | F25: ='OD-APUMA(Val)'!F25*F$49 -> 377 | G25: ='OD-APUMA(Val)'!G25*G$49 -> 0 | H25: ='OD-APUMA(Val)'!H25*H$49 -> 0 | I25: ='OD-APUMA(Val)'!I25*I$49 -> 0 | J25: ='OD-APUMA(Val)'!J25*J$49 -> 0 | ... X25: ='OD-APUMA(Val)'!X25*X$49 -> 0 | Y25: 0 | Z25: ='OD-APUMA(Val)'!Z25*Z$49 -> 0 | AA25: ='OD-APUMA(Val)'!AA25*AA$49 -> 78 | AB25: ='OD-APUMA(Val)'!AB25*AB$49 -> 0 | AC25: ='OD-APUMA(Val)'!AC25*AC$49 -> 0 | AD25: ='OD-APUMA(Val)'!AD25*AD$49 -> 0 | AE25: ='OD-APUMA(Val)'!AE25*AE$49 -> 156 | AF25: ='OD-APUMA(Val)'!AF25*AF$49 -> 0 | AG25: ='OD-APUMA(Val)'!AG25*AG$49 -> 0 | ... AQ25: ='OD-APUMA(Val)'!AQ25*AQ$49 -> 0 | AR25: =SUM('OD-APUMA(Val)'!C25:AQ25) -> 34944 | AS25: =MAX('OD-APUMA(Val)'!C25:AQ25) -> 33397 | AT25: =SUM(C25:AQ25)/AR25 -> 0.044270833 | AU25: =AT25^4 -> 3.8412342e-06
A26: 80 | B26: 118885 | C26: ='OD-APUMA(Val)'!C26*C$49 -> 0 | D26: ='OD-APUMA(Val)'!D26*D$49 -> 247 | E26: ='OD-APUMA(Val)'!E26*E$49 -> 0 | F26: ='OD-APUMA(Val)'!F26*F$49 -> 0 | G26: ='OD-APUMA(Val)'!G26*G$49 -> 0 | H26: ='OD-APUMA(Val)'!H26*H$49 -> 0 | I26: ='OD-APUMA(Val)'!I26*I$49 -> 0 | J26: ='OD-APUMA(Val)'!J26*J$49 -> 0 | ... Y26: ='OD-APUMA(Val)'!Y26*Y$49 -> 0 | Z26: 0 | AA26: ='OD-APUMA(Val)'!AA26*AA$49 -> 0 | AB26: ='OD-APUMA(Val)'!AB26*AB$49 -> 78 | AC26: ='OD-APUMA(Val)'!AC26*AC$49 -> 0 | AD26: ='OD-APUMA(Val)'!AD26*AD$49 -> 260 | AE26: ='OD-APUMA(Val)'!AE26*AE$49 -> 598 | AF26: ='OD-APUMA(Val)'!AF26*AF$49 -> 104 | AG26: ='OD-APUMA(Val)'!AG26*AG$49 -> 0 | AH26: ='OD-APUMA(Val)'!AH26*AH$49 -> 0 | ... AQ26: ='OD-APUMA(Val)'!AQ26*AQ$49 -> 312 | AR26: =SUM('OD-APUMA(Val)'!C26:AQ26) -> 91208 | AS26: =MAX('OD-APUMA(Val)'!C26:AQ26) -> 82537 | AT26: =SUM(C26:AQ26)/AR26 -> 0.095068415 | AU26: =AT26^4 -> 8.1685508e-05
A27: 86 | B27: 634894 | C27: ='OD-APUMA(Val)'!C27*C$49 -> 91 | D27: ='OD-APUMA(Val)'!D27*D$49 -> 78 | E27: ='OD-APUMA(Val)'!E27*E$49 -> 130 | F27: ='OD-APUMA(Val)'!F27*F$49 -> 0 | G27: ='OD-APUMA(Val)'!G27*G$49 -> 0 | H27: ='OD-APUMA(Val)'!H27*H$49 -> 143 | I27: ='OD-APUMA(Val)'!I27*I$49 -> 0 | J27: ='OD-APUMA(Val)'!J27*J$49 -> 0 | ... Z27: ='OD-APUMA(Val)'!Z27*Z$49 -> 0 | AA27: 0 | AB27: ='OD-APUMA(Val)'!AB27*AB$49 -> 35737 | AC27: ='OD-APUMA(Val)'!AC27*AC$49 -> 65 | AD27: ='OD-APUMA(Val)'!AD27*AD$49 -> 0 | AE27: ='OD-APUMA(Val)'!AE27*AE$49 -> 1768 | AF27: ='OD-APUMA(Val)'!AF27*AF$49 -> 0 | AG27: ='OD-APUMA(Val)'!AG27*AG$49 -> 260 | AH27: ='OD-APUMA(Val)'!AH27*AH$49 -> 0 | AI27: ='OD-APUMA(Val)'!AI27*AI$49 -> 481 | ... AQ27: ='OD-APUMA(Val)'!AQ27*AQ$49 -> 0 | AR27: =SUM('OD-APUMA(Val)'!C27:AQ27) -> 632060 | AS27: =MAX('OD-APUMA(Val)'!C27:AQ27) -> 448058 | AT27: =SUM(C27:AQ27)/AR27 -> 0.29111477 | AU27: =AT27^4 -> 0.0071821909
A28: 87 | B28: 401882 | C28: ='OD-APUMA(Val)'!C28*C$49 -> 273 | D28: ='OD-APUMA(Val)'!D28*D$49 -> 117 | E28: ='OD-APUMA(Val)'!E28*E$49 -> 0 | F28: ='OD-APUMA(Val)'!F28*F$49 -> 182 | G28: ='OD-APUMA(Val)'!G28*G$49 -> 0 | H28: ='OD-APUMA(Val)'!H28*H$49 -> 143 | I28: ='OD-APUMA(Val)'!I28*I$49 -> 0 | J28: ='OD-APUMA(Val)'!J28*J$49 -> 0 | ... AA28: ='OD-APUMA(Val)'!AA28*AA$49 -> 83265 | AB28: 0 | AC28: ='OD-APUMA(Val)'!AC28*AC$49 -> 104 | AD28: ='OD-APUMA(Val)'!AD28*AD$49 -> 0 | AE28: ='OD-APUMA(Val)'!AE28*AE$49 -> 806 | AF28: ='OD-APUMA(Val)'!AF28*AF$49 -> 0 | AG28: ='OD-APUMA(Val)'!AG28*AG$49 -> 208 | AH28: ='OD-APUMA(Val)'!AH28*AH$49 -> 0 | AI28: ='OD-APUMA(Val)'!AI28*AI$49 -> 559 | AJ28: ='OD-APUMA(Val)'!AJ28*AJ$49 -> 169 | ... AQ28: ='OD-APUMA(Val)'!AQ28*AQ$49 -> 0 | AR28: =SUM('OD-APUMA(Val)'!C28:AQ28) -> 401219 | AS28: =MAX('OD-APUMA(Val)'!C28:AQ28) -> 243971 | AT28: =SUM(C28:AQ28)/AR28 -> 0.39192561 | AU28: =AT28^4 -> 0.023594705
A29: 88 | B29: 405808 | C29: ='OD-APUMA(Val)'!C29*C$49 -> 0 | D29: ='OD-APUMA(Val)'!D29*D$49 -> 117 | E29: ='OD-APUMA(Val)'!E29*E$49 -> 0 | F29: ='OD-APUMA(Val)'!F29*F$49 -> 351 | G29: ='OD-APUMA(Val)'!G29*G$49 -> 195 | H29: ='OD-APUMA(Val)'!H29*H$49 -> 182 | I29: ='OD-APUMA(Val)'!I29*I$49 -> 0 | J29: ='OD-APUMA(Val)'!J29*J$49 -> 91 | ... AB29: ='OD-APUMA(Val)'!AB29*AB$49 -> 169 | AC29: 0 | AD29: ='OD-APUMA(Val)'!AD29*AD$49 -> 104 | AE29: ='OD-APUMA(Val)'!AE29*AE$49 -> 741 | AF29: ='OD-APUMA(Val)'!AF29*AF$49 -> 520 | AG29: ='OD-APUMA(Val)'!AG29*AG$49 -> 117 | AH29: ='OD-APUMA(Val)'!AH29*AH$49 -> 130 | AI29: ='OD-APUMA(Val)'!AI29*AI$49 -> 143 | AJ29: ='OD-APUMA(Val)'!AJ29*AJ$49 -> 0 | AK29: ='OD-APUMA(Val)'!AK29*AK$49 -> 104 | ... AQ29: ='OD-APUMA(Val)'!AQ29*AQ$49 -> 377 | AR29: =SUM('OD-APUMA(Val)'!C29:AQ29) -> 268060 | AS29: =MAX('OD-APUMA(Val)'!C29:AQ29) -> 250822 | AT29: =SUM(C29:AQ29)/AR29 -> 0.064306499 | AU29: =AT29^4 -> 1.7100919e-05
A30: 89 | B30: 320827 | C30: ='OD-APUMA(Val)'!C30*C$49 -> 104 | D30: ='OD-APUMA(Val)'!D30*D$49 -> 0 | E30: ='OD-APUMA(Val)'!E30*E$49 -> 0 | F30: ='OD-APUMA(Val)'!F30*F$49 -> 182 | G30: ='OD-APUMA(Val)'!G30*G$49 -> 0 | H30: ='OD-APUMA(Val)'!H30*H$49 -> 0 | I30: ='OD-APUMA(Val)'!I30*I$49 -> 0 | J30: ='OD-APUMA(Val)'!J30*J$49 -> 0 | ... AC30: ='OD-APUMA(Val)'!AC30*AC$49 -> 156 | AD30: 0 | AE30: ='OD-APUMA(Val)'!AE30*AE$49 -> 7618 | AF30: ='OD-APUMA(Val)'!AF30*AF$49 -> 208 | AG30: ='OD-APUMA(Val)'!AG30*AG$49 -> 169 | AH30: ='OD-APUMA(Val)'!AH30*AH$49 -> 91 | AI30: ='OD-APUMA(Val)'!AI30*AI$49 -> 0 | AJ30: ='OD-APUMA(Val)'!AJ30*AJ$49 -> 1664 | AK30: ='OD-APUMA(Val)'!AK30*AK$49 -> 0 | AL30: ='OD-APUMA(Val)'!AL30*AL$49 -> 91 | ... AQ30: ='OD-APUMA(Val)'!AQ30*AQ$49 -> 208 | AR30: =SUM('OD-APUMA(Val)'!C30:AQ30) -> 221559 | AS30: =MAX('OD-APUMA(Val)'!C30:AQ30) -> 207935 | AT30: =SUM(C30:AQ30)/AR30 -> 0.061491521 | AU30: =AT30^4 -> 1.4297528e-05
A31: 90 | B31: 4714869 | C31: ='OD-APUMA(Val)'!C31*C$49 -> 1573 | D31: ='OD-APUMA(Val)'!D31*D$49 -> 2535 | E31: ='OD-APUMA(Val)'!E31*E$49 -> 1079 | F31: ='OD-APUMA(Val)'!F31*F$49 -> 533 | G31: ='OD-APUMA(Val)'!G31*G$49 -> 312 | H31: ='OD-APUMA(Val)'!H31*H$49 -> 273 | I31: ='OD-APUMA(Val)'!I31*I$49 -> 273 | J31: ='OD-APUMA(Val)'!J31*J$49 -> 364 | ... AD31: ='OD-APUMA(Val)'!AD31*AD$49 -> 9503 | AE31: 0 | AF31: ='OD-APUMA(Val)'!AF31*AF$49 -> 793 | AG31: ='OD-APUMA(Val)'!AG31*AG$49 -> 136591 | AH31: ='OD-APUMA(Val)'!AH31*AH$49 -> 6617 | AI31: ='OD-APUMA(Val)'!AI31*AI$49 -> 468 | AJ31: ='OD-APUMA(Val)'!AJ31*AJ$49 -> 32331 | AK31: ='OD-APUMA(Val)'!AK31*AK$49 -> 3419 | AL31: ='OD-APUMA(Val)'!AL31*AL$49 -> 156 | AM31: ='OD-APUMA(Val)'!AM31*AM$49 -> 520 | ... AQ31: ='OD-APUMA(Val)'!AQ31*AQ$49 -> 21801 | AR31: =SUM('OD-APUMA(Val)'!C31:AQ31) -> 4091568 | AS31: =MAX('OD-APUMA(Val)'!C31:AQ31) -> 3859648 | AT31: =SUM(C31:AQ31)/AR31 -> 0.056682426 | AU31: =AT31^4 -> 1.032271e-05
A32: 91 | B32: 195273 | C32: ='OD-APUMA(Val)'!C32*C$49 -> 91 | D32: ='OD-APUMA(Val)'!D32*D$49 -> 0 | E32: ='OD-APUMA(Val)'!E32*E$49 -> 130 | F32: ='OD-APUMA(Val)'!F32*F$49 -> 78 | G32: ='OD-APUMA(Val)'!G32*G$49 -> 0 | H32: ='OD-APUMA(Val)'!H32*H$49 -> 0 | I32: ='OD-APUMA(Val)'!I32*I$49 -> 0 | J32: ='OD-APUMA(Val)'!J32*J$49 -> 130 | ... AE32: ='OD-APUMA(Val)'!AE32*AE$49 -> 260 | AF32: 0 | AG32: ='OD-APUMA(Val)'!AG32*AG$49 -> 0 | AH32: ='OD-APUMA(Val)'!AH32*AH$49 -> 0 | AI32: ='OD-APUMA(Val)'!AI32*AI$49 -> 0 | AJ32: ='OD-APUMA(Val)'!AJ32*AJ$49 -> 143 | AK32: ='OD-APUMA(Val)'!AK32*AK$49 -> 0 | AL32: ='OD-APUMA(Val)'!AL32*AL$49 -> 0 | AM32: ='OD-APUMA(Val)'!AM32*AM$49 -> 2275 | AN32: ='OD-APUMA(Val)'!AN32*AN$49 -> 0 | ... AQ32: ='OD-APUMA(Val)'!AQ32*AQ$49 -> 143 | AR32: =SUM('OD-APUMA(Val)'!C32:AQ32) -> 164359 | AS32: =MAX('OD-APUMA(Val)'!C32:AQ32) -> 152750 | AT32: =SUM(C32:AQ32)/AR32 -> 0.07063197 | AU32: =AT32^4 -> 2.4888876e-05
A33: 92 | B33: 1138865 | C33: ='OD-APUMA(Val)'!C33*C$49 -> 390 | D33: ='OD-APUMA(Val)'!D33*D$49 -> 104 | E33: ='OD-APUMA(Val)'!E33*E$49 -> 364 | F33: ='OD-APUMA(Val)'!F33*F$49 -> 182 | G33: ='OD-APUMA(Val)'!G33*G$49 -> 65 | H33: ='OD-APUMA(Val)'!H33*H$49 -> 78 | I33: ='OD-APUMA(Val)'!I33*I$49 -> 78 | J33: ='OD-APUMA(Val)'!J33*J$49 -> 0 | ... AF33: ='OD-APUMA(Val)'!AF33*AF$49 -> 0 | AG33: 0 | AH33: ='OD-APUMA(Val)'!AH33*AH$49 -> 9178 | AI33: ='OD-APUMA(Val)'!AI33*AI$49 -> 143 | AJ33: ='OD-APUMA(Val)'!AJ33*AJ$49 -> 9529 | AK33: ='OD-APUMA(Val)'!AK33*AK$49 -> 7098 | AL33: ='OD-APUMA(Val)'!AL33*AL$49 -> 78 | AM33: ='OD-APUMA(Val)'!AM33*AM$49 -> 416 | AN33: ='OD-APUMA(Val)'!AN33*AN$49 -> 0 | AO33: ='OD-APUMA(Val)'!AO33*AO$49 -> 78 | ... AQ33: ='OD-APUMA(Val)'!AQ33*AQ$49 -> 468 | AR33: =SUM('OD-APUMA(Val)'!C33:AQ33) -> 1278199 | AS33: =MAX('OD-APUMA(Val)'!C33:AQ33) -> 1047085 | AT33: =SUM(C33:AQ33)/AR33 -> 0.18081222 | AU33: =AT33^4 -> 0.0010688361
A34: 93 | B34: 687843 | C34: ='OD-APUMA(Val)'!C34*C$49 -> 364 | D34: ='OD-APUMA(Val)'!D34*D$49 -> 351 | E34: ='OD-APUMA(Val)'!E34*E$49 -> 260 | F34: ='OD-APUMA(Val)'!F34*F$49 -> 39 | G34: ='OD-APUMA(Val)'!G34*G$49 -> 0 | H34: ='OD-APUMA(Val)'!H34*H$49 -> 117 | I34: ='OD-APUMA(Val)'!I34*I$49 -> 104 | J34: ='OD-APUMA(Val)'!J34*J$49 -> 0 | ... AG34: ='OD-APUMA(Val)'!AG34*AG$49 -> 48828 | AH34: 0 | AI34: ='OD-APUMA(Val)'!AI34*AI$49 -> 104 | AJ34: ='OD-APUMA(Val)'!AJ34*AJ$49 -> 40846 | AK34: ='OD-APUMA(Val)'!AK34*AK$49 -> 7150 | AL34: ='OD-APUMA(Val)'!AL34*AL$49 -> 0 | AM34: ='OD-APUMA(Val)'!AM34*AM$49 -> 0 | AN34: ='OD-APUMA(Val)'!AN34*AN$49 -> 0 | AO34: ='OD-APUMA(Val)'!AO34*AO$49 -> 0 | AP34: ='OD-APUMA(Val)'!AP34*AP$49 -> 0 | AQ34: ='OD-APUMA(Val)'!AQ34*AQ$49 -> 117 | AR34: =SUM('OD-APUMA(Val)'!C34:AQ34) -> 482651 | AS34: =MAX('OD-APUMA(Val)'!C34:AQ34) -> 345176 | AT34: =SUM(C34:AQ34)/AR34 -> 0.28483314 | AU34: =AT34^4 -> 0.0065820636
A35: 94 | B35: 559078 | C35: ='OD-APUMA(Val)'!C35*C$49 -> 390 | D35: ='OD-APUMA(Val)'!D35*D$49 -> 481 | E35: ='OD-APUMA(Val)'!E35*E$49 -> 117 | F35: ='OD-APUMA(Val)'!F35*F$49 -> 104 | G35: ='OD-APUMA(Val)'!G35*G$49 -> 286 | H35: ='OD-APUMA(Val)'!H35*H$49 -> 169 | I35: ='OD-APUMA(Val)'!I35*I$49 -> 403 | J35: ='OD-APUMA(Val)'!J35*J$49 -> 429 | ... AH35: ='OD-APUMA(Val)'!AH35*AH$49 -> 0 | AI35: 0 | AJ35: ='OD-APUMA(Val)'!AJ35*AJ$49 -> 130 | AK35: ='OD-APUMA(Val)'!AK35*AK$49 -> 689 | AL35: ='OD-APUMA(Val)'!AL35*AL$49 -> 6344 | AM35: ='OD-APUMA(Val)'!AM35*AM$49 -> 1222 | AN35: ='OD-APUMA(Val)'!AN35*AN$49 -> 2327 | AO35: ='OD-APUMA(Val)'!AO35*AO$49 -> 0 | AP35: ='OD-APUMA(Val)'!AP35*AP$49 -> 182 | AQ35: ='OD-APUMA(Val)'!AQ35*AQ$49 -> 0 | AR35: =SUM('OD-APUMA(Val)'!C35:AQ35) -> 482352 | AS35: =MAX('OD-APUMA(Val)'!C35:AQ35) -> 424983 | AT35: =SUM(C35:AQ35)/AR35 -> 0.11893596 | AU35: =AT35^4 -> 0.00020010262
A36: 95 | B36: 822029 | C36: ='OD-APUMA(Val)'!C36*C$49 -> 390 | D36: ='OD-APUMA(Val)'!D36*D$49 -> 676 | E36: ='OD-APUMA(Val)'!E36*E$49 -> 546 | F36: ='OD-APUMA(Val)'!F36*F$49 -> 208 | G36: ='OD-APUMA(Val)'!G36*G$49 -> 0 | H36: ='OD-APUMA(Val)'!H36*H$49 -> 0 | I36: ='OD-APUMA(Val)'!I36*I$49 -> 0 | J36: ='OD-APUMA(Val)'!J36*J$49 -> 0 | ... AI36: ='OD-APUMA(Val)'!AI36*AI$49 -> 0 | AJ36: 0 | AK36: ='OD-APUMA(Val)'!AK36*AK$49 -> 767 | AL36: ='OD-APUMA(Val)'!AL36*AL$49 -> 130 | AM36: ='OD-APUMA(Val)'!AM36*AM$49 -> 221 | AN36: ='OD-APUMA(Val)'!AN36*AN$49 -> 0 | AO36: ='OD-APUMA(Val)'!AO36*AO$49 -> 117 | AP36: ='OD-APUMA(Val)'!AP36*AP$49 -> 65 | AQ36: ='OD-APUMA(Val)'!AQ36*AQ$49 -> 325 | AR36: =SUM('OD-APUMA(Val)'!C36:AQ36) -> 607932 | AS36: =MAX('OD-APUMA(Val)'!C36:AQ36) -> 414232 | AT36: =SUM(C36:AQ36)/AR36 -> 0.31862116 | AU36: =AT36^4 -> 0.010306198
A37: 96 | B37: 1264757 | C37: ='OD-APUMA(Val)'!C37*C$49 -> 572 | D37: ='OD-APUMA(Val)'!D37*D$49 -> 169 | E37: ='OD-APUMA(Val)'!E37*E$49 -> 130 | F37: ='OD-APUMA(Val)'!F37*F$49 -> 390 | G37: ='OD-APUMA(Val)'!G37*G$49 -> 78 | H37: ='OD-APUMA(Val)'!H37*H$49 -> 130 | I37: ='OD-APUMA(Val)'!I37*I$49 -> 208 | J37: ='OD-APUMA(Val)'!J37*J$49 -> 260 | ... AJ37: ='OD-APUMA(Val)'!AJ37*AJ$49 -> 1456 | AK37: 0 | AL37: ='OD-APUMA(Val)'!AL37*AL$49 -> 169 | AM37: ='OD-APUMA(Val)'!AM37*AM$49 -> 403 | AN37: ='OD-APUMA(Val)'!AN37*AN$49 -> 65 | AO37: ='OD-APUMA(Val)'!AO37*AO$49 -> 91 | AP37: ='OD-APUMA(Val)'!AP37*AP$49 -> 234 | AQ37: ='OD-APUMA(Val)'!AQ37*AQ$49 -> 429 | AR37: =SUM('OD-APUMA(Val)'!C37:AQ37) -> 1221532 | AS37: =MAX('OD-APUMA(Val)'!C37:AQ37) -> 1184040 | AT37: =SUM(C37:AQ37)/AR37 -> 0.030692606 | AU37: =AT37^4 -> 8.8743191e-07
A38: 97 | B38: 154115 | C38: ='OD-APUMA(Val)'!C38*C$49 -> 0 | D38: ='OD-APUMA(Val)'!D38*D$49 -> 0 | E38: ='OD-APUMA(Val)'!E38*E$49 -> 0 | F38: ='OD-APUMA(Val)'!F38*F$49 -> 0 | G38: ='OD-APUMA(Val)'!G38*G$49 -> 0 | H38: ='OD-APUMA(Val)'!H38*H$49 -> 0 | I38: ='OD-APUMA(Val)'!I38*I$49 -> 0 | J38: ='OD-APUMA(Val)'!J38*J$49 -> 0 | ... AK38: ='OD-APUMA(Val)'!AK38*AK$49 -> 0 | AL38: 0 | AM38: ='OD-APUMA(Val)'!AM38*AM$49 -> 3159 | AN38: ='OD-APUMA(Val)'!AN38*AN$49 -> 234 | AO38: ='OD-APUMA(Val)'!AO38*AO$49 -> 0 | AP38: ='OD-APUMA(Val)'!AP38*AP$49 -> 4927 | AQ38: ='OD-APUMA(Val)'!AQ38*AQ$49 -> 0 | AR38: =SUM('OD-APUMA(Val)'!C38:AQ38) -> 109590 | AS38: =MAX('OD-APUMA(Val)'!C38:AQ38) -> 85462 | AT38: =SUM(C38:AQ38)/AR38 -> 0.22016607 | AU38: =AT38^4 -> 0.0023496414
A39: 98 | B39: 686517 | C39: ='OD-APUMA(Val)'!C39*C$49 -> 91 | D39: ='OD-APUMA(Val)'!D39*D$49 -> 143 | E39: ='OD-APUMA(Val)'!E39*E$49 -> 234 | F39: ='OD-APUMA(Val)'!F39*F$49 -> 182 | G39: ='OD-APUMA(Val)'!G39*G$49 -> 0 | H39: ='OD-APUMA(Val)'!H39*H$49 -> 0 | I39: ='OD-APUMA(Val)'!I39*I$49 -> 0 | J39: ='OD-APUMA(Val)'!J39*J$49 -> 0 | ... AL39: ='OD-APUMA(Val)'!AL39*AL$49 -> 780 | AM39: 0 | AN39: ='OD-APUMA(Val)'!AN39*AN$49 -> 403 | AO39: ='OD-APUMA(Val)'!AO39*AO$49 -> 273 | AP39: ='OD-APUMA(Val)'!AP39*AP$49 -> 156 | AQ39: ='OD-APUMA(Val)'!AQ39*AQ$49 -> 130 | AR39: =SUM('OD-APUMA(Val)'!C39:AQ39) -> 804063 | AS39: =MAX('OD-APUMA(Val)'!C39:AQ39) -> 714948 | AT39: =SUM(C39:AQ39)/AR39 -> 0.11083087 | AU39: =AT39^4 -> 0.00015088391
A40: 99 | B40: 183391 | C40: ='OD-APUMA(Val)'!C40*C$49 -> 130 | D40: ='OD-APUMA(Val)'!D40*D$49 -> 0 | E40: ='OD-APUMA(Val)'!E40*E$49 -> 0 | F40: ='OD-APUMA(Val)'!F40*F$49 -> 0 | G40: ='OD-APUMA(Val)'!G40*G$49 -> 0 | H40: ='OD-APUMA(Val)'!H40*H$49 -> 0 | I40: ='OD-APUMA(Val)'!I40*I$49 -> 0 | J40: ='OD-APUMA(Val)'!J40*J$49 -> 104 | ... AM40: ='OD-APUMA(Val)'!AM40*AM$49 -> 936 | AN40: 0 | AO40: ='OD-APUMA(Val)'!AO40*AO$49 -> 1118 | AP40: ='OD-APUMA(Val)'!AP40*AP$49 -> 91 | AQ40: ='OD-APUMA(Val)'!AQ40*AQ$49 -> 0 | AR40: =SUM('OD-APUMA(Val)'!C40:AQ40) -> 158938 | AS40: =MAX('OD-APUMA(Val)'!C40:AQ40) -> 99255 | AT40: =SUM(C40:AQ40)/AR40 -> 0.37551121 | AU40: =AT40^4 -> 0.019883444
...

Sheet NeighborEffect-i=3
A1: Sum of TRIPS | B1: D-APUMA
A2: O-APUMA | B2: 0 | C2: 1 | D2: 2 | E2: 3 | F2: 4 | G2: 5 | H2: 6 | I2: 7 | J2: 8 | K2: 9 | L2: 10 | M2: 11 | N2: 12 | O2: 15 | P2: 19 | Q2: 22 | R2: 26 | S2: 27 | T2: 30 | U2: 31 | V2: 32 | W2: 75 | X2: 76 | Y2: 77 | Z2: 80 | AA2: 86 | AB2: 87 | AC2: 88 | AD2: 89 | AE2: 90 | AF2: 91 | AG2: 92 | AH2: 93 | AI2: 94 | AJ2: 95 | AK2: 96 | AL2: 97 | AM2: 98 | AN2: 99 | AO2: 100 | AP2: 101 | AQ2: 103 | AR2: Work | AS2: Locals | AT2: OutOfStateSum | AU2: N1^4
A3: 1 | B3: 70434 | C3: 0 | D3: ='OD-APUMA(Val)'!D3*D$49 -> 13.859238 | E3: ='OD-APUMA(Val)'!E3*E$49 -> 67.729722 | F3: ='OD-APUMA(Val)'!F3*F$49 -> 18.773238 | G3: ='OD-APUMA(Val)'!G3*G$49 -> 18.547528 | H3: ='OD-APUMA(Val)'!H3*H$49 -> 2.1138061 | I3: ='OD-APUMA(Val)'!I3*I$49 -> 403 | J3: ='OD-APUMA(Val)'!J3*J$49 -> 0 | K3: ='OD-APUMA(Val)'!K3*K$49 -> 0 | ... AQ3: ='OD-APUMA(Val)'!AQ3*AQ$49 -> 0 | AR3: =SUM('OD-APUMA(Val)'!C3:AQ3) -> 35412 | AS3: =MAX('OD-APUMA(Val)'!C3:AQ3) -> 32903 | AT3: =SUM(C3:AQ3)/AR3 -> 0.032094042 | AU3: =AT3^4 -> 1.0609568e-06
A4: 2 | B4: 70551 | C4: ='OD-APUMA(Val)'!C4*C$49 -> 31.414472 | D4: 0 | E4: ='OD-APUMA(Val)'!E4*E$49 -> 0 | F4: ='OD-APUMA(Val)'!F4*F$49 -> 49.279751 | G4: ='OD-APUMA(Val)'!G4*G$49 -> 0 | H4: ='OD-APUMA(Val)'!H4*H$49 -> 0 | I4: ='OD-APUMA(Val)'!I4*I$49 -> 0 | J4: ='OD-APUMA(Val)'!J4*J$49 -> 0 | K4: ='OD-APUMA(Val)'!K4*K$49 -> 0 | L4: ='OD-APUMA(Val)'!L4*L$49 -> 0 | ... AQ4: ='OD-APUMA(Val)'!AQ4*AQ$49 -> 0 | AR4: =SUM('OD-APUMA(Val)'!C4:AQ4) -> 50492 | AS4: =MAX('OD-APUMA(Val)'!C4:AQ4) -> 49764 | AT4: =SUM(C4:AQ4)/AR4 -> 0.0033275465 | AU4: =AT4^4 -> 1.2260171e-10
A5: 3 | B5: 93327 | C5: ='OD-APUMA(Val)'!C5*C$49 -> 74.796362 | D5: ='OD-APUMA(Val)'!D5*D$49 -> 7.3372436 | E5: 0 | F5: ='OD-APUMA(Val)'!F5*F$49 -> 9.3866192 | G5: ='OD-APUMA(Val)'!G5*G$49 -> 352.40303 | H5: ='OD-APUMA(Val)'!H5*H$49 -> 1.6440714 | I5: ='OD-APUMA(Val)'!I5*I$49 -> 0 | J5: ='OD-APUMA(Val)'!J5*J$49 -> 0 | K5: ='OD-APUMA(Val)'!K5*K$49 -> 0 | L5: ='OD-APUMA(Val)'!L5*L$49 -> 91 | M5: ='OD-APUMA(Val)'!M5*M$49 -> 0 | ... AQ5: ='OD-APUMA(Val)'!AQ5*AQ$49 -> 0 | AR5: =SUM('OD-APUMA(Val)'!C5:AQ5) -> 59163 | AS5: =MAX('OD-APUMA(Val)'!C5:AQ5) -> 55562 | AT5: =SUM(C5:AQ5)/AR5 -> 0.028394453 | AU5: =AT5^4 -> 6.5003094e-07
A6: 4 | B6: 79183 | C6: ='OD-APUMA(Val)'!C6*C$49 -> 0 | D6: ='OD-APUMA(Val)'!D6*D$49 -> 0 | E6: ='OD-APUMA(Val)'!E6*E$49 -> 0 | F6: 0 | G6: ='OD-APUMA(Val)'!G6*G$49 -> 11.128517 | H6: ='OD-APUMA(Val)'!H6*H$49 -> 0 | I6: ='OD-APUMA(Val)'!I6*I$49 -> 182 | J6: ='OD-APUMA(Val)'!J6*J$49 -> 96.055598 | K6: ='OD-APUMA(Val)'!K6*K$49 -> 65 | L6: ='OD-APUMA(Val)'!L6*L$49 -> 0 | M6: ='OD-APUMA(Val)'!M6*M$49 -> 0 | N6: ='OD-APUMA(Val)'!N6*N$49 -> 0 | ... AQ6: ='OD-APUMA(Val)'!AQ6*AQ$49 -> 0 | AR6: =SUM('OD-APUMA(Val)'!C6:AQ6) -> 51012 | AS6: =MAX('OD-APUMA(Val)'!C6:AQ6) -> 47697 | AT6: =SUM(C6:AQ6)/AR6 -> 0.060155834 | AU6: =AT6^4 -> 1.3095166e-05
A7: 5 | B7: 66183 | C7: ='OD-APUMA(Val)'!C7*C$49 -> 0 | D7: ='OD-APUMA(Val)'!D7*D$49 -> 33.425221 | E7: ='OD-APUMA(Val)'!E7*E$49 -> 197.54502 | F7: ='OD-APUMA(Val)'!F7*F$49 -> 11.733274 | G7: 0 | H7: ='OD-APUMA(Val)'!H7*H$49 -> 19.963725 | I7: ='OD-APUMA(Val)'!I7*I$49 -> 572 | J7: ='OD-APUMA(Val)'!J7*J$49 -> 0 | K7: ='OD-APUMA(Val)'!K7*K$49 -> 0 | L7: ='OD-APUMA(Val)'!L7*L$49 -> 0 | M7: ='OD-APUMA(Val)'!M7*M$49 -> 143 | N7: ='OD-APUMA(Val)'!N7*N$49 -> 0 | O7: ='OD-APUMA(Val)'!O7*O$49 -> 0 | ... AQ7: ='OD-APUMA(Val)'!AQ7*AQ$49 -> 0 | AR7: =SUM('OD-APUMA(Val)'!C7:AQ7) -> 34164 | AS7: =MAX('OD-APUMA(Val)'!C7:AQ7) -> 28613 | AT7: =SUM(C7:AQ7)/AR7 -> 0.052090346 | AU7: =AT7^4 -> 7.3625623e-06
A8: 6 | B8: 111722 | C8: ='OD-APUMA(Val)'!C8*C$49 -> 34.406326 | D8: ='OD-APUMA(Val)'!D8*D$49 -> 0 | E8: ='OD-APUMA(Val)'!E8*E$49 -> 5.6441435 | F8: ='OD-APUMA(Val)'!F8*F$49 -> 0 | G8: ='OD-APUMA(Val)'!G8*G$49 -> 396.9171 | H8: 0 | I8: ='OD-APUMA(Val)'!I8*I$49 -> 260 | J8: ='OD-APUMA(Val)'!J8*J$49 -> 1355.4512 | K8: ='OD-APUMA(Val)'!K8*K$49 -> 117 | L8: ='OD-APUMA(Val)'!L8*L$49 -> 0 | M8: ='OD-APUMA(Val)'!M8*M$49 -> 117 | N8: ='OD-APUMA(Val)'!N8*N$49 -> 0 | O8: ='OD-APUMA(Val)'!O8*O$49 -> 0 | P8: ='OD-APUMA(Val)'!P8*P$49 -> 0 | ... AQ8: ='OD-APUMA(Val)'!AQ8*AQ$49 -> 0 | AR8: =SUM('OD-APUMA(Val)'!C8:AQ8) -> 67522 | AS8: =MAX('OD-APUMA(Val)'!C8:AQ8) -> 62647 | AT8: =SUM(C8:AQ8)/AR8 -> 0.042292413 | AU8: =AT8^4 -> 3.1992623e-06
A9: 7 | B9: 61087 | C9: ='OD-APUMA(Val)'!C9*C$49 -> 11.967418 | D9: ='OD-APUMA(Val)'!D9*D$49 -> 0 | E9: ='OD-APUMA(Val)'!E9*E$49 -> 54.183778 | F9: ='OD-APUMA(Val)'!F9*F$49 -> 68.05299 | G9: ='OD-APUMA(Val)'!G9*G$49 -> 22.257034 | H9: ='OD-APUMA(Val)'!H9*H$49 -> 3.7578776 | I9: 0 | J9: ='OD-APUMA(Val)'!J9*J$49 -> 533.64221 | K9: ='OD-APUMA(Val)'!K9*K$49 -> 78 | L9: ='OD-APUMA(Val)'!L9*L$49 -> 0 | M9: ='OD-APUMA(Val)'!M9*M$49 -> 3822 | N9: ='OD-APUMA(Val)'!N9*N$49 -> 0 | O9: ='OD-APUMA(Val)'!O9*O$49 -> 0 | P9: ='OD-APUMA(Val)'!P9*P$49 -> 117 | Q9: ='OD-APUMA(Val)'!Q9*Q$49 -> 117 | ... AQ9: ='OD-APUMA(Val)'!AQ9*AQ$49 -> 0 | AR9: =SUM('OD-APUMA(Val)'!C9:AQ9) -> 41067 | AS9: =MAX('OD-APUMA(Val)'!C9:AQ9) -> 32396 | AT9: =SUM(C9:AQ9)/AR9 -> 0.17014807 | AU9: =AT9^4 -> 0.00083812372
A10: 8 | B10: 74074 | C10: ='OD-APUMA(Val)'!C10*C$49 -> 0 | D10: ='OD-APUMA(Val)'!D10*D$49 -> 0 | E10: ='OD-APUMA(Val)'!E10*E$49 -> 0 | F10: ='OD-APUMA(Val)'!F10*F$49 -> 0 | G10: ='OD-APUMA(Val)'!G10*G$49 -> 114.99467 | H10: ='OD-APUMA(Val)'!H10*H$49 -> 11.978235 | I10: ='OD-APUMA(Val)'!I10*I$49 -> 312 | J10: 0 | K10: ='OD-APUMA(Val)'!K10*K$49 -> 0 | L10: ='OD-APUMA(Val)'!L10*L$49 -> 1521 | M10: ='OD-APUMA(Val)'!M10*M$49 -> 1196 | N10: ='OD-APUMA(Val)'!N10*N$49 -> 0 | O10: ='OD-APUMA(Val)'!O10*O$49 -> 0 | P10: ='OD-APUMA(Val)'!P10*P$49 -> 0 | Q10: ='OD-APUMA(Val)'!Q10*Q$49 -> 0 | R10: ='OD-APUMA(Val)'!R10*R$49 -> 0 | ... AQ10: ='OD-APUMA(Val)'!AQ10*AQ$49 -> 0 | AR10: =SUM('OD-APUMA(Val)'!C10:AQ10) -> 46839 | AS10: =MAX('OD-APUMA(Val)'!C10:AQ10) -> 38493 | AT10: =SUM(C10:AQ10)/AR10 -> 0.15813687 | AU10: =AT10^4 -> 0.00062536355
A11: 9 | B11: 57291 | C11: ='OD-APUMA(Val)'!C11*C$49 -> 16.4552 | D11: ='OD-APUMA(Val)'!D11*D$49 -> 0 | E11: ='OD-APUMA(Val)'!E11*E$49 -> 0 | F11: ='OD-APUMA(Val)'!F11*F$49 -> 37.546477 | G11: ='OD-APUMA(Val)'!G11*G$49 -> 0 | H11: ='OD-APUMA(Val)'!H11*H$49 -> 0 | I11: ='OD-APUMA(Val)'!I11*I$49 -> 0 | J11: ='OD-APUMA(Val)'!J11*J$49 -> 0 | K11: 0 | L11: ='OD-APUMA(Val)'!L11*L$49 -> 104 | M11: ='OD-APUMA(Val)'!M11*M$49 -> 0 | N11: ='OD-APUMA(Val)'!N11*N$49 -> 0 | O11: ='OD-APUMA(Val)'!O11*O$49 -> 429 | P11: ='OD-APUMA(Val)'!P11*P$49 -> 897 | Q11: ='OD-APUMA(Val)'!Q11*Q$49 -> 195 | R11: ='OD-APUMA(Val)'!R11*R$49 -> 0 | S11: ='OD-APUMA(Val)'!S11*S$49 -> 0 | ... AQ11: ='OD-APUMA(Val)'!AQ11*AQ$49 -> 0 | AR11: =SUM('OD-APUMA(Val)'!C11:AQ11) -> 51909 | AS11: =MAX('OD-APUMA(Val)'!C11:AQ11) -> 37791 | AT11: =SUM(C11:AQ11)/AR11 -> 0.26267741 | AU11: =AT11^4 -> 0.0047609206
A12: 10 | B12: 75231 | C12: ='OD-APUMA(Val)'!C12*C$49 -> 7.4796362 | D12: ='OD-APUMA(Val)'!D12*D$49 -> 0 | E12: ='OD-APUMA(Val)'!E12*E$49 -> 19.190088 | F12: ='OD-APUMA(Val)'!F12*F$49 -> 0 | G12: ='OD-APUMA(Val)'!G12*G$49 -> 51.933078 | H12: ='OD-APUMA(Val)'!H12*H$49 -> 3.9927449 | I12: ='OD-APUMA(Val)'!I12*I$49 -> 0 | J12: ='OD-APUMA(Val)'!J12*J$49 -> 416.24092 | K12: ='OD-APUMA(Val)'!K12*K$49 -> 169 | L12: 0 | M12: ='OD-APUMA(Val)'!M12*M$49 -> 208 | N12: ='OD-APUMA(Val)'!N12*N$49 -> 195 | O12: ='OD-APUMA(Val)'!O12*O$49 -> 0 | P12: ='OD-APUMA(Val)'!P12*P$49 -> 0 | Q12: ='OD-APUMA(Val)'!Q12*Q$49 -> 78 | R12: ='OD-APUMA(Val)'!R12*R$49 -> 72.710134 | S12: ='OD-APUMA(Val)'!S12*S$49 -> 0 | T12: ='OD-APUMA(Val)'!T12*T$49 -> 0 | ... AQ12: ='OD-APUMA(Val)'!AQ12*AQ$49 -> 0 | AR12: =SUM('OD-APUMA(Val)'!C12:AQ12) -> 66885 | AS12: =MAX('OD-APUMA(Val)'!C12:AQ12) -> 44408 | AT12: =SUM(C12:AQ12)/AR12 -> 0.32390726 | AU12: =AT12^4 -> 0.011007348
A13: 11 | B13: 90948 | C13: ='OD-APUMA(Val)'!C13*C$49 -> 0 | D13: ='OD-APUMA(Val)'!D13*D$49 -> 0 | E13: ='OD-APUMA(Val)'!E13*E$49 -> 37.251347 | F13: ='OD-APUMA(Val)'!F13*F$49 -> 262.82534 | G13: ='OD-APUMA(Val)'!G13*G$49 -> 118.70418 | H13: ='OD-APUMA(Val)'!H13*H$49 -> 0 | I13: ='OD-APUMA(Val)'!I13*I$49 -> 1872 | J13: ='OD-APUMA(Val)'!J13*J$49 -> 202.78404 | ... L13: ='OD-APUMA(Val)'!L13*L$49 -> 1131 | M13: 0 | N13: ='OD-APUMA(Val)'!N13*N$49 -> 104 | O13: ='OD-APUMA(Val)'!O13*O$49 -> 0 | P13: ='OD-APUMA(Val)'!P13*P$49 -> 91 | Q13: ='OD-APUMA(Val)'!Q13*Q$49 -> 26 | R13: ='OD-APUMA(Val)'!R13*R$49 -> 193.89369 | S13: ='OD-APUMA(Val)'!S13*S$49 -> 0 | T13: ='OD-APUMA(Val)'!T13*T$49 -> 0 | U13: ='OD-APUMA(Val)'!U13*U$49 -> 0 | ... AQ13: ='OD-APUMA(Val)'!AQ13*AQ$49 -> 16.86644 | AR13: =SUM('OD-APUMA(Val)'!C13:AQ13) -> 80626 | AS13: =MAX('OD-APUMA(Val)'!C13:AQ13) -> 46007 | AT13: =SUM(C13:AQ13)/AR13 -> 0.39319103 | AU13: =AT13^4 -> 0.023900908
A14: 12 | B14: 66781 | C14: ='OD-APUMA(Val)'!C14*C$49 -> 0 | D14: ='OD-APUMA(Val)'!D14*D$49 -> 8.9677422 | E14: ='OD-APUMA(Val)'!E14*E$49 -> 25.96306 | F14: ='OD-APUMA(Val)'!F14*F$49 -> 0 | G14: ='OD-APUMA(Val)'!G14*G$49 -> 1658.149 | H14: ='OD-APUMA(Val)'!H14*H$49 -> 2.5835408 | I14: ='OD-APUMA(Val)'!I14*I$49 -> 130 | J14: ='OD-APUMA(Val)'!J14*J$49 -> 0 | ... M14: ='OD-APUMA(Val)'!M14*M$49 -> 1651 | N14: 0 | O14: ='OD-APUMA(Val)'!O14*O$49 -> 0 | P14: ='OD-APUMA(Val)'!P14*P$49 -> 156 | Q14: ='OD-APUMA(Val)'!Q14*Q$49 -> 182 | R14: ='OD-APUMA(Val)'!R14*R$49 -> 193.89369 | S14: ='OD-APUMA(Val)'!S14*S$49 -> 0 | T14: ='OD-APUMA(Val)'!T14*T$49 -> 0 | U14: ='OD-APUMA(Val)'!U14*U$49 -> 0 | V14: ='OD-APUMA(Val)'!V14*V$49 -> 0 | ... AQ14: ='OD-APUMA(Val)'!AQ14*AQ$49 -> 8.4332198 | AR14: =SUM('OD-APUMA(Val)'!C14:AQ14) -> 56082 | AS14: =MAX('OD-APUMA(Val)'!C14:AQ14) -> 30693 | AT14: =SUM(C14:AQ14)/AR14 -> 0.35960258 | AU14: =AT14^4 -> 0.016722114
A15: 15 | B15: 103519 | C15: ='OD-APUMA(Val)'!C15*C$49 -> 0 | D15: ='OD-APUMA(Val)'!D15*D$49 -> 0 | E15: ='OD-APUMA(Val)'!E15*E$49 -> 9.0306296 | F15: ='OD-APUMA(Val)'!F15*F$49 -> 23.466548 | G15: ='OD-APUMA(Val)'!G15*G$49 -> 0 | H15: ='OD-APUMA(Val)'!H15*H$49 -> 0 | I15: ='OD-APUMA(Val)'!I15*I$49 -> 0 | J15: ='OD-APUMA(Val)'!J15*J$49 -> 160.09266 | ... N15: ='OD-APUMA(Val)'!N15*N$49 -> 0 | O15: 0 | P15: ='OD-APUMA(Val)'!P15*P$49 -> 33098 | Q15: ='OD-APUMA(Val)'!Q15*Q$49 -> 3744 | R15: ='OD-APUMA(Val)'!R15*R$49 -> 0 | S15: ='OD-APUMA(Val)'!S15*S$49 -> 0 | T15: ='OD-APUMA(Val)'!T15*T$49 -> 0 | U15: ='OD-APUMA(Val)'!U15*U$49 -> 0 | V15: ='OD-APUMA(Val)'!V15*V$49 -> 0 | W15: ='OD-APUMA(Val)'!W15*W$49 -> 0 | ... AQ15: ='OD-APUMA(Val)'!AQ15*AQ$49 -> 0 | AR15: =SUM('OD-APUMA(Val)'!C15:AQ15) -> 124878 | AS15: =MAX('OD-APUMA(Val)'!C15:AQ15) -> 72592 | AT15: =SUM(C15:AQ15)/AR15 -> 0.41304557 | AU15: =AT15^4 -> 0.029106627
A16: 19 | B16: 347230 | C16: ='OD-APUMA(Val)'!C16*C$49 -> 16.4552 | D16: ='OD-APUMA(Val)'!D16*D$49 -> 4.8914957 | E16: ='OD-APUMA(Val)'!E16*E$49 -> 13.545944 | F16: ='OD-APUMA(Val)'!F16*F$49 -> 32.853167 | G16: ='OD-APUMA(Val)'!G16*G$49 -> 0 | H16: ='OD-APUMA(Val)'!H16*H$49 -> 0 | I16: ='OD-APUMA(Val)'!I16*I$49 -> 78 | J16: ='OD-APUMA(Val)'!J16*J$49 -> 0 | ... O16: ='OD-APUMA(Val)'!O16*O$49 -> 4095 | P16: 0 | Q16: ='OD-APUMA(Val)'!Q16*Q$49 -> 29393 | R16: ='OD-APUMA(Val)'!R16*R$49 -> 0 | S16: ='OD-APUMA(Val)'!S16*S$49 -> 0 | T16: ='OD-APUMA(Val)'!T16*T$49 -> 0 | U16: ='OD-APUMA(Val)'!U16*U$49 -> 0 | V16: ='OD-APUMA(Val)'!V16*V$49 -> 3.0980301 | W16: ='OD-APUMA(Val)'!W16*W$49 -> 0 | X16: ='OD-APUMA(Val)'!X16*X$49 -> 170.82049 | ... AQ16: ='OD-APUMA(Val)'!AQ16*AQ$49 -> 0 | AR16: =SUM('OD-APUMA(Val)'!C16:AQ16) -> 385580 | AS16: =MAX('OD-APUMA(Val)'!C16:AQ16) -> 313768 | AT16: =SUM(C16:AQ16)/AR16 -> 0.18145007 | AU16: =AT16^4 -> 0.0010839981
A17: 22 | B17: 313391 | C17: ='OD-APUMA(Val)'!C17*C$49 -> 19.447054 | D17: ='OD-APUMA(Val)'!D17*D$49 -> 0 | E17: ='OD-APUMA(Val)'!E17*E$49 -> 19.190088 | F17: ='OD-APUMA(Val)'!F17*F$49 -> 0 | G17: ='OD-APUMA(Val)'!G17*G$49 -> 51.933078 | H17: ='OD-APUMA(Val)'!H17*H$49 -> 0 | I17: ='OD-APUMA(Val)'!I17*I$49 -> 0 | J17: ='OD-APUMA(Val)'!J17*J$49 -> 0 | ... P17: ='OD-APUMA(Val)'!P17*P$49 -> 80925 | Q17: 0 | R17: ='OD-APUMA(Val)'!R17*R$49 -> 0 | S17: ='OD-APUMA(Val)'!S17*S$49 -> 0 | T17: ='OD-APUMA(Val)'!T17*T$49 -> 0 | U17: ='OD-APUMA(Val)'!U17*U$49 -> 0 | V17: ='OD-APUMA(Val)'!V17*V$49 -> 0 | W17: ='OD-APUMA(Val)'!W17*W$49 -> 0 | X17: ='OD-APUMA(Val)'!X17*X$49 -> 185.67445 | Y17: ='OD-APUMA(Val)'!Y17*Y$49 -> 0 | ... AQ17: ='OD-APUMA(Val)'!AQ17*AQ$49 -> 0 | AR17: =SUM('OD-APUMA(Val)'!C17:AQ17) -> 350818 | AS17: =MAX('OD-APUMA(Val)'!C17:AQ17) -> 203580 | AT17: =SUM(C17:AQ17)/AR17 -> 0.41584682 | AU17: =AT17^4 -> 0.029904293
A18: 26 | B18: 95186 | C18: ='OD-APUMA(Val)'!C18*C$49 -> 0 | D18: ='OD-APUMA(Val)'!D18*D$49 -> 0 | E18: ='OD-APUMA(Val)'!E18*E$49 -> 2.2576574 | F18: ='OD-APUMA(Val)'!F18*F$49 -> 0 | G18: ='OD-APUMA(Val)'!G18*G$49 -> 59.35209 | H18: ='OD-APUMA(Val)'!H18*H$49 -> 0 | I18: ='OD-APUMA(Val)'!I18*I$49 -> 0 | J18: ='OD-APUMA(Val)'!J18*J$49 -> 0 | ... Q18: ='OD-APUMA(Val)'!Q18*Q$49 -> 299 | R18: 0 | S18: ='OD-APUMA(Val)'!S18*S$49 -> 98.384968 | T18: ='OD-APUMA(Val)'!T18*T$49 -> 7.2130677 | U18: ='OD-APUMA(Val)'!U18*U$49 -> 0 | V18: ='OD-APUMA(Val)'!V18*V$49 -> 0 | W18: ='OD-APUMA(Val)'!W18*W$49 -> 0 | X18: ='OD-APUMA(Val)'!X18*X$49 -> 0 | Y18: ='OD-APUMA(Val)'!Y18*Y$49 -> 0 | Z18: ='OD-APUMA(Val)'!Z18*Z$49 -> 0 | ... AQ18: ='OD-APUMA(Val)'!AQ18*AQ$49 -> 0 | AR18: =SUM('OD-APUMA(Val)'!C18:AQ18) -> 59358 | AS18: =MAX('OD-APUMA(Val)'!C18:AQ18) -> 49543 | AT18: =SUM(C18:AQ18)/AR18 -> 0.1446425 | AU18: =AT18^4 -> 0.00043770715
A19: 27 | B19: 78299 | C19: ='OD-APUMA(Val)'!C19*C$49 -> 0 | D19: ='OD-APUMA(Val)'!D19*D$49 -> 0 | E19: ='OD-APUMA(Val)'!E19*E$49 -> 0 | F19: ='OD-APUMA(Val)'!F19*F$49 -> 0 | G19: ='OD-APUMA(Val)'!G19*G$49 -> 0 | H19: ='OD-APUMA(Val)'!H19*H$49 -> 0 | I19: ='OD-APUMA(Val)'!I19*I$49 -> 0 | J19: ='OD-APUMA(Val)'!J19*J$49 -> 0 | ... R19: ='OD-APUMA(Val)'!R19*R$49 -> 266.60383 | S19: 0 | T19: ='OD-APUMA(Val)'!T19*T$49 -> 61.311075 | U19: ='OD-APUMA(Val)'!U19*U$49 -> 20.230573 | V19: ='OD-APUMA(Val)'!V19*V$49 -> 2.3235226 | W19: ='OD-APUMA(Val)'!W19*W$49 -> 1.8924933 | X19: ='OD-APUMA(Val)'!X19*X$49 -> 200.5284 | Y19: ='OD-APUMA(Val)'!Y19*Y$49 -> 0.017697328 | Z19: ='OD-APUMA(Val)'!Z19*Z$49 -> 0 | AA19: ='OD-APUMA(Val)'!AA19*AA$49 -> 91 | ... AQ19: ='OD-APUMA(Val)'!AQ19*AQ$49 -> 0 | AR19: =SUM('OD-APUMA(Val)'!C19:AQ19) -> 50674 | AS19: =MAX('OD-APUMA(Val)'!C19:AQ19) -> 34346 | AT19: =SUM(C19:AQ19)/AR19 -> 0.11217575 | AU19: =AT19^4 -> 0.00015834193
A20: 30 | B20: 108225 | C20: ='OD-APUMA(Val)'!C20*C$49 -> 0 | D20: ='OD-APUMA(Val)'!D20*D$49 -> 0 | E20: ='OD-APUMA(Val)'!E20*E$49 -> 0 | F20: ='OD-APUMA(Val)'!F20*F$49 -> 0 | G20: ='OD-APUMA(Val)'!G20*G$49 -> 0 | H20: ='OD-APUMA(Val)'!H20*H$49 -> 0 | I20: ='OD-APUMA(Val)'!I20*I$49 -> 0 | J20: ='OD-APUMA(Val)'!J20*J$49 -> 0 | ... S20: ='OD-APUMA(Val)'!S20*S$49 -> 238.58355 | T20: 0 | U20: ='OD-APUMA(Val)'!U20*U$49 -> 25.288216 | V20: ='OD-APUMA(Val)'!V20*V$49 -> 0 | W20: ='OD-APUMA(Val)'!W20*W$49 -> 0 | X20: ='OD-APUMA(Val)'!X20*X$49 -> 0 | Y20: ='OD-APUMA(Val)'!Y20*Y$49 -> 0 | Z20: ='OD-APUMA(Val)'!Z20*Z$49 -> 0 | AA20: ='OD-APUMA(Val)'!AA20*AA$49 -> 52 | AB20: ='OD-APUMA(Val)'!AB20*AB$49 -> 0 | ... AQ20: ='OD-APUMA(Val)'!AQ20*AQ$49 -> 0 | AR20: =SUM('OD-APUMA(Val)'!C20:AQ20) -> 68432 | AS20: =MAX('OD-APUMA(Val)'!C20:AQ20) -> 59956 | AT20: =SUM(C20:AQ20)/AR20 -> 0.098317828 | AU20: =AT20^4 -> 9.3439197e-05
A21: 31 | B21: 63609 | C21: ='OD-APUMA(Val)'!C21*C$49 -> 0 | D21: ='OD-APUMA(Val)'!D21*D$49 -> 0 | E21: ='OD-APUMA(Val)'!E21*E$49 -> 0 | F21: ='OD-APUMA(Val)'!F21*F$49 -> 0 | G21: ='OD-APUMA(Val)'!G21*G$49 -> 0 | H21: ='OD-APUMA(Val)'!H21*H$49 -> 0 | I21: ='OD-APUMA(Val)'!I21*I$49 -> 0 | J21: ='OD-APUMA(Val)'!J21*J$49 -> 0 | ... T21: ='OD-APUMA(Val)'!T21*T$49 -> 0 | U21: 0 | V21: ='OD-APUMA(Val)'!V21*V$49 -> 3.4852838 | W21: ='OD-APUMA(Val)'!W21*W$49 -> 20.628177 | X21: ='OD-APUMA(Val)'!X21*X$49 -> 0 | Y21: ='OD-APUMA(Val)'!Y21*Y$49 -> 0 | Z21: ='OD-APUMA(Val)'!Z21*Z$49 -> 22.587457 | AA21: ='OD-APUMA(Val)'!AA21*AA$49 -> 169 | AB21: ='OD-APUMA(Val)'!AB21*AB$49 -> 0 | AC21: ='OD-APUMA(Val)'!AC21*AC$49 -> 70.382722 | ... AQ21: ='OD-APUMA(Val)'!AQ21*AQ$49 -> 0 | AR21: =SUM('OD-APUMA(Val)'!C21:AQ21) -> 35698 | AS21: =MAX('OD-APUMA(Val)'!C21:AQ21) -> 30563 | AT21: =SUM(C21:AQ21)/AR21 -> 0.011356037 | AU21: =AT21^4 -> 1.6630573e-08
A22: 32 | B22: 187317 | C22: ='OD-APUMA(Val)'!C22*C$49 -> 0 | D22: ='OD-APUMA(Val)'!D22*D$49 -> 0 | E22: ='OD-APUMA(Val)'!E22*E$49 -> 5.6441435 | F22: ='OD-APUMA(Val)'!F22*F$49 -> 0 | G22: ='OD-APUMA(Val)'!G22*G$49 -> 0 | H22: ='OD-APUMA(Val)'!H22*H$49 -> 0 | I22: ='OD-APUMA(Val)'!I22*I$49 -> 0 | J22: ='OD-APUMA(Val)'!J22*J$49 -> 0 | ... U22: ='OD-APUMA(Val)'!U22*U$49 -> 0 | V22: 0 | W22: ='OD-APUMA(Val)'!W22*W$49 -> 0 | X22: ='OD-APUMA(Val)'!X22*X$49 -> 0 | Y22: ='OD-APUMA(Val)'!Y22*Y$49 -> 0 | Z22: ='OD-APUMA(Val)'!Z22*Z$49 -> 227.61207 | AA22: ='OD-APUMA(Val)'!AA22*AA$49 -> 156 | AB22: ='OD-APUMA(Val)'!AB22*AB$49 -> 0 | AC22: ='OD-APUMA(Val)'!AC22*AC$49 -> 4.0534552 | AD22: ='OD-APUMA(Val)'!AD22*AD$49 -> 0 | ... AQ22: ='OD-APUMA(Val)'!AQ22*AQ$49 -> 217.85818 | AR22: =SUM('OD-APUMA(Val)'!C22:AQ22) -> 180141 | AS22: =MAX('OD-APUMA(Val)'!C22:AQ22) -> 169559 | AT22: =SUM(C22:AQ22)/AR22 -> 0.007963296 | AU22: =AT22^4 -> 4.021346e-09
A23: 75 | B23: 192426 | C23: ='OD-APUMA(Val)'!C23*C$49 -> 0 | D23: ='OD-APUMA(Val)'!D23*D$49 -> 6.5219943 | E23: ='OD-APUMA(Val)'!E23*E$49 -> 0 | F23: ='OD-APUMA(Val)'!F23*F$49 -> 0 | G23: ='OD-APUMA(Val)'!G23*G$49 -> 0 | H23: ='OD-APUMA(Val)'!H23*H$49 -> 0 | I23: ='OD-APUMA(Val)'!I23*I$49 -> 0 | J23: ='OD-APUMA(Val)'!J23*J$49 -> 0 | ... V23: ='OD-APUMA(Val)'!V23*V$49 -> 0 | W23: 0 | X23: ='OD-APUMA(Val)'!X23*X$49 -> 0 | Y23: ='OD-APUMA(Val)'!Y23*Y$49 -> 0 | Z23: ='OD-APUMA(Val)'!Z23*Z$49 -> 2.8958278 | AA23: ='OD-APUMA(Val)'!AA23*AA$49 -> 0 | AB23: ='OD-APUMA(Val)'!AB23*AB$49 -> 91 | AC23: ='OD-APUMA(Val)'!AC23*AC$49 -> 159.55874 | AD23: ='OD-APUMA(Val)'!AD23*AD$49 -> 76.004663 | AE23: ='OD-APUMA(Val)'!AE23*AE$49 -> 44.271202 | ... AQ23: ='OD-APUMA(Val)'!AQ23*AQ$49 -> 0 | AR23: =SUM('OD-APUMA(Val)'!C23:AQ23) -> 118170 | AS23: =MAX('OD-APUMA(Val)'!C23:AQ23) -> 106184 | AT23: =SUM(C23:AQ23)/AR23 -> 0.0088278661 | AU23: =AT23^4 -> 6.073275e-09
A24: 76 | B24: 116324 | C24: ='OD-APUMA(Val)'!C24*C$49 -> 0 | D24: ='OD-APUMA(Val)'!D24*D$49 -> 0 | E24: ='OD-APUMA(Val)'!E24*E$49 -> 0 | F24: ='OD-APUMA(Val)'!F24*F$49 -> 25.813203 | G24: ='OD-APUMA(Val)'!G24*G$49 -> 0 | H24: ='OD-APUMA(Val)'!H24*H$49 -> 0 | I24: ='OD-APUMA(Val)'!I24*I$49 -> 0 | J24: ='OD-APUMA(Val)'!J24*J$49 -> 0 | ... W24: ='OD-APUMA(Val)'!W24*W$49 -> 0 | X24: 0 | Y24: ='OD-APUMA(Val)'!Y24*Y$49 -> 0 | Z24: ='OD-APUMA(Val)'!Z24*Z$49 -> 0 | AA24: ='OD-APUMA(Val)'!AA24*AA$49 -> 871 | AB24: ='OD-APUMA(Val)'!AB24*AB$49 -> 182 | AC24: ='OD-APUMA(Val)'!AC24*AC$49 -> 1.4739837 | AD24: ='OD-APUMA(Val)'!AD24*AD$49 -> 7.9014749 | AE24: ='OD-APUMA(Val)'!AE24*AE$49 -> 22.135601 | AF24: ='OD-APUMA(Val)'!AF24*AF$49 -> 92.950698 | ... AQ24: ='OD-APUMA(Val)'!AQ24*AQ$49 -> 9.8387564 | AR24: =SUM('OD-APUMA(Val)'!C24:AQ24) -> 112996 | AS24: =MAX('OD-APUMA(Val)'!C24:AQ24) -> 88868 | AT24: =SUM(C24:AQ24)/AR24 -> 0.16714566 | AU24: =AT24^4 -> 0.00078051345
A25: 77 | B25: 73463 | C25: ='OD-APUMA(Val)'!C25*C$49 -> 0 | D25: ='OD-APUMA(Val)'!D25*D$49 -> 0 | E25: ='OD-APUMA(Val)'!E25*E$49 -> 0 | F25: ='OD-APUMA(Val)'!F25*F$49 -> 68.05299 | G25: ='OD-APUMA(Val)'!G25*G$49 -> 0 | H25: ='OD-APUMA(Val)'!H25*H$49 -> 0 | I25: ='OD-APUMA(Val)'!I25*I$49 -> 0 | J25: ='OD-APUMA(Val)'!J25*J$49 -> 0 | ... X25: ='OD-APUMA(Val)'!X25*X$49 -> 0 | Y25: 0 | Z25: ='OD-APUMA(Val)'!Z25*Z$49 -> 0 | AA25: ='OD-APUMA(Val)'!AA25*AA$49 -> 78 | AB25: ='OD-APUMA(Val)'!AB25*AB$49 -> 0 | AC25: ='OD-APUMA(Val)'!AC25*AC$49 -> 0 | AD25: ='OD-APUMA(Val)'!AD25*AD$49 -> 0 | AE25: ='OD-APUMA(Val)'!AE25*AE$49 -> 13.980379 | AF25: ='OD-APUMA(Val)'!AF25*AF$49 -> 0 | AG25: ='OD-APUMA(Val)'!AG25*AG$49 -> 0 | ... AQ25: ='OD-APUMA(Val)'!AQ25*AQ$49 -> 0 | AR25: =SUM('OD-APUMA(Val)'!C25:AQ25) -> 34944 | AS25: =MAX('OD-APUMA(Val)'!C25:AQ25) -> 33397 | AT25: =SUM(C25:AQ25)/AR25 -> 0.013204019 | AU25: =AT25^4 -> 3.0396571e-08
A26: 80 | B26: 118885 | C26: ='OD-APUMA(Val)'!C26*C$49 -> 0 | D26: ='OD-APUMA(Val)'!D26*D$49 -> 15.489737 | E26: ='OD-APUMA(Val)'!E26*E$49 -> 0 | F26: ='OD-APUMA(Val)'!F26*F$49 -> 0 | G26: ='OD-APUMA(Val)'!G26*G$49 -> 0 | H26: ='OD-APUMA(Val)'!H26*H$49 -> 0 | I26: ='OD-APUMA(Val)'!I26*I$49 -> 0 | J26: ='OD-APUMA(Val)'!J26*J$49 -> 0 | ... Y26: ='OD-APUMA(Val)'!Y26*Y$49 -> 0 | Z26: 0 | AA26: ='OD-APUMA(Val)'!AA26*AA$49 -> 0 | AB26: ='OD-APUMA(Val)'!AB26*AB$49 -> 78 | AC26: ='OD-APUMA(Val)'!AC26*AC$49 -> 0 | AD26: ='OD-APUMA(Val)'!AD26*AD$49 -> 7.5252142 | AE26: ='OD-APUMA(Val)'!AE26*AE$49 -> 53.591455 | AF26: ='OD-APUMA(Val)'!AF26*AF$49 -> 2.1870753 | AG26: ='OD-APUMA(Val)'!AG26*AG$49 -> 0 | AH26: ='OD-APUMA(Val)'!AH26*AH$49 -> 0 | ... AQ26: ='OD-APUMA(Val)'!AQ26*AQ$49 -> 33.732879 | AR26: =SUM('OD-APUMA(Val)'!C26:AQ26) -> 91208 | AS26: =MAX('OD-APUMA(Val)'!C26:AQ26) -> 82537 | AT26: =SUM(C26:AQ26)/AR26 -> 0.012549113 | AU26: =AT26^4 -> 2.4800029e-08
A27: 86 | B27: 634894 | C27: ='OD-APUMA(Val)'!C27*C$49 -> 10.471491 | D27: ='OD-APUMA(Val)'!D27*D$49 -> 4.8914957 | E27: ='OD-APUMA(Val)'!E27*E$49 -> 11.288287 | F27: ='OD-APUMA(Val)'!F27*F$49 -> 0 | G27: ='OD-APUMA(Val)'!G27*G$49 -> 0 | H27: ='OD-APUMA(Val)'!H27*H$49 -> 2.5835408 | I27: ='OD-APUMA(Val)'!I27*I$49 -> 0 | J27: ='OD-APUMA(Val)'!J27*J$49 -> 0 | ... Z27: ='OD-APUMA(Val)'!Z27*Z$49 -> 0 | AA27: 0 | AB27: ='OD-APUMA(Val)'!AB27*AB$49 -> 35737 | AC27: ='OD-APUMA(Val)'!AC27*AC$49 -> 1.8424796 | AD27: ='OD-APUMA(Val)'!AD27*AD$49 -> 0 | AE27: ='OD-APUMA(Val)'!AE27*AE$49 -> 158.4443 | AF27: ='OD-APUMA(Val)'!AF27*AF$49 -> 0 | AG27: ='OD-APUMA(Val)'!AG27*AG$49 -> 35.771274 | AH27: ='OD-APUMA(Val)'!AH27*AH$49 -> 0 | AI27: ='OD-APUMA(Val)'!AI27*AI$49 -> 481 | ... AQ27: ='OD-APUMA(Val)'!AQ27*AQ$49 -> 0 | AR27: =SUM('OD-APUMA(Val)'!C27:AQ27) -> 632060 | AS27: =MAX('OD-APUMA(Val)'!C27:AQ27) -> 448058 | AT27: =SUM(C27:AQ27)/AR27 -> 0.28716073 | AU27: =AT27^4 -> 0.0067998634
A28: 87 | B28: 401882 | C28: ='OD-APUMA(Val)'!C28*C$49 -> 31.414472 | D28: ='OD-APUMA(Val)'!D28*D$49 -> 7.3372436 | E28: ='OD-APUMA(Val)'!E28*E$49 -> 0 | F28: ='OD-APUMA(Val)'!F28*F$49 -> 32.853167 | G28: ='OD-APUMA(Val)'!G28*G$49 -> 0 | H28: ='OD-APUMA(Val)'!H28*H$49 -> 2.5835408 | I28: ='OD-APUMA(Val)'!I28*I$49 -> 0 | J28: ='OD-APUMA(Val)'!J28*J$49 -> 0 | ... AA28: ='OD-APUMA(Val)'!AA28*AA$49 -> 83265 | AB28: 0 | AC28: ='OD-APUMA(Val)'!AC28*AC$49 -> 2.9479674 | AD28: ='OD-APUMA(Val)'!AD28*AD$49 -> 0 | AE28: ='OD-APUMA(Val)'!AE28*AE$49 -> 72.231961 | AF28: ='OD-APUMA(Val)'!AF28*AF$49 -> 0 | AG28: ='OD-APUMA(Val)'!AG28*AG$49 -> 28.61702 | AH28: ='OD-APUMA(Val)'!AH28*AH$49 -> 0 | AI28: ='OD-APUMA(Val)'!AI28*AI$49 -> 559 | AJ28: ='OD-APUMA(Val)'!AJ28*AJ$49 -> 47.552595 | ... AQ28: ='OD-APUMA(Val)'!AQ28*AQ$49 -> 0 | AR28: =SUM('OD-APUMA(Val)'!C28:AQ28) -> 401219 | AS28: =MAX('OD-APUMA(Val)'!C28:AQ28) -> 243971 | AT28: =SUM(C28:AQ28)/AR28 -> 0.385172 | AU28: =AT28^4 -> 0.022009939
A29: 88 | B29: 405808 | C29: ='OD-APUMA(Val)'!C29*C$49 -> 0 | D29: ='OD-APUMA(Val)'!D29*D$49 -> 7.3372436 | E29: ='OD-APUMA(Val)'!E29*E$49 -> 0 | F29: ='OD-APUMA(Val)'!F29*F$49 -> 63.35968 | G29: ='OD-APUMA(Val)'!G29*G$49 -> 55.642584 | H29: ='OD-APUMA(Val)'!H29*H$49 -> 3.2881429 | I29: ='OD-APUMA(Val)'!I29*I$49 -> 0 | J29: ='OD-APUMA(Val)'!J29*J$49 -> 74.709909 | ... AB29: ='OD-APUMA(Val)'!AB29*AB$49 -> 169 | AC29: 0 | AD29: ='OD-APUMA(Val)'!AD29*AD$49 -> 3.0100857 | AE29: ='OD-APUMA(Val)'!AE29*AE$49 -> 66.406802 | AF29: ='OD-APUMA(Val)'!AF29*AF$49 -> 10.935376 | AG29: ='OD-APUMA(Val)'!AG29*AG$49 -> 16.097073 | AH29: ='OD-APUMA(Val)'!AH29*AH$49 -> 38.409975 | AI29: ='OD-APUMA(Val)'!AI29*AI$49 -> 143 | AJ29: ='OD-APUMA(Val)'!AJ29*AJ$49 -> 0 | AK29: ='OD-APUMA(Val)'!AK29*AK$49 -> 0 | ... AQ29: ='OD-APUMA(Val)'!AQ29*AQ$49 -> 40.760562 | AR29: =SUM('OD-APUMA(Val)'!C29:AQ29) -> 268060 | AS29: =MAX('OD-APUMA(Val)'!C29:AQ29) -> 250822 | AT29: =SUM(C29:AQ29)/AR29 -> 0.013828496 | AU29: =AT29^4 -> 3.6567879e-08
A30: 89 | B30: 320827 | C30: ='OD-APUMA(Val)'!C30*C$49 -> 11.967418 | D30: ='OD-APUMA(Val)'!D30*D$49 -> 0 | E30: ='OD-APUMA(Val)'!E30*E$49 -> 0 | F30: ='OD-APUMA(Val)'!F30*F$49 -> 32.853167 | G30: ='OD-APUMA(Val)'!G30*G$49 -> 0 | H30: ='OD-APUMA(Val)'!H30*H$49 -> 0 | I30: ='OD-APUMA(Val)'!I30*I$49 -> 0 | J30: ='OD-APUMA(Val)'!J30*J$49 -> 0 | ... AC30: ='OD-APUMA(Val)'!AC30*AC$49 -> 4.4219511 | AD30: 0 | AE30: ='OD-APUMA(Val)'!AE30*AE$49 -> 682.70853 | AF30: ='OD-APUMA(Val)'!AF30*AF$49 -> 4.3741505 | AG30: ='OD-APUMA(Val)'!AG30*AG$49 -> 23.251328 | AH30: ='OD-APUMA(Val)'!AH30*AH$49 -> 26.886983 | AI30: ='OD-APUMA(Val)'!AI30*AI$49 -> 0 | AJ30: ='OD-APUMA(Val)'!AJ30*AJ$49 -> 468.21017 | AK30: ='OD-APUMA(Val)'!AK30*AK$49 -> 0 | AL30: ='OD-APUMA(Val)'!AL30*AL$49 -> 91 | ... AQ30: ='OD-APUMA(Val)'!AQ30*AQ$49 -> 22.488586 | AR30: =SUM('OD-APUMA(Val)'!C30:AQ30) -> 221559 | AS30: =MAX('OD-APUMA(Val)'!C30:AQ30) -> 207935 | AT30: =SUM(C30:AQ30)/AR30 -> 0.0087165755 | AU30: =AT30^4 -> 5.772761e-09
A31: 90 | B31: 4714869 | C31: ='OD-APUMA(Val)'!C31*C$49 -> 181.0072 | D31: ='OD-APUMA(Val)'!D31*D$49 -> 158.97361 | E31: ='OD-APUMA(Val)'!E31*E$49 -> 93.692782 | F31: ='OD-APUMA(Val)'!F31*F$49 -> 96.212847 | G31: ='OD-APUMA(Val)'!G31*G$49 -> 89.028134 | H31: ='OD-APUMA(Val)'!H31*H$49 -> 4.9322143 | I31: ='OD-APUMA(Val)'!I31*I$49 -> 273 | J31: ='OD-APUMA(Val)'!J31*J$49 -> 298.83964 | ... AD31: ='OD-APUMA(Val)'!AD31*AD$49 -> 275.04658 | AE31: 0 | AF31: ='OD-APUMA(Val)'!AF31*AF$49 -> 16.676449 | AG31: ='OD-APUMA(Val)'!AG31*AG$49 -> 18792.439 | AH31: ='OD-APUMA(Val)'!AH31*AH$49 -> 1955.0677 | AI31: ='OD-APUMA(Val)'!AI31*AI$49 -> 468 | AJ31: ='OD-APUMA(Val)'!AJ31*AJ$49 -> 9097.1773 | AK31: ='OD-APUMA(Val)'!AK31*AK$49 -> 0 | AL31: ='OD-APUMA(Val)'!AL31*AL$49 -> 156 | AM31: ='OD-APUMA(Val)'!AM31*AM$49 -> 520 | ... AQ31: ='OD-APUMA(Val)'!AQ31*AQ$49 -> 2357.0849 | AR31: =SUM('OD-APUMA(Val)'!C31:AQ31) -> 4091568 | AS31: =MAX('OD-APUMA(Val)'!C31:AQ31) -> 3859648 | AT31: =SUM(C31:AQ31)/AR31 -> 0.010761124 | AU31: =AT31^4 -> 1.3410054e-08
