Workbook

Sheet Summary
A1: NAME | B1: COU | C1: INTPUMA | D1: DMLPUMA | F1: INTPUMA | G1: COU | J1: COU | K1: INTPUMA | O1: INTPUMA | P1: DMLPUMA | R1: INTPUMA | S1: DMLPUMA
A2: Alameda County (part) | B2: 1 | C2: 21 | D2: =VLOOKUP(C2,$O$2:$P$86,2) -> 86 | F2: 1 | G2: 15 | J2: 1 | K2: 20 | O2: 1 | P2: 1 | R2: 1 | S2: 1
A3: Alpine County | B3: 3 | C3: 26 | D3: =VLOOKUP(C3,$O$2:$P$86,2) -> 26 | F3: 1 | G3: 35 | J3: 1 | K3: 21 | O3: 2 | P3: 2 | R3: 2 | S3: 2
A4: Amador County | B4: 5 | C4: 26 | D4: =VLOOKUP(C4,$O$2:$P$86,2) -> 26 | F4: 1 | G4: 49 | J4: 1 | K4: 74 | O4: 3 | P4: 3 | R4: 3 | S4: 3
A5: Butte County | B5: 7 | C5: 6 | D5: =VLOOKUP(C5,$O$2:$P$86,2) -> 6 | F5: 1 | G5: 93 | J5: 3 | K5: 26 | O5: 4 | P5: 4 | R5: 4 | S5: 4
A6: Calaveras County | B6: 9 | C6: 26 | D6: =VLOOKUP(C6,$O$2:$P$86,2) -> 26 | F6: 2 | G6: 23 | J6: 5 | K6: 26 | O6: 5 | P6: 5 | R6: 5 | S6: 5
A7: Colusa County | B7: 11 | C7: 5 | D7: =VLOOKUP(C7,$O$2:$P$86,2) -> 5 | F7: 3 | G7: 89 | J7: 7 | K7: 6 | O7: 6 | P7: 6 | R7: 6 | S7: 6
A8: Contra Costa County (part) | B8: 13 | C8: 18 | D8: =VLOOKUP(C8,$O$2:$P$86,2) -> 87 | F8: 4 | G8: 33 | J8: 9 | K8: 26 | O8: 7 | P8: 7 | R8: 7 | S8: 7
A9: Del Norte County | B9: 15 | C9: 1 | D9: =VLOOKUP(C9,$O$2:$P$86,2) -> 1 | F9: 4 | G9: 45 | J9: 11 | K9: 5 | O9: 8 | P9: 8 | R9: 8 | S9: 8
A10: El Dorado County | B10: 17 | C10: 12 | D10: =VLOOKUP(C10,$O$2:$P$86,2) -> 12 | F10: 5 | G10: 11 | J10: 13 | K10: 17 | O10: 9 | P10: 9 | R10: 9 | S10: 9
A11: Fresno County (part) | B11: 19 | C11: 41 | D11: =VLOOKUP(C11,$O$2:$P$86,2) -> 88 | F11: 5 | G11: 21 | J11: 13 | K11: 18 | O11: 10 | P11: 10 | R11: 10 | S11: 10
A12: Glenn County | B12: 21 | C12: 5 | D12: =VLOOKUP(C12,$O$2:$P$86,2) -> 5 | F12: 5 | G12: 103 | J12: 15 | K12: 1 | O12: 11 | P12: 11 | R12: 11 | S12: 11
A13: Humboldt County | B13: 23 | C13: 2 | D13: =VLOOKUP(C13,$O$2:$P$86,2) -> 2 | F13: 5 | G13: 105 | J13: 17 | K13: 12 | O13: 12 | P13: 12 | R13: 12 | S13: 12
... A27: Mono County | B27: 51 | C27: 26 | D27: =VLOOKUP(C27,$O$2:$P$86,2) -> 26 | F27: 16 | G27: 95 | J27: 37 | K27: 54 | O27: 26 | P27: 26 | R27: 21 | S27: 86
A28: Monterey County (part) | B28: 53 | C28: 39 | D28: 91 | F28: 17 | G28: 13 | J28: 37 | K28: 55 | O28: 27 | P28: 27 | R28: 74 | S28: 86
A29: Napa County | B29: 55 | C29: 9 | D29: =VLOOKUP(C29,$O$2:$P$86,2) -> 9 | F29: 18 | G29: 13 | J29: 37 | K29: 56 | O29: 28 | P29: 94 | R29: 17 | S29: 87
A30: Nevada County | B30: 57 | C30: 7 | D30: =VLOOKUP(C30,$O$2:$P$86,2) -> 7 | F30: 19 | G30: 75 | J30: 37 | K30: 57 | O30: 29 | P30: 94 | R30: 18 | S30: 87
A31: Orange County (part) | B31: 59 | C31: 48 | D31: =VLOOKUP(C31,$O$2:$P$86,2) -> 92 | F31: 20 | G31: 1 | J31: 37 | K31: 58 | O31: 30 | P31: 30 | R31: 40 | S31: 88
A32: Placer County | B32: 61 | C32: 11 | D32: =VLOOKUP(C32,$O$2:$P$86,2) -> 11 | F32: 21 | G32: 1 | J32: 37 | K32: 59 | O32: 31 | P32: 31 | R32: 41 | S32: 88
A33: Plumas County | B33: 63 | C33: 7 | D33: =VLOOKUP(C33,$O$2:$P$86,2) -> 7 | F33: 22 | G33: 81 | J33: 37 | K33: 60 | O33: 32 | P33: 32 | R33: 78 | S33: 89
A34: Riverside County (part) | B34: 65 | C34: 69 | D34: =VLOOKUP(C34,$O$2:$P$86,2) -> 93 | F34: 23 | G34: 77 | J34: 37 | K34: 61 | O34: 33 | P34: 96 | R34: 79 | S34: 89
A35: Sacramento County (part) | B35: 67 | C35: 29 | D35: =VLOOKUP(C35,$O$2:$P$86,2) -> 94 | F35: 24 | G35: 99 | J35: 37 | K35: 62 | O35: 34 | P35: 96 | R35: 52 | S35: 90
A36: San Benito County | B36: 69 | C36: 27 | D36: =VLOOKUP(C36,$O$2:$P$86,2) -> 27 | F36: 25 | G36: 99 | J36: 37 | K36: 63 | O36: 35 | P36: 96 | R36: 53 | S36: 90
A37: San Bernardino County (part) | B37: 71 | C37: 72 | D37: =VLOOKUP(C37,$O$2:$P$86,2) -> 95 | F37: 26 | G37: 3 | J37: 37 | K37: 64 | O37: 36 | P37: 96 | R37: 54 | S37: 90
A38: San Diego County (part) | B38: 73 | C38: 37 | D38: =VLOOKUP(C38,$O$2:$P$86,2) -> 96 | F38: 26 | G38: 5 | J38: 37 | K38: 65 | O38: 37 | P38: 96 | R38: 55 | S38: 90
A39: San Francisco city (part) | B39: 75 | C39: 19 | D39: =VLOOKUP(C39,$O$2:$P$86,2) -> 19 | F39: 26 | G39: 9 | J39: 37 | K39: 66 | O39: 38 | P39: 91 | R39: 56 | S39: 90
A40: San Joaquin County (part) | B40: 77 | C40: 23 | D40: =VLOOKUP(C40,$O$2:$P$86,2) -> 97 | F40: 26 | G40: 27 | J40: 39 | K40: 27 | O40: 39 | P40: 91 | R40: 57 | S40: 90
... A59: Yuba County | B59: 115 | C59: 8 | D59: =VLOOKUP(C59,$O$2:$P$86,2) -> 8 | F59: 41 | G59: 19 | J59: 61 | K59: 11 | O59: 58 | P59: 90 | R59: 84 | S59: 92
F60: 42 | G60: 59 | J60: 63 | K60: 7 | O60: 59 | P60: 90 | R60: 68 | S60: 93
F61: 43 | G61: 59 | J61: 65 | K61: 68 | O61: 60 | P61: 90 | R61: 69 | S61: 93
F62: 44 | G62: 59 | J62: 65 | K62: 69 | O62: 61 | P62: 90 | R62: 81 | S62: 93
F63: 45 | G63: 59 | J63: 65 | K63: 81 | O63: 62 | P63: 90 | R63: 28 | S63: 94
F64: 46 | G64: 59 | J64: 67 | K64: 28 | O64: 63 | P64: 90 | R64: 29 | S64: 94
F65: 47 | G65: 59 | J65: 67 | K65: 29 | O65: 64 | P65: 90 | R65: 70 | S65: 95
F66: 48 | G66: 59 | J66: 69 | K66: 27 | O66: 65 | P66: 90 | R66: 71 | S66: 95
F67: 49 | G67: 85 | J67: 71 | K67: 70 | O67: 66 | P67: 90 | R67: 72 | S67: 95
F68: 50 | G68: 85 | J68: 71 | K68: 71 | O68: 67 | P68: 103 | R68: 82 | S68: 95
F69: 51 | G69: 85 | J69: 71 | K69: 72 | O69: 68 | P69: 93 | R69: 33 | S69: 96
F70: 52 | G70: 37 | J70: 71 | K70: 82 | O70: 69 | P70: 93 | R70: 34 | S70: 96
F71: 53 | G71: 37 | J71: 73 | K71: 33 | O71: 70 | P71: 95 | R71: 35 | S71: 96
...

Sheet IntPUMAPop
A1: Sum of POPULATION
A2: INTPUMA | B2: Total | C2: DMLPUMA
A3: 1 | B3: 104267 | C3: =VLOOKUP(A3,Summary!$O$1:$P$86,2) -> 1
A4: 2 | B4: 119118 | C4: =VLOOKUP(A4,Summary!$O$1:$P$86,2) -> 2
A5: 3 | B5: 147036 | C5: =VLOOKUP(A5,Summary!$O$1:$P$86,2) -> 3
A6: 4 | B6: 130976 | C6: =VLOOKUP(A6,Summary!$O$1:$P$86,2) -> 4
A7: 5 | B7: 103761 | C7: =VLOOKUP(A7,Summary!$O$1:$P$86,2) -> 5
A8: 6 | B8: 182120 | C8: =VLOOKUP(A8,Summary!$O$1:$P$86,2) -> 6
A9: 7 | B9: 101567 | C9: =VLOOKUP(A9,Summary!$O$1:$P$86,2) -> 7
A10: 8 | B10: 122643 | C10: =VLOOKUP(A10,Summary!$O$1:$P$86,2) -> 8
A11: 9 | B11: 110765 | C11: =VLOOKUP(A11,Summary!$O$1:$P$86,2) -> 9
A12: 10 | B12: 141092 | C12: =VLOOKUP(A12,Summary!$O$1:$P$86,2) -> 10
A13: 11 | B13: 172796 | C13: =VLOOKUP(A13,Summary!$O$1:$P$86,2) -> 11
A14: 12 | B14: 125995 | C14: =VLOOKUP(A14,Summary!$O$1:$P$86,2) -> 12
... A87: 85 | B87: 210943 | C87: =VLOOKUP(A87,Summary!$O$1:$P$86,2) -> 97
A88: Grand Total | B88: 29646839

Sheet CountyPop
A1: Sum of POPULATION
A2: COU | B2: Total
A3: 1 | B3: 1279182 | C3: Alameda County (part) | D3: 1
A4: 3 | B4: 1113 | C4: Alpine County | D4: 3
A5: 5 | B5: 30039 | C5: Amador County | D5: 5
A6: 7 | B6: 182120 | C6: Butte County | D6: 7
A7: 9 | B7: 31998 | C7: Calaveras County | D7: 9
A8: 11 | B8: 16275 | C8: Colusa County | D8: 11
A9: 13 | B9: 803732 | C9: Contra Costa County (part) | D9: 13
A10: 15 | B10: 23460 | C10: Del Norte County | D10: 15
A11: 17 | B11: 125995 | C11: El Dorado County | D11: 17
A12: 19 | B12: 667490 | C12: Fresno County (part) | D12: 19
A13: 21 | B13: 24798 | C13: Glenn County | D13: 21
A14: 23 | B14: 119118 | C14: Humboldt County | D14: 23
... A60: 115 | B60: 58228 | C60: Yuba County | D60: 115
A61: Grand Total | B61: 29646839

Sheet MSAPop
A1: Sum of POPULATION
A2: MSA/PMSA | B2: Total
A3: 360 | B3: 2410556
A4: 680 | B4: 543477
A5: 1620 | B5: 182120
A6: 2840 | B6: 667490
A7: 4480 | B7: 8863164
A8: 4940 | B8: 178403
A9: 5170 | B9: 370522
A10: 5775 | B10: 2082914
A11: 6000 | B11: 576441
A12: 6690 | B12: 147036
A13: 6780 | B13: 2588793
A14: 6920 | B14: 1481102
... A26: 9999 | B26: 1247972
A27: Grand Total | B27: 29646839

Sheet CountSum
B1: Sum of POPULATION | C1: COU
A2: DMLPUMA | B2: INTPUMA | C2: 1 | D2: 3 | E2: 5 | F2: 7 | G2: 9 | H2: 11 | I2: 13 | J2: 15 | K2: 17 | L2: 19 | M2: 21 | N2: 23 | O2: 25 | P2: 27 | Q2: 29 | R2: 31 | S2: 33 | T2: 35 | U2: 37 | V2: 39 | W2: 41 | X2: 43 | Y2: 45 | Z2: 47 | AA2: 49 | AB2: 51 | AC2: 53 | AD2: 55 | AE2: 57 | AF2: 59 | AG2: 61 | AH2: 63 | AI2: 65 | AJ2: 67 | AK2: 69 | AL2: 71 | AM2: 73 | AN2: 75 | AO2: 77 | AP2: 79 | AQ2: 81 | AR2: 83 | AS2: 85 | AT2: 87 | AU2: 89 | AV2: 91 | AW2: 93 | AX2: 95 | AY2: 97 | AZ2: 99 | BA2: 101 | BB2: 103 | BC2: 105 | BD2: 107 | BE2: 109 | BF2: 111 | BG2: 113 | BH2: 115 | BI2: Grand Total | BJ2: COUNT
A3: 1 | B3: 1 | J3: 23460 | T3: 27598 | AA3: 9678 | AW3: 43531 | BI3: 104267 | BJ3: =COUNT(C3:BH3) -> 4
A4: 2 | B4: 2 | N4: 119118 | BI4: 119118 | BJ4: =COUNT(C4:BH4) -> 1
A5: 3 | B5: 3 | AU5: 147036 | BI5: 147036 | BJ5: =COUNT(C5:BH5) -> 1
A6: 4 | B6: 4 | S6: 50631 | Y6: 80345 | BI6: 130976 | BJ6: =COUNT(C6:BH6) -> 2
A7: 5 | B7: 5 | H7: 16275 | M7: 24798 | BB7: 49625 | BC7: 13063 | BI7: 103761 | BJ7: =COUNT(C7:BH7) -> 4
A8: 6 | B8: 6 | F8: 182120 | BI8: 182120 | BJ8: =COUNT(C8:BH8) -> 1
A9: 7 | B9: 7 | AE9: 78510 | AH9: 19739 | AV9: 3318 | BI9: 101567 | BJ9: =COUNT(C9:BH9) -> 3
A10: 8 | B10: 8 | BA10: 64415 | BH10: 58228 | BI10: 122643 | BJ10: =COUNT(C10:BH10) -> 2
A11: 9 | B11: 9 | AD11: 110765 | BI11: 110765 | BJ11: =COUNT(C11:BH11) -> 1
A12: 10 | B12: 10 | BG12: 141092 | BI12: 141092 | BJ12: =COUNT(C12:BH12) -> 1
A13: 11 | B13: 11 | AG13: 172796 | BI13: 172796 | BJ13: =COUNT(C13:BH13) -> 1
A14: 12 | B14: 12 | K14: 125995 | BI14: 125995 | BJ14: =COUNT(C14:BH14) -> 1
A15: 100 | B15: 13 | AY15: 113313 | BI15: 113313 | BJ15: =COUNT(C15:BH15) -> 1
A16: 100 | B16: 14 | AY16: 272885 | BI16: 272885 | BJ16: =COUNT(C16:BH16) -> 1
A17: 15 | B17: 15 | W17: 230096 | BI17: 230096 | BJ17: =COUNT(C17:BH17) -> 1
A18: 99 | B18: 16 | AX18: 231222 | BI18: 231222 | BJ18: =COUNT(C18:BH18) -> 1
A19: 87 | B19: 17 | I19: 112583 | BI19: 112583 | BJ19: =COUNT(C19:BH19) -> 1
A20: 87 | B20: 18 | I20: 691149 | BI20: 691149 | BJ20: =COUNT(C20:BH20) -> 1
A21: 19 | B21: 19 | AN21: 723959 | BI21: 723959 | BJ21: =COUNT(C21:BH21) -> 1
A22: 86 | B22: 20 | C22: 124791 | BI22: 124791 | BJ22: =COUNT(C22:BH22) -> 1
A23: 86 | B23: 21 | C23: 791512 | BI23: 791512 | BJ23: =COUNT(C23:BH23) -> 1
A24: 22 | B24: 22 | AQ24: 649623 | BI24: 649623 | BJ24: =COUNT(C24:BH24) -> 1
A25: 97 | B25: 23 | AO25: 269685 | BI25: 269685 | BJ25: =COUNT(C25:BH25) -> 1
A26: 101 | B26: 24 | AZ26: 164730 | BI26: 164730 | BJ26: =COUNT(C26:BH26) -> 1
A27: 101 | B27: 25 | AZ27: 205792 | BI27: 205792 | BJ27: =COUNT(C27:BH27) -> 1
A28: 26 | B28: 26 | D28: 1113 | E28: 30039 | G28: 31998 | P28: 18281 | X28: 14302 | AB28: 9956 | BE28: 48456 | BI28: 154145 | BJ28: =COUNT(C28:BH28) -> 7
A29: 27 | B29: 27 | V29: 88090 | AK29: 36697 | BI29: 124787 | BJ29: =COUNT(C29:BH29) -> 2
A30: 94 | B30: 28 | AJ30: 369365 | BI30: 369365 | BJ30: =COUNT(C30:BH30) -> 1
A31: 94 | B31: 29 | AJ31: 671854 | BI31: 671854 | BJ31: =COUNT(C31:BH31) -> 1
A32: 30 | B32: 30 | Z32: 178403 | BI32: 178403 | BJ32: =COUNT(C32:BH32) -> 1
A33: 31 | B33: 31 | R33: 101469 | BI33: 101469 | BJ33: =COUNT(C33:BH33) -> 1
A34: 32 | B34: 32 | AR34: 369608 | BI34: 369608 | BJ34: =COUNT(C34:BH34) -> 1
A35: 96 | B35: 33 | AM35: 1110549 | BI35: 1110549 | BJ35: =COUNT(C35:BH35) -> 1
A36: 96 | B36: 34 | AM36: 128398 | BI36: 128398 | BJ36: =COUNT(C36:BH36) -> 1
A37: 96 | B37: 35 | AM37: 108635 | BI37: 108635 | BJ37: =COUNT(C37:BH37) -> 1
A38: 96 | B38: 36 | AM38: 135163 | BI38: 135163 | BJ38: =COUNT(C38:BH38) -> 1
A39: 96 | B39: 37 | AM39: 1015271 | BI39: 1015271 | BJ39: =COUNT(C39:BH39) -> 1
A40: 91 | B40: 38 | AC40: 108777 | BI40: 108777 | BJ40: =COUNT(C40:BH40) -> 1
...

Sheet CaliforniaPUMA-abbrev
A1: NAME | B1: POPULATION | C1: ST | D1: COU | E1: MCD | F1: PLACE | G1: TRACT | H1: MSA/PMSA | I1: PUMA | J1: INTPUMA | L1: BUCKET | P1: INTPUMA | Q1: MSA/PMSA | S1: INTPUMA | T1: MSA/PMSA
A2: Del Norte County | B2: 23460 | C2: 6 | D2: 15 | H2: 9999 | I2: 1 | J2: =INT(I2) -> 1 | L2: =1 -> 1 | P2: 1 | Q2: 9999 | S2: 1 | T2: 9999
A3: Lassen County | B3: 27598 | C3: 6 | D3: 35 | H3: 9999 | I3: 1 | J3: =INT(I3) -> 1 | L3: =L2+1 -> 2 | P3: 1 | Q3: 9999 | S3: 2 | T3: 9999
A4: Modoc County | B4: 9678 | C4: 6 | D4: 49 | H4: 9999 | I4: 1 | J4: =INT(I4) -> 1 | L4: =L3+1 -> 3 | P4: 1 | Q4: 9999 | S4: 3 | T4: 6690
A5: Siskiyou County | B5: 43531 | C5: 6 | D5: 93 | H5: 9999 | I5: 1 | J5: =INT(I5) -> 1 | L5: =L4+1 -> 4 | P5: 1 | Q5: 9999 | S5: 4 | T5: 9999
A6: Humboldt County | B6: 119118 | C6: 6 | D6: 23 | H6: 9999 | I6: 2 | J6: =INT(I6) -> 2 | L6: =L5+1 -> 5 | P6: 2 | Q6: 9999 | S6: 5 | T6: 9999
A7: Shasta County | B7: 147036 | C7: 6 | D7: 89 | H7: 6690 | I7: 3 | J7: =INT(I7) -> 3 | L7: =L6+1 -> 6 | P7: 3 | Q7: 6690 | S7: 6 | T7: 1620
A8: Lake County | B8: 50631 | C8: 6 | D8: 33 | H8: 9999 | I8: 4 | J8: =INT(I8) -> 4 | L8: =L7+1 -> 7 | P8: 4 | Q8: 9999 | S8: 7 | T8: 9999
A9: Mendocino County | B9: 80345 | C9: 6 | D9: 45 | H9: 9999 | I9: 4 | J9: =INT(I9) -> 4 | L9: =L8+1 -> 8 | P9: 4 | Q9: 9999 | S9: 8 | T9: 9340
A10: Colusa County | B10: 16275 | C10: 6 | D10: 11 | H10: 9999 | I10: 5 | J10: =INT(I10) -> 5 | L10: =L9+1 -> 9 | P10: 5 | Q10: 9999 | S10: 9 | T10: 8720
A11: Glenn County | B11: 24798 | C11: 6 | D11: 21 | H11: 9999 | I11: 5 | J11: =INT(I11) -> 5 | L11: =L10+1 -> 10 | P11: 5 | Q11: 9999 | S11: 10 | T11: 6920
A12: Tehama County | B12: 49625 | C12: 6 | D12: 103 | H12: 9999 | I12: 5 | J12: =INT(I12) -> 5 | L12: =L11+1 -> 11 | P12: 5 | Q12: 9999 | S12: 11 | T12: 6920
A13: Trinity County | B13: 13063 | C13: 6 | D13: 105 | H13: 9999 | I13: 5 | J13: =INT(I13) -> 5 | L13: =L12+1 -> 12 | P13: 5 | Q13: 9999 | S13: 12 | T13: 6920
A14: Butte County | B14: 182120 | C14: 6 | D14: 7 | H14: 1620 | I14: 6 | J14: =INT(I14) -> 6 | L14: =L13+1 -> 13 | P14: 6 | Q14: 1620 | S14: 13 | T14: 7500
... A23: El Dorado County | B23: 125995 | C23: 6 | D23: 17 | H23: 6920 | I23: 12 | J23: =INT(I23) -> 12 | L23: =L22+1 -> 22 | P23: 12 | Q23: 6920 | S23: 22 | T23: 7360
A24: Santa Rosa city | B24: 113313 | C24: 6 | D24: 97 | F24: 2615 | H24: 7500 | I24: 13 | J24: =INT(I24) -> 13 | L24: =L23+1 -> 23 | P24: 13 | Q24: 7500 | S24: 23 | T24: 8120
A25: Bodega Bay CDP | B25: 1127 | C25: 6 | D25: 97 | F25: 291 | H25: 7500 | I25: 14.01 | J25: =INT(I25) -> 14 | L25: =L24+1 -> 24 | P25: 14 | Q25: 7500 | S25: 24 | T25: 5170
A26: Cloverdale city | B26: 4924 | C26: 6 | D26: 97 | F26: 545 | H26: 7500 | I26: 14.01 | J26: =INT(I26) -> 14 | L26: =L25+1 -> 25 | P26: 14 | Q26: 7500 | S26: 25 | T26: 5170
A27: Forestville CDP | B27: 2443 | C27: 6 | D27: 97 | F27: 1045 | H27: 7500 | I27: 14.01 | J27: =INT(I27) -> 14 | L27: =L26+1 -> 26 | P27: 14 | Q27: 7500 | S27: 26 | T27: 9999
A28: Graton CDP | B28: 1409 | C28: 6 | D28: 97 | F28: 1153 | H28: 7500 | I28: 14.01 | J28: =INT(I28) -> 14 | L28: =L27+1 -> 27 | P28: 14 | Q28: 7500 | S28: 27 | T28: 9999
A29: Guerneville CDP | B29: 1966 | C29: 6 | D29: 97 | F29: 1183 | H29: 7500 | I29: 14.01 | J29: =INT(I29) -> 14 | L29: =L28+1 -> 28 | P29: 14 | Q29: 7500 | S29: 28 | T29: 6920
A30: Healdsburg city | B30: 9469 | C30: 6 | D30: 97 | F30: 1230 | H30: 7500 | I30: 14.01 | J30: =INT(I30) -> 14 | L30: =L29+1 -> 29 | P30: 14 | Q30: 7500 | S30: 29 | T30: 6920
A31: Larkfield-Wikiup CDP | B31: 6779 | C31: 6 | D31: 97 | F31: 1484 | H31: 7500 | I31: 14.01 | J31: =INT(I31) -> 14 | L31: =L30+1 -> 30 | P31: 14 | Q31: 7500 | S31: 30 | T31: 4940
A32: Monte Rio CDP | B32: 1058 | C32: 6 | D32: 97 | F32: 1832 | H32: 7500 | I32: 14.01 | J32: =INT(I32) -> 14 | L32: =L31+1 -> 31 | P32: 14 | Q32: 7500 | S32: 31 | T32: 9999
A33: Occidental CDP | B33: 1300 | C33: 6 | D33: 97 | F33: 1982 | H33: 7500 | I33: 14.01 | J33: =INT(I33) -> 14 | L33: =L32+1 -> 32 | P33: 14 | Q33: 7500 | S33: 32 | T33: 7480
A34: Roseland CDP | B34: 8779 | C34: 6 | D34: 97 | F34: 2395 | H34: 7500 | I34: 14.01 | J34: =INT(I34) -> 14 | L34: =L33+1 -> 33 | P34: 14 | Q34: 7500 | S34: 33 | T34: 7320
A35: Sebastopol city | B35: 7004 | C35: 6 | D35: 97 | F35: 2665 | H35: 7500 | I35: 14.01 | J35: =INT(I35) -> 14 | L35: =L34+1 -> 34 | P35: 14 | Q35: 7500 | S35: 34 | T35: 7320
... A37: Windsor CDP | B37: 13371 | C37: 6 | D37: 97 | F37: 3131 | H37: 7500 | I37: 14.01 | J37: =INT(I37) -> 14 | L37: =L36+1 -> 36 | P37: 14 | Q37: 7500 | S37: 36 | T37: 7320
A38: Sonoma County (part) | B38: 4411 | C38: 6 | D38: 97 | E38: 5 | F38: 9999 | G38: 154100 | H38: 7500 | I38: 14.01 | J38: =INT(I38) -> 14 | L38: =L37+1 -> 37 | P38: 14 | Q38: 7500 | S38: 37 | T38: 7320
A39: Sonoma County (part) | B39: 1783 | C39: 6 | D39: 97 | E39: 5 | F39: 9999 | G39: 154200 | H39: 7500 | I39: 14.01 | J39: =INT(I39) -> 14 | L39: =L38+1 -> 38 | P39: 14 | Q39: 7500 | S39: 38 | T39: 7120
A40: Sonoma County (part) | B40: 1890 | C40: 6 | D40: 97 | E40: 10 | F40: 9999 | G40: 153800 | H40: 7500 | I40: 14.01 | J40: =INT(I40) -> 14 | L40: =L39+1 -> 39 | P40: 14 | Q40: 7500 | S40: 39 | T40: 7120
A41: Sonoma County (part) | B41: 2842 | C41: 6 | D41: 97 | E41: 10 | F41: 9999 | G41: 153900 | H41: 7500 | I41: 14.01 | J41: =INT(I41) -> 14 | L41: =L40+1 -> 40 | P41: 14 | Q41: 7500 | S41: 40 | T41: 2840
A42: Sonoma County (part) | B42: 2879 | C42: 6 | D42: 97 | E42: 10 | F42: 9999 | G42: 154000 | H42: 7500 | I42: 14.01 | J42: =INT(I42) -> 14 | L42: =L41+1 -> 41 | P42: 14 | Q42: 7500 | S42: 41 | T42: 2840
A43: Sonoma County (part) | B43: 4444 | C43: 6 | D43: 97 | E43: 25 | F43: 9999 | G43: 153701 | H43: 7500 | I43: 14.01 | J43: =INT(I43) -> 14 | L43: =L42+1 -> 42 | P43: 14 | Q43: 7500 | S43: 42 | T43: 360
A44: Sonoma County (part) | B44: 5244 | C44: 6 | D44: 97 | E44: 25 | F44: 9999 | G44: 153702 | H44: 7500 | I44: 14.01 | J44: =INT(I44) -> 14 | L44: =L43+1 -> 43 | P44: 14 | Q44: 7500 | S44: 43 | T44: 360
A45: Sonoma County (part) | B45: 4937 | C45: 6 | D45: 97 | E45: 25 | F45: 9999 | G45: 154300 | H45: 7500 | I45: 14.01 | J45: =INT(I45) -> 14 | L45: =L44+1 -> 44 | P45: 14 | Q45: 7500 | S45: 44 | T45: 360
A46: Rohnert Park city (part) | B46: 41 | C46: 6 | D46: 97 | E46: 30 | F46: 2377 | G46: 153200 | H46: 7500 | I46: 14.01 | J46: =INT(I46) -> 14 | L46: =L45+1 -> 45 | P46: 14 | Q46: 7500 | S46: 45 | T46: 360
A47: Sonoma County (part) | B47: 2660 | C47: 6 | D47: 97 | E47: 30 | F47: 9999 | G47: 151400 | H47: 7500 | I47: 14.01 | J47: =INT(I47) -> 14 | L47: =L46+1 -> 46 | P47: 14 | Q47: 7500 | S47: 46 | T47: 360
A48: Sonoma County (part) | B48: 588 | C48: 6 | D48: 97 | E48: 30 | F48: 9999 | G48: 151501 | H48: 7500 | I48: 14.01 | J48: =INT(I48) -> 14 | L48: =L47+1 -> 47 | P48: 14 | Q48: 7500 | S48: 47 | T48: 360
A49: Sonoma County (part) | B49: 1499 | C49: 6 | D49: 97 | E49: 30 | F49: 9999 | G49: 151502 | H49: 7500 | I49: 14.01 | J49: =INT(I49) -> 14 | L49: =L48+1 -> 48 | P49: 14 | Q49: 7500 | S49: 48 | T49: 360
...
