Workbook

Sheet NeighborTollShare
A1: x | B1: x | C1: NOTWORK | D1: WORK | E1: TOTAL | F1: alabama | G1: alaska | H1: arizona | I1: arkansas | J1: califo~1 | K1: colorado | L1: connec~1 | M1: deleware | N1: district-of-columbia | O1: florida | P1: georgia | Q1: hawaii | R1: idaho | S1: illinois | T1: indiana | U1: iowa | V1: kansas | W1: kentucky | X1: louisi~1 | Y1: maine | Z1: maryland | AA1: massac~1 | AB1: michigan | AC1: minnes~1 | AD1: missis~1 | AE1: missouri | AF1: montana | AG1: nebraska | AH1: nevada | AI1: new-ha~1 | AJ1: new-je~1 | AK1: new-me~1 | AL1: new-york | AM1: north-~1 | AN1: north-~2 | AO1: ohio | AP1: oklahoma | AQ1: oregon | AR1: pennsy~1 | AS1: rhode-~1 | AT1: south-~1 | AU1: south-~2 | AV1: tennes~1 | AW1: texas | AX1: utah | AY1: vermont | AZ1: virginia | BA1: washin~1 | BB1: west-v~1 | BC1: wiscon~1 | BD1: wyoming | BE1: 98 | BF1: AVG-Neighbor-1 | BG1: TollShare | BI1: =A1 -> x | BJ1: =BF1 -> AVG-Neighbor-1 | BL1: AVG-Neighbor-2
A2: alabama | B2: 4032992 | C2: 2299994 | D2: 1732238 | E2: 4032992 | F2: 0 | G2: =Table!G2*G$55 -> 0 | H2: =Table!H2*H$55 -> 0 | I2: =Table!I2*I$55 -> 0 | J2: =Table!J2*J$55 -> 16.025273 | K2: =Table!K2*K$55 -> 0.065071109 | L2: =Table!L2*L$55 -> 0.0033785152 | M2: =Table!M2*M$55 -> 0 | N2: =Table!N2*N$55 -> 0 | ... BD2: =Table!BD2*BD$55 -> 0 | BE2: 760 | BF2: =SUM(F2:BE2)/(D2) -> 0.0010378069 | BG2: 0 | BI2: =A2 -> alabama | BJ2: =BF2 -> 0.0010378069 | BL2: =SUM(F2:BD2)/(D2-Table!BG2) -> 0.016641465
A3: alaska | B3: 550696 | C3: 286591 | D3: 263887 | E3: 550696 | F3: =Table!F3*F$55 -> 0 | G3: 0 | H3: =Table!H3*H$55 -> 0 | I3: =Table!I3*I$55 -> 0 | J3: =Table!J3*J$55 -> 2.5792656 | K3: =Table!K3*K$55 -> 0 | L3: =Table!L3*L$55 -> 0 | M3: =Table!M3*M$55 -> 0 | N3: =Table!N3*N$55 -> 0 | O3: =Table!O3*O$55 -> 0 | ... BD3: =Table!BD3*BD$55 -> 0 | BE3: 218 | BF3: =SUM(F3:BE3)/(D3) -> 0.00096929457 | BG3: 0.062887408 | BI3: =A3 -> alaska | BJ3: =BF3 -> 0.00096929457 | BL3: =SUM(F3:BD3)/(D3-Table!BG3) -> 0.032432821
A4: arizona | B4: 3652849 | C4: 2060434 | D4: 1591203 | E4: 3652849 | F4: =Table!F4*F$55 -> 0 | G4: =Table!G4*G$55 -> 6.9805023 | H4: 0 | I4: =Table!I4*I$55 -> 0 | J4: =Table!J4*J$55 -> 159.17451 | K4: =Table!K4*K$55 -> 1.6356511 | L4: =Table!L4*L$55 -> 0.011434975 | M4: =Table!M4*M$55 -> 0 | N4: =Table!N4*N$55 -> 0 | O4: =Table!O4*O$55 -> 39.072444 | P4: =Table!P4*P$55 -> 1.0757581 | ... BD4: =Table!BD4*BD$55 -> 0 | BE4: 1212 | BF4: =SUM(F4:BE4)/(D4) -> 0.0011052052 | BG4: 0 | BI4: =A4 -> arizona | BJ4: =BF4 -> 0.0011052052 | BL4: =SUM(F4:BD4)/(D4-Table!BG4) -> 0.021735556
A5: arkansas | B5: 2344205 | C5: 1355487 | D5: 988408 | E5: 2344205 | F5: =Table!F5*F$55 -> 0 | G5: =Table!G5*G$55 -> 6.7289527 | H5: =Table!H5*H$55 -> 0 | I5: 0 | J5: =Table!J5*J$55 -> 7.4840986 | K5: =Table!K5*K$55 -> 0.16267777 | L5: =Table!L5*L$55 -> 0 | M5: =Table!M5*M$55 -> 0 | N5: =Table!N5*N$55 -> 0 | O5: =Table!O5*O$55 -> 30.744254 | P5: =Table!P5*P$55 -> 1.0883156 | Q5: =Table!Q5*Q$55 -> 0 | ... BD5: =Table!BD5*BD$55 -> 0 | BE5: 310 | BF5: =SUM(F5:BE5)/(D5) -> 0.00096823265 | BG5: 0 | BI5: =A5 -> arkansas | BJ5: =BF5 -> 0.00096823265 | BL5: =SUM(F5:BD5)/(D5-Table!BG5) -> 0.020268432
A6: califo~1 | B6: 29715727 | C6: 15806498 | D6: 13897185 | E6: 29715727 | F6: =Table!F6*F$55 -> 0 | G6: =Table!G6*G$55 -> 40.876815 | H6: =Table!H6*H$55 -> 0 | I6: =Table!I6*I$55 -> 0 | J6: 0 | K6: =Table!K6*K$55 -> 4.2325799 | L6: =Table!L6*L$55 -> 0.066530761 | M6: =Table!M6*M$55 -> 18.439073 | N6: =Table!N6*N$55 -> 0 | O6: =Table!O6*O$55 -> 173.95799 | P6: =Table!P6*P$55 -> 4.210944 | Q6: =Table!Q6*Q$55 -> 0 | R6: =Table!R6*R$55 -> 0 | ... BD6: =Table!BD6*BD$55 -> 0 | BE6: 12044 | BF6: =SUM(F6:BE6)/(D6) -> 0.0010374397 | BG6: 0.021141521 | BI6: =A6 -> califo~1 | BJ6: =BF6 -> 0.0010374397 | BL6: =SUM(F6:BD6)/(D6-Table!BG6) -> 0.046286746
A7: colorado | B7: 3282756 | C7: 1649976 | D7: 1631955 | E7: 3282756 | F7: =Table!F7*F$55 -> 0 | G7: =Table!G7*G$55 -> 19.620871 | H7: =Table!H7*H$55 -> 0 | I7: =Table!I7*I$55 -> 0 | J7: =Table!J7*J$55 -> 47.441574 | K7: 0 | L7: =Table!L7*L$55 -> 0.0054576015 | M7: =Table!M7*M$55 -> 11.366552 | N7: =Table!N7*N$55 -> 0 | O7: =Table!O7*O$55 -> 27.786579 | P7: =Table!P7*P$55 -> 0.70321928 | Q7: =Table!Q7*Q$55 -> 0 | R7: =Table!R7*R$55 -> 0 | S7: =Table!S7*S$55 -> 78.534221 | ... BD7: =Table!BD7*BD$55 -> 0 | BE7: 825 | BF7: =SUM(F7:BE7)/(D7) -> 0.0009007506 | BG7: 0.0029577777 | BI7: =A7 -> colorado | BJ7: =BF7 -> 0.0009007506 | BL7: =SUM(F7:BD7)/(D7-Table!BG7) -> 0.038557176
A8: connec~1 | B8: 3282130 | C8: 1609151 | D8: 1672230 | E8: 3282130 | F8: =Table!F8*F$55 -> 0 | G8: =Table!G8*G$55 -> 0 | H8: =Table!H8*H$55 -> 0 | I8: =Table!I8*I$55 -> 0 | J8: =Table!J8*J$55 -> 12.748337 | K8: =Table!K8*K$55 -> 0.36380666 | L8: 0 | M8: =Table!M8*M$55 -> 8.3354716 | N8: =Table!N8*N$55 -> 0 | O8: =Table!O8*O$55 -> 51.603647 | P8: =Table!P8*P$55 -> 1.4817835 | Q8: =Table!Q8*Q$55 -> 0 | R8: =Table!R8*R$55 -> 0 | S8: =Table!S8*S$55 -> 48.286058 | T8: =Table!T8*T$55 -> 4.0444306 | ... BD8: =Table!BD8*BD$55 -> 0 | BE8: 749 | BF8: =SUM(F8:BE8)/(D8) -> 0.012794545 | BG8: 0.00025988579 | BI8: =A8 -> connec~1 | BJ8: =BF8 -> 0.012794545 | BL8: =SUM(F8:BD8)/(D8-Table!BG8) -> 0.26023043
A9: deleware | B9: 661667 | C9: 327531 | D9: 333913 | E9: 661667 | F9: =Table!F9*F$55 -> 0 | G9: =Table!G9*G$55 -> 0 | H9: =Table!H9*H$55 -> 0 | I9: =Table!I9*I$55 -> 0 | J9: =Table!J9*J$55 -> 3.3403604 | K9: =Table!K9*K$55 -> 0 | L9: =Table!L9*L$55 -> 0.02157052 | M9: 0 | N9: =Table!N9*N$55 -> 0 | O9: =Table!O9*O$55 -> 8.9508588 | P9: =Table!P9*P$55 -> 0.24277809 | Q9: =Table!Q9*Q$55 -> 0 | R9: =Table!R9*R$55 -> 0 | S9: =Table!S9*S$55 -> 9.990219 | T9: =Table!T9*T$55 -> 1.7454911 | U9: =Table!U9*U$55 -> 0 | ... BD9: =Table!BD9*BD$55 -> 0 | BE9: 223 | BF9: =SUM(F9:BE9)/(D9) -> 0.011952304 | BG9: 0.25259005 | BI9: =A9 -> deleware | BJ9: =BF9 -> 0.011952304 | BL9: =SUM(F9:BD9)/(D9-Table!BG9) -> 0.11872671
A10: district-of-columbia | B10: 609866 | C10: 303582 | D10: 305807 | E10: 609866 | F10: =Table!F10*F$55 -> 0 | G10: =Table!G10*G$55 -> 0 | H10: =Table!H10*H$55 -> 0 | I10: =Table!I10*I$55 -> 0 | J10: =Table!J10*J$55 -> 4.2705873 | K10: =Table!K10*K$55 -> 0 | L10: =Table!L10*L$55 -> 0.0023389721 | M10: =Table!M10*M$55 -> 21.217564 | N10: 0 | O10: =Table!O10*O$55 -> 1.7123382 | P10: =Table!P10*P$55 -> 0.23859226 | Q10: =Table!Q10*Q$55 -> 0 | R10: =Table!R10*R$55 -> 0 | S10: =Table!S10*S$55 -> 1.2950284 | T10: =Table!T10*T$55 -> 2.8523879 | U10: =Table!U10*U$55 -> 0 | V10: =Table!V10*V$55 -> 2.3243048 | ... BD10: =Table!BD10*BD$55 -> 0 | BE10: 477 | BF10: =SUM(F10:BE10)/(D10) -> 0.015570901 | BG10: 0 | BI10: =A10 -> district-of-columbia | BJ10: =BF10 -> 0.015570901 | BL10: =SUM(F10:BD10)/(D10-Table!BG10) -> 0.062113166
A11: florida | B11: 12922903 | C11: 7132347 | D11: 5786177 | E11: 12922903 | F11: =Table!F11*F$55 -> 0 | G11: =Table!G11*G$55 -> 8.7413497 | H11: =Table!H11*H$55 -> 0 | I11: =Table!I11*I$55 -> 0 | J11: =Table!J11*J$55 -> 50.211113 | K11: =Table!K11*K$55 -> 2.1503044 | L11: =Table!L11*L$55 -> 0.29600991 | M11: =Table!M11*M$55 -> 50.51801 | N11: =Table!N11*N$55 -> 0 | O11: 0 | P11: =Table!P11*P$55 -> 40.523011 | Q11: =Table!Q11*Q$55 -> 0 | R11: =Table!R11*R$55 -> 0 | S11: =Table!S11*S$55 -> 198.13934 | T11: =Table!T11*T$55 -> 33.121758 | U11: =Table!U11*U$55 -> 0.20071627 | V11: =Table!V11*V$55 -> 6.9729144 | W11: =Table!W11*W$55 -> 5.5453536 | ... BD11: =Table!BD11*BD$55 -> 0 | BE11: 4379 | BF11: =SUM(F11:BE11)/(D11) -> 0.0013827027 | BG11: 0.077833555 | BI11: =A11 -> florida | BJ11: =BF11 -> 0.0013827027 | BL11: =SUM(F11:BD11)/(D11-Table!BG11) -> 0.062671969
A12: georgia | B12: 6466023 | C12: 3356359 | D12: 3108090 | E12: 6466023 | F12: =Table!F12*F$55 -> 0 | G12: =Table!G12*G$55 -> 2.8299334 | H12: =Table!H12*H$55 -> 0 | I12: =Table!I12*I$55 -> 0 | J12: =Table!J12*J$55 -> 33.699585 | K12: =Table!K12*K$55 -> 1.0736733 | L12: =Table!L12*L$55 -> 0.018192005 | M12: =Table!M12*M$55 -> 0 | ... O12: =Table!O12*O$55 -> 648.50918 | P12: 0 | Q12: =Table!Q12*Q$55 -> 0 | R12: =Table!R12*R$55 -> 0 | S12: =Table!S12*S$55 -> 58.091273 | T12: =Table!T12*T$55 -> 8.6848824 | U12: =Table!U12*U$55 -> 0.095528062 | V12: =Table!V12*V$55 -> 10.071988 | W12: =Table!W12*W$55 -> 3.4404862 | X12: =Table!X12*X$55 -> 12.782024 | ... BD12: =Table!BD12*BD$55 -> 0 | BE12: 1574 | BF12: =SUM(F12:BE12)/(D12) -> 0.00099897011 | BG12: 0.0041858291 | BI12: =A12 -> georgia | BJ12: =BF12 -> 0.00099897011 | BL12: =SUM(F12:BD12)/(D12-Table!BG12) -> 0.02061609
A13: hawaii | B13: 1104668 | C13: 540368 | D13: 562967 | E13: 1104668 | F13: =Table!F13*F$55 -> 0 | G13: =Table!G13*G$55 -> 1.5721852 | H13: =Table!H13*H$55 -> 0 | I13: =Table!I13*I$55 -> 0 | J13: =Table!J13*J$55 -> 30.951187 | K13: =Table!K13*K$55 -> 0.073944442 | L13: =Table!L13*L$55 -> 0 | M13: =Table!M13*M$55 -> 0 | ... P13: =Table!P13*P$55 -> 0.41858291 | Q13: 0 | R13: =Table!R13*R$55 -> 0 | S13: =Table!S13*S$55 -> 5.7351257 | T13: =Table!T13*T$55 -> 1.4474804 | U13: =Table!U13*U$55 -> 0 | V13: =Table!V13*V$55 -> 0 | W13: =Table!W13*W$55 -> 0 | X13: =Table!X13*X$55 -> 0.73459911 | Y13: =Table!Y13*Y$55 -> 0 | ... BD13: =Table!BD13*BD$55 -> 0 | BE13: 1333 | BF13: =SUM(F13:BE13)/(D13) -> 0.0025331665 | BG13: 0 | BI13: =A13 -> hawaii | BJ13: =BF13 -> 0.0025331665 | BL13: =SUM(F13:BD13)/(D13-Table!BG13) -> 0.035368224
A14: idaho | B14: 990916 | C14: 557000 | D14: 433860 | E14: 990916 | F14: =Table!F14*F$55 -> 0 | G14: =Table!G14*G$55 -> 16.853825 | H14: =Table!H14*H$55 -> 0 | I14: =Table!I14*I$55 -> 0 | J14: =Table!J14*J$55 -> 19.619332 | K14: =Table!K14*K$55 -> 0.18929777 | L14: =Table!L14*L$55 -> 0 | M14: =Table!M14*M$55 -> 5.051801 | ... Q14: =Table!Q14*Q$55 -> 0 | R14: 0 | S14: =Table!S14*S$55 -> 5.1801135 | T14: =Table!T14*T$55 -> 0.51087544 | U14: =Table!U14*U$55 -> 0 | V14: =Table!V14*V$55 -> 0.51651218 | W14: =Table!W14*W$55 -> 0 | X14: =Table!X14*X$55 -> 0 | Y14: =Table!Y14*Y$55 -> 0 | Z14: =Table!Z14*Z$55 -> 0 | ... BD14: =Table!BD14*BD$55 -> 0 | BE14: 56 | BF14: =SUM(F14:BE14)/(D14) -> 0.0011444505 | BG14: 0 | BI14: =A14 -> idaho | BJ14: =BF14 -> 0.0011444505 | BL14: =SUM(F14:BD14)/(D14-Table!BG14) -> 0.025523251
A15: illinois | B15: 11393796 | C15: 6058554 | D15: 5333793 | E15: 11393796 | F15: =Table!F15*F$55 -> 0 | G15: =Table!G15*G$55 -> 1.69796 | H15: =Table!H15*H$55 -> 0 | I15: =Table!I15*I$55 -> 0 | J15: =Table!J15*J$55 -> 45.15829 | K15: =Table!K15*K$55 -> 0.84296664 | L15: =Table!L15*L$55 -> 0.089660596 | M15: =Table!M15*M$55 -> 23.490874 | ... R15: =Table!R15*R$55 -> 0 | S15: 0 | T15: =Table!T15*T$55 -> 920.59754 | U15: =Table!U15*U$55 -> 24.372536 | V15: =Table!V15*V$55 -> 23.824124 | W15: =Table!W15*W$55 -> 22.367387 | X15: =Table!X15*X$55 -> 12.605721 | Y15: =Table!Y15*Y$55 -> 7.8816239 | Z15: =Table!Z15*Z$55 -> 18.758864 | AA15: =Table!AA15*AA$55 -> 41.473982 | ... BD15: =Table!BD15*BD$55 -> 0 | BE15: 1449 | BF15: =SUM(F15:BE15)/(D15) -> 0.00067228915 | BG15: 0.092502027 | BI15: =A15 -> illinois | BJ15: =BF15 -> 0.00067228915 | BL15: =SUM(F15:BD15)/(D15-Table!BG15) -> 0.013967169
A16: indiana | B16: 5548329 | C16: 2965742 | D16: 2582095 | E16: 5548329 | F16: =Table!F16*F$55 -> 0 | G16: =Table!G16*G$55 -> 4.6536682 | H16: =Table!H16*H$55 -> 0 | I16: =Table!I16*I$55 -> 0 | J16: =Table!J16*J$55 -> 13.06546 | K16: =Table!K16*K$55 -> 0.22774888 | L16: =Table!L16*L$55 -> 0.024169378 | M16: =Table!M16*M$55 -> 7.0725213 | ... S16: =Table!S16*S$55 -> 4838.5961 | T16: 0 | U16: =Table!U16*U$55 -> 0.20822971 | V16: =Table!V16*V$55 -> 12.654548 | W16: =Table!W16*W$55 -> 335.43472 | X16: =Table!X16*X$55 -> 2.4094851 | Y16: =Table!Y16*Y$55 -> 0 | Z16: =Table!Z16*Z$55 -> 7.7986287 | AA16: =Table!AA16*AA$55 -> 16.007502 | AB16: =Table!AB16*AB$55 -> 47.282414 | ... BD16: =Table!BD16*BD$55 -> 0 | BE16: 492 | BF16: =SUM(F16:BE16)/(D16) -> 0.0026257318 | BG16: 0.042572953 | BI16: =A16 -> indiana | BJ16: =BF16 -> 0.0026257318 | BL16: =SUM(F16:BD16)/(D16-Table!BG16) -> 0.050428579
A17: iowa | B17: 2766658 | C17: 1449735 | D17: 1316719 | E17: 2766658 | F17: =Table!F17*F$55 -> 0 | G17: =Table!G17*G$55 -> 0.50309926 | H17: =Table!H17*H$55 -> 0 | I17: =Table!I17*I$55 -> 0 | J17: =Table!J17*J$55 -> 7.9914951 | K17: =Table!K17*K$55 -> 0.31056666 | L17: =Table!L17*L$55 -> 0 | M17: =Table!M17*M$55 -> 0 | ... T17: =Table!T17*T$55 -> 8.6848824 | U17: 0 | V17: =Table!V17*V$55 -> 21.435255 | W17: =Table!W17*W$55 -> 0.71007577 | X17: =Table!X17*X$55 -> 0.61706325 | Y17: =Table!Y17*Y$55 -> 0 | Z17: =Table!Z17*Z$55 -> 1.7564479 | AA17: =Table!AA17*AA$55 -> 0.83155853 | AB17: =Table!AB17*AB$55 -> 0.50237564 | AC17: =Table!AC17*AC$55 -> 0 | ... BD17: =Table!BD17*BD$55 -> 0 | BE17: 204 | BF17: =SUM(F17:BE17)/(D17) -> 0.0017501896 | BG17: 0.001073349 | BI17: =A17 -> iowa | BJ17: =BF17 -> 0.0017501896 | BL17: =SUM(F17:BD17)/(D17-Table!BG17) -> 0.037112103
A18: kansas | B18: 2471342 | C18: 1296974 | D18: 1174154 | E18: 2471342 | F18: =Table!F18*F$55 -> 0 | G18: =Table!G18*G$55 -> 0 | H18: =Table!H18*H$55 -> 0 | I18: =Table!I18*I$55 -> 0 | J18: =Table!J18*J$55 -> 7.1246927 | K18: =Table!K18*K$55 -> 1.331 | L18: =Table!L18*L$55 -> 0.024429264 | M18: =Table!M18*M$55 -> 0 | ... U18: =Table!U18*U$55 -> 0.35098513 | V18: 0 | W18: =Table!W18*W$55 -> 0.82842173 | X18: =Table!X18*X$55 -> 1.4691982 | Y18: =Table!Y18*Y$55 -> 0 | Z18: =Table!Z18*Z$55 -> 8.9930133 | AA18: =Table!AA18*AA$55 -> 0 | AB18: =Table!AB18*AB$55 -> 0.37678173 | AC18: =Table!AC18*AC$55 -> 0 | AD18: =Table!AD18*AD$55 -> 0 | ... BD18: =Table!BD18*BD$55 -> 0 | BE18: 214 | BF18: =SUM(F18:BE18)/(D18) -> 0.00053828297 | BG18: 0.064564023 | BI18: =A18 -> kansas | BJ18: =BF18 -> 0.00053828297 | BL18: =SUM(F18:BD18)/(D18-Table!BG18) -> 0.0047015825
A19: kentucky | B19: 3667395 | C19: 2107119 | D19: 1559792 | E19: 3667395 | F19: =Table!F19*F$55 -> 0 | G19: =Table!G19*G$55 -> 0 | H19: =Table!H19*H$55 -> 0 | I19: =Table!I19*I$55 -> 0 | J19: =Table!J19*J$55 -> 11.627837 | K19: =Table!K19*K$55 -> 1.0766311 | L19: =Table!L19*L$55 -> 0 | M19: =Table!M19*M$55 -> 5.304391 | ... V19: =Table!V19*V$55 -> 6.5209663 | W19: 0 | X19: =Table!X19*X$55 -> 3.7611474 | Y19: =Table!Y19*Y$55 -> 0 | Z19: =Table!Z19*Z$55 -> 9.8361083 | AA19: =Table!AA19*AA$55 -> 3.7420134 | AB19: =Table!AB19*AB$55 -> 1.8248056 | AC19: =Table!AC19*AC$55 -> 0 | AD19: =Table!AD19*AD$55 -> 0 | AE19: =Table!AE19*AE$55 -> 0.45885022 | ... BD19: =Table!BD19*BD$55 -> 0 | BE19: 484 | BF19: =SUM(F19:BE19)/(D19) -> 0.0026066729 | BG19: 0.008453283 | BI19: =A19 -> kentucky | BJ19: =BF19 -> 0.0026066729 | BL19: =SUM(F19:BD19)/(D19-Table!BG19) -> 0.034216326
A20: louisi~1 | B20: 4188408 | C20: 2563518 | D20: 1623594 | E20: 4188408 | F20: =Table!F20*F$55 -> 0 | G20: =Table!G20*G$55 -> 7.9238134 | H20: =Table!H20*H$55 -> 0 | I20: =Table!I20*I$55 -> 0 | J20: =Table!J20*J$55 -> 19.788464 | K20: =Table!K20*K$55 -> 0.55901998 | L20: =Table!L20*L$55 -> 0.032745609 | M20: =Table!M20*M$55 -> 0 | ... W20: =Table!W20*W$55 -> 1.1411932 | X20: 0 | Y20: =Table!Y20*Y$55 -> 1.8915897 | Z20: =Table!Z20*Z$55 -> 4.4262487 | AA20: =Table!AA20*AA$55 -> 7.7958612 | AB20: =Table!AB20*AB$55 -> 1.1968361 | AC20: =Table!AC20*AC$55 -> 0 | AD20: =Table!AD20*AD$55 -> 0 | AE20: =Table!AE20*AE$55 -> 0.24841726 | AF20: =Table!AF20*AF$55 -> 0 | ... BD20: =Table!BD20*BD$55 -> 0 | BE20: 1296 | BF20: =SUM(F20:BE20)/(D20) -> 0.0012659265 | BG20: 0.029383964 | BI20: =A20 -> louisi~1 | BJ20: =BF20 -> 0.0012659265 | BL20: =SUM(F20:BD20)/(D20-Table!BG20) -> 0.024366276
A21: maine | B21: 1226904 | C21: 653357 | D21: 573276 | E21: 1226904 | F21: =Table!F21*F$55 -> 0 | G21: =Table!G21*G$55 -> 5.5340919 | H21: =Table!H21*H$55 -> 0 | I21: =Table!I21*I$55 -> 0 | J21: =Table!J21*J$55 -> 1.458765 | K21: =Table!K21*K$55 -> 0.026619999 | L21: =Table!L21*L$55 -> 0.065231332 | M21: =Table!M21*M$55 -> 0 | ... X21: =Table!X21*X$55 -> 2.4094851 | Y21: 0 | Z21: =Table!Z21*Z$55 -> 3.7236696 | AA21: =Table!AA21*AA$55 -> 249.98728 | AB21: =Table!AB21*AB$55 -> 0.15514542 | AC21: =Table!AC21*AC$55 -> 0 | AD21: =Table!AD21*AD$55 -> 0 | AE21: =Table!AE21*AE$55 -> 0.016713088 | AF21: =Table!AF21*AF$55 -> 0 | AG21: =Table!AG21*AG$55 -> 0 | ... BD21: =Table!BD21*BD$55 -> 0 | BE21: 271 | BF21: =SUM(F21:BE21)/(D21) -> 0.0040378486 | BG21: 0.10508832 | BI21: =A21 -> maine | BJ21: =BF21 -> 0.0040378486 | BL21: =SUM(F21:BD21)/(D21-Table!BG21) -> 0.11374676
A22: maryland | B22: 4780796 | C22: 2304040 | D22: 2475649 | E22: 4780796 | F22: =Table!F22*F$55 -> 0 | G22: =Table!G22*G$55 -> 1.6350726 | H22: =Table!H22*H$55 -> 0 | I22: =Table!I22*I$55 -> 0 | J22: =Table!J22*J$55 -> 19.492483 | K22: =Table!K22*K$55 -> 0.58859776 | L22: =Table!L22*L$55 -> 0.045220127 | M22: =Table!M22*M$55 -> 4761.8276 | ... Y22: =Table!Y22*Y$55 -> 10.929185 | Z22: 0 | AA22: =Table!AA22*AA$55 -> 30.040052 | AB22: =Table!AB22*AB$55 -> 2.2163631 | AC22: =Table!AC22*AC$55 -> 0 | AD22: =Table!AD22*AD$55 -> 0 | AE22: =Table!AE22*AE$55 -> 0.082046066 | AF22: =Table!AF22*AF$55 -> 0 | AG22: =Table!AG22*AG$55 -> 0.15960665 | AH22: =Table!AH22*AH$55 -> 0 | ... BD22: =Table!BD22*BD$55 -> 0 | BE22: 1107 | BF22: =SUM(F22:BE22)/(D22) -> 0.0052109919 | BG22: 0.070257916 | BI22: =A22 -> maryland | BJ22: =BF22 -> 0.0052109919 | BL22: =SUM(F22:BD22)/(D22-Table!BG22) -> 0.027478196
A23: massac~1 | B23: 6015898 | C23: 3031218 | D23: 2983607 | E23: 6015898 | F23: =Table!F23*F$55 -> 0 | G23: =Table!G23*G$55 -> 0 | H23: =Table!H23*H$55 -> 0 | I23: =Table!I23*I$55 -> 0 | J23: =Table!J23*J$55 -> 23.34024 | K23: =Table!K23*K$55 -> 0.80451553 | L23: =Table!L23*L$55 -> 7.1206106 | M23: =Table!M23*M$55 -> 7.8302915 | ... Z23: =Table!Z23*Z$55 -> 36.253085 | AA23: 0 | AB23: =Table!AB23*AB$55 -> 0.9678119 | AC23: =Table!AC23*AC$55 -> 0 | AD23: =Table!AD23*AD$55 -> 0 | AE23: =Table!AE23*AE$55 -> 0.091162296 | AF23: =Table!AF23*AF$55 -> 0 | AG23: =Table!AG23*AG$55 -> 0 | AH23: =Table!AH23*AH$55 -> 0 | AI23: =Table!AI23*AI$55 -> 2162.8636 | ... BD23: =Table!BD23*BD$55 -> 0 | BE23: 1073 | BF23: =SUM(F23:BE23)/(D23) -> 0.0022584269 | BG23: 0.10394482 | BI23: =A23 -> massac~1 | BJ23: =BF23 -> 0.0022584269 | BL23: =SUM(F23:BD23)/(D23-Table!BG23) -> 0.06131232
A24: michigan | B24: 9284810 | C24: 5196906 | D24: 4086456 | E24: 9284810 | F24: =Table!F24*F$55 -> 0 | G24: =Table!G24*G$55 -> 5.4712045 | H24: =Table!H24*H$55 -> 0 | I24: =Table!I24*I$55 -> 0 | J24: =Table!J24*J$55 -> 33.234472 | K24: =Table!K24*K$55 -> 0.38155332 | L24: =Table!L24*L$55 -> 0.03144618 | M24: =Table!M24*M$55 -> 9.5984218 | ... AA24: =Table!AA24*AA$55 -> 25.050701 | AB24: 0 | AC24: =Table!AC24*AC$55 -> 0 | AD24: =Table!AD24*AD$55 -> 0 | AE24: =Table!AE24*AE$55 -> 0.31071149 | AF24: =Table!AF24*AF$55 -> 0 | AG24: =Table!AG24*AG$55 -> 0.2354198 | AH24: =Table!AH24*AH$55 -> 0 | AI24: =Table!AI24*AI$55 -> 0 | AJ24: =Table!AJ24*AJ$55 -> 92.103231 | ... BD24: =Table!BD24*BD$55 -> 0 | BE24: 1448 | BF24: =SUM(F24:BE24)/(D24) -> 0.00098023958 | BG24: 0.0073878771 | BI24: =A24 -> michigan | BJ24: =BF24 -> 0.00098023958 | BL24: =SUM(F24:BD24)/(D24-Table!BG24) -> 0.041963314
A25: minnes~1 | B25: 4366568 | C25: 2207656 | D25: 2158427 | E25: 4366568 | F25: =Table!F25*F$55 -> 0 | G25: =Table!G25*G$55 -> 0 | H25: =Table!H25*H$55 -> 0 | I25: =Table!I25*I$55 -> 0 | J25: =Table!J25*J$55 -> 19.492483 | K25: =Table!K25*K$55 -> 0.6359222 | L25: =Table!L25*L$55 -> 0.015853033 | M25: =Table!M25*M$55 -> 0 | ... AB25: =Table!AB25*AB$55 -> 3.4131992 | AC25: 0 | AD25: =Table!AD25*AD$55 -> 0 | AE25: =Table!AE25*AE$55 -> 0.26361097 | AF25: =Table!AF25*AF$55 -> 0 | AG25: =Table!AG25*AG$55 -> 0.51074127 | AH25: =Table!AH25*AH$55 -> 0 | AI25: =Table!AI25*AI$55 -> 1.0599963 | AJ25: =Table!AJ25*AJ$55 -> 24.323999 | AK25: =Table!AK25*AK$55 -> 0 | ... BD25: =Table!BD25*BD$55 -> 0 | BE25: 485 | BF25: =SUM(F25:BE25)/(D25) -> 0.00044479489 | BG25: 0 | BI25: =A25 -> minnes~1 | BJ25: =BF25 -> 0.00044479489 | BL25: =SUM(F25:BD25)/(D25-Table!BG25) -> 0.012429222
A26: missis~1 | B26: 2560194 | C26: 1537800 | D26: 1021722 | E26: 2560194 | F26: =Table!F26*F$55 -> 0 | G26: =Table!G26*G$55 -> 5.6598667 | H26: =Table!H26*H$55 -> 0 | I26: =Table!I26*I$55 -> 0 | J26: =Table!J26*J$55 -> 4.7568423 | K26: =Table!K26*K$55 -> 0.11535333 | L26: =Table!L26*L$55 -> 0.0023389721 | M26: =Table!M26*M$55 -> 0 | ... AC26: =Table!AC26*AC$55 -> 0 | AD26: 0 | AE26: =Table!AE26*AE$55 -> 0.13674344 | AF26: =Table!AF26*AF$55 -> 0 | AG26: =Table!AG26*AG$55 -> 0 | AH26: =Table!AH26*AH$55 -> 0 | AI26: =Table!AI26*AI$55 -> 0 | AJ26: =Table!AJ26*AJ$55 -> 9.0190108 | AK26: =Table!AK26*AK$55 -> 0 | AL26: =Table!AL26*AL$55 -> 45.791441 | ... BD26: =Table!BD26*BD$55 -> 0 | BE26: 672 | BF26: =SUM(F26:BE26)/(D26) -> 0.0013495705 | BG26: 0 | BI26: =A26 -> missis~1 | BJ26: =BF26 -> 0.0013495705 | BL26: =SUM(F26:BD26)/(D26-Table!BG26) -> 0.011786146
A27: missouri | B27: 5101921 | C27: 2763262 | D27: 2337818 | E27: 5101921 | F27: =Table!F27*F$55 -> 0 | G27: =Table!G27*G$55 -> 1.5092978 | H27: =Table!H27*H$55 -> 0 | I27: =Table!I27*I$55 -> 0 | J27: =Table!J27*J$55 -> 20.634125 | K27: =Table!K27*K$55 -> 0.85479775 | L27: =Table!L27*L$55 -> 0.033785152 | M27: =Table!M27*M$55 -> 0 | ... AD27: =Table!AD27*AD$55 -> 0 | AE27: 0 | AF27: =Table!AF27*AF$55 -> 0 | AG27: =Table!AG27*AG$55 -> 1.3367057 | AH27: =Table!AH27*AH$55 -> 0 | AI27: =Table!AI27*AI$55 -> 4.3577627 | AJ27: =Table!AJ27*AJ$55 -> 69.965659 | AK27: =Table!AK27*AK$55 -> 0 | AL27: =Table!AL27*AL$55 -> 104.52394 | AM27: =Table!AM27*AM$55 -> 0.098212925 | ... BD27: =Table!BD27*BD$55 -> 0 | BE27: 841 | BF27: =SUM(F27:BE27)/(D27) -> 0.0032806524 | BG27: 0.0007596858 | BI27: =A27 -> missouri | BJ27: =BF27 -> 0.0032806524 | BL27: =SUM(F27:BD27)/(D27-Table!BG27) -> 0.060895414
A28: montana | B28: 796317 | C28: 446885 | D28: 349367 | E28: 796317 | F28: =Table!F28*F$55 -> 0 | G28: =Table!G28*G$55 -> 10.753747 | H28: =Table!H28*H$55 -> 0 | I28: =Table!I28*I$55 -> 0 | J28: =Table!J28*J$55 -> 12.727196 | K28: =Table!K28*K$55 -> 0.10056444 | L28: =Table!L28*L$55 -> 0.0059773731 | M28: =Table!M28*M$55 -> 0 | ... AE28: =Table!AE28*AE$55 -> 0.012154973 | AF28: 0 | AG28: =Table!AG28*AG$55 -> 0 | AH28: =Table!AH28*AH$55 -> 0 | AI28: =Table!AI28*AI$55 -> 0 | AJ28: =Table!AJ28*AJ$55 -> 6.2859772 | AK28: =Table!AK28*AK$55 -> 0 | AL28: =Table!AL28*AL$55 -> 4.9773306 | AM28: =Table!AM28*AM$55 -> 0.019199519 | AN28: =Table!AN28*AN$55 -> 0 | ... BD28: =Table!BD28*BD$55 -> 0 | BE28: 65 | BF28: =SUM(F28:BE28)/(D28) -> 0.00043170036 | BG28: 0 | BI28: =A28 -> montana | BJ28: =BF28 -> 0.00043170036 | BL28: =SUM(F28:BD28)/(D28-Table!BG28) -> 0.019838618
A29: nebraska | B29: 1578049 | C29: 803789 | D29: 774005 | E29: 1578049 | F29: =Table!F29*F$55 -> 0 | G29: =Table!G29*G$55 -> 0.50309926 | H29: =Table!H29*H$55 -> 0 | I29: =Table!I29*I$55 -> 0 | J29: =Table!J29*J$55 -> 9.5559676 | K29: =Table!K29*K$55 -> 1.6208622 | L29: =Table!L29*L$55 -> 0 | M29: =Table!M29*M$55 -> 0 | ... AF29: =Table!AF29*AF$55 -> 0 | AG29: 0 | AH29: =Table!AH29*AH$55 -> 0 | AI29: =Table!AI29*AI$55 -> 0 | AJ29: =Table!AJ29*AJ$55 -> 7.9257973 | AK29: =Table!AK29*AK$55 -> 0 | AL29: =Table!AL29*AL$55 -> 36.832246 | AM29: =Table!AM29*AM$55 -> 0 | AN29: =Table!AN29*AN$55 -> 0 | AO29: =Table!AO29*AO$55 -> 1.3479063 | ... BD29: =Table!BD29*BD$55 -> 0 | BE29: 255 | BF29: =SUM(F29:BE29)/(D29) -> 0.00059786599 | BG29: 0.0019950831 | BI29: =A29 -> nebraska | BJ29: =BF29 -> 0.00059786599 | BL29: =SUM(F29:BD29)/(D29-Table!BG29) -> 0.011502119
A30: nevada | B30: 1195956 | C30: 595440 | D30: 600342 | E30: 1195956 | F30: =Table!F30*F$55 -> 0 | G30: =Table!G30*G$55 -> 4.4021186 | H30: =Table!H30*H$55 -> 0 | I30: =Table!I30*I$55 -> 0 | J30: =Table!J30*J$55 -> 99.069169 | K30: =Table!K30*K$55 -> 0.67141554 | L30: =Table!L30*L$55 -> 0 | M30: =Table!M30*M$55 -> 5.304391 | ... AG30: =Table!AG30*AG$55 -> 0.047881994 | AH30: 0 | AI30: =Table!AI30*AI$55 -> 0 | AJ30: =Table!AJ30*AJ$55 -> 10.385528 | AK30: =Table!AK30*AK$55 -> 0 | AL30: =Table!AL30*AL$55 -> 49.773306 | AM30: =Table!AM30*AM$55 -> 0.015507304 | AN30: =Table!AN30*AN$55 -> 0 | AO30: =Table!AO30*AO$55 -> 2.5643096 | AP30: =Table!AP30*AP$55 -> 2.355326 | ... BD30: =Table!BD30*BD$55 -> 0 | BE30: 174 | BF30: =SUM(F30:BE30)/(D30) -> 0.00064789807 | BG30: 0 | BI30: =A30 -> nevada | BJ30: =BF30 -> 0.00064789807 | BL30: =SUM(F30:BD30)/(D30-Table!BG30) -> 0.028908072
A31: new-ha~1 | B31: 1104242 | C31: 539361 | D31: 564611 | E31: 1104242 | F31: =Table!F31*F$55 -> 0 | G31: =Table!G31*G$55 -> 2.1381719 | H31: =Table!H31*H$55 -> 0 | I31: =Table!I31*I$55 -> 0 | J31: =Table!J31*J$55 -> 4.0591721 | K31: =Table!K31*K$55 -> 0.079859998 | L31: =Table!L31*L$55 -> 0.17906131 | M31: =Table!M31*M$55 -> 7.0725213 | ... AH31: =Table!AH31*AH$55 -> 0 | AI31: 0 | AJ31: =Table!AJ31*AJ$55 -> 71.058873 | AK31: =Table!AK31*AK$55 -> 0 | AL31: =Table!AL31*AL$55 -> 244.22102 | AM31: =Table!AM31*AM$55 -> 0.045045026 | AN31: =Table!AN31*AN$55 -> 0 | AO31: =Table!AO31*AO$55 -> 3.9450917 | AP31: =Table!AP31*AP$55 -> 0.5318478 | AQ31: =Table!AQ31*AQ$55 -> 0.037093282 | ... BD31: =Table!BD31*BD$55 -> 0 | BE31: 270 | BF31: =SUM(F31:BE31)/(D31) -> 0.016551793 | BG31: 0.11777737 | BI31: =A31 -> new-ha~1 | BJ31: =BF31 -> 0.016551793 | BL31: =SUM(F31:BD31)/(D31-Table!BG31) -> 0.095689887
A32: new-je~1 | B32: 7698998 | C32: 3899647 | D32: 3797719 | E32: 7698998 | F32: =Table!F32*F$55 -> 0 | G32: =Table!G32*G$55 -> 2.3268341 | H32: =Table!H32*H$55 -> 0 | I32: =Table!I32*I$55 -> 0 | J32: =Table!J32*J$55 -> 27.10343 | K32: =Table!K32*K$55 -> 0.5176111 | L32: =Table!L32*L$55 -> 0.64971446 | M32: =Table!M32*M$55 -> 1705.7406 | ... AI32: =Table!AI32*AI$55 -> 13.662175 | AJ32: 0 | AK32: =Table!AK32*AK$55 -> 0 | AL32: =Table!AL32*AL$55 -> 102251.96 | AM32: =Table!AM32*AM$55 -> 0.37217529 | AN32: =Table!AN32*AN$55 -> 0 | AO32: =Table!AO32*AO$55 -> 20.941862 | AP32: =Table!AP32*AP$55 -> 2.4313042 | AQ32: =Table!AQ32*AQ$55 -> 0.34443762 | AR32: =Table!AR32*AR$55 -> 13295.866 | ... BD32: =Table!BD32*BD$55 -> 0 | BE32: 1632 | BF32: =SUM(F32:BE32)/(D32) -> 0.031452011 | BG32: 0.27330336 | BI32: =A32 -> new-je~1 | BJ32: =BF32 -> 0.031452011 | BL32: =SUM(F32:BD32)/(D32-Table!BG32) -> 0.26496767
A33: new-me~1 | B33: 1507146 | C33: 876153 | D33: 630531 | E33: 1507146 | F33: =Table!F33*F$55 -> 0 | G33: =Table!G33*G$55 -> 5.6598667 | H33: =Table!H33*H$55 -> 0 | I33: =Table!I33*I$55 -> 0 | J33: =Table!J33*J$55 -> 12.811762 | K33: =Table!K33*K$55 -> 2.2893199 | L33: =Table!L33*L$55 -> 0.0023389721 | M33: =Table!M33*M$55 -> 4.5466209 | ... AJ33: =Table!AJ33*AJ$55 -> 9.8389208 | AK33: 0 | AL33: =Table!AL33*AL$55 -> 41.809577 | AM33: =Table!AM33*AM$55 -> 0.013291975 | AN33: =Table!AN33*AN$55 -> 0 | AO33: =Table!AO33*AO$55 -> 1.4794094 | AP33: =Table!AP33*AP$55 -> 18.234782 | AQ33: =Table!AQ33*AQ$55 -> 0.095382725 | AR33: =Table!AR33*AR$55 -> 17.546585 | AS33: =Table!AS33*AS$55 -> 0.78468847 | ... BD33: =Table!BD33*BD$55 -> 0 | BE33: 462 | BF33: =SUM(F33:BE33)/(D33) -> 0.001344487 | BG33: 0 | BI33: =A33 -> new-me~1 | BJ33: =BF33 -> 0.001344487 | BL33: =SUM(F33:BD33)/(D33-Table!BG33) -> 0.024310879
A34: new-york | B34: 17919274 | C34: 9723449 | D34: 8192105 | E34: 17919274 | F34: =Table!F34*F$55 -> 0 | G34: =Table!G34*G$55 -> 8.4898001 | H34: =Table!H34*H$55 -> 0 | I34: =Table!I34*I$55 -> 0 | J34: =Table!J34*J$55 -> 62.790318 | K34: =Table!K34*K$55 -> 1.0500111 | L34: =Table!L34*L$55 -> 7.9831716 | M34: =Table!M34*M$55 -> 72.493344 | ... AK34: =Table!AK34*AK$55 -> 0 | AL34: 0 | AM34: =Table!AM34*AM$55 -> 0.72515107 | AN34: =Table!AN34*AN$55 -> 0 | AO34: =Table!AO34*AO$55 -> 41.390587 | AP34: =Table!AP34*AP$55 -> 7.6738039 | AQ34: =Table!AQ34*AQ$55 -> 0.62528675 | AR34: =Table!AR34*AR$55 -> 1254.1129 | AS34: =Table!AS34*AS$55 -> 18.720425 | AT34: =Table!AT34*AT$55 -> 0 | ... BD34: =Table!BD34*BD$55 -> 0 | BE34: 3720 | BF34: =SUM(F34:BE34)/(D34) -> 0.0049779152 | BG34: 0.33182204 | BI34: =A34 -> new-york | BJ34: =BF34 -> 0.0049779152 | BL34: =SUM(F34:BD34)/(D34-Table!BG34) -> 0.18576987
A35: north-~1 | B35: 6612198 | C35: 3321672 | D35: 3288867 | E35: 6612198 | F35: =Table!F35*F$55 -> 0 | G35: =Table!G35*G$55 -> 0.37732445 | H35: =Table!H35*H$55 -> 0 | I35: =Table!I35*I$55 -> 0 | J35: =Table!J35*J$55 -> 20.549559 | K35: =Table!K35*K$55 -> 0.46141332 | L35: =Table!L35*L$55 -> 0.024169378 | M35: =Table!M35*M$55 -> 46.981749 | ... AL35: =Table!AL35*AL$55 -> 372.30433 | AM35: 0 | AN35: =Table!AN35*AN$55 -> 0 | AO35: =Table!AO35*AO$55 -> 21.599377 | AP35: =Table!AP35*AP$55 -> 14.81576 | AQ35: =Table!AQ35*AQ$55 -> 0 | AR35: =Table!AR35*AR$55 -> 84.574538 | AS35: =Table!AS35*AS$55 -> 0.44839341 | AT35: =Table!AT35*AT$55 -> 0 | AU35: =Table!AU35*AU$55 -> 0 | ... BD35: =Table!BD35*BD$55 -> 0 | BE35: 1659 | BF35: =SUM(F35:BE35)/(D35) -> 0.0011473447 | BG35: 0.00073844304 | BI35: =A35 -> north-~1 | BJ35: =BF35 -> 0.0011473447 | BL35: =SUM(F35:BD35)/(D35-Table!BG35) -> 0.0363048
A36: north-~2 | B36: 635095 | C36: 340720 | D36: 294310 | E36: 635095 | F36: =Table!F36*F$55 -> 0 | G36: =Table!G36*G$55 -> 6.2887408 | H36: =Table!H36*H$55 -> 0 | I36: =Table!I36*I$55 -> 0 | J36: =Table!J36*J$55 -> 0.63424564 | K36: =Table!K36*K$55 -> 0.39929999 | L36: =Table!L36*L$55 -> 0 | M36: =Table!M36*M$55 -> 0 | ... AM36: =Table!AM36*AM$55 -> 0 | AN36: 0 | AO36: =Table!AO36*AO$55 -> 1.1506518 | AP36: =Table!AP36*AP$55 -> 4.9385867 | AQ36: =Table!AQ36*AQ$55 -> 0.15897121 | AR36: =Table!AR36*AR$55 -> 3.5093169 | AS36: =Table!AS36*AS$55 -> 0 | AT36: =Table!AT36*AT$55 -> 0 | AU36: =Table!AU36*AU$55 -> 0 | AV36: =Table!AV36*AV$55 -> 0 | ... BD36: =Table!BD36*BD$55 -> 0 | BE36: 65 | BF36: =SUM(F36:BE36)/(D36) -> 0.00041210664 | BG36: 0 | BI36: =A36 -> north-~2 | BJ36: =BF36 -> 0.00041210664 | BL36: =SUM(F36:BD36)/(D36-Table!BG36) -> 0.005211769
A37: ohio | B37: 10832284 | C37: 6001391 | D37: 4829648 | E37: 10832284 | F37: =Table!F37*F$55 -> 0 | G37: =Table!G37*G$55 -> 2.2010593 | H37: =Table!H37*H$55 -> 0 | I37: =Table!I37*I$55 -> 0 | J37: =Table!J37*J$55 -> 28.583337 | K37: =Table!K37*K$55 -> 1.0855044 | L37: =Table!L37*L$55 -> 0.071468591 | M37: =Table!M37*M$55 -> 16.923533 | ... AN37: =Table!AN37*AN$55 -> 0 | AO37: 0 | AP37: =Table!AP37*AP$55 -> 7.7497822 | AQ37: =Table!AQ37*AQ$55 -> 0.21726065 | AR37: =Table!AR37*AR$55 -> 1419.7527 | AS37: =Table!AS37*AS$55 -> 2.6529944 | AT37: =Table!AT37*AT$55 -> 0 | AU37: =Table!AU37*AU$55 -> 0 | AV37: =Table!AV37*AV$55 -> 0.054002808 | AW37: =Table!AW37*AW$55 -> 25.638377 | ... BD37: =Table!BD37*BD$55 -> 0 | BE37: 1245 | BF37: =SUM(F37:BE37)/(D37) -> 0.0014012682 | BG37: 0.032875764 | BI37: =A37 -> ohio | BJ37: =BF37 -> 0.0014012682 | BL37: =SUM(F37:BD37)/(D37-Table!BG37) -> 0.051340849
A38: oklahoma | B38: 3137119 | C38: 1768425 | D38: 1368128 | E38: 3137119 | F38: =Table!F38*F$55 -> 0 | G38: =Table!G38*G$55 -> 5.2196549 | H38: =Table!H38*H$55 -> 0 | I38: =Table!I38*I$55 -> 0 | J38: =Table!J38*J$55 -> 16.236688 | K38: =Table!K38*K$55 -> 0.60634443 | L38: =Table!L38*L$55 -> 0.017672233 | M38: =Table!M38*M$55 -> 0 | ... AO38: =Table!AO38*AO$55 -> 8.2518168 | AP38: 0 | AQ38: =Table!AQ38*AQ$55 -> 0.19606449 | AR38: =Table!AR38*AR$55 -> 16.376812 | AS38: =Table!AS38*AS$55 -> 0.78468847 | AT38: =Table!AT38*AT$55 -> 0 | AU38: =Table!AU38*AU$55 -> 0 | AV38: =Table!AV38*AV$55 -> 0.011891059 | AW38: =Table!AW38*AW$55 -> 237.25398 | AX38: =Table!AX38*AX$55 -> 0.028034379 | ... BD38: =Table!BD38*BD$55 -> 0 | BE38: 566 | BF38: =SUM(F38:BE38)/(D38) -> 0.00095107086 | BG38: 0.075978257 | BI38: =A38 -> oklahoma | BJ38: =BF38 -> 0.00095107086 | BL38: =SUM(F38:BD38)/(D38-Table!BG38) -> 0.018373236
A39: oregon | B39: 2832819 | C39: 1538425 | D39: 1293876 | E39: 2832819 | F39: =Table!F39*F$55 -> 0 | G39: =Table!G39*G$55 -> 49.303728 | H39: =Table!H39*H$55 -> 0 | I39: =Table!I39*I$55 -> 0 | J39: =Table!J39*J$55 -> 89.893749 | K39: =Table!K39*K$55 -> 0.38746888 | L39: =Table!L39*L$55 -> 0 | M39: =Table!M39*M$55 -> 0 | ... AP39: =Table!AP39*AP$55 -> 4.1028259 | AQ39: 0 | AR39: =Table!AR39*AR$55 -> 12.048655 | AS39: =Table!AS39*AS$55 -> 0 | AT39: =Table!AT39*AT$55 -> 0 | AU39: =Table!AU39*AU$55 -> 0 | AV39: =Table!AV39*AV$55 -> 0.0011020981 | AW39: =Table!AW39*AW$55 -> 4.8505038 | AX39: =Table!AX39*AX$55 -> 0.1532546 | AY39: =Table!AY39*AY$55 -> 0 | ... BD39: =Table!BD39*BD$55 -> 0 | BE39: 518 | BF39: =SUM(F39:BE39)/(D39) -> 0.0011617284 | BG39: 0.0052990403 | BI39: =A39 -> oregon | BJ39: =BF39 -> 0.0011617284 | BL39: =SUM(F39:BD39)/(D39-Table!BG39) -> 0.035970806
A40: pennsy~1 | B40: 11853450 | C40: 6514916 | D40: 5337143 | E40: 11853450 | F40: =Table!F40*F$55 -> 0 | G40: =Table!G40*G$55 -> 3.4588074 | H40: =Table!H40*H$55 -> 0 | I40: =Table!I40*I$55 -> 0 | J40: =Table!J40*J$55 -> 33.297896 | K40: =Table!K40*K$55 -> 0.56197776 | L40: =Table!L40*L$55 -> 0.2120668 | M40: =Table!M40*M$55 -> 5351.8779 | ... AQ40: =Table!AQ40*AQ$55 -> 0.57759539 | AR40: 0 | AS40: =Table!AS40*AS$55 -> 2.8024588 | AT40: =Table!AT40*AT$55 -> 0 | AU40: =Table!AU40*AU$55 -> 0 | AV40: =Table!AV40*AV$55 -> 0.02111388 | AW40: =Table!AW40*AW$55 -> 25.861105 | AX40: =Table!AX40*AX$55 -> 0.022427503 | AY40: =Table!AY40*AY$55 -> 0 | AZ40: =Table!AZ40*AZ$55 -> 163.40763 | ... BD40: =Table!BD40*BD$55 -> 0 | BE40: 1391 | BF40: =SUM(F40:BE40)/(D40) -> 0.0092821416 | BG40: 0.11697723 | BI40: =A40 -> pennsy~1 | BJ40: =BF40 -> 0.0092821416 | BL40: =SUM(F40:BD40)/(D40-Table!BG40) -> 0.21098324
...

Sheet Summary
A1: State | B1: WorkersWhoLiveInState | C1: ResidentsWhoWorkInState
A2: alabama | B2: 0.97614812 | C2: 0.96400148
A3: alaska | B3: 0.97016628 | C3: 0.99558523
A4: arizona | B4: 0.98879281 | C4: 0.98419561
A5: arkansas | B5: 0.95970581 | C5: 0.96770362
A6: califo~1 | B6: 0.99547697 | C6: 0.99631019
A7: colorado | B7: 0.99205546 | C7: 0.98974972
A8: connec~1 | B8: 0.95438758 | C8: 0.95255497
A9: deleware | B9: 0.86167112 | C9: 0.90495428
A10: district-of-columbia | B10: 0.32370875 | C10: 0.77442635
A11: florida | B11: 0.99200579 | C11: 0.9900131
A12: georgia | B12: 0.97186218 | C12: 0.97610848
A13: hawaii | B13: 0.9904759 | C13: 0.99532477
... A52: wyoming | B52: 0.974379 | C52: 0.97993956
A53: 98 | B53: 0.18293943

Sheet Sheet2
A1: SUMMARY OUTPUT
A3: Regression Statistics
A4: Multiple R | B4: 0.45033909
A5: R Square | B5: 0.20280529
A6: Adjusted R Square | B6: 0.07302941
A7: Standard Error | B7: 0.070100559
A8: Observations | B8: 51
A10: ANOVA
B11: df | C11: SS | D11: MS | E11: F | F11: Significance F
A12: Regression | B12: 7 | C12: 0.05375592 | D12: 0.0076794171 | E12: 1.5627348 | F12: 0.17257795
A13: Residual | B13: 43 | C13: 0.2113058 | D13: 0.0049140884
A14: Total | B14: 50 | C14: 0.26506172
B16: Coefficients | C16: Standard Error | D16: t Stat | E16: P-value | F16: Lower 95% | G16: Upper 95% | H16: Lower 95.0% | I16: Upper 95.0%
A17: Intercept | B17: -1.7856862 | C17: 1079289.8 | D17: -1.6545012e-06 | E17: 0.99999869 | F17: -2176595.6 | G17: 2176592 | H17: -2176595.6 | I17: 2176592
A18: Rhoii/RhoTot | B18: 0.23325246 | C18: 0 | D18: 65535 | E18: =#REF! -> #NUM! | F18: 0.23325246 | G18: 0.23325246 | H18: 0.23325246 | I18: 0.23325246
A19: Rhoij/RhoTot | B19: 18.000783 | C19: 0 | D19: 65535 | E19: =#REF! -> #NUM! | F19: 18.000783 | G19: 18.000783 | H19: 18.000783 | I19: 18.000783
A20: Rhoji/RhoTot | B20: 2.1135523 | C20: 0 | D20: 65535 | E20: =#REF! -> #NUM! | F20: 2.1135523 | G20: 2.1135523 | H20: 2.1135523 | I20: 2.1135523
A21: Rhoii/RhoOrig | B21: 0.51410497 | C21: 505142.11 | D21: 1.0177433e-06 | E21: 0.99999919 | F21: -1018714.9 | G21: 1018716 | H21: -1018714.9 | I21: 1018716
A22: Rhoij/RhoOrig | B22: -7.990619 | C22: 252571.05 | D22: -3.1637113e-05 | E22: 0.9999749 | F22: -509365.71 | G22: 509349.73 | H22: -509365.71 | I22: 509349.73
A23: Rhoij/RhoCordon | B23: 0.9911072 | C23: 508795.33 | D23: 1.9479487e-06 | E23: 0.99999845 | F23: -1026081.9 | G23: 1026083.9 | H23: -1026081.9 | I23: 1026083.9
A24: Rhoji/RhoCordon | B24: 1.0710787 | C24: 508795.33 | D24: 2.1051269e-06 | E24: 0.99999833 | F24: -1026081.8 | G24: 1026083.9 | H24: -1026081.8 | I24: 1026083.9

Sheet Sheet3
A1: SUMMARY OUTPUT
A3: Regression Statistics
A4: Multiple R | B4: 0.45033909
A5: R Square | B5: 0.20280529
A6: Adjusted R Square | B6: 0.13348401
A7: Standard Error | B7: 0.067776134
A8: Observations | B8: 51
A10: ANOVA
B11: df | C11: SS | D11: MS | E11: F | F11: Significance F
A12: Regression | B12: 4 | C12: 0.05375592 | D12: 0.01343898 | E12: 2.925585 | F12: 0.030842147
A13: Residual | B13: 46 | C13: 0.2113058 | D13: 0.0045936044
A14: Total | B14: 50 | C14: 0.26506172
B16: Coefficients | C16: Standard Error | D16: t Stat | E16: P-value | F16: Lower 95% | G16: Upper 95% | H16: Lower 95.0% | I16: Upper 95.0%
A17: Intercept | B17: 0.032749979 | C17: 0.067407828 | D17: 0.4858483 | E17: 0.6293811 | F17: -0.10293481 | G17: 0.16843477 | H17: -0.10293481 | I17: 0.16843477
A18: Rhoij/RhoTot | B18: 17.767531 | C18: 11.87594 | D18: 1.4960947 | E18: 0.14145898 | F18: -6.1374732 | G18: 41.672535 | H18: -6.1374732 | I18: 41.672535
A19: Rhoji/RhoTot | B19: 1.8802999 | C19: 1.7202962 | D19: 1.0930093 | E19: 0.28008086 | F19: -1.5824736 | G19: 5.3430733 | H19: -1.5824736 | I19: 5.3430733
A20: Rhoij/RhoOrig | B20: -8.2476715 | C20: 6.1687322 | D20: -1.3370124 | E20: 0.18779326 | F20: -20.664673 | G20: 4.1693305 | H20: -20.664673 | I20: 4.1693305
A21: Rhoij/RhoCordon | B21: -0.079971536 | C21: 0.11640163 | D21: -0.68703106 | E21: 0.49551241 | F21: -0.31427564 | G21: 0.15433257 | H21: -0.31427564 | I21: 0.15433257

Sheet Sheet4
A1: SUMMARY OUTPUT
A3: Regression Statistics
A4: Multiple R | B4: 0.24084791
A5: R Square | B5: 0.058007717
A6: Adjusted R Square | B6: 0.018758038
A7: Standard Error | B7: 0.072123461
A8: Observations | B8: 51
A10: ANOVA
B11: df | C11: SS | D11: MS | E11: F | F11: Significance F
A12: Regression | B12: 2 | C12: 0.015375625 | D12: 0.0076878126 | E12: 1.4779157 | F12: 0.23830672
A13: Residual | B13: 48 | C13: 0.2496861 | D13: 0.0052017936
A14: Total | B14: 50 | C14: 0.26506172
B16: Coefficients | C16: Standard Error | D16: t Stat | E16: P-value | F16: Lower 95% | G16: Upper 95% | H16: Lower 95.0% | I16: Upper 95.0%
A17: Intercept | B17: 0.043521119 | C17: 0.039021348 | D17: 1.1153156 | E17: 0.2702681 | F17: -0.034936515 | G17: 0.12197875 | H17: -0.034936515 | I17: 0.12197875
A18: Rhoij/RhoOrig | B18: 0.34174188 | C18: 0.20156589 | D18: 1.6954351 | E18: 0.096471265 | F18: -0.063533262 | G18: 0.74701703 | H18: -0.063533262 | I18: 0.74701703
A19: Rhoij/RhoCordon | B19: -0.033627674 | C19: 0.074387582 | D19: -0.45206032 | E19: 0.65326185 | F19: -0.18319384 | G19: 0.1159385 | H19: -0.18319384 | I19: 0.1159385

Sheet Sheet5
A1: SUMMARY OUTPUT
A3: Regression Statistics
A4: Multiple R | B4: 0.32529364
A5: R Square | B5: 0.10581595
A6: Adjusted R Square | B6: 0.068558285
A7: Standard Error | B7: 0.070269416
A8: Observations | B8: 51
A10: ANOVA
B11: df | C11: SS | D11: MS | E11: F | F11: Significance F
A12: Regression | B12: 2 | C12: 0.028047759 | D12: 0.014023879 | E12: 2.8401121 | F12: 0.068272532
A13: Residual | B13: 48 | C13: 0.23701396 | D13: 0.0049377909
A14: Total | B14: 50 | C14: 0.26506172
B16: Coefficients | C16: Standard Error | D16: t Stat | E16: P-value | F16: Lower 95% | G16: Upper 95% | H16: Lower 95.0% | I16: Upper 95.0%
A17: Intercept | B17: 0.019500436 | C17: 0.014410125 | D17: 1.3532455 | E17: 0.18231638 | F17: -0.0094730443 | G17: 0.048473917 | H17: -0.0094730443 | I17: 0.048473917
A18: Rhoij/RhoTot | B18: 1.2620023 | C18: 0.52988623 | D18: 2.3816477 | E18: 0.021248107 | F18: 0.1965953 | G18: 2.3274094 | H18: 0.1965953 | I18: 2.3274094
A19: Rhoji/RhoTot | B19: -0.16160579 | C19: 0.16852971 | D19: -0.95891571 | E19: 0.34240661 | F19: -0.50045729 | G19: 0.17724571 | H19: -0.50045729 | I19: 0.17724571

Sheet Sheet1
A1: x | B1: x | C1: NONWORKERS | D1: WORKERS | E1: RESIDENTS | F1: In-State | G1: Ri | H1: Ro | I1: JOBS | J1: WorkersWhoLiveInState | K1: Wi | L1: Wo | N1: Rhoii | O1: Rhoij | P1: Rhoji | R1: RhoTot | S1: RhoOrig | T1: RhoCordon | V1: Rhoii/RhoOrig | X1: Rhoii/RhoTot | Y1: Rhoij/RhoTot | Z1: Rhoji/RhoTot | AA1: Rhoij/RhoOrig | AB1: Rhoij/RhoCordon | AC1: Rhoji/RhoCordon | AE1: STATE | AF1: FULLNAME | AG1: TollShare
A2: alabama | B2: 4032992 | C2: 2299994 | D2: 1732238 | E2: 4032992 | F2: 0.96400148 | G2: 1669880 | H2: =D2-G2 -> 62358 | I2: 1710683 | J2: 0.97614812 | K2: =J2*I2 -> 1669880 | L2: =I2-K2 -> 40803 | N2: =G2 -> 1669880 | O2: =H2 -> 62358 | P2: =L2 -> 40803 | R2: =N2+0.5*(O2+P2) -> 1721460.5 | S2: =N2+0.5*O2 -> 1701059 | T2: =O2+P2 -> 103161 | V2: =Rhoii/RhoOrig -> 0.98167083 | X2: =Rhoii/RhoTot -> 0.97003678 | Y2: =0.5*Rhoij/RhoTot -> 0.018111946 | Z2: =0.5*Rhoji/RhoTot -> 0.011851274 | AA2: =Rhoij/RhoOrig -> 0.03665834 | AB2: =Rhoij/RhoCordon -> 0.60447262 | AC2: =Rhoji/RhoCordon -> 0.39552738 | AE2: AL | AF2: ALABAMA | AG2: 0
A3: alaska | B3: 550696 | C3: 286591 | D3: 263887 | E3: 550696 | F3: 0.99558523 | G3: 262722 | H3: =D3-G3 -> 1165 | I3: 270801 | J3: 0.97016628 | K3: =J3*I3 -> 262722 | L3: =I3-K3 -> 8079 | N3: =G3 -> 262722 | O3: =H3 -> 1165 | P3: =L3 -> 8079 | R3: =N3+0.5*(O3+P3) -> 267344 | S3: =N3+0.5*O3 -> 263304.5 | T3: =O3+P3 -> 9244 | V3: =Rhoii/RhoOrig -> 0.99778773 | X3: =Rhoii/RhoTot -> 0.98271141 | Y3: =0.5*Rhoij/RhoTot -> 0.0021788407 | Z3: =0.5*Rhoji/RhoTot -> 0.015109746 | AA3: =Rhoij/RhoOrig -> 0.0044245351 | AB3: =Rhoij/RhoCordon -> 0.12602769 | AC3: =Rhoji/RhoCordon -> 0.87397231 | AE3: AK | AF3: ALASKA | AG3: 0.12971993
A4: arizona | B4: 3652849 | C4: 2060434 | D4: 1591203 | E4: 3652849 | F4: 0.98419561 | G4: 1566055 | H4: =D4-G4 -> 25148 | I4: 1583805 | J4: 0.98879281 | K4: =J4*I4 -> 1566055 | L4: =I4-K4 -> 17750 | N4: =G4 -> 1566055 | O4: =H4 -> 25148 | P4: =L4 -> 17750 | R4: =N4+0.5*(O4+P4) -> 1587504 | S4: =N4+0.5*O4 -> 1578629 | T4: =O4+P4 -> 42898 | V4: =Rhoii/RhoOrig -> 0.99203486 | X4: =Rhoii/RhoTot -> 0.98648885 | Y4: =0.5*Rhoij/RhoTot -> 0.00792061 | Z4: =0.5*Rhoji/RhoTot -> 0.0055905371 | AA4: =Rhoij/RhoOrig -> 0.015930279 | AB4: =Rhoij/RhoCordon -> 0.5862278 | AC4: =Rhoji/RhoCordon -> 0.4137722 | AE4: AZ | AF4: ARIZONA | AG4: 0
A5: arkansas | B5: 2344205 | C5: 1355487 | D5: 988408 | E5: 2344205 | F5: 0.96770362 | G5: 956486 | H5: =D5-G5 -> 31922 | I5: 996645 | J5: 0.95970581 | K5: =J5*I5 -> 956486 | L5: =I5-K5 -> 40159 | N5: =G5 -> 956486 | O5: =H5 -> 31922 | P5: =L5 -> 40159 | R5: =N5+0.5*(O5+P5) -> 992526.5 | S5: =N5+0.5*O5 -> 972447 | T5: =O5+P5 -> 72081 | V5: =Rhoii/RhoOrig -> 0.98358677 | X5: =Rhoii/RhoTot -> 0.96368812 | Y5: =0.5*Rhoij/RhoTot -> 0.016081183 | Z5: =0.5*Rhoji/RhoTot -> 0.020230694 | AA5: =Rhoij/RhoOrig -> 0.032826468 | AB5: =Rhoij/RhoCordon -> 0.44286289 | AC5: =Rhoji/RhoCordon -> 0.55713711 | AE5: AR | AF5: ARKANSAS | AG5: 0
A6: califo~1 | B6: 29715727 | C6: 15806498 | D6: 13897185 | E6: 29715727 | F6: 0.99631019 | G6: 13845907 | H6: =D6-G6 -> 51278 | I6: 13908817 | J6: 0.99547697 | K6: =J6*I6 -> 13845907 | L6: =I6-K6 -> 62910 | N6: =G6 -> 13845907 | O6: =H6 -> 51278 | P6: =L6 -> 62910 | R6: =N6+0.5*(O6+P6) -> 13903001 | S6: =N6+0.5*O6 -> 13871546 | T6: =O6+P6 -> 114188 | V6: =Rhoii/RhoOrig -> 0.99815168 | X6: =Rhoii/RhoTot -> 0.9958934 | Y6: =0.5*Rhoij/RhoTot -> 0.0018441342 | Z6: =0.5*Rhoji/RhoTot -> 0.0022624612 | AA6: =Rhoij/RhoOrig -> 0.0036966319 | AB6: =Rhoij/RhoCordon -> 0.44906645 | AC6: =Rhoji/RhoCordon -> 0.55093355 | AE6: CA | AF6: CALIFORNIA | AG6: 0.021141521
A7: colorado | B7: 3282756 | C7: 1649976 | D7: 1631955 | E7: 3282756 | F7: 0.98974972 | G7: 1615227 | H7: =D7-G7 -> 16728 | I7: 1628162 | J7: 0.99205546 | K7: =J7*I7 -> 1615227 | L7: =I7-K7 -> 12935 | N7: =G7 -> 1615227 | O7: =H7 -> 16728 | P7: =L7 -> 12935 | R7: =N7+0.5*(O7+P7) -> 1630058.5 | S7: =N7+0.5*O7 -> 1623591 | T7: =O7+P7 -> 29663 | V7: =Rhoii/RhoOrig -> 0.99484846 | X7: =Rhoii/RhoTot -> 0.99090125 | Y7: =0.5*Rhoij/RhoTot -> 0.0051311042 | Z7: =0.5*Rhoji/RhoTot -> 0.003967649 | AA7: =Rhoij/RhoOrig -> 0.010303087 | AB7: =Rhoij/RhoCordon -> 0.56393487 | AC7: =Rhoji/RhoCordon -> 0.43606513 | AE7: CO | AF7: COLORADO | AG7: 0.0029577777
A8: connec~1 | B8: 3282130 | C8: 1609151 | D8: 1672230 | E8: 3282130 | F8: 0.95255497 | G8: 1592891 | H8: =D8-G8 -> 79339 | I8: 1669019 | J8: 0.95438758 | K8: =J8*I8 -> 1592891 | L8: =I8-K8 -> 76128 | N8: =G8 -> 1592891 | O8: =H8 -> 79339 | P8: =L8 -> 76128 | R8: =N8+0.5*(O8+P8) -> 1670624.5 | S8: =N8+0.5*O8 -> 1632560.5 | T8: =O8+P8 -> 155467 | V8: =Rhoii/RhoOrig -> 0.97570105 | X8: =Rhoii/RhoTot -> 0.95347039 | Y8: =0.5*Rhoij/RhoTot -> 0.023745312 | Z8: =0.5*Rhoji/RhoTot -> 0.022784294 | AA8: =Rhoij/RhoOrig -> 0.048597893 | AB8: =Rhoij/RhoCordon -> 0.51032695 | AC8: =Rhoji/RhoCordon -> 0.48967305 | AE8: CT | AF8: CONNECTICUT | AG8: 0.00025988579
A9: deleware | B9: 661667 | C9: 327531 | D9: 333913 | E9: 661667 | F9: 0.90495428 | G9: 302176 | H9: =D9-G9 -> 31737 | I9: 350686 | J9: 0.86167112 | K9: =J9*I9 -> 302176 | L9: =I9-K9 -> 48510 | N9: =G9 -> 302176 | O9: =H9 -> 31737 | P9: =L9 -> 48510 | R9: =N9+0.5*(O9+P9) -> 342299.5 | S9: =N9+0.5*O9 -> 318044.5 | T9: =O9+P9 -> 80247 | V9: =Rhoii/RhoOrig -> 0.95010604 | X9: =Rhoii/RhoTot -> 0.88278248 | Y9: =0.5*Rhoij/RhoTot -> 0.046358525 | Z9: =0.5*Rhoji/RhoTot -> 0.070858999 | AA9: =Rhoij/RhoOrig -> 0.099787923 | AB9: =Rhoij/RhoCordon -> 0.39549142 | AC9: =Rhoji/RhoCordon -> 0.60450858 | AE9: DE | AF9: DELAWARE | AG9: 0.25259005
A10: district-of-columbia | B10: 609866 | C10: 303582 | D10: 305807 | E10: 609866 | F10: 0.77442635 | G10: 236825 | H10: =D10-G10 -> 68982 | I10: 731599 | J10: 0.32370875 | K10: =J10*I10 -> 236825 | L10: =I10-K10 -> 494774 | N10: =G10 -> 236825 | O10: =H10 -> 68982 | P10: =L10 -> 494774 | R10: =N10+0.5*(O10+P10) -> 518703 | S10: =N10+0.5*O10 -> 271316 | T10: =O10+P10 -> 563756 | V10: =Rhoii/RhoOrig -> 0.87287517 | X10: =Rhoii/RhoTot -> 0.45657149 | Y10: =0.5*Rhoij/RhoTot -> 0.066494699 | Z10: =0.5*Rhoji/RhoTot -> 0.47693381 | AA10: =Rhoij/RhoOrig -> 0.25424966 | AB10: =Rhoij/RhoCordon -> 0.12236145 | AC10: =Rhoji/RhoCordon -> 0.87763855 | AE10: DC | AF10: district-of-columbia | AG10: 0
A11: florida | B11: 12922903 | C11: 7132347 | D11: 5786177 | E11: 12922903 | F11: 0.9900131 | G11: 5728391 | H11: =D11-G11 -> 57786 | I11: 5774554 | J11: 0.99200579 | K11: =J11*I11 -> 5728391 | L11: =I11-K11 -> 46163 | N11: =G11 -> 5728391 | O11: =H11 -> 57786 | P11: =L11 -> 46163 | R11: =N11+0.5*(O11+P11) -> 5780365.5 | S11: =N11+0.5*O11 -> 5757284 | T11: =O11+P11 -> 103949 | V11: =Rhoii/RhoOrig -> 0.99498149 | X11: =Rhoii/RhoTot -> 0.99100844 | Y11: =0.5*Rhoij/RhoTot -> 0.0049984728 | Z11: =0.5*Rhoji/RhoTot -> 0.0039930866 | AA11: =Rhoij/RhoOrig -> 0.010037024 | AB11: =Rhoij/RhoCordon -> 0.55590722 | AC11: =Rhoji/RhoCordon -> 0.44409278 | AE11: FL | AF11: FLORIDA | AG11: 0.077833555
A12: georgia | B12: 6466023 | C12: 3356359 | D12: 3108090 | E12: 6466023 | F12: 0.97610848 | G12: 3033833 | H12: =D12-G12 -> 74257 | I12: 3121670 | J12: 0.97186218 | K12: =J12*I12 -> 3033833 | L12: =I12-K12 -> 87837 | N12: =G12 -> 3033833 | O12: =H12 -> 74257 | P12: =L12 -> 87837 | R12: =N12+0.5*(O12+P12) -> 3114880 | S12: =N12+0.5*O12 -> 3070961.5 | T12: =O12+P12 -> 162094 | V12: =Rhoii/RhoOrig -> 0.98790981 | X12: =Rhoii/RhoTot -> 0.9739807 | Y12: =0.5*Rhoij/RhoTot -> 0.011919721 | Z12: =0.5*Rhoji/RhoTot -> 0.01409958 | AA12: =Rhoij/RhoOrig -> 0.024180375 | AB12: =Rhoij/RhoCordon -> 0.45811073 | AC12: =Rhoji/RhoCordon -> 0.54188927 | AE12: GA | AF12: GEORGIA | AG12: 0.0041858291
A13: hawaii | B13: 1104668 | C13: 540368 | D13: 562967 | E13: 1104668 | F13: 0.99532477 | G13: 560335 | H13: =D13-G13 -> 2632 | I13: 565723 | J13: 0.9904759 | K13: =J13*I13 -> 560335 | L13: =I13-K13 -> 5388 | N13: =G13 -> 560335 | O13: =H13 -> 2632 | P13: =L13 -> 5388 | R13: =N13+0.5*(O13+P13) -> 564345 | S13: =N13+0.5*O13 -> 561651 | T13: =O13+P13 -> 8020 | V13: =Rhoii/RhoOrig -> 0.99765691 | X13: =Rhoii/RhoTot -> 0.99289442 | Y13: =0.5*Rhoij/RhoTot -> 0.0023319069 | Z13: =0.5*Rhoji/RhoTot -> 0.0047736757 | AA13: =Rhoij/RhoOrig -> 0.0046861841 | AB13: =Rhoij/RhoCordon -> 0.32817955 | AC13: =Rhoji/RhoCordon -> 0.67182045 | AE13: HI | AF13: HAWAII | AG13: 0
... A52: wyoming | B52: 453189 | C52: 245624 | D52: 207473 | E52: 453189 | F52: 0.97993956 | G52: 203311 | H52: =D52-G52 -> 4162 | I52: 208657 | J52: 0.974379 | K52: =J52*I52 -> 203311 | L52: =I52-K52 -> 5346 | N52: =G52 -> 203311 | O52: =H52 -> 4162 | P52: =L52 -> 5346 | R52: =N52+0.5*(O52+P52) -> 208065 | S52: =N52+0.5*O52 -> 205392 | T52: =O52+P52 -> 9508 | V52: =Rhoii/RhoOrig -> 0.98986815 | X52: =Rhoii/RhoTot -> 0.97715137 | Y52: =0.5*Rhoij/RhoTot -> 0.010001682 | Z52: =0.5*Rhoji/RhoTot -> 0.012846947 | AA52: =Rhoij/RhoOrig -> 0.020263691 | AB52: =Rhoij/RhoCordon -> 0.43773664 | AC52: =Rhoji/RhoCordon -> 0.56226336 | AE52: WY | AF52: WYOMING | AG52: 0
A53: TOTAL | B53: 247919856 | C53: 133153993 | D53: 114700027 | E53: 247919856 | G53: =SUM(G2:G52) -> 110767228 | H53: =D53-G53 -> 3932799 | I53: 65836 | J53: 0.18293943 | K53: =J53*I53 -> 12044 | L53: =I53-K53 -> 53792 | N53: =G53 -> 110767228 | O53: =H53 -> 3932799 | P53: =L53 -> 53792 | R53: =N53+0.5*(O53+P53) -> 1.1276052e+08 | S53: =N53+0.5*O53 -> 1.1273363e+08 | T53: =O53+P53 -> 3986591 | V53: =Rhoii/RhoOrig -> 0.98255712 | X53: =Rhoii/RhoTot -> 0.98232275 | Y53: =0.5*Rhoij/RhoTot -> 0.017438723 | Z53: =0.5*Rhoji/RhoTot -> 0.00023852319 | AA53: =Rhoij/RhoOrig -> 0.034885766 | AB53: =Rhoij/RhoCordon -> 0.98650677 | AC53: =Rhoji/RhoCordon -> 0.013493233 | AE53: US | AG53: 0.062887408

Sheet Table
A1: x | B1: x | C1: NOTWORK | D1: WORK | E1: TOTAL | F1: alabama | G1: alaska | H1: arizona | I1: arkansas | J1: califo~1 | K1: colorado | L1: connec~1 | M1: deleware | N1: district-of-columbia | O1: florida | P1: georgia | Q1: hawaii | R1: idaho | S1: illinois | T1: indiana | U1: iowa | V1: kansas | W1: kentucky | X1: louisi~1 | Y1: maine | Z1: maryland | AA1: massac~1 | AB1: michigan | AC1: minnes~1 | AD1: missis~1 | AE1: missouri | AF1: montana | AG1: nebraska | AH1: nevada | AI1: new-ha~1 | AJ1: new-je~1 | AK1: new-me~1 | AL1: new-york | AM1: north-~1 | AN1: north-~2 | AO1: ohio | AP1: oklahoma | AQ1: oregon | AR1: pennsy~1 | AS1: rhode-~1 | AT1: south-~1 | AU1: south-~2 | AV1: tennes~1 | AW1: texas | AX1: utah | AY1: vermont | AZ1: virginia | BA1: washin~1 | BB1: west-v~1 | BC1: wiscon~1 | BD1: wyoming | BE1: 98 | BF1: In-State | BG1: In-StateTot'
A2: alabama | B2: 4032992 | C2: 2299994 | D2: =SUM(F2:BD2) -> 1732238 | E2: =C2+D2+BE2 -> 4032992 | F2: 1669880 | G2: 0 | H2: 118 | I2: 175 | J2: 758 | K2: 22 | L2: 13 | M2: 0 | N2: 267 | O2: 6311 | P2: 30252 | Q2: 0 | R2: 0 | S2: 361 | T2: 67 | U2: 0 | V2: 245 | W2: 228 | X2: 2135 | Y2: 19 | Z2: 98 | AA2: 42 | AB2: 279 | AC2: 172 | AD2: 9740 | AE2: 152 | AF2: 0 | AG2: 7 | AH2: 32 | AI2: 0 | AJ2: 203 | AK2: 32 | AL2: 348 | AM2: 689 | AN2: 32 | AO2: 252 | AP2: 118 | AQ2: 35 | AR2: 224 | AS2: 0 | AT2: 0 | AU2: 845 | AV2: 6337 | AW2: 999 | AX2: 0 | AY2: 0 | AZ2: 581 | BA2: 81 | BB2: 16 | BC2: 73 | BD2: 0 | BE2: 760 | BF2: =MAX(F2:BD2)/D2 -> 0.96400148 | BG2: =BF2*D2 -> 1669880
A3: alaska | B3: 550696 | C3: 286591 | D3: =SUM(F3:BD3) -> 263887 | E3: =C3+D3+BE3 -> 550696 | F3: 0 | G3: 262722 | H3: 60 | I3: 99 | J3: 122 | K3: 0 | L3: 0 | M3: 0 | N3: 0 | O3: 0 | P3: 23 | Q3: 61 | R3: 27 | S3: 11 | T3: 8 | U3: 0 | V3: 0 | W3: 7 | X3: 0 | Y3: 0 | Z3: 0 | AA3: 19 | AB3: 0 | AC3: 27 | AD3: 11 | AE3: 22 | AF3: 0 | AG3: 0 | AH3: 73 | AI3: 0 | AJ3: 0 | AK3: 0 | AL3: 30 | AM3: 8 | AN3: 0 | AO3: 15 | AP3: 23 | AQ3: 8 | AR3: 0 | AS3: 0 | AT3: 0 | AU3: 12 | AV3: 7 | AW3: 58 | AX3: 0 | AY3: 0 | AZ3: 8 | BA3: 426 | BB3: 0 | BC3: 0 | BD3: 0 | BE3: 218 | BF3: =MAX(F3:BD3)/D3 -> 0.99558523 | BG3: =BF3*D3 -> 262722
A4: arizona | B4: 3652849 | C4: 2060434 | D4: =SUM(F4:BD4) -> 1591203 | E4: =C4+D4+BE4 -> 3652849 | F4: 57 | G4: 111 | H4: 1566055 | I4: 31 | J4: 7529 | K4: 553 | L4: 44 | M4: 0 | N4: 137 | O4: 502 | P4: 257 | Q4: 46 | R4: 129 | S4: 659 | T4: 191 | U4: 79 | V4: 196 | W4: 73 | X4: 0 | Y4: 0 | Z4: 230 | AA4: 99 | AB4: 257 | AC4: 181 | AD4: 16 | AE4: 337 | AF4: 0 | AG4: 90 | AH4: 8186 | AI4: 0 | AJ4: 139 | AK4: 1555 | AL4: 343 | AM4: 106 | AN4: 69 | AO4: 308 | AP4: 85 | AQ4: 71 | AR4: 190 | AS4: 28 | AT4: 145 | AU4: 72 | AV4: 51 | AW4: 996 | AX4: 449 | AY4: 0 | AZ4: 104 | BA4: 121 | BB4: 8 | BC4: 137 | BD4: 181 | BE4: 1212 | BF4: =MAX(F4:BD4)/D4 -> 0.98419561 | BG4: =BF4*D4 -> 1566055
A5: arkansas | B5: 2344205 | C5: 1355487 | D5: =SUM(F5:BD5) -> 988408 | E5: =C5+D5+BE5 -> 2344205 | F5: 294 | G5: 107 | H5: 32 | I5: 956486 | J5: 354 | K5: 55 | L5: 0 | M5: 0 | N5: 28 | O5: 395 | P5: 260 | Q5: 0 | R5: 0 | S5: 312 | T5: 97 | U5: 51 | V5: 299 | W5: 78 | X5: 1574 | Y5: 0 | Z5: 90 | AA5: 0 | AB5: 97 | AC5: 71 | AD5: 1216 | AE5: 2997 | AF5: 7 | AG5: 72 | AH5: 29 | AI5: 0 | AJ5: 47 | AK5: 50 | AL5: 42 | AM5: 66 | AN5: 0 | AO5: 81 | AP5: 2973 | AQ5: 57 | AR5: 18 | AS5: 3 | AT5: 29 | AU5: 65 | AV5: 10671 | AW5: 9042 | AX5: 0 | AY5: 0 | AZ5: 191 | BA5: 22 | BB5: 0 | BC5: 50 | BD5: 0 | BE5: 310 | BF5: =MAX(F5:BD5)/D5 -> 0.96770362 | BG5: =BF5*D5 -> 956486
A6: califo~1 | B6: 29715727 | C6: 15806498 | D6: =SUM(F6:BD6) -> 13897185 | E6: =C6+D6+BE6 -> 29715727 | F6: 319 | G6: 650 | H6: 5099 | I6: 256 | J6: 13845907 | K6: 1431 | L6: 256 | M6: 73 | N6: 743 | O6: 2235 | P6: 1006 | Q6: 1725 | R6: 296 | S6: 1340 | T6: 453 | U6: 99 | V6: 177 | W6: 338 | X6: 486 | Y6: 83 | Z6: 600 | AA6: 879 | AB6: 823 | AC6: 408 | AD6: 130 | AE6: 760 | AF6: 116 | AG6: 283 | AH6: 11509 | AI6: 118 | AJ6: 886 | AK6: 426 | AL6: 3513 | AM6: 471 | AN6: 91 | AO6: 806 | AP6: 386 | AQ6: 2026 | AR6: 587 | AS6: 162 | AT6: 41 | AU6: 258 | AV6: 357 | AW6: 3540 | AX6: 1122 | AY6: 19 | AZ6: 1097 | BA6: 2464 | BB6: 84 | BC6: 139 | BD6: 112 | BE6: 12044 | BF6: =MAX(F6:BD6)/D6 -> 0.99631019 | BG6: =BF6*D6 -> 13845907
A7: colorado | B7: 3282756 | C7: 1649976 | D7: =SUM(F7:BD7) -> 1631955 | E7: =C7+D7+BE7 -> 3282756 | F7: 210 | G7: 312 | H7: 987 | I7: 81 | J7: 2244 | K7: 1615227 | L7: 21 | M7: 45 | N7: 39 | O7: 357 | P7: 168 | Q7: 129 | R7: 105 | S7: 849 | T7: 123 | U7: 207 | V7: 822 | W7: 138 | X7: 51 | Y7: 0 | Z7: 60 | AA7: 153 | AB7: 99 | AC7: 207 | AD7: 45 | AE7: 246 | AF7: 132 | AG7: 867 | AH7: 666 | AI7: 0 | AJ7: 348 | AK7: 1287 | AL7: 528 | AM7: 117 | AN7: 72 | AO7: 306 | AP7: 303 | AQ7: 120 | AR7: 114 | AS7: 0 | AT7: 57 | AU7: 27 | AV7: 150 | AW7: 1182 | AX7: 753 | AY7: 0 | AZ7: 297 | BA7: 342 | BB7: 6 | BC7: 174 | BD7: 1182 | BE7: 825 | BF7: =MAX(F7:BD7)/D7 -> 0.98974972 | BG7: =BF7*D7 -> 1615227
A8: connec~1 | B8: 3282130 | C8: 1609151 | D8: =SUM(F8:BD8) -> 1672230 | E8: =C8+D8+BE8 -> 3282130 | F8: 22 | G8: 0 | H8: 72 | I8: 86 | J8: 603 | K8: 123 | L8: 1592891 | M8: 33 | N8: 332 | O8: 663 | P8: 354 | Q8: 54 | R8: 0 | S8: 522 | T8: 95 | U8: 22 | V8: 0 | W8: 30 | X8: 72 | Y8: 89 | Z8: 501 | AA8: 11942 | AB8: 77 | AC8: 68 | AD8: 30 | AE8: 135 | AF8: 0 | AG8: 0 | AH8: 17 | AI8: 259 | AJ8: 3220 | AK8: 17 | AL8: 54519 | AM8: 181 | AN8: 0 | AO8: 179 | AP8: 11 | AQ8: 23 | AR8: 656 | AS8: 2945 | AT8: 0 | AU8: 72 | AV8: 102 | AW8: 463 | AX8: 0 | AY8: 173 | AZ8: 431 | BA8: 62 | BB8: 25 | BC8: 59 | BD8: 0 | BE8: 749 | BF8: =MAX(F8:BD8)/D8 -> 0.95255497 | BG8: =BF8*D8 -> 1592891
A9: deleware | B9: 661667 | C9: 327531 | D9: =SUM(F9:BD9) -> 333913 | E9: =C9+D9+BE9 -> 661667 | F9: 20 | G9: 0 | H9: 0 | I9: 0 | J9: 158 | K9: 0 | L9: 83 | M9: 302176 | N9: 265 | O9: 115 | P9: 58 | Q9: 0 | R9: 0 | S9: 108 | T9: 41 | U9: 0 | V9: 0 | W9: 0 | X9: 0 | Y9: 0 | Z9: 9755 | AA9: 36 | AB9: 64 | AC9: 0 | AD9: 0 | AE9: 19 | AF9: 0 | AG9: 22 | AH9: 0 | AI9: 0 | AJ9: 3524 | AK9: 0 | AL9: 440 | AM9: 32 | AN9: 0 | AO9: 57 | AP9: 19 | AQ9: 0 | AR9: 16449 | AS9: 0 | AT9: 0 | AU9: 64 | AV9: 0 | AW9: 35 | AX9: 0 | AY9: 16 | AZ9: 357 | BA9: 0 | BB9: 0 | BC9: 0 | BD9: 0 | BE9: 223 | BF9: =MAX(F9:BD9)/D9 -> 0.90495428 | BG9: =BF9*D9 -> 302176
A10: district-of-columbia | B10: 609866 | C10: 303582 | D10: =SUM(F10:BD10) -> 305807 | E10: =C10+D10+BE10 -> 609866 | F10: 17 | G10: 0 | H10: 0 | I10: 0 | J10: 202 | K10: 0 | L10: 9 | M10: 84 | N10: 236825 | O10: 22 | P10: 57 | Q10: 0 | R10: 0 | S10: 14 | T10: 67 | U10: 0 | V10: 36 | W10: 19 | X10: 15 | Y10: 36 | Z10: 37439 | AA10: 77 | AB10: 0 | AC10: 0 | AD10: 19 | AE10: 0 | AF10: 0 | AG10: 0 | AH10: 0 | AI10: 0 | AJ10: 46 | AK10: 0 | AL10: 505 | AM10: 156 | AN10: 0 | AO10: 82 | AP10: 0 | AQ10: 0 | AR10: 407 | AS10: 0 | AT10: 0 | AU10: 14 | AV10: 0 | AW10: 82 | AX10: 0 | AY10: 0 | AZ10: 29311 | BA10: 190 | BB10: 57 | BC10: 19 | BD10: 0 | BE10: 477 | BF10: =MAX(F10:BD10)/D10 -> 0.77442635 | BG10: =BF10*D10 -> 236825
A11: florida | B11: 12922903 | C11: 7132347 | D11: =SUM(F11:BD11) -> 5786177 | E11: =C11+D11+BE11 -> 12922903 | F11: 8557 | G11: 139 | H11: 243 | I11: 154 | J11: 2375 | K11: 727 | L11: 1139 | M11: 200 | N11: 415 | O11: 5728391 | P11: 9681 | Q11: 103 | R11: 0 | S11: 2142 | T11: 778 | U11: 187 | V11: 108 | W11: 656 | X11: 1785 | Y11: 226 | Z11: 1111 | AA11: 1441 | AB11: 1636 | AC11: 454 | AD11: 441 | AE11: 427 | AF11: 17 | AG11: 10 | AH11: 227 | AI11: 203 | AJ11: 2010 | AK11: 119 | AL11: 5596 | AM11: 2052 | AN11: 22 | AO11: 1283 | AP11: 310 | AQ11: 77 | AR11: 1785 | AS11: 215 | AT11: 0 | AU11: 1848 | AV11: 1115 | AW11: 2467 | AX11: 75 | AY11: 24 | AZ11: 2216 | BA11: 219 | BB11: 315 | BC11: 456 | BD11: 0 | BE11: 4379 | BF11: =MAX(F11:BD11)/D11 -> 0.9900131 | BG11: =BF11*D11 -> 5728391
A12: georgia | B12: 6466023 | C12: 3356359 | D12: =SUM(F12:BD12) -> 3108090 | E12: =C12+D12+BE12 -> 6466023 | F12: 8322 | G12: 45 | H12: 101 | I12: 124 | J12: 1594 | K12: 363 | L12: 70 | M12: 0 | N12: 328 | O12: 8332 | P12: 3033833 | Q12: 39 | R12: 28 | S12: 628 | T12: 204 | U12: 89 | V12: 156 | W12: 407 | X12: 435 | Y12: 67 | Z12: 659 | AA12: 230 | AB12: 443 | AC12: 188 | AD12: 444 | AE12: 355 | AF12: 0 | AG12: 92 | AH12: 42 | AI12: 90 | AJ12: 440 | AK12: 0 | AL12: 1071 | AM12: 2958 | AN12: 0 | AO12: 663 | AP12: 149 | AQ12: 36 | AR12: 489 | AS12: 31 | AT12: 58 | AU12: 17853 | AV12: 23865 | AW12: 1206 | AX12: 81 | AY12: 14 | AZ12: 1090 | BA12: 106 | BB12: 63 | BC12: 209 | BD12: 0 | BE12: 1574 | BF12: =MAX(F12:BD12)/D12 -> 0.97610848 | BG12: =BF12*D12 -> 3033833
A13: hawaii | B13: 1104668 | C13: 540368 | D13: =SUM(F13:BD13) -> 562967 | E13: =C13+D13+BE13 -> 1104668 | F13: 59 | G13: 25 | H13: 142 | I13: 0 | J13: 1464 | K13: 25 | L13: 0 | M13: 0 | N13: 50 | O13: 23 | P13: 100 | Q13: 560335 | R13: 0 | S13: 62 | T13: 34 | U13: 0 | V13: 0 | W13: 0 | X13: 25 | Y13: 0 | Z13: 17 | AA13: 17 | AB13: 36 | AC13: 0 | AD13: 31 | AE13: 31 | AF13: 8 | AG13: 0 | AH13: 47 | AI13: 0 | AJ13: 84 | AK13: 0 | AL13: 44 | AM13: 34 | AN13: 0 | AO13: 33 | AP13: 8 | AQ13: 22 | AR13: 0 | AS13: 16 | AT13: 0 | AU13: 0 | AV13: 0 | AW13: 70 | AX13: 0 | AY13: 0 | AZ13: 42 | BA13: 83 | BB13: 0 | BC13: 0 | BD13: 0 | BE13: 1333 | BF13: =MAX(F13:BD13)/D13 -> 0.99532477 | BG13: =BF13*D13 -> 560335
... A52: wyoming | B52: 453189 | C52: 245624 | D52: =SUM(F52:BD52) -> 207473 | E52: =C52+D52+BE52 -> 453189 | F52: 0 | G52: 59 | H52: 18 | I52: 0 | J52: 184 | K52: 806 | L52: 0 | M52: 0 | N52: 0 | O52: 54 | P52: 39 | Q52: 0 | R52: 258 | S52: 127 | T52: 0 | U52: 46 | V52: 0 | W52: 0 | X52: 0 | Y52: 29 | Z52: 0 | AA52: 0 | AB52: 0 | AC52: 7 | AD52: 0 | AE52: 61 | AF52: 807 | AG52: 561 | AH52: 146 | AI52: 7 | AJ52: 0 | AK52: 46 | AL52: 22 | AM52: 8 | AN52: 134 | AO52: 7 | AP52: 39 | AQ52: 39 | AR52: 0 | AS52: 0 | AT52: 194 | AU52: 0 | AV52: 0 | AW52: 122 | AX52: 273 | AY52: 0 | AZ52: 0 | BA52: 40 | BB52: 18 | BC52: 11 | BD52: 203311 | BE52: 92 | BF52: =MAX(F52:BD52)/D52 -> 0.97993956 | BG52: =BF52*D52 -> 203311
A53: TOTAL | B53: =SUM(B2:B52) -> 247919856 | C53: =SUM(C2:C52) -> 133153993 | D53: =SUM(D2:D52) -> 114700027 | E53: =SUM(E2:E52) -> 247919856 | F53: =SUM(F2:F52) -> 1710683 | G53: =SUM(G2:G52) -> 270801 | H53: =SUM(H2:H52) -> 1583805 | I53: =SUM(I2:I52) -> 996645 | ... BE53: =SUM(BE2:BE52) -> 65836
