Workbook

Sheet Select (2)
A2: STATE | B2: TollShare (S) | C2: Workers Who Live Out of State (O) | D2: Percent Federal Land | E2: TollShare in Neighboring States | F2: Residents Who Work Out of State | G2: TollMile1963 | H2: Freeways, Expwy, Interstates 1995 Miles
A3: ALABAMA | B3: 0 | C3: 0.023851877 | D3: 0.03281 | E3: 0.016641465 | F3: 0.035998518 | G3: 0 | H3: 925
A4: ARIZONA | B4: 0 | C4: 0.011207188 | D4: 0.41534 | E4: 0.021735556 | F4: 0.015804395 | G4: 0 | H4: 1250
A5: ARKANSAS | B5: 0 | C5: 0.040294187 | D5: 0.08266 | E5: 0.020268432 | F5: 0.03229638 | G5: 0 | H5: 646
A6: CALIFORNIA | B6: 0.021141521 | C6: 0.0045230302 | D6: 0.44598 | E6: 0.046286746 | F6: 0.003689812 | G6: 0 | H6: 3750
A7: COLORADO | B7: 0.0029577777 | C7: 0.0079445411 | D7: 0.35954 | E7: 0.038557176 | F7: 0.010250283 | G7: 17.3 | H7: 1170
A8: CONNECTICUT | B8: 0.00025988579 | C8: 0.045612423 | D8: 0.00238 | E8: 0.26023043 | F8: 0.047445028 | G8: 193.9 | H8: 542
A9: DELAWARE | B9: 0.25259005 | C9: 0.13832888 | D9: 0.02219 | E9: 0.11872671 | F9: 0.095045716 | G9: 11.2 | H9: 51
A10: FLORIDA | B10: 0.077833555 | C10: 0.0079942105 | D10: 0.07562 | E10: 0.062671969 | F10: 0.009986905 | G10: 206.6 | H10: 1861
A11: GEORGIA | B11: 0.0041858291 | C11: 0.028137824 | D11: 0.03892 | E11: 0.02061609 | F11: 0.023891522 | G11: 11.1 | H11: 1413
A12: HAWAII | B12: 0 | C12: 0.0095240957 | D12: 0.08548 | E12: 0.035368224 | F12: 0.0046752296 | G12: 0 | H12: 77
A13: IDAHO | B13: 0 | C13: 0.026148588 | D13: 0.60588 | E13: 0.025523251 | F13: 0.039782418 | G13: 0 | H13: 613
A14: ILLINOIS | B14: 0.092502027 | C14: 0.028193774 | D14: 0.01266 | E14: 0.013967169 | F14: 0.02868334 | G14: 185.3 | H14: 2245
... A51: WYOMING | B51: 0 | C51: 0.025620995 | D51: 0.48452 | E51: 0.011513892 | F51: 0.020060442 | G51: 0 | H51: 916

Sheet LAND_ALL
A1: SUMMARY OUTPUT = TOLL SHARE
A3: Regression Statistics
A4: Multiple R | B4: 0.30177658
A5: R Square | B5: 0.091069107
A6: Adjusted R Square | B6: 0.072133046
A7: Standard Error | B7: 0.069811443
A8: Observations | B8: 50
A10: ANOVA
B11: df | C11: SS | D11: MS | E11: F | F11: Significance F
A12: Regression | B12: 1 | C12: 0.023438763 | D12: 0.023438763 | E12: 4.8092953 | F12: 0.033184676
A13: Residual | B13: 48 | C13: 0.23393461 | D13: 0.0048736376
A14: Total | B14: 49 | C14: 0.25737337
B16: Coefficients | C16: Standard Error | D16: t Stat | E16: P-value | F16: Lower 95% | G16: Upper 95% | H16: Lower 95.0% | I16: Upper 95.0%
A17: Intercept | B17: 0.068596656 | C17: 0.015935773 | D17: 4.3045704 | E17: 8.2014384e-05 | F17: 0.036555656 | G17: 0.10063766 | H17: 0.036555656 | I17: 0.10063766
A18: Land | B18: -4.6245325e-07 | C18: 2.1087598e-07 | D18: -2.1930106 | E18: 0.033184676 | F18: -8.8644757e-07 | G18: -3.8458925e-08 | H18: -8.8644757e-07 | I18: -3.8458925e-08
A20: note; Excluding Alaska

Sheet LAND_TOLLSTATES
A1: SUMMARY OUTPUT = TOLLSHARE
A3: Regression Statistics
A4: Multiple R | B4: 0.32039386
A5: R Square | B5: 0.10265222
A6: Adjusted R Square | B6: 0.074610105
A7: Standard Error | B7: 0.07809766
A8: Observations | B8: 34
A10: ANOVA
B11: df | C11: SS | D11: MS | E11: F | F11: Significance F
A12: Regression | B12: 1 | C12: 0.022327165 | D12: 0.022327165 | E12: 3.6606444 | F12: 0.064694973
A13: Residual | B13: 32 | C13: 0.19517582 | D13: 0.0060992445
A14: Total | B14: 33 | C14: 0.21750299
B16: Coefficients | C16: Standard Error | D16: t Stat | E16: P-value | F16: Lower 95% | G16: Upper 95% | H16: Lower 95.0% | I16: Upper 95.0%
A17: Intercept | B17: 0.089767616 | C17: 0.020318011 | D17: 4.4181301 | E17: 0.0001067953 | F17: 0.048381217 | G17: 0.13115401 | H17: 0.048381217 | I17: 0.13115401
A18: Land | B18: -5.2988934e-07 | C18: 2.7695321e-07 | D18: -1.9132811 | E18: 0.064694973 | F18: -1.0940241e-06 | G18: 3.4245419e-08 | H18: -1.0940241e-06 | I18: 3.4245419e-08

Sheet LANDPOP_TOLL STATES
A1: SUMMARY OUTPUT = TOLLSHARE
A3: Regression Statistics
A4: Multiple R | B4: 0.52576629
A5: R Square | B5: 0.27643019
A6: Adjusted R Square | B6: 0.22474663
A7: Standard Error | B7: 0.072871138
A8: Observations | B8: 31
A10: ANOVA
B11: df | C11: SS | D11: MS | E11: F | F11: Significance F
A12: Regression | B12: 2 | C12: 0.056803379 | D12: 0.02840169 | E12: 5.3485132 | F12: 0.010782665
A13: Residual | B13: 28 | C13: 0.14868568 | D13: 0.0053102028
A14: Total | B14: 30 | C14: 0.20548906
B16: Coefficients | C16: Standard Error | D16: t Stat | E16: P-value | F16: Lower 95% | G16: Upper 95% | H16: Lower 95.0% | I16: Upper 95.0%
A17: Intercept | B17: 0.084518127 | C17: 0.021197003 | D17: 3.9872678 | E17: 0.00043479502 | F17: 0.041097987 | G17: 0.12793827 | H17: 0.041097987 | I17: 0.12793827
A18: Land | B18: -9.8951041e-07 | C18: 3.1070623e-07 | D18: -3.1847138 | E18: 0.0035393176 | F18: -1.625964e-06 | G18: -3.5305684e-07 | H18: -1.625964e-06 | I18: -3.5305684e-07
A19: Population | B19: 5.5009846e-09 | C19: 2.3677663e-09 | D19: 2.3232802 | E19: 0.027649236 | F19: 6.5082967e-10 | G19: 1.035114e-08 | H19: 6.5082967e-10 | I19: 1.035114e-08

Sheet NOTLOG-NOTLOG
A1: SUMMARY OUTPUT = TOLLSHARE
A3: Regression Statistics
A4: Multiple R | B4: 0.52524528
A5: R Square | B5: 0.27588261
A6: Adjusted R Square | B6: 0.22865756
A7: Standard Error | B7: 0.063651315
A8: Observations | B8: 50
A10: ANOVA
B11: df | C11: SS | D11: MS | E11: F | F11: Significance F
A12: Regression | B12: 3 | C12: 0.071004836 | D12: 0.023668279 | E12: 5.8418704 | F12: 0.0018128071
A13: Residual | B13: 46 | C13: 0.18636853 | D13: 0.0040514899
A14: Total | B14: 49 | C14: 0.25737337
B16: Coefficients | C16: Standard Error | D16: t Stat | E16: P-value | F16: Lower 95% | G16: Upper 95% | H16: Lower 95.0% | I16: Upper 95.0%
A17: Intercept | B17: 0.060379361 | C17: 0.016619183 | D17: 3.6331125 | E17: 0.00070284463 | F17: 0.026926713 | G17: 0.093832009 | H17: 0.026926713 | I17: 0.093832009
A18: Land | B18: -5.5036323e-07 | C18: 2.7299915e-07 | D18: -2.0159888 | E18: 0.049663348 | F18: -1.0998815e-06 | G18: -8.4496983e-10 | H18: -1.0998815e-06 | I18: -8.4496983e-10
A19: Population | B19: 6.8127914e-09 | C19: 2.1458802e-09 | D19: 3.1748237 | E19: 0.0026747285 | F19: 2.4933626e-09 | G19: 1.113222e-08 | H19: 2.4933626e-09 | I19: 1.113222e-08
A20: (Miles ) | B20: -2.8583114e-07 | C20: 3.1061193e-07 | D20: -0.92021945 | E20: 0.36225889 | F20: -9.1105993e-07 | G20: 3.3939765e-07 | H20: -9.1105993e-07 | I20: 3.3939765e-07

Sheet LOG-LOG
A1: SUMMARY OUTPUT = LOG(TOLLSHARE+1)
A3: Regression Statistics
A4: Multiple R | B4: 0.43702648
A5: R Square | B5: 0.19099214
A6: Adjusted R Square | B6: 0.13823076
A7: Standard Error | B7: 0.05989135
A8: Observations | B8: 50
A10: ANOVA
B11: df | C11: SS | D11: MS | E11: F | F11: Significance F
A12: Regression | B12: 3 | C12: 0.038953708 | D12: 0.012984569 | E12: 3.6199231 | F12: 0.019860649
A13: Residual | B13: 46 | C13: 0.1650008 | D13: 0.0035869738
A14: Total | B14: 49 | C14: 0.2039545
B16: Coefficients | C16: Standard Error | D16: t Stat | E16: P-value | F16: Lower 95% | G16: Upper 95% | H16: Lower 95.0% | I16: Upper 95.0%
A17: Intercept | B17: -0.13536874 | C17: 0.12818269 | D17: -1.056061 | E17: 0.29645534 | F17: -0.39338688 | G17: 0.12264939 | H17: -0.39338688 | I17: 0.12264939
A18: Log(Land) | B18: -0.010065957 | C18: 0.014199601 | D18: -0.70889014 | E18: 0.48197008 | F18: -0.038648243 | G18: 0.018516329 | H18: -0.038648243 | I18: 0.018516329
A19: Log(Pop) | B19: 0.028572082 | C19: 0.012859039 | D19: 2.2219454 | E19: 0.031246069 | F19: 0.0026882042 | G19: 0.054455959 | H19: 0.0026882042 | I19: 0.054455959
A20: Log(Miles) | B20: -0.013657511 | C20: 0.024184801 | D20: -0.56471462 | E20: 0.57501158 | F20: -0.062338945 | G20: 0.035023923 | H20: -0.062338945 | I20: 0.035023923

Sheet LOG-NOTLOG
A1: SUMMARY OUTPUT = LOG(TOLLSHARE+1)
A3: Regression Statistics
A4: Multiple R | B4: 0.53002648
A5: R Square | B5: 0.28092807
A6: Adjusted R Square | B6: 0.23403207
A7: Standard Error | B7: 0.056464294
A8: Observations | B8: 50
A10: ANOVA
B11: df | C11: SS | D11: MS | E11: F | F11: Significance F
A12: Regression | B12: 3 | C12: 0.057296545 | D12: 0.019098848 | E12: 5.990449 | F12: 0.0015557225
A13: Residual | B13: 46 | C13: 0.14665796 | D13: 0.0031882165
A14: Total | B14: 49 | C14: 0.2039545
B16: Coefficients | C16: Standard Error | D16: t Stat | E16: P-value | F16: Lower 95% | G16: Upper 95% | H16: Lower 95.0% | I16: Upper 95.0%
A17: Intercept | B17: 0.055374647 | C17: 0.014742671 | D17: 3.7560796 | E17: 0.00048430801 | F17: 0.025699217 | G17: 0.085050077 | H17: 0.025699217 | I17: 0.085050077
A18: Land | B18: -5.0618435e-07 | C18: 2.4217417e-07 | D18: -2.0901666 | E18: 0.042158531 | F18: -9.9365521e-07 | G18: -1.87135e-08 | H18: -9.9365521e-07 | I18: -1.87135e-08
A19: Population | B19: 6.0565939e-09 | C19: 1.9035838e-09 | D19: 3.1816797 | E19: 0.0026234891 | F19: 2.2248821e-09 | G19: 9.8883058e-09 | H19: 2.2248821e-09 | I19: 9.8883058e-09
A20: (Miles ) | B20: -2.4248485e-07 | C20: 2.7554e-07 | D20: -0.88003502 | E20: 0.38341494 | F20: -7.9711758e-07 | G20: 3.1214788e-07 | H20: -7.9711758e-07 | I20: 3.1214788e-07

Sheet NOTLOG-LOG
A1: SUMMARY OUTPUT = TOLLSHARE
A3: Regression Statistics
A4: Multiple R | B4: 0.43070297
A5: R Square | B5: 0.18550505
A6: Adjusted R Square | B6: 0.13238581
A7: Standard Error | B7: 0.067506732
A8: Observations | B8: 50
A10: ANOVA
B11: df | C11: SS | D11: MS | E11: F | F11: Significance F
A12: Regression | B12: 3 | C12: 0.04774406 | D12: 0.015914687 | E12: 3.4922387 | F12: 0.022925023
A13: Residual | B13: 46 | C13: 0.20962931 | D13: 0.0045571589
A14: Total | B14: 49 | C14: 0.25737337
B16: Coefficients | C16: Standard Error | D16: t Stat | E16: P-value | F16: Lower 95% | G16: Upper 95% | H16: Lower 95.0% | I16: Upper 95.0%
A17: Intercept | B17: -0.14970517 | C17: 0.14448154 | D17: -1.0361543 | E17: 0.30554661 | F17: -0.44053116 | G17: 0.14112082 | H17: -0.44053116 | I17: 0.14112082
A18: Log(Land) | B18: -0.011001857 | C18: 0.016005127 | D18: -0.68739581 | E18: 0.49528472 | F18: -0.043218475 | G18: 0.021214761 | H18: -0.043218475 | I18: 0.021214761
A19: Log(Pop) | B19: 0.031678732 | C19: 0.014494108 | D19: 2.1856283 | E19: 0.033971306 | F19: 0.0025036342 | G19: 0.06085383 | H19: 0.0025036342 | I19: 0.06085383
A20: Log(Miles) | B20: -0.015437662 | C20: 0.027259978 | D20: -0.56631234 | E20: 0.57393419 | F20: -0.0703091 | G20: 0.039433776 | H20: -0.0703091 | I20: 0.039433776

Sheet LOG-NL=f(L,P,O)
A1: SUMMARY OUTPUT=LOG(TOLLSHARE)
A3: Regression Statistics
A4: Multiple R | B4: 0.57832753
A5: R Square | B5: 0.33446273
A6: Adjusted R Square | B6: 0.29009358
A7: Standard Error | B7: 0.054721227
A8: Observations | B8: 49
A10: ANOVA
B11: df | C11: SS | D11: MS | E11: F | F11: Significance F
A12: Regression | B12: 3 | C12: 0.067717281 | D12: 0.022572427 | E12: 7.5381818 | F12: 0.00034402839
A13: Residual | B13: 45 | C13: 0.13474857 | D13: 0.0029944126
A14: Total | B14: 48 | C14: 0.20246585
B16: Coefficients | C16: Standard Error | D16: t Stat | E16: P-value | F16: Lower 95% | G16: Upper 95% | H16: Lower 95.0% | I16: Upper 95.0%
A17: Intercept | B17: -0.037036339 | C17: 0.048108705 | D17: -0.76984693 | E17: 0.44541332 | F17: -0.13393224 | G17: 0.059859563 | H17: -0.13393224 | I17: 0.059859563
A18: Land | B18: -3.9473742e-07 | C18: 2.2906913e-07 | D18: -1.723224 | E18: 0.091713944 | F18: -8.5610631e-07 | G18: 6.6631465e-08 | H18: -8.5610631e-07 | I18: 6.6631465e-08
A19: Population | B19: 5.5368747e-09 | C19: 1.4927896e-09 | D19: 3.7090792 | E19: 0.00056917187 | F19: 2.5302423e-09 | G19: 8.5435071e-09 | H19: 2.5302423e-09 | I19: 8.5435071e-09
A20: Out of State Visitors | B20: 0.11494298 | C20: 0.058845997 | D20: 1.9532846 | E20: 0.057020591 | F20: -0.0035789366 | G20: 0.2334649 | H20: -0.0035789366 | I20: 0.2334649

Sheet LOG-NL=f(L,P,O,O')
A1: SUMMARY OUTPUT DEP=LOG(TOLLSHARE)
A3: Regression Statistics
A4: Multiple R | B4: 0.58777682
A5: R Square | B5: 0.34548159
A6: Adjusted R Square | B6: 0.28597992
A7: Standard Error | B7: 0.054879543
A8: Observations | B8: 49
A10: ANOVA
B11: df | C11: SS | D11: MS | E11: F | F11: Significance F
A12: Regression | B12: 4 | C12: 0.069948225 | D12: 0.017487056 | E12: 5.8062501 | F12: 0.00076702496
A13: Residual | B13: 44 | C13: 0.13251763 | D13: 0.0030117642
A14: Total | B14: 48 | C14: 0.20246585
B16: Coefficients | C16: Standard Error | D16: t Stat | E16: P-value | F16: Lower 95% | G16: Upper 95% | H16: Lower 95.0% | I16: Upper 95.0%
A17: Intercept | B17: -0.048123306 | C17: 0.049937976 | D17: -0.96366151 | E17: 0.34048224 | F17: -0.14876668 | G17: 0.052520069 | H17: -0.14876668 | I17: 0.052520069
A18: Land | B18: -3.618394e-07 | C18: 2.328901e-07 | D18: -1.5536917 | E18: 0.12742211 | F18: -8.3119854e-07 | G18: 1.0751973e-07 | H18: -8.3119854e-07 | I18: 1.0751973e-07
A19: Population | B19: 5.3266576e-09 | C19: 1.516902e-09 | D19: 3.5115371 | E19: 0.0010427503 | F19: 2.2695427e-09 | G19: 8.3837725e-09 | H19: 2.2695427e-09 | I19: 8.3837725e-09
A20: Out of State Visitors | B20: 0.043732698 | C20: 0.1016298 | D20: 0.43031374 | E20: 0.66906788 | F20: -0.16108869 | G20: 0.24855409 | H20: -0.16108869 | I20: 0.24855409
A21: Residents Out-of-State Trips | B21: 0.08954556 | C21: 0.10404237 | D21: 0.86066439 | E21: 0.39408866 | F21: -0.12013804 | G21: 0.29922916 | H21: -0.12013804 | I21: 0.29922916

Sheet NL-NL=f(L,P,O,J)
A1: SUMMARY OUTPUT DEP=(TOLLSHARE)
A3: Regression Statistics
A4: Multiple R | B4: 0.61208541
A5: R Square | B5: 0.37464854
A6: Adjusted R Square | B6: 0.31779841
A7: Standard Error | B7: 0.060277301
A8: Observations | B8: 49
A10: ANOVA
B11: df | C11: SS | D11: MS | E11: F | F11: Significance F
A12: Regression | B12: 4 | C12: 0.095776764 | D12: 0.023944191 | E12: 6.5901086 | F12: 0.00030235015
A13: Residual | B13: 44 | C13: 0.15986753 | D13: 0.003633353
A14: Total | B14: 48 | C14: 0.2556443
B16: Coefficients | C16: Standard Error | D16: t Stat | E16: P-value | F16: Lower 95% | G16: Upper 95% | H16: Lower 95.0% | I16: Upper 95.0%
A17: Intercept | B17: -0.051365023 | C17: 0.053171063 | D17: -0.96603341 | E17: 0.3393074 | F17: -0.15852425 | G17: 0.055794209 | H17: -0.15852425 | I17: 0.055794209
A18: Land | B18: -3.0042324e-07 | C18: 2.6253547e-07 | D18: -1.1443149 | E18: 0.25868016 | F18: -8.2952869e-07 | G18: 2.2868221e-07 | H18: -8.2952869e-07 | I18: 2.2868221e-07
A19: Population | B19: 6.1151379e-09 | C19: 1.6446592e-09 | D19: 3.7181793 | E19: 0.00056455578 | F19: 2.8005452e-09 | G19: 9.4297307e-09 | H19: 2.8005452e-09 | I19: 9.4297307e-09
A20: Out of State Visitors | B20: 0.092976745 | C20: 0.06767362 | D20: 1.3738994 | E20: 0.17643211 | F20: -0.04341047 | G20: 0.22936396 | H20: -0.04341047 | I20: 0.22936396
A21: JTW-OOSRATIO | B21: 0.51157019 | C21: 0.27945719 | D21: 1.8305851 | E21: 0.073940601 | F21: -0.051638758 | G21: 1.0747791 | H21: -0.051638758 | I21: 1.0747791

Sheet LOG-NL=f(L,P,O,J)
A1: SUMMARY OUTPUT DEP=LOG(TOLLSHARE)
A3: Regression Statistics
A4: Multiple R | B4: 0.62304808
A5: R Square | B5: 0.38818891
A6: Adjusted R Square | B6: 0.33256972
A7: Standard Error | B7: 0.053058898
A8: Observations | B8: 49
A10: ANOVA
B11: df | C11: SS | D11: MS | E11: F | F11: Significance F
A12: Regression | B12: 4 | C12: 0.078594997 | D12: 0.019648749 | E12: 6.9794059 | F12: 0.00019281336
A13: Residual | B13: 44 | C13: 0.12387085 | D13: 0.0028152467
A14: Total | B14: 48 | C14: 0.20246585
B16: Coefficients | C16: Standard Error | D16: t Stat | E16: P-value | F16: Lower 95% | G16: Upper 95% | H16: Lower 95.0% | I16: Upper 95.0%
A17: Intercept | B17: -0.044551253 | C17: 0.046803655 | D17: -0.95187552 | E17: 0.34636001 | F17: -0.13887782 | G17: 0.049775312 | H17: -0.13887782 | I17: 0.049775312
A18: Land | B18: -2.6929885e-07 | C18: 2.3109599e-07 | D18: -1.1653116 | E18: 0.25017153 | F18: -7.3504219e-07 | G18: 1.964445e-07 | H18: -7.3504219e-07 | I18: 1.964445e-07
A19: Population | B19: 5.4824786e-09 | C19: 1.4477059e-09 | D19: 3.7870112 | E19: 0.00045870171 | F19: 2.5648191e-09 | G19: 8.4001381e-09 | H19: 2.5648191e-09 | I19: 8.4001381e-09
A20: Out of State Visitors | B20: 0.081303803 | C20: 0.059569484 | D20: 1.3648566 | E20: 0.17923728 | F20: -0.038750599 | G20: 0.2013582 | H20: -0.038750599 | I20: 0.2013582
A21: JTW-OOSRATIO | B21: 0.48353771 | C21: 0.24599128 | D21: 1.9656701 | E21: 0.055667483 | F21: -0.01222513 | G21: 0.97930055 | H21: -0.01222513 | I21: 0.97930055

Sheet LOG-NL=f(P,O,J)
A1: SUMMARY OUTPUT DEP=LOG(TOLLSHARE)
A3: Regression Statistics
A4: Multiple R | B4: 0.60770624
A5: R Square | B5: 0.36930687
A6: Adjusted R Square | B6: 0.32726066
A7: Standard Error | B7: 0.053269508
A8: Observations | B8: 49
A10: ANOVA
B11: df | C11: SS | D11: MS | E11: F | F11: Significance F
A12: Regression | B12: 3 | C12: 0.074772029 | D12: 0.02492401 | E12: 8.7833572 | F12: 0.00010722492
A13: Residual | B13: 45 | C13: 0.12769382 | D13: 0.0028376405
A14: Total | B14: 48 | C14: 0.20246585
B16: Coefficients | C16: Standard Error | D16: t Stat | E16: P-value | F16: Lower 95% | G16: Upper 95% | H16: Lower 95.0% | I16: Upper 95.0%
A17: Intercept | B17: -0.083768024 | C17: 0.032656433 | D17: -2.5651309 | E17: 0.013718193 | F17: -0.14954145 | G17: -0.017994595 | H17: -0.14954145 | I17: -0.017994595
A18: Population | B18: 5.231133e-09 | C18: 1.4372306e-09 | D18: 3.6397312 | E18: 0.0007011007 | F18: 2.3364021e-09 | G18: 8.1258639e-09 | H18: 2.3364021e-09 | I18: 8.1258639e-09
A19: Out of State Visitors | B19: 0.11537827 | C19: 0.052105024 | D19: 2.2143406 | E19: 0.031913523 | F19: 0.010433367 | G19: 0.22032317 | H19: 0.010433367 | I19: 0.22032317
A20: JTW-OOSRATIO | B20: 0.56269481 | C20: 0.23736503 | D20: 2.3705885 | E20: 0.022103944 | F20: 0.084617125 | G20: 1.0407725 | H20: 0.084617125 | I20: 1.0407725

Sheet LAND=f(P,O,J)
A1: SUMMARY OUTPUT | C1: DEP=LAND
A3: Regression Statistics
A4: Multiple R | B4: 0.70905336
A5: R Square | B5: 0.50275667
A6: Adjusted R Square | B6: 0.46960711
A7: Standard Error | B7: 34226.269
A8: Observations | B8: 49
A10: ANOVA
B11: df | C11: SS | D11: MS | E11: F | F11: Significance F
A12: Regression | B12: 3 | C12: 5.3299177e+10 | D12: 1.7766392e+10 | E12: 15.166317 | F12: 5.8618249e-07
A13: Residual | B13: 45 | C13: 5.2714687e+10 | D13: 1.1714375e+09
A14: Total | B14: 48 | C14: 1.0601386e+11
B16: Coefficients | C16: Standard Error | D16: t Stat | E16: P-value | F16: Lower 95% | G16: Upper 95% | H16: Lower 95.0% | I16: Upper 95.0%
A17: Intercept | B17: 145625.47 | C17: 20982.132 | D17: 6.9404515 | E17: 1.2488141e-08 | F17: 103365.29 | G17: 187885.65 | H17: 103365.29 | I17: 187885.65
A18: Population | B18: 0.00093333345 | C18: 0.00092343712 | D18: 1.0107168 | E18: 0.31755591 | F18: -0.0009265643 | G18: 0.0027932312 | H18: -0.0009265643 | I18: 0.0027932312
A19: Out of State Visitors | B19: -126530.3 | C19: 33478.074 | D19: -3.7794976 | E19: 0.00045980175 | F19: -193958.6 | G19: -59102.002 | H19: -193958.6 | I19: -59102.002
A20: JTW-OOSRATIO | B20: -293937.76 | C20: 152509.75 | D20: -1.9273375 | E20: 0.060264622 | F20: -601108.15 | G20: 13232.625 | H20: -601108.15 | I20: 13232.625

Sheet LOG-NL-f(P,O,J,Neigh)
A1: SUMMARY OUTPUT
A3: Regression Statistics
A4: Multiple R | B4: 0.61564034
A5: R Square | B5: 0.37901302
A6: Adjusted R Square | B6: 0.32255966
A7: Standard Error | B7: 0.053455303
A8: Observations | B8: 49
A10: ANOVA
B11: df | C11: SS | D11: MS | E11: F | F11: Significance F
A12: Regression | B12: 4 | C12: 0.076737194 | D12: 0.019184299 | E12: 6.7137371 | F12: 0.00026186774
A13: Residual | B13: 44 | C13: 0.12572866 | D13: 0.0028574694
A14: Total | B14: 48 | C14: 0.20246585
B16: Coefficients | C16: Standard Error | D16: t Stat | E16: P-value | F16: Lower 95% | G16: Upper 95% | H16: Lower 95.0% | I16: Upper 95.0%
A17: Intercept | B17: -0.073043671 | C17: 0.035229658 | D17: -2.0733573 | E17: 0.044025531 | F17: -0.14404438 | G17: -0.0020429618 | H17: -0.14404438 | I17: -0.0020429618
A18: Population | B18: 4.3473785e-09 | C18: 1.7932428e-09 | D18: 2.4243112 | E18: 0.019513824 | F18: 7.3333526e-10 | G18: 7.9614217e-09 | H18: 7.3333526e-10 | I18: 7.9614217e-09
A19: Out of State Visitors | B19: 0.094089328 | C19: 0.058248716 | D19: 1.615303 | E19: 0.11339411 | F19: -0.023303241 | G19: 0.2114819 | H19: -0.023303241 | I19: 0.2114819
A20: JTW-OOSRATIO | B20: 0.57005613 | C20: 0.23835826 | D20: 2.3915938 | E20: 0.021115966 | F20: 0.08967664 | G20: 1.0504356 | H20: 0.08967664 | I20: 1.0504356
A21: Neighbor | B21: 0.087477707 | C21: 0.10548451 | D21: 0.82929436 | E21: 0.41141438 | F21: -0.12511234 | G21: 0.30006776 | H21: -0.12511234 | I21: 0.30006776

Sheet LOG-NL-f(P,Ov,Ow,Ro)
A1: SUMMARY OUTPUT
A3: Regression Statistics
A4: Multiple R | B4: 0.66672354
A5: R Square | B5: 0.44452028
A6: Adjusted R Square | B6: 0.39402212
A7: Standard Error | B7: 0.050557275
A8: Observations | B8: 49
A10: ANOVA
B11: df | C11: SS | D11: MS | E11: F | F11: Significance F
A12: Regression | B12: 4 | C12: 0.090000176 | D12: 0.022500044 | E12: 8.8027032 | F12: 2.6019384e-05
A13: Residual | B13: 44 | C13: 0.11246567 | D13: 0.002556038
A14: Total | B14: 48 | C14: 0.20246585
B16: Coefficients | C16: Standard Error | D16: t Stat | E16: P-value | F16: Lower 95% | G16: Upper 95% | H16: Lower 95.0% | I16: Upper 95.0%
A17: Intercept | B17: -0.079348132 | C17: 0.030949124 | D17: -2.5638248 | E17: 0.013844973 | F17: -0.14172199 | G17: -0.016974273 | H17: -0.14172199 | I17: -0.016974273
A18: Population | B18: 5.3836885e-09 | C18: 1.3654139e-09 | D18: 3.9428987 | E18: 0.00028502217 | F18: 2.6318778e-09 | G18: 8.1354992e-09 | H18: 2.6318778e-09 | I18: 8.1354992e-09
A19: Out of State Visitors - ATS | B19: 0.073414122 | C19: 0.05210132 | D19: 1.4090645 | E19: 0.1658445 | F19: -0.031589186 | G19: 0.17841743 | H19: -0.031589186 | I19: 0.17841743
A20: Workers Who Live OOS (JTW) | B20: 1.0552674 | C20: 0.45852086 | D20: 2.30146 | E20: 0.026159921 | F20: 0.1311794 | G20: 1.9793555 | H20: 0.1311794 | I20: 1.9793555
A21: Residents Who Work OOS - JTW | B21: 0.12568122 | C21: 0.2944636 | D21: 0.42681413 | E21: 0.67159595 | F21: -0.46777114 | G21: 0.71913359 | H21: -0.46777114 | I21: 0.71913359

Sheet LOG-NL-f(P,Ow)
A1: SUMMARY OUTPUT
A3: Regression Statistics
A4: Multiple R | B4: 0.64488023
A5: R Square | B5: 0.41587051
A6: Adjusted R Square | B6: 0.39047357
A7: Standard Error | B7: 0.050705088
A8: Observations | B8: 49
A10: ANOVA
B11: df | C11: SS | D11: MS | E11: F | F11: Significance F
A12: Regression | B12: 2 | C12: 0.084199576 | D12: 0.042099788 | E12: 16.374831 | F12: 4.2629483e-06
A13: Residual | B13: 46 | C13: 0.11826627 | D13: 0.002571006
A14: Total | B14: 48 | C14: 0.20246585
B16: Coefficients | C16: Standard Error | D16: t Stat | E16: P-value | F16: Lower 95% | G16: Upper 95% | H16: Lower 95.0% | I16: Upper 95.0%
A17: Intercept | B17: -0.041368367 | C17: 0.01583121 | D17: -2.6130895 | E17: 0.012083475 | F17: -0.07323491 | G17: -0.0095018253 | H17: -0.07323491 | I17: -0.0095018253
A18: Population | B18: 4.8138207e-09 | C18: 1.3130456e-09 | D18: 3.6661489 | E18: 0.00063626459 | F18: 2.1707995e-09 | G18: 7.4568419e-09 | H18: 2.1707995e-09 | I18: 7.4568419e-09
A19: Workers Who Live OOS (JTW) | B19: 1.4673608 | C19: 0.28182092 | D19: 5.2067136 | E19: 4.379022e-06 | F19: 0.90008527 | G19: 2.0346364 | H19: 0.90008527 | I19: 2.0346364

Sheet LOG-NL-f(D,Ow)
A1: SUMMARY OUTPUT
A3: Regression Statistics
A4: Multiple R | B4: 0.61969375
A5: R Square | B5: 0.38402034
A6: Adjusted R Square | B6: 0.35723861
A7: Standard Error | B7: 0.052069111
A8: Observations | B8: 49
A10: ANOVA
B11: df | C11: SS | D11: MS | E11: F | F11: Significance F
A12: Regression | B12: 2 | C12: 0.077751004 | D12: 0.038875502 | E12: 14.338895 | F12: 1.4455282e-05
A13: Residual | B13: 46 | C13: 0.12471485 | D13: 0.0027111923
A14: Total | B14: 48 | C14: 0.20246585
B16: Coefficients | C16: Standard Error | D16: t Stat | E16: P-value | F16: Lower 95% | G16: Upper 95% | H16: Lower 95.0% | I16: Upper 95.0%
A17: Intercept | B17: -0.010652988 | C17: 0.012881278 | D17: -0.82701323 | E17: 0.41249914 | F17: -0.036581631 | G17: 0.015275656 | H17: -0.036581631 | I17: 0.015275656
A18: Density | B18: 0.00011010313 | C18: 3.4195534e-05 | D18: 3.2198102 | E18: 0.0023550126 | F18: 4.1271156e-05 | G18: 0.0001789351 | H18: 4.1271156e-05 | I18: 0.0001789351
A19: Workers Who Live OOS (JTW) | B19: 0.81456094 | C19: 0.30302 | D19: 2.6881425 | E19: 0.0099709095 | F19: 0.20461391 | G19: 1.424508 | H19: 0.20461391 | I19: 1.424508

Sheet LOG-NL-f(D,P,Ow)
A1: SUMMARY OUTPUT
A3: Regression Statistics
A4: Multiple R | B4: 0.69321191
A5: R Square | B5: 0.48054275
A6: Adjusted R Square | B6: 0.44591226
A7: Standard Error | B7: 0.048344218
A8: Observations | B8: 49
A10: ANOVA
B11: df | C11: SS | D11: MS | E11: F | F11: Significance F
A12: Regression | B12: 3 | C12: 0.097293495 | D12: 0.032431165 | E12: 13.876293 | F12: 1.5349295e-06
A13: Residual | B13: 45 | C13: 0.10517235 | D13: 0.0023371634
A14: Total | B14: 48 | C14: 0.20246585
B16: Coefficients | C16: Standard Error | D16: t Stat | E16: P-value | F16: Lower 95% | G16: Upper 95% | H16: Lower 95.0% | I16: Upper 95.0%
A17: Intercept | B17: -0.037662652 | C17: 0.015175073 | D17: -2.4818762 | E17: 0.016869097 | F17: -0.068226817 | G17: -0.0070984873 | H17: -0.068226817 | I17: -0.0070984873
A18: Density | B18: 7.9273204e-05 | C18: 3.3491617e-05 | D18: 2.3669566 | E18: 0.022297099 | F18: 1.1817627e-05 | G18: 0.00014672878 | H18: 1.1817627e-05 | I18: 0.00014672878
A19: Population | B19: 3.8187444e-09 | C19: 1.3206118e-09 | D19: 2.891648 | E19: 0.005882994 | F19: 1.1588958e-09 | G19: 6.4785929e-09 | H19: 1.1588958e-09 | I19: 6.4785929e-09
A20: Workers Who Live OOS (JTW) | B20: 1.1374718 | C20: 0.30269448 | D20: 3.7578213 | E20: 0.00049110568 | F20: 0.52781383 | G20: 1.7471297 | H20: 0.52781383 | I20: 1.7471297

Sheet LOG-NL-f(D,P,Ow,Ov)
A1: SUMMARY OUTPUT
A3: Regression Statistics
A4: Multiple R | B4: 0.6941583
A5: R Square | B5: 0.48185574
A6: Adjusted R Square | B6: 0.43475172
A7: Standard Error | B7: 0.04882867
A8: Observations | B8: 49
A10: ANOVA
B11: df | C11: SS | D11: MS | E11: F | F11: Significance F
A12: Regression | B12: 4 | C12: 0.097559332 | D12: 0.024389833 | E12: 10.229609 | F12: 6.0590444e-06
A13: Residual | B13: 44 | C13: 0.10490652 | D13: 0.002384239
A14: Total | B14: 48 | C14: 0.20246585
B16: Coefficients | C16: Standard Error | D16: t Stat | E16: P-value | F16: Lower 95% | G16: Upper 95% | H16: Lower 95.0% | I16: Upper 95.0%
A17: Intercept | B17: -0.047997591 | C17: 0.034538227 | D17: -1.3896947 | E17: 0.17161361 | F17: -0.11760481 | G17: 0.021609628 | H17: -0.11760481 | I17: 0.021609628
A18: Density | B18: 7.246396e-05 | C18: 3.9498457e-05 | D18: 1.8346023 | E18: 0.073331566 | F18: -7.1399471e-06 | G18: 0.00015206787 | H18: -7.1399471e-06 | I18: 0.00015206787
A19: Population | B19: 4.0498836e-09 | C19: 1.5027661e-09 | D19: 2.6949527 | E19: 0.0099315742 | F19: 1.0212576e-09 | G19: 7.0785096e-09 | H19: 1.0212576e-09 | I19: 7.0785096e-09
A20: Workers Who Live OOS (JTW) | B20: 1.0923672 | C20: 0.33423923 | D20: 3.2682194 | E20: 0.0021040148 | F20: 0.41875227 | G20: 1.765982 | H20: 0.41875227 | I20: 1.765982
A21: Out of State Visitors - ATS | B21: 0.019565337 | C21: 0.058594235 | D21: 0.33391232 | E21: 0.74003199 | F21: -0.09852358 | G21: 0.13765425 | H21: -0.09852358 | I21: 0.13765425

Sheet LOG-NL-f(D,P,Ow,Ro)
A1: SUMMARY OUTPUT
A3: Regression Statistics
A4: Multiple R | B4: 0.69339961
A5: R Square | B5: 0.48080302
A6: Adjusted R Square | B6: 0.4336033
A7: Standard Error | B7: 0.048878248
A8: Observations | B8: 49
A10: ANOVA
B11: df | C11: SS | D11: MS | E11: F | F11: Significance F
A12: Regression | B12: 4 | C12: 0.097346192 | D12: 0.024336548 | E12: 10.186564 | F12: 6.3230773e-06
A13: Residual | B13: 44 | C13: 0.10511966 | D13: 0.0023890831
A14: Total | B14: 48 | C14: 0.20246585
B16: Coefficients | C16: Standard Error | D16: t Stat | E16: P-value | F16: Lower 95% | G16: Upper 95% | H16: Lower 95.0% | I16: Upper 95.0%
A17: Intercept | B17: -0.037451132 | C17: 0.015408664 | D17: -2.4305242 | E17: 0.019222282 | F17: -0.068505253 | G17: -0.0063970105 | H17: -0.068505253 | I17: -0.0063970105
A18: Density | B18: 8.0831709e-05 | C18: 3.5450329e-05 | D18: 2.2801399 | E18: 0.027500464 | F18: 9.3862695e-06 | G18: 0.00015227715 | H18: 9.3862695e-06 | I18: 0.00015227715
A19: Population | B19: 3.7910009e-09 | C19: 1.3482039e-09 | D19: 2.8118899 | E19: 0.0073296023 | F19: 1.0738746e-09 | G19: 6.5081273e-09 | H19: 1.0738746e-09 | I19: 6.5081273e-09
A20: Workers Who Live OOS (JTW) | B20: 1.178937 | C20: 0.41425746 | D20: 2.8459042 | E20: 0.006701026 | F20: 0.34405603 | G20: 2.0138181 | H20: 0.34405603 | I20: 2.0138181
A21: Residents Who Work OOS - JTW | B21: -0.044142266 | C21: 0.29721992 | D21: -0.14851719 | E21: 0.8826132 | F21: -0.64314962 | G21: 0.55486509 | H21: -0.64314962 | I21: 0.55486509

Sheet Log-NL-f(D,P,Ow,Ro,Ov,Nj)
A1: SUMMARY OUTPUT
A3: Regression Statistics
A4: Multiple R | B4: 0.74475203
A5: R Square | B5: 0.55465559
A6: Adjusted R Square | B6: 0.49103496
A7: Standard Error | B7: 0.046333942
A8: Observations | B8: 49
A10: ANOVA
B11: df | C11: SS | D11: MS | E11: F | F11: Significance F
A12: Regression | B12: 6 | C12: 0.11229881 | D12: 0.018716469 | E12: 8.7181718 | F12: 3.5108352e-06
A13: Residual | B13: 42 | C13: 0.090167035 | D13: 0.0021468342
A14: Total | B14: 48 | C14: 0.20246585
B16: Coefficients | C16: Standard Error | D16: t Stat | E16: P-value | F16: Lower 95% | G16: Upper 95% | H16: Lower 95.0% | I16: Upper 95.0%
A17: Intercept | B17: -0.02904958 | C17: 0.033823018 | D17: -0.85887013 | E17: 0.39528762 | F17: -0.097307214 | G17: 0.039208055 | H17: -0.097307214 | I17: 0.039208055
A18: Density | B18: 1.8545931e-05 | C18: 4.459039e-05 | D18: 0.41591766 | E18: 0.67958784 | F18: -7.1441147e-05 | G18: 0.00010853301 | H18: -7.1441147e-05 | I18: 0.00010853301
A19: Population | B19: 3.8687293e-09 | C19: 1.4538804e-09 | D19: 2.660968 | E19: 0.010989171 | F19: 9.3467889e-10 | G19: 6.8027798e-09 | H19: 9.3467889e-10 | I19: 6.8027798e-09
A20: Workers Who Live OOS (JTW) | B20: 1.1162651 | C20: 0.42140516 | D20: 2.6489119 | E20: 0.011329534 | F20: 0.26583483 | G20: 1.9666954 | H20: 0.26583483 | I20: 1.9666954
A21: Residents Who Work OOS - JTW | B21: -0.32908195 | C21: 0.30259918 | D21: -1.0875176 | E21: 0.28300983 | F21: -0.93975202 | G21: 0.28158812 | H21: -0.93975202 | I21: 0.28158812
A22: Out of State Visitors - ATS | B22: -0.0037189413 | C22: 0.056512721 | D22: -0.065807154 | E22: 0.94784361 | F22: -0.11776627 | G22: 0.11032838 | H22: -0.11776627 | I22: 0.11032838
A23: Neighbors-JTW | B23: 5.4318737 | C23: 2.0359046 | D23: 2.6680395 | E23: 0.010793936 | F23: 1.3232507 | G23: 9.5404967 | H23: 1.3232507 | I23: 9.5404967

Sheet L-NL-f(D,P,Ow,Rw,Ov,Nj,Lf)
A1: SUMMARY OUTPUT
A3: Regression Statistics
A4: Multiple R | B4: 0.74868186
A5: R Square | B5: 0.56052453
A6: Adjusted R Square | B6: 0.48549214
A7: Standard Error | B7: 0.046585556
A8: Observations | B8: 49
A10: ANOVA
B11: df | C11: SS | D11: MS | E11: F | F11: Significance F
A12: Regression | B12: 7 | C12: 0.11348708 | D12: 0.016212439 | E12: 7.4704335 | F12: 8.6642401e-06
A13: Residual | B13: 41 | C13: 0.088978774 | D13: 0.002170214
A14: Total | B14: 48 | C14: 0.20246585
B16: Coefficients | C16: Standard Error | D16: t Stat | E16: P-value | F16: Lower 95% | G16: Upper 95% | H16: Lower 95.0% | I16: Upper 95.0%
A17: Intercept | B17: -0.026296431 | C17: 0.034209629 | D17: -0.76868508 | E17: 0.44648571 | F17: -0.095384216 | G17: 0.042791354 | H17: -0.095384216 | I17: 0.042791354
A18: Density | B18: 9.6398283e-06 | C18: 4.6420061e-05 | D18: 0.20766514 | E18: 0.83651851 | F18: -8.4107437e-05 | G18: 0.00010338709 | H18: -8.4107437e-05 | I18: 0.00010338709
A19: Population | B19: 3.8749615e-09 | C19: 1.4617999e-09 | D19: 2.6508152 | E19: 0.011359921 | F19: 9.2279506e-10 | G19: 6.827128e-09 | H19: 9.2279506e-10 | I19: 6.827128e-09
A20: Workers Who Live OOS (JTW) | B20: 1.0593974 | C20: 0.43060728 | D20: 2.4602404 | E20: 0.018187677 | F20: 0.18976791 | G20: 1.929027 | H20: 0.18976791 | I20: 1.929027
A21: Residents Who Work OOS - JTW | B21: -0.3466039 | C21: 0.30516256 | D21: -1.1358009 | E21: 0.26263578 | F21: -0.96289253 | G21: 0.26968473 | H21: -0.96289253 | I21: 0.26968473
A22: Out of State Visitors - ATS | B22: 0.0044704354 | C22: 0.05788744 | D22: 0.077226344 | E22: 0.93881913 | F22: -0.11243569 | G22: 0.12137656 | H22: -0.11243569 | I22: 0.12137656
A23: Neighbors-JTW | B23: 5.5563259 | C23: 2.0538584 | D23: 2.705311 | E23: 0.0098954408 | F23: 1.4084723 | G23: 9.7041794 | H23: 1.4084723 | I23: 9.7041794
A24: Percent Federal | B24: -0.028311512 | C24: 0.03826118 | D24: -0.73995397 | E24: 0.46354414 | F24: -0.10558158 | G24: 0.048958551 | H24: -0.10558158 | I24: 0.048958551

Sheet L-NL-f-(P,Ow,Ro,Nj,Lf)
A1: SUMMARY OUTPUT
A3: Regression Statistics
A4: Multiple R | B4: 0.74814738
A5: R Square | B5: 0.5597245
A6: Adjusted R Square | B6: 0.50852967
A7: Standard Error | B7: 0.045530658
A8: Observations | B8: 49
A10: ANOVA
B11: df | C11: SS | D11: MS | E11: F | F11: Significance F
A12: Regression | B12: 5 | C12: 0.1133251 | D12: 0.022665019 | E12: 10.933224 | F12: 7.8770322e-07
A13: Residual | B13: 43 | C13: 0.089140754 | D13: 0.0020730408
A14: Total | B14: 48 | C14: 0.20246585
B16: Coefficients | C16: Standard Error | D16: t Stat | E16: P-value | F16: Lower 95% | G16: Upper 95% | H16: Lower 95.0% | I16: Upper 95.0%
A17: Intercept | B17: -0.023586513 | C17: 0.017214247 | D17: -1.3701739 | E17: 0.17774436 | F17: -0.058302328 | G17: 0.011129302 | H17: -0.058302328 | I17: 0.011129302
A18: Population | B18: 3.9172032e-09 | C18: 1.2195433e-09 | D18: 3.2120246 | E18: 0.0024974218 | F18: 1.4577614e-09 | G18: 6.3766451e-09 | H18: 1.4577614e-09 | I18: 6.3766451e-09
A19: Workers Who Live OOS (JTW) | B19: 1.0758968 | C19: 0.38872897 | D19: 2.76773 | E19: 0.0082925499 | F19: 0.29195068 | G19: 1.859843 | H19: 0.29195068 | I19: 1.859843
A20: Residents Who Work OOS - JTW | B20: -0.34893738 | C20: 0.29570026 | D20: -1.1800374 | E20: 0.24447246 | F20: -0.94527338 | G20: 0.24739863 | H20: -0.94527338 | I20: 0.24739863
A21: Neighbors-JTW | B21: 5.8924428 | C21: 1.6062202 | D21: 3.6685149 | E21: 0.00066790363 | F21: 2.6531932 | G21: 9.1316924 | H21: 2.6531932 | I21: 9.1316924
A22: Percent Federal Land | B22: -0.029736997 | C22: 0.035946478 | D22: -0.82725758 | E22: 0.41265854 | F22: -0.10222993 | G22: 0.042755936 | H22: -0.10222993 | I22: 0.042755936

Sheet N-N-f(P,Ow,Ro,Nj,Lf)
A1: SUMMARY OUTPUT
A3: Regression Statistics
A4: Multiple R | B4: 0.74843093
A5: R Square | B5: 0.56014886
A6: Adjusted R Square | B6: 0.50900338
A7: Standard Error | B7: 0.05113717
A8: Observations | B8: 49
A10: ANOVA
B11: df | C11: SS | D11: MS | E11: F | F11: Significance F
A12: Regression | B12: 5 | C12: 0.14319886 | D12: 0.028639772 | E12: 10.952069 | F12: 7.7234931e-07
A13: Residual | B13: 43 | C13: 0.11244544 | D13: 0.0026150101
A14: Total | B14: 48 | C14: 0.2556443
B16: Coefficients | C16: Standard Error | D16: t Stat | E16: P-value | F16: Lower 95% | G16: Upper 95% | H16: Lower 95.0% | I16: Upper 95.0%
A17: Intercept | B17: -0.027846753 | C17: 0.01933396 | D17: -1.4403027 | E17: 0.15702362 | F17: -0.066837372 | G17: 0.011143865 | H17: -0.066837372 | I17: 0.011143865
A18: Population | B18: 4.3506032e-09 | C18: 1.3697144e-09 | D18: 3.176285 | E18: 0.0027595373 | F18: 1.5883129e-09 | G18: 7.1128936e-09 | H18: 1.5883129e-09 | I18: 7.1128936e-09
A19: Workers Who Live OOS (JTW) | B19: 1.2514925 | C19: 0.43659592 | D19: 2.8664777 | E19: 0.0064018293 | F19: 0.37101348 | G19: 2.1319715 | H19: 0.37101348 | I19: 2.1319715
A20: Residents Who Work OOS - JTW | B20: -0.45580694 | C20: 0.33211193 | D20: -1.3724498 | E20: 0.17704032 | F20: -1.125574 | G20: 0.21396013 | H20: -1.125574 | I20: 0.21396013
A21: Neighbors-JTW | B21: 6.8059469 | C21: 1.8040055 | D21: 3.7726863 | E21: 0.00048919416 | F21: 3.1678256 | G21: 10.444068 | H21: 3.1678256 | I21: 10.444068
A22: Percent Federal Land | B22: -0.031074295 | C22: 0.040372823 | D22: -0.76968348 | E22: 0.44569546 | F22: -0.1124938 | G22: 0.050345206 | H22: -0.1124938 | I22: 0.050345206

Sheet FINAL-1
A1: SUMMARY OUTPUT
A3: Regression Statistics
A4: Multiple R | B4: 0.80929777
A5: R Square | B5: 0.65496287
A6: Adjusted R Square | B6: 0.60567186
A7: Standard Error | B7: 0.045827517
A8: Observations | B8: 49
A10: ANOVA
B11: df | C11: SS | D11: MS | E11: F | F11: Significance F
A12: Regression | B12: 6 | C12: 0.16743752 | D12: 0.027906254 | E12: 13.287672 | F12: 2.2465024e-08
A13: Residual | B13: 42 | C13: 0.088206774 | D13: 0.0021001613
A14: Total | B14: 48 | C14: 0.2556443
B16: Coefficients | C16: Standard Error | D16: t Stat | E16: P-value | F16: Lower 95% | G16: Upper 95% | H16: Lower 95.0% | I16: Upper 95.0%
A17: Intercept | B17: -0.032232115 | C17: 0.017374503 | D17: -1.8551388 | E17: 0.070604392 | F17: -0.067295292 | G17: 0.0028310628 | H17: -0.067295292 | I17: 0.0028310628
A18: Population | B18: 3.6887339e-09 | C18: 1.2428596e-09 | D18: 2.9679409 | E18: 0.0049337146 | F18: 1.1805408e-09 | G18: 6.1969269e-09 | H18: 1.1805408e-09 | I18: 6.1969269e-09
A19: Workers Who Live OOS (JTW) | B19: 1.0094547 | C19: 0.39769709 | D19: 2.5382502 | E19: 0.014937372 | F19: 0.20686926 | G19: 1.8120402 | H19: 0.20686926 | I19: 1.8120402
A20: Residents Who Work OOS - JTW | B20: -0.35220966 | C20: 0.29918634 | D20: -1.1772251 | E20: 0.24573404 | F20: -0.95599234 | G20: 0.25157301 | H20: -0.95599234 | I20: 0.25157301
A21: Neighbors-JTW | B21: 3.0300498 | C21: 1.9618943 | D21: 1.5444511 | E21: 0.12998133 | F21: -0.92921434 | G21: 6.989314 | H21: -0.92921434 | I21: 6.989314
A22: Percent Federal Land | B22: -0.0011164502 | C22: 0.037239971 | D22: -0.029979889 | E22: 0.9762251 | F22: -0.076269777 | G22: 0.074036877 | H22: -0.076269777 | I22: 0.074036877
A23: OldTollMileRatio | B23: 0.28837827 | C23: 0.084885699 | D23: 3.3972539 | E23: 0.0014999034 | F23: 0.11707194 | G23: 0.4596846 | H23: 0.11707194 | I23: 0.4596846

Sheet Sheet3
A1: SUMMARY OUTPUT
A3: Regression Statistics
A4: Multiple R | B4: 0.8092932
A5: R Square | B5: 0.65495549
A6: Adjusted R Square | B6: 0.61483404
A7: Standard Error | B7: 0.045291988
A8: Observations | B8: 49
A10: ANOVA
B11: df | C11: SS | D11: MS | E11: F | F11: Significance F
A12: Regression | B12: 5 | C12: 0.16743564 | D12: 0.033487127 | E12: 16.324321 | F12: 5.1946687e-09
A13: Residual | B13: 43 | C13: 0.088208661 | D13: 0.0020513642
A14: Total | B14: 48 | C14: 0.2556443
B16: Coefficients | C16: Standard Error | D16: t Stat | E16: P-value | F16: Lower 95% | G16: Upper 95% | H16: Lower 95.0% | I16: Upper 95.0%
A17: Intercept | B17: -0.032508894 | C17: 0.014546723 | D17: -2.2347916 | E17: 0.030679435 | F17: -0.061845136 | G17: -0.0031726516 | H17: -0.061845136 | I17: -0.0031726516
A18: Population | B18: 3.6930513e-09 | C18: 1.2200621e-09 | D18: 3.0269371 | E18: 0.0041626729 | F18: 1.2325633e-09 | G18: 6.1535394e-09 | H18: 1.2325633e-09 | I18: 6.1535394e-09
A19: Workers Who Live OOS (JTW) | B19: 1.010389 | C19: 0.39184127 | D19: 2.578567 | E19: 0.013427768 | F19: 0.22016627 | G19: 1.8006117 | H19: 0.22016627 | I19: 1.8006117
A20: Neighbors-JTW | B20: 3.0225883 | C20: 1.9233024 | D20: 1.5715616 | E20: 0.1233824 | F20: -0.85611811 | G20: 6.9012946 | H20: -0.85611811 | I20: 6.9012946
A21: OldTollMileRatio | B21: 0.28898088 | C21: 0.081507771 | D21: 3.5454396 | E21: 0.00096037513 | F21: 0.12460491 | G21: 0.45335685 | H21: 0.12460491 | I21: 0.45335685
A22: Residents Who Work OOS - JTW | B22: -0.35104428 | C22: 0.29318377 | D22: -1.1973524 | E22: 0.23772837 | F22: -0.94230529 | G22: 0.24021673 | H22: -0.94230529 | I22: 0.24021673

Sheet Sheet8
A1: SUMMARY OUTPUT
A3: Regression Statistics
A4: Multiple R | B4: 0.80111602
A5: R Square | B5: 0.64178687
A6: Adjusted R Square | B6: 0.59061357
A7: Standard Error | B7: 0.046694331
A8: Observations | B8: 49
A10: ANOVA
B11: df | C11: SS | D11: MS | E11: F | F11: Significance F
A12: Regression | B12: 6 | C12: 0.16406915 | D12: 0.027344859 | E12: 12.541439 | F12: 4.7520166e-08
A13: Residual | B13: 42 | C13: 0.091575144 | D13: 0.0021803606
A14: Total | B14: 48 | C14: 0.2556443
B16: Coefficients | C16: Standard Error | D16: t Stat | E16: P-value | F16: Lower 95% | G16: Upper 95% | H16: Lower 95.0% | I16: Upper 95.0%
A17: Intercept | B17: -0.038801562 | C17: 0.017547604 | D17: -2.2112172 | E17: 0.0325181 | F17: -0.074214071 | G17: -0.0033890534 | H17: -0.074214071 | I17: -0.0033890534
A18: Population | B18: 3.6072544e-09 | C18: 1.2834578e-09 | D18: 2.8105751 | E18: 0.0074806042 | F18: 1.017131e-09 | G18: 6.1973779e-09 | H18: 1.017131e-09 | I18: 6.1973779e-09
A19: OldTollMileRatio | B19: 0.30730054 | C19: 0.095654802 | D19: 3.2125992 | E19: 0.0025266029 | F19: 0.11426128 | G19: 0.50033981 | H19: 0.11426128 | I19: 0.50033981
A20: Workers Who Live OOS (JTW) | B20: 0.98450068 | C20: 0.40634343 | D20: 2.4228291 | E20: 0.01979143 | F20: 0.16446618 | G20: 1.8045352 | H20: 0.16446618 | I20: 1.8045352
A21: AVG-Neighbor-2 | B21: 0.14181836 | C21: 0.16346134 | D21: 0.86759576 | E21: 0.39054586 | F21: -0.18806007 | G21: 0.4716968 | H21: -0.18806007 | I21: 0.4716968
A22: Residents Who Work OOS - JTW | B22: -0.149297 | C22: 0.27830043 | D22: -0.53645983 | E22: 0.59447109 | F22: -0.71093019 | G22: 0.41233619 | H22: -0.71093019 | I22: 0.41233619
A23: Percent Federal Land | B23: 0.0051962971 | C23: 0.03765486 | D23: 0.13799805 | E23: 0.89090146 | F23: -0.070794311 | G23: 0.081186905 | H23: -0.070794311 | I23: 0.081186905

Sheet Ro=f(L,D)
A1: SUMMARY OUTPUT | C1: dep=residents who work of jurisdiction
A3: Regression Statistics
A4: Multiple R | B4: 0.56537565
A5: R Square | B5: 0.31964963
A6: Adjusted R Square | B6: 0.29006918
A7: Standard Error | B7: 0.032531977
A8: Observations | B8: 49
A10: ANOVA
B11: df | C11: SS | D11: MS | E11: F | F11: Significance F
A12: Regression | B12: 2 | C12: 0.022872852 | D12: 0.011436426 | E12: 10.806111 | F12: 0.0001421839
A13: Residual | B13: 46 | C13: 0.048683158 | D13: 0.0010583295
A14: Total | B14: 48 | C14: 0.07155601
B16: Coefficients | C16: Standard Error | D16: t Stat | E16: P-value | F16: Lower 95% | G16: Upper 95% | H16: Lower 95.0% | I16: Upper 95.0%
A17: Intercept | B17: 0.054607413 | C17: 0.010513105 | D17: 5.1942233 | E17: 4.5680971e-06 | F17: 0.033445651 | G17: 0.075769174 | H17: 0.033445651 | I17: 0.075769174
A18: Land | B18: -3.2107613e-07 | C18: 1.1386428e-07 | D18: -2.8198144 | E18: 0.0070661387 | F18: -5.5027282e-07 | G18: -9.187945e-08 | H18: -5.5027282e-07 | I18: -9.187945e-08
A19: Density | B19: 4.240699e-05 | C19: 2.242714e-05 | D19: 1.8908782 | E19: 0.064948512 | F19: -2.7364585e-06 | G19: 8.7550439e-05 | H19: -2.7364585e-06 | I19: 8.7550439e-05

Sheet N-N-f(P,M,Ow,RoxN2^4)
A1: XLSTAT - Regression / Started on 11/18/98 at 1:12:35 PM
A2: Input data :
A3: Y variable : Workbook = Levinson-stat.xls / Sheet = Select / Range = $C$3:$C$52
A4: Numerical variables : Workbook = Levinson-stat.xls / Sheet = Select / Range = $M$3:$P$52
A5: Categorical variables : None
B8: Mean | C8: Std. dev. | D8: Min | E8: Max
A9: TollShare | B9: 0.042004283 | C9: 0.072978921 | D9: 0 | E9: 0.33182204
A10: Population | B10: 5338722.4 | C10: 5779174.7 | D10: 480184 | E10: 31589153
A11: OldTollMileRatio | B11: 0.074880138 | C11: 0.11461002 | D11: 0 | E11: 0.42472527
A12: Workers Who Live OOS (JTW) | B12: 0.037239314 | C12: 0.026926035 | D12: 0.0045230302 | E12: 0.13832888
A13: AVG-Neighbor-2 | B13: 2.1584088e-08 | C13: 1.3232308e-07 | D13: 1.3511322e-16 | E13: 9.261788e-07
A16: Correlation coefficient r : 0.8093
A17: Determination coefficient r² : 0.6549
A18: Adjusted determination coefficient : 0.6235
A21: Evaluating significance of information carried by variables (H0 = Y=Mean(Y)):
B23: DF | C23: Sum of squares | D23: Mean of squares | E23: Fisher's F | F23: Pr > F
A24: Model | B24: 4 | C24: 0.16742144 | D24: 0.041855361 | E24: 20.874817 | F24: 0.0001
A25: Residuals | B25: 44 | C25: 0.088222852 | D25: 0.0020050648
A26: Total | B26: 48 | C26: 0.2556443
A29: Model analysis (Type I SS) :
A31: Source | B31: DF | C31: Type I SS | D31: Mean Square | E31: Fisher's F | F31: Pr. >F
A32: Population | B32: 1 | C32: 0.018182342 | D32: 0.018182342 | E32: 9.0682064 | F32: 0.0042980641
A33: OldTollMileRatio | B33: 1 | C33: 0.12632283 | D33: 0.12632283 | E33: 63.00187 | F33: 0.0001
A34: Workers Who Live OOS (JTW) | B34: 1 | C34: 0.017078413 | D34: 0.017078413 | E34: 8.5176362 | F34: 0.0055234705
A35: AVG-Neighbor-2 | B35: 1 | C35: 0.0058378567 | D35: 0.0058378567 | E35: 2.9115551 | F35: 0.094996934
A38: Regression parameters and corresponding statistics :
B40: Value | C40: Std dev. | D40: Student's t | E40: Corresponding probability | F40: Lower 95% bound | G40: Upper 95% bound
A41: Intercept | B41: -0.034466014 | C41: 0.014231442 | D41: -2.4218217 | E41: 0.019631758 | F41: -0.063147598 | G41: -0.0057844288
A42: Population | B42: 3.8296086e-09 | C42: 1.1981435e-09 | D42: 3.1962855 | E42: 0.0025774017 | F42: 1.4149092e-09 | G42: 6.2443081e-09
A43: OldTollMileRatio | B43: 0.29964411 | C43: 0.072469895 | D43: 4.1347391 | E43: 0.00015714171 | F43: 0.15359064 | G43: 0.44569758
A44: Workers Who Live OOS (JTW) | B44: 0.84697193 | C44: 0.28925856 | D44: 2.9280791 | E44: 0.0053833613 | F44: 0.26400963 | G44: 1.4299342
A45: AVG-Neighbor-2^4 | B45: 94839.933 | C45: 55581.304 | D45: 1.706328 | E45: 0.094996934 | F45: -17176.82 | G45: 206856.69

Sheet Sheet1
A1: XLSTAT - Regression / Started on 11/24/98 at 10:43:32 AM
A2: Input data :
A3: Y variable : Workbook = Levinson-stat.xls / Sheet = Select / Range = $C$3:$C$52
A4: Numerical variables : Workbook = Levinson-stat.xls / Sheet = Select / Range = $M$3:$P$52
A5: Categorical variables : None
B8: Mean | C8: Std. dev. | D8: Min | E8: Max
A9: TollShare | B9: 0.029757828 | C9: 0.068399474 | D9: 0 | E9: 0.33182204
A10: Population | B10: 4649000.5 | C10: 3539126.2 | D10: 480184 | E10: 31589153
A11: OldTollMileRatio | B11: 0.04455473 | C11: 0.11195769 | D11: 0 | E11: 0.42472527
A12: Workers Who Live OOS (JTW) | B12: 0.03286254 | C12: 0.021499074 | D12: 0.0045230302 | E12: 0.13832888
A13: N1^4 | B13: 6.0124712e-08 | C13: 2.3157569e-07 | D13: 2.5762505e-14 | E13: 9.7857405e-07
A16: Correlation coefficient r : 0.9803
A17: Determination coefficient r² : 0.9609
A18: Adjusted determination coefficient : 0.9609
A21: Evaluating significance of information carried by variables (H0 = Y=Mean(Y)):
B23: DF | C23: Sum of squares | D23: Mean of squares | E23: Fisher's F | F23: Pr > F
A24: Model | B24: 4 | C24: 28.93175 | D24: 7.2329375 | E24: 39555.079 | F24: 0.0001
A25: Residuals | B25: 6431.3637 | C25: 1.1760222 | D25: 0.00018285737
A26: Total | B26: 6435.3637 | C26: 30.107772
A29: Model analysis (Type I SS) :
A31: Source | B31: DF | C31: Type I SS | D31: Mean Square | E31: Fisher's F | F31: Pr. >F
A32: Population | B32: 1 | C32: 3.0908722 | D32: 3.0908722 | E32: 16903.187 | F32: 0.0001
A33: OldTollMileRatio | B33: 1 | C33: 24.55254 | D33: 24.55254 | E33: 134271.54 | F33: 0.0001
A34: Workers Who Live OOS (JTW) | B34: 1 | C34: 0.55686054 | D34: 0.55686054 | E34: 3045.3274 | F34: 0.0001
A35: N1^4 | B35: 1 | C35: 0.73147761 | D35: 0.73147761 | E35: 4000.2633 | F35: 0.0001
A38: Regression parameters and corresponding statistics :
B40: Value | C40: Std dev. | D40: Student's t | E40: Corresponding probability | F40: Lower 95% bound | G40: Upper 95% bound
A41: Intercept | B41: -0.023353064 | C41: 0.00052629701 | D41: -44.372404 | E41: 0.0001 | F41: -0.024384782 | G41: -0.022321346
A42: Population | B42: 2.7335222e-09 | C42: 5.9479334e-11 | D42: 45.957511 | E42: 0.0001 | F42: 2.6169228e-09 | G42: 2.8501215e-09
A43: OldTollMileRatio | B43: 0.33608254 | C43: 0.0033523891 | D43: 100.25165 | E43: 0.0001 | F43: 0.32951074 | G43: 0.34265435
A44: Workers Who Live OOS (JTW) | B44: 0.60665934 | C44: 0.010899014 | D44: 55.661856 | E44: 0.0001 | F44: 0.58529363 | G44: 0.62802505
A45: N1^4 | B45: 91348.655 | C45: 1444.3015 | D45: 63.247635 | E45: 0.0001 | F45: 88517.341 | G45: 94179.968
A48: Residuals analysis :
A50: Observation | B50: Weight | C50: Population | D50: TollShare | E50: predicted TollShare | F50: Residuals | G50: Reduced residuals | H50: Lower value (95% confidence range) | I50: Upper value (95% confidence range)
A51: 1 | B51: 492.23816 | C51: 4252982 | D51: 0 | E51: 0.0027426265 | F51: -0.0027426265 | G51: -0.083896849 | H51: -0.023768561 | I51: 0.029253814
A52: 2 | B52: 113.65499 | C52: 4217940 | D52: 0 | E52: -0.0050241499 | F52: 0.0050241499 | G52: 0.09495006 | H52: -0.031537727 | I52: 0.021489427
A53: 3 | B53: 109.13923 | C53: 2483769 | D53: 0 | E53: 0.007881299 | F53: -0.007881299 | G53: -0.20222595 | H53: -0.018630631 | I53: 0.034393229
A54: 4 | B54: 14.439643 | C54: 31589153 | D54: 0.021141521 | E54: 0.06574063 | F54: -0.044599109 | G54: -1.0477333 | H54: 0.039066321 | I54: 0.092414939
A55: 5 | B55: 84.069065 | C55: 3746585 | D55: 0.0029577777 | E55: -0.0033225748 | F55: 0.0062803524 | G55: 0.12387685 | H55: -0.029838314 | I55: 0.023193165
A56: 6 | B56: 7.9400339 | C56: 3274662 | D56: 0.00025988579 | E56: 0.13595066 | F56: -0.13569078 | G56: -3.145317 | H56: 0.10935748 | I56: 0.16254385
...

Sheet Final-2
A1: XLSTAT - Regression / Started on 11/18/98 at 4:10:42 PM
A2: Input data :
A3: Y variable : Workbook = Levinson-stat.xls / Sheet = Select / Range = $C$3:$C$52
A4: Numerical variables : Workbook = Levinson-stat.xls / Sheet = Select / Range = $M$3:$P$52
A5: Categorical variables : None
B8: Mean | C8: Std. dev. | D8: Min | E8: Max
A9: TollShare | B9: 0.042004283 | C9: 0.072978921 | D9: 0 | E9: 0.33182204
A10: Population | B10: 5338722.4 | C10: 5779174.7 | D10: 480184 | E10: 31589153
A11: OldTollMileRatio | B11: 0.074880138 | C11: 0.11461002 | D11: 0 | E11: 0.42472527
A12: Workers Who Live OOS (JTW) | B12: 0.037239314 | C12: 0.026926035 | D12: 0.0045230302 | E12: 0.13832888
A13: N1^4 | B13: 2.3050017e-08 | C13: 1.3983592e-07 | D13: 2.5762505e-14 | E13: 9.7857405e-07
A16: Correlation coefficient r : 0.8093
A17: Determination coefficient r² : 0.6549
A18: Adjusted determination coefficient : 0.6235
A21: Evaluating significance of information carried by variables (H0 = Y=Mean(Y)):
B23: DF | C23: Sum of squares | D23: Mean of squares | E23: Fisher's F | F23: Pr > F
A24: Model | B24: 4 | C24: 0.16741939 | D24: 0.041854847 | E24: 20.874074 | F24: 0.0001
A25: Residuals | B25: 44 | C25: 0.088224908 | D25: 0.0020051115
A26: Total | B26: 48 | C26: 0.2556443
A29: Model analysis (Type I SS) :
A31: Source | B31: DF | C31: Type I SS | D31: Mean Square | E31: Fisher's F | F31: Pr. >F
A32: Population | B32: 1 | C32: 0.018182342 | D32: 0.018182342 | E32: 9.0679951 | F32: 0.0042984747
A33: OldTollMileRatio | B33: 1 | C33: 0.12632283 | D33: 0.12632283 | E33: 63.000402 | F33: 0.0001
A34: Workers Who Live OOS (JTW) | B34: 1 | C34: 0.017078413 | D34: 0.017078413 | E34: 8.5174378 | F34: 0.0055239737
A35: N1^4 | B35: 1 | C35: 0.0058358015 | D35: 0.0058358015 | E35: 2.9104623 | F35: 0.095057047
A38: Regression parameters and corresponding statistics :
B40: Value | C40: Std dev. | D40: Student's t | E40: Corresponding probability | F40: Lower 95% bound | G40: Upper 95% bound
A41: Intercept | B41: -0.03443583 | C41: 0.014233036 | D41: -2.4194296 | E41: 0.019745682 | F41: -0.063120628 | G41: -0.0057510309
A42: Population | B42: 3.83059e-09 | C42: 1.1981497e-09 | D42: 3.197088 | E42: 0.0025716043 | F42: 1.4158781e-09 | G42: 6.245302e-09
A43: OldTollMileRatio | B43: 0.29938505 | C43: 0.072537536 | D43: 4.1273121 | E43: 0.00016083649 | F43: 0.15319526 | G43: 0.44557484
A44: Workers Who Live OOS (JTW) | B44: 0.84588027 | C44: 0.28925903 | D44: 2.9243003 | E44: 0.0054382243 | F44: 0.26291703 | G44: 1.4288435
A45: N1^4 | B45: 89876.772 | C45: 52682.513 | D45: 1.7060077 | E45: 0.095057047 | F45: -16297.851 | G45: 196051.4

Sheet Ow=f(L,D)
A1: SUMMARY OUTPUT | C1: dep=Workers who live out of jurisdiction
A3: Regression Statistics
A4: Multiple R | B4: 0.52836965
A5: R Square | B5: 0.27917449
A6: Adjusted R Square | B6: 0.24783425
A7: Standard Error | B7: 0.023352274
A8: Observations | B8: 49
A10: ANOVA
B11: df | C11: SS | D11: MS | E11: F | F11: Significance F
A12: Regression | B12: 2 | C12: 0.0097154246 | D12: 0.0048577123 | E12: 8.9078607 | F12: 0.00053714732
A13: Residual | B13: 46 | C13: 0.025085121 | D13: 0.00054532872
A14: Total | B14: 48 | C14: 0.034800546
B16: Coefficients | C16: Standard Error | D16: t Stat | E16: P-value | F16: Lower 95% | G16: Upper 95% | H16: Lower 95.0% | I16: Upper 95.0%
A17: Intercept | B17: 0.047792862 | C17: 0.0075465719 | D17: 6.3330559 | E17: 9.1567688e-08 | F17: 0.032602415 | G17: 0.062983309 | H17: 0.032602415 | I17: 0.062983309
A18: Land | B18: -2.3584376e-07 | C18: 8.1734653e-08 | D18: -2.8854806 | E18: 0.0059312955 | F18: -4.0036693e-07 | G18: -7.1320594e-08 | H18: -4.0036693e-07 | I18: -7.1320594e-08
A19: Density | B19: 2.1238643e-05 | C19: 1.6098768e-05 | D19: 1.3192714 | E19: 0.19360779 | F19: -1.1166464e-05 | G19: 5.3643751e-05 | H19: -1.1166464e-05 | I19: 5.3643751e-05

Sheet Chart1

Sheet L-L
A1: SUMMARY OUTPUT
A3: Regression Statistics
A4: Multiple R | B4: 0.76590337
A5: R Square | B5: 0.58660797
A6: Adjusted R Square | B6: 0.54902688
A7: Standard Error | B7: 0.04361447
A8: Observations | B8: 49
A10: ANOVA
B11: df | C11: SS | D11: MS | E11: F | F11: Significance F
A12: Regression | B12: 4 | C12: 0.11876808 | D12: 0.029692021 | E12: 15.609125 | F12: 5.0483424e-08
A13: Residual | B13: 44 | C13: 0.083697768 | D13: 0.001902222
A14: Total | B14: 48 | C14: 0.20246585
B16: Coefficients | C16: Standard Error | D16: t Stat | E16: P-value | F16: Lower 95% | G16: Upper 95% | H16: Lower 95.0% | I16: Upper 95.0%
A17: Intercept | B17: -0.060622599 | C17: 0.10496975 | D17: -0.57752445 | E17: 0.56652898 | F17: -0.27217523 | G17: 0.15093003 | H17: -0.27217523 | I17: 0.15093003
A18: LN(POP) | B18: 0.011626831 | C18: 0.006937455 | D18: 1.6759504 | E18: 0.10084079 | F18: -0.0023546908 | G18: 0.025608352 | H18: -0.0023546908 | I18: 0.025608352
A19: LN(OLDMILES+1) | B19: 0.35694687 | C19: 0.086481262 | D19: 4.1274475 | E19: 0.00016076841 | F19: 0.18265534 | G19: 0.53123839 | H19: 0.18265534 | I19: 0.53123839
A20: LN(Ow) | B20: 0.0077926212 | C20: 0.010065617 | D20: 0.77418217 | E20: 0.44296327 | F20: -0.012493296 | G20: 0.028078539 | H20: -0.012493296 | I20: 0.028078539
A21: LN(N1^4) | B21: 0.0028160177 | C21: 0.002085214 | D21: 1.3504694 | E21: 0.18377085 | F21: -0.0013864548 | G21: 0.0070184902 | H21: -0.0013864548 | I21: 0.0070184902

Sheet NL-L
A1: SUMMARY OUTPUT
A3: Regression Statistics
A4: Multiple R | B4: 0.75590611
A5: R Square | B5: 0.57139405
A6: Adjusted R Square | B6: 0.53242987
A7: Standard Error | B7: 0.049902329
A8: Observations | B8: 49
A10: ANOVA
B11: df | C11: SS | D11: MS | E11: F | F11: Significance F
A12: Regression | B12: 4 | C12: 0.14607363 | D12: 0.036518407 | E12: 14.664599 | F12: 1.091143e-07
A13: Residual | B13: 44 | C13: 0.10957067 | D13: 0.0024902425
A14: Total | B14: 48 | C14: 0.2556443
B16: Coefficients | C16: Standard Error | D16: t Stat | E16: P-value | F16: Lower 95% | G16: Upper 95% | H16: Lower 95.0% | I16: Upper 95.0%
A17: Intercept | B17: -0.066541498 | C17: 0.12010315 | D17: -0.55403625 | E17: 0.58235905 | F17: -0.30859348 | G17: 0.17551049 | H17: -0.30859348 | I17: 0.17551049
A18: LN(POP) | B18: 0.012956463 | C18: 0.0079376217 | D18: 1.6322852 | E18: 0.10975678 | F18: -0.003040762 | G18: 0.028953688 | H18: -0.003040762 | I18: 0.028953688
A19: LN(OLDMILES+1) | B19: 0.39248128 | C19: 0.098949189 | D19: 3.9664932 | E19: 0.00026504563 | F19: 0.1930623 | G19: 0.59190026 | H19: 0.1930623 | I19: 0.59190026
A20: LN(Ow) | B20: 0.0090230454 | C20: 0.011516768 | D20: 0.78347027 | E20: 0.43754812 | F20: -0.014187475 | G20: 0.032233565 | H20: -0.014187475 | I20: 0.032233565
A21: LN(N1^4) | B21: 0.0031727336 | C21: 0.0023858374 | D21: 1.3298197 | E21: 0.19043065 | F21: -0.0016356056 | G21: 0.0079810727 | H21: -0.0016356056 | I21: 0.0079810727

Sheet NL-NL
A1: SUMMARY OUTPUT
A3: Regression Statistics
A4: Multiple R | B4: 0.80925394
A5: R Square | B5: 0.65489194
A6: Adjusted R Square | B6: 0.62351848
A7: Standard Error | B7: 0.044778472
A8: Observations | B8: 49
A10: ANOVA
B11: df | C11: SS | D11: MS | E11: F | F11: Significance F
A12: Regression | B12: 4 | C12: 0.16741939 | D12: 0.041854847 | E12: 20.874074 | F12: 1.0537751e-09
A13: Residual | B13: 44 | C13: 0.088224908 | D13: 0.0020051115
A14: Total | B14: 48 | C14: 0.2556443
B16: Coefficients | C16: Standard Error | D16: t Stat | E16: P-value | F16: Lower 95% | G16: Upper 95% | H16: Lower 95.0% | I16: Upper 95.0%
A17: Intercept | B17: -0.03443583 | C17: 0.014233036 | D17: -2.4194296 | E17: 0.019745682 | F17: -0.063120628 | G17: -0.0057510309 | H17: -0.063120628 | I17: -0.0057510309
A18: Population | B18: 3.83059e-09 | C18: 1.1981497e-09 | D18: 3.197088 | E18: 0.0025716043 | F18: 1.4158781e-09 | G18: 6.245302e-09 | H18: 1.4158781e-09 | I18: 6.245302e-09
A19: OldTollMileRatio | B19: 0.29938505 | C19: 0.072537536 | D19: 4.1273121 | E19: 0.00016083649 | F19: 0.15319526 | G19: 0.44557484 | H19: 0.15319526 | I19: 0.44557484
A20: Workers Who Live OOS (JTW) | B20: 0.84588027 | C20: 0.28925903 | D20: 2.9243003 | E20: 0.0054382243 | F20: 0.26291703 | G20: 1.4288435 | H20: 0.26291703 | I20: 1.4288435
A21: N1^4 | B21: 89876.772 | C21: 52682.513 | D21: 1.7060077 | E21: 0.095057047 | F21: -16297.851 | G21: 196051.4 | H21: -16297.851 | I21: 196051.4

Sheet L-NL
A1: SUMMARY OUTPUT
A3: Regression Statistics
A4: Multiple R | B4: 0.81513466
A5: R Square | B5: 0.66444451
A6: Adjusted R Square | B6: 0.63393947
A7: Standard Error | B7: 0.039294496
A8: Observations | B8: 49
A10: ANOVA
B11: df | C11: SS | D11: MS | E11: F | F11: Significance F
A12: Regression | B12: 4 | C12: 0.13452732 | D12: 0.033631831 | E12: 21.781464 | F12: 5.7601638e-10
A13: Residual | B13: 44 | C13: 0.067938527 | D13: 0.0015440574
A14: Total | B14: 48 | C14: 0.20246585
B16: Coefficients | C16: Standard Error | D16: t Stat | E16: P-value | F16: Lower 95% | G16: Upper 95% | H16: Lower 95.0% | I16: Upper 95.0%
A17: Intercept | B17: -0.029467612 | C17: 0.01248993 | D17: -2.3593095 | E17: 0.022812108 | F17: -0.054639411 | G17: -0.0042958121 | H17: -0.054639411 | I17: -0.0042958121
A18: Population | B18: 3.4071093e-09 | C18: 1.0514135e-09 | D18: 3.2405037 | E18: 0.0022757171 | F18: 1.2881248e-09 | G18: 5.5260939e-09 | H18: 1.2881248e-09 | I18: 5.5260939e-09
A19: OldTollMileRatio | B19: 0.27608133 | C19: 0.063653934 | D19: 4.3372234 | E19: 8.2940326e-05 | F19: 0.14779526 | G19: 0.4043674 | H19: 0.14779526 | I19: 0.4043674
A20: Workers Who Live OOS (JTW) | B20: 0.74888358 | C20: 0.25383375 | D20: 2.9502916 | E20: 0.0050711707 | F20: 0.23731528 | G20: 1.2604519 | H20: 0.23731528 | I20: 1.2604519
A21: N1^4 | B21: 73400.249 | C21: 46230.537 | D21: 1.5877006 | E21: 0.11951517 | F21: -19771.272 | G21: 166571.77 | H21: -19771.272 | I21: 166571.77

Sheet Sheet4
A1: 0 | B1: 0
A2: 3.5693265 | B2: 1.368132
A3: 0 | B3: 0
A4: -0.12784769 | B4: 2.7596126
A5: 0 | B5: 0
A6: 2.5288976 | B6: 2.0808406
A7: 0 | B7: 0
A8: 3.5294084 | B8: -1.191604
A9: 0 | B9: 0
A10: -3.5779789 | B10: 1.2779655
A11: 0 | B11: 0
A12: 3.8974224 | B12: -0.014484166
... A18: -2.4145428 | B18: -0.2238202

Sheet Sheet5
A1: 0 | B1: 0
A2: 3.5693265 | B2: 1.368132
A3: 0 | B3: 0
A4: -0.12784769 | B4: 2.7596126
A5: 0 | B5: 0
A6: 2.5288976 | B6: 2.0808406
A7: 0 | B7: 0
A8: 3.5294084 | B8: -1.191604
A9: 0 | B9: 0
A10: -3.5779789 | B10: 1.2779655
A11: 0 | B11: 0
A12: 3.8974224 | B12: -0.014484166
... A18: -2.4145428 | B18: -0.2238202

Sheet Correlate
B1: TollShare | C1: Population | D1: TollMile1963 | E1: ImportedWorkers | F1: ResidentsWhoWorkInState | G1: NeighborTolls | H1: Land | I1: Density | J1: Federal
A2: TollShare | B2: 1
A3: Population | B3: 0.26669007 | C3: 1
A4: TollMile1963 | B4: 0.70652169 | C4: 0.38911354 | D4: 1
A5: ImportedWorkers | B5: 0.48513559 | C5: -0.27094325 | D5: 0.15674437 | E5: 1
A6: ResidentsWhoWorkInState | B6: -0.38005433 | C6: 0.24462457 | D6: -0.11361942 | E6: -0.76487976 | F6: 1
A7: NeighborTolls | B7: 0.61280471 | C7: -0.03359231 | D7: 0.35833907 | E7: 0.54376982 | F7: -0.64353577 | G7: 1
